File: Data/As Grown/YBCO_Gd_0_12182017_resistivity.dat
[Header]
; AC Transport Data File (default extension .dat)
; Copyright 1998, Quantum Design, Inc. All rights reserved.
TITLE,PPMS_MANG
FILEOPENTIME,30382072.64,12/18/2017,4:48 pm
BYAPP,ACTRANSPORT,2.0,1.1
INFO,PPMS AC Transport Option Release 2.2.4. Build 2,APPNAME
INFO,,SAMPLE1_MATERIAL
INFO,,SAMPLE1_COMMENT
INFO,1.0,SAMPLE1_LEAD_SEPARATION
INFO,1.0,SAMPLE1_CROSS_SECTION
INFO,,SAMPLE2_MATERIAL
INFO,,SAMPLE2_COMMENT
INFO,1.0,SAMPLE2_LEAD_SEPARATION
INFO,1.0,SAMPLE2_CROSS_SECTION
DATATYPE,COMMENT,1
DATATYPE,TIME,2
FIELDGROUP,ACResist,2,4,5,6,7,8,9,10,13,14,15,16,53
FIELDGROUP,ACHall,2,4,5,6,7,8,9,10,17,18,19,20,53
FIELDGROUP,ACIVcurve,2,4,5,6,7,8,9,10,53
FIELDGROUP,ACCritCurrent,2,4,5,6,7,8,9,21,22,23,24,53
STARTUPGROUP,All
STARTUPAXIS,X,2
STARTUPAXIS,Y1,3
[Data]
Comment,Time Stamp (sec),Status (code),Temperature (K),Magnetic Field (Oe),Sample Position (deg),Excitation (mA),Frequency (Hz),Volts ch1,Volts ch2,V Std.Dev. ch1,V Std.Dev. ch2,Res. ch1 (ohm-cm),Res. ch2 (ohm-cm),Res. Std.Dev. ch1,Res. Std.Dev. ch2,Hall ch1 (cm^3/coul),Hall ch2 (cm^3/coul),Hall Std.Dev. ch1,Hall Std.Dev. ch2,Crit.Cur. ch1 (mA),Crit.Cur. ch2 (mA),C.Cur. Std.Dev. ch1,C.Cur. Std.Dev. ch2,ACT Status (code),ACT Gain,2nd Harm. ch1 (dB),2nd Harm. ch2 (dB),3rd Harm. ch1 (dB),3rd Harm. ch2 (dB),Quad.Error ch1 (ohm-cm-rad),Quad.Error ch2 (ohm-cm-rad),Drive Signal ch1 (V),Drive Signal ch2 (V),Bridge 1 Resistance (ohms),Bridge 1 Excitation (uA),Bridge 2 Resistance (ohms),Bridge 2 Excitation (uA),Bridge 3 Resistance (ohms),Bridge 3 Excitation (uA),Bridge 4 Resistance (ohms),Bridge 4 Excitation (uA),Signal 1 Vin (V),Signal 2 Vin (V),Digital Inputs (code),Drive 1 Iout (mA),Drive 1 Ipower (watts),Drive 2 Iout (mA),Drive 2 Ipower (watts),Pressure (),Map 20 (),Map 21 (),Map 22 (),Map 23 (),Map 24 (),Map 25 (),Map 26 (),Map 27 (),Map 28 (),Map 29 ()
,30382224.945,4370,299.99375,0,90.0143967,5.15482948090714,173,0.0157186703687149,,2.15231219167226E-6,,3.04931907498231,,0.000417534454613598,,,,,,,,,,0,250,-97.0897716235611,,-85.8807797810395,,-1.18150700409165E-6,,0.0157186707560623,,,,,,,,,,,,,,,,,,,,,,,,,,,
,30382293.14,4370,298.0138,0,90.0143967,5.15482948090714,173,,0.00762559157087143,,1.11218646791615E-6,,1.47931240944884,,0.000215756538693768,,,,,,,,,0,500,,-90.8935873289141,,-80.5969337102699,,7.97994918623064E-8,,0.00762559157451369,,,,,,,,,,,,,,,,,,,,,,,,,,
,30382361.23,4370,295.363,0,90.0143967,5.15482948090714,173,0.0156603266722048,,2.13386333254378E-6,,3.03800074457474,,0.000413955491985741,,,,,,,,,,0,250,-96.8326621335779,,-86.2068839767464,,-1.1811282314734E-6,,0.0156603270607461,,,,,,,,,,,,,,,,,,,,,,,,,,,
,30382431.425,4370,293.1698,0,90.0143967,5.15482948090714,173,,0.00758919893360395,,1.13478383152422E-6,,1.47225247694795,,0.00022014027045582,,,,,,,,,0,500,,-89.437723869095,,-79.9958723549242,,8.78058065860084E-8,,0.00758919893803488,,,,,,,,,,,,,,,,,,,,,,,,,,
,30382503.04,4370,290.7118,0,90.0143967,5.15482948090714,173,0.0155715623822163,,2.12844933859102E-6,,3.02078100031837,,0.000412905205704786,,,,,,,,,,0,250,-95.7862317909275,,-85.923200815218,,-1.15236251115441E-6,,0.0155715627541709,,,,,,,,,,,,,,,,,,,,,,,,,,,
,30382571.525,4370,288.4127,0,90.0143967,5.15482948090714,173,,0.0075498859052498,,1.14521079055173E-6,,1.46462600788124,,0.000222163027132595,,,,,,,,,0,500,,-90.0532766397596,,-79.6613477982651,,9.39275096036806E-8,,0.0075498859103465,,,,,,,,,,,,,,,,,,,,,,,,,,
,30382641.25,4370,286.09305,0,90.0143967,5.15482948090714,173,0.0154870473735643,,2.11426560884814E-6,,3.00438559193415,,0.00041015364845855,,,,,,,,,,0,250,-95.5028630012595,,-85.9567011119246,,-1.13432778873486E-6,,0.0154870477359344,,,,,,,,,,,,,,,,,,,,,,,,,,,
,30382711.74,4370,283.7415,0,90.0143967,5.15482948090714,173,,0.00750726268656068,,1.13597272629162E-6,,1.45635738378562,,0.000220370904222644,,,,,,,,,0,500,,-89.1014952879592,,-79.4303614170386,,9.839723454413E-8,,0.00750726269218575,,,,,,,,,,,,,,,,,,,,,,,,,,
,30382780.745,4370,281.43545,0,90.0143967,5.15482948090714,173,0.0154029656949652,,2.10274554164204E-6,,2.98807424755057,,0.000407918824260071,,,,,,,,,,0,250,-97.2383172569701,,-86.1816016919586,,-1.12320454043099E-6,,0.0154029660522028,,,,,,,,,,,,,,,,,,,,,,,,,,,
,30382850.58,4370,279.1085,0,90.0143967,5.15482948090714,173,,0.00746171161952675,,1.14701931129574E-6,,1.44752077652347,,0.000222513863757022,,,,,,,,,0,500,,-90.3160157493719,,-78.765122762558,,1.06406587009784E-7,,0.00746171162614499,,,,,,,,,,,,,,,,,,,,,,,,,,
,30382920.345,4370,276.7843,0,90.0143967,5.15482948090714,173,0.0153195654593289,,2.09183195255116E-6,,2.9718950995821,,0.000405801652977151,,,,,,,,,,0,250,-96.0472714995802,,-86.0957646235976,,-1.11116447253825E-6,,0.0153195658108522,,,,,,,,,,,,,,,,,,,,,,,,,,,
,30382987,4370,274.5526,0,90.0143967,5.15482948090714,173,,0.00741967618658376,,1.132309268334E-6,,1.43936617928389,,0.000219660214620494,,,,,,,,,0,500,,-91.1301311287301,,-78.6445515579316,,1.17082509797178E-7,,0.00741967619464205,,,,,,,,,,,,,,,,,,,,,,,,,,
,30383056.845,4370,272.2204,0,90.0143967,5.15482948090714,173,0.0152326419968844,,2.08227726035127E-6,,2.95503246721533,,0.000403948098760796,,,,,,,,,,0,250,-95.7503210123645,,-86.2103722418121,,-1.085699370811E-6,,0.0152326423343953,,,,,,,,,,,,,,,,,,,,,,,,,,,
,30383124.375,4370,269.957,0,90.0143967,5.15482948090714,173,,0.00736512192949445,,1.15122451567951E-6,,1.42878301278569,,0.0002233296401462,,,,,,,,,0,500,,-90.8446979315157,,-78.1233079320854,,1.15307556889433E-7,,0.00736512193736816,,,,,,,,,,,,,,,,,,,,,,,,,,
,30383191.025,4370,267.73915,0,90.0143967,5.15482948090714,173,0.0151792642638565,,2.0725807763232E-6,,2.94467750621849,,0.000402067040327407,,,,,,,,,,0,250,-95.2986392672119,,-85.9220723865794,,-1.08076194583416E-6,,0.0151792645994806,,,,,,,,,,,,,,,,,,,,,,,,,,,
,30383258.155,4370,265.49855,0,90.0143967,5.15482948090714,173,,0.00730863897221946,,1.14936231705897E-6,,1.41782569140054,,0.000222968383867704,,,,,,,,,0,500,,-91.80711056884,,-77.7900172888284,,1.20920067643986E-7,,0.00730863898094524,,,,,,,,,,,,,,,,,,,,,,,,,,
,30383327.16,4370,263.2051,0,90.0143967,5.15482948090714,173,0.0151232988237195,,2.08176874474362E-6,,2.93382054575536,,0.000403849441290432,,,,,,,,,,0,250,-95.5642534361439,,-85.750394440653,,-1.07426616336461E-6,,0.0151232991565485,,,,,,,,,,,,,,,,,,,,,,,,,,,
,30383395.285,4370,260.92355,0,90.0143967,5.15482948090714,173,,0.00725369282296864,,1.15852787427667E-6,,1.40716650087963,,0.000224746436409461,,,,,,,,,0,500,,-90.5020398236721,,-77.4421666564107,,1.28928361197164E-7,,0.00725369283296361,,,,,,,,,,,,,,,,,,,,,,,,,,
,30383463.095,4370,258.6714,0,90.0143967,5.15482948090714,173,0.0150391206474788,,2.0621721337794E-6,,2.91749048378479,,0.000400047821393632,,,,,,,,,,0,250,-95.6220100106292,,-86.0981830522569,,-1.04016713937948E-6,,0.0150391209612605,,,,,,,,,,,,,,,,,,,,,,,,,,,
,30383529.84,4370,256.43975,0,90.0143967,5.15482948090714,173,,0.00721187206129271,,1.15677162214501E-6,,1.39905354912833,,0.000224405733681054,,,,,,,,,0,500,,-91.7451224616303,,-77.264105342923,,1.31997693524918E-7,,0.00721187207182999,,,,,,,,,,,,,,,,,,,,,,,,,,
,30383598.93,4370,254.14145,0,90.0143967,5.15482948090714,173,0.0149376342851659,,2.05025370385693E-6,,2.89780273812306,,0.000397735716560389,,,,,,,,,,0,250,-94.0136687273699,,-85.9884799382834,,-1.01970870048296E-6,,0.0149376345887747,,,,,,,,,,,,,,,,,,,,,,,,,,,
,30383665.255,4370,251.93385,0,90.0143967,5.15482948090714,173,,0.00718237495670917,,1.17260712735716E-6,,1.39333130559951,,0.000227477711283649,,,,,,,,,0,500,,-91.3994516844023,,-77.0300089375846,,1.46941137197132E-7,,0.00718237496982098,,,,,,,,,,,,,,,,,,,,,,,,,,
,30383732.705,4370,249.68605,0,90.0143967,5.15482948090714,173,0.0147839217001893,,2.03258671339658E-6,,2.86798341999647,,0.000394308424791656,,,,,,,,,,0,250,-93.6693065925494,,-85.9505039553911,,-9.98072888428675E-7,,0.0147839219940752,,,,,,,,,,,,,,,,,,,,,,,,,,,
,30383798.305,4370,247.4968,0,90.0143967,5.15482948090714,173,,0.00717441671819846,,1.17602145614155E-6,,1.39178745988583,,0.000228140067164587,,,,,,,,,0,500,,-91.2334275194851,,-76.9795966969791,,1.53265099193723E-7,,0.00717441673247897,,,,,,,,,,,,,,,,,,,,,,,,,,
,30383867.135,4370,245.2053,0,90.0143967,5.15482948090714,173,0.0146503155676055,,2.02859181353221E-6,,2.84206463434548,,0.000393533430515973,,,,,,,,,,0,250,-94.0877254649728,,-85.9008714264228,,-9.57002904055581E-7,,0.0146503158402667,,,,,,,,,,,,,,,,,,,,,,,,,,,
,30383935.235,4370,242.93165,0,90.0143967,5.15482948090714,173,,0.00713686764811239,,1.17797161649291E-6,,1.38450318833526,,0.000228518383111441,,,,,,,,,0,500,,-90.6504359767559,,-76.5853814413116,,1.55476304306251E-7,,0.00713686766288525,,,,,,,,,,,,,,,,,,,,,,,,,,
,30384001.89,4370,240.7082,0,90.0143967,5.15482948090714,173,0.0145458719541163,,1.98566707471234E-6,,2.82180320285878,,0.000385206306266917,,,,,,,,,,0,250,-92.7806124503353,,-86.3818041112954,,-9.50525528651943E-7,,0.0145458722250304,,,,,,,,,,,,,,,,,,,,,,,,,,,
,30384068.205,4370,238.5031,0,90.0143967,5.15482948090714,173,,0.00710028902988482,,1.18651971250859E-6,,1.37740717813987,,0.000230176653073969,,,,,,,,,0,500,,-91.3821579066865,,-76.3589277107556,,1.73516937401633E-7,,0.0071002890483797,,,,,,,,,,,,,,,,,,,,,,,,,,
,30384135.4,4370,236.27035,0,90.0143967,5.15482948090714,173,0.0144442334983671,,1.99993750802059E-6,,2.80208595587965,,0.000387974668381586,,,,,,,,,,0,250,-92.8872211224746,,-85.9869036630653,,-9.34490274547758E-7,,0.0144442337620603,,,,,,,,,,,,,,,,,,,,,,,,,,,
,30384201.475,4370,234.0639,0,90.0143967,5.15482948090714,173,,0.00705421432513706,,1.18282159553471E-6,,1.3684689900653,,0.000229459241668853,,,,,,,,,0,500,,-90.8187362231332,,-76.2986073133479,,1.81104747408317E-7,,0.00705421434541645,,,,,,,,,,,,,,,,,,,,,,,,,,
,30384270.365,4370,231.76285,0,90.0143967,5.15482948090714,173,0.0143533263653266,,1.98832660719097E-6,,2.78445052141763,,0.00038572222370951,,,,,,,,,,0,250,-91.8821425370618,,-86.3813264302884,,-8.99710467411547E-7,,0.014353326611305,,,,,,,,,,,,,,,,,,,,,,,,,,,
,30384338.375,4370,229.5006,0,90.0143967,5.15482948090714,173,,0.00701296718432242,,1.18637940685614E-6,,1.36046731761381,,0.000230149430615575,,,,,,,,,0,500,,-90.3848782486369,,-76.1946253276566,,1.85404817351877E-7,,0.00701296720570126,,,,,,,,,,,,,,,,,,,,,,,,,,
,30384408.145,4370,227.17195,0,90.0143967,5.15482948090714,173,0.0142475471646317,,1.979627448366E-6,,2.76392999651043,,0.000384034636473622,,,,,,,,,,0,250,-91.9947683223859,,-85.7704412557861,,-8.77107839767683E-7,,0.0142475474001419,,,,,,,,,,,,,,,,,,,,,,,,,,,
,30384476.165,4370,224.915,0,90.0143967,5.15482948090714,173,,0.00697220948675318,,1.20161409211997E-6,,1.35256059404396,,0.000233104852643337,,,,,,,,,0,500,,-90.1136540874595,,-75.8737641567288,,1.89586555991409E-7,,0.00697220950923796,,,,,,,,,,,,,,,,,,,,,,,,,,
,30384543.07,4370,222.6761,0,90.0143967,5.15482948090714,173,0.0141341325317197,,1.96985350487705E-6,,2.74192824491815,,0.000382138547581986,,,,,,,,,,0,250,-90.6695414800215,,-85.8611429360549,,-8.55826152691551E-7,,0.0141341327577391,,,,,,,,,,,,,,,,,,,,,,,,,,,
,30384610.205,4370,220.44625,0,90.0143967,5.15482948090714,173,,0.00693401391639758,,1.20615732750035E-6,,1.34515090631307,,0.000233986207094311,,,,,,,,,0,500,,-89.2391108127675,,-75.6781920303295,,2.02011251177451E-7,,0.00693401394206666,,,,,,,,,,,,,,,,,,,,,,,,,,
,30384678.155,4370,218.17955,0,90.0143967,5.15482948090714,173,0.0140305150806718,,1.9521410609175E-6,,2.72182708811918,,0.000378702443038055,,,,,,,,,,0,250,-90.34864352618,,-86.006966825616,,-8.31031036375005E-7,,0.0140305152953583,,,,,,,,,,,,,,,,,,,,,,,,,,,
,30384745.555,4370,215.9336,0,90.0143967,5.15482948090714,173,,0.00689639628128999,,1.21008520062809E-6,,1.33785333430423,,0.000234748185483404,,,,,,,,,0,500,,-89.1858088166029,,-75.542872040857,,2.17838194981622E-7,,0.00689639631130163,,,,,,,,,,,,,,,,,,,,,,,,,,
,30384814.69,4370,213.63015,0,90.0143967,5.15482948090714,173,0.0139119659161623,,1.94959510947027E-6,,2.69882927053114,,0.000378208536353763,,,,,,,,,,0,250,-89.7540792424856,,-86.0972711782048,,-8.22253895340707E-7,,0.0139119661281288,,,,,,,,,,,,,,,,,,,,,,,,,,,
,30384881.945,4370,211.39455,0,90.0143967,5.15482948090714,173,,0.00685458483816483,,1.20051580413074E-6,,1.32974219145138,,0.000232891786509944,,,,,,,,,0,500,,-88.6288162277545,,-75.6208109845885,,2.25158322907929E-7,,0.00685458487042292,,,,,,,,,,,,,,,,,,,,,,,,,,
,30384950.345,4370,209.1104,0,90.0143967,5.15482948090714,173,0.0138033532891491,,1.94203571259398E-6,,2.67775908179995,,0.000376742055411065,,,,,,,,,,0,250,-89.1352569490288,,-86.2573512787056,,-8.03519515659486E-7,,0.0138033534931594,,,,,,,,,,,,,,,,,,,,,,,,,,,
,30385018.225,4370,206.85145,0,90.0143967,5.15482948090714,173,,0.00681300858080879,,1.20315735717635E-6,,1.32167667321373,,0.000233404227497293,,,,,,,,,0,500,,-88.4497810174186,,-75.4778436497438,,2.37796263157806E-7,,0.00681300861700932,,,,,,,,,,,,,,,,,,,,,,,,,,
,30385086.85,4370,204.5655,0,90.0143967,5.15482948090714,173,0.0137003450139316,,1.92989039053376E-6,,2.65777610406171,,0.00037438593582193,,,,,,,,,,0,250,-88.1328757738659,,-86.8198307803601,,-7.8952060694929E-7,,0.0137003452123762,,,,,,,,,,,,,,,,,,,,,,,,,,,
,30385152.985,4370,202.36175,0,90.0143967,5.15482948090714,173,,0.00676682237052078,,1.20931838149009E-6,,1.31271685483309,,0.000234599421494499,,,,,,,,,0,500,,-87.769668549402,,-75.3707636355223,,2.40708400701813E-7,,0.00676682240786656,,,,,,,,,,,,,,,,,,,,,,,,,,
,30385220.07,4370,200.12415,0,90.0143967,5.15482948090714,173,0.013595973705611,,1.92377272290125E-6,,2.6375287070479,,0.000373199141316094,,,,,,,,,,0,250,-88.4290602539973,,-86.5023187846652,,-7.65726716011654E-7,,0.0135959738937077,,,,,,,,,,,,,,,,,,,,,,,,,,,
,30385287.92,4370,197.86635,0,90.0143967,5.15482948090714,173,,0.00672352053623451,,1.19258148372835E-6,,1.30431658641143,,0.000231352576637185,,,,,,,,,0,500,,-87.4344773769214,,-75.3421482773937,,2.54793883115026E-7,,0.00672352057834838,,,,,,,,,,,,,,,,,,,,,,,,,,
,30385357.01,4370,195.56035,0,90.0143967,5.15482948090714,173,0.0134819919691894,,1.90940245574325E-6,,2.61541694658577,,0.00037041139649381,,,,,,,,,,0,250,-87.0711903196115,,-86.6454336440958,,-7.52066152879847E-7,,0.0134819921521686,,,,,,,,,,,,,,,,,,,,,,,,,,,
,30385424.565,4370,193.3088,0,90.0143967,5.15482948090714,173,,0.00668047966589604,,1.19820364335513E-6,,1.29596694340784,,0.000232443234624258,,,,,,,,,0,500,,-87.0773008191301,,-75.3184216784989,,2.677136078655E-7,,0.00668047971268864,,,,,,,,,,,,,,,,,,,,,,,,,,
,30385494.4,4370,190.98375,0,90.0143967,5.15482948090714,173,0.0133726023006663,,1.90736986483854E-6,,2.59419602018898,,0.000370017079392516,,,,,,,,,,0,250,-86.8656410961122,,-86.8799398992459,,-7.35145652650386E-7,,0.0133726024769348,,,,,,,,,,,,,,,,,,,,,,,,,,,
,30385562.25,4370,188.7186,0,90.0143967,5.15482948090714,173,,0.00662950361346951,,1.18996684096387E-6,,1.28607792796436,,0.000230845349324789,,,,,,,,,0,500,,-85.9832894407658,,-75.2582702205737,,2.77221306921906E-7,,0.00662950366403055,,,,,,,,,,,,,,,,,,,,,,,,,,
,30385630.04,4370,186.46445,0,90.0143967,5.15482948090714,173,0.0132998510210383,,1.88665174106813E-6,,2.58008271758217,,0.000365997895761483,,,,,,,,,,0,250,-86.1936013647001,,-86.7618821998115,,-7.27845703967354E-7,,0.0132998511947686,,,,,,,,,,,,,,,,,,,,,,,,,,,
,30385697.37,4370,184.22485,0,90.0143967,5.15482948090714,173,,0.00657486200012453,,1.17970241449128E-6,,1.27547781828401,,0.000228854118837153,,,,,,,,,0,500,,-85.9218922143079,,-75.353637422128,,2.85163321185985E-7,,0.0065748620540687,,,,,,,,,,,,,,,,,,,,,,,,,,
,30385764.945,4370,181.9744,0,90.0143967,5.15482948090714,173,0.0131928081683731,,1.88703395641007E-6,,2.55931706060852,,0.000366072035229917,,,,,,,,,,0,250,-85.4533709085427,,-86.583017261771,,-7.15710036518283E-7,,0.0131928083377214,,,,,,,,,,,,,,,,,,,,,,,,,,,
,30385833.29,4370,179.69635,0,90.0143967,5.15482948090714,173,,0.0064935511625814,,1.18204008273842E-6,,1.25970405686078,,0.000229307606396449,,,,,,,,,0,500,,-85.2056377993923,,-75.2597438010487,,2.95983667011449E-7,,0.00649355122142471,,,,,,,,,,,,,,,,,,,,,,,,,,
,30385901.36,4370,177.4235,0,90.0143967,5.15482948090714,173,0.0131416049758177,,1.89680987881319E-6,,2.54938395557272,,0.000367968495412662,,,,,,,,,,0,250,-84.699951061159,,-86.563070064718,,-7.09974543862029E-7,,0.0131416051431119,,,,,,,,,,,,,,,,,,,,,,,,,,,
,30385967.36,4370,175.22365,0,90.0143967,5.15482948090714,173,,0.00644797159487484,,1.16819909541093E-6,,1.2508619242469,,0.000226622548260734,,,,,,,,,0,500,,-84.817559936342,,-75.3260201878005,,3.06979498588719E-7,,0.00644797165861887,,,,,,,,,,,,,,,,,,,,,,,,,,
,30386035.77,4370,172.94145,0,90.0143967,5.15482948090714,173,0.0130256833879446,,1.88178960913052E-6,,2.52689587988363,,0.000365054654755776,,,,,,,,,,0,250,-84.3906650897409,,-86.9976988174764,,-6.88686978738064E-7,,0.013025683546758,,,,,,,,,,,,,,,,,,,,,,,,,,,
,30386104.235,4370,170.66885,0,90.0143967,5.15482948090714,173,,0.0064023879930423,,1.17554691431173E-6,,1.24201900920094,,0.000228047972010222,,,,,,,,,0,500,,-83.9891847009774,,-75.1944100210327,,3.20385177090119E-7,,0.0064023880629696,,,,,,,,,,,,,,,,,,,,,,,,,,
,30386174.01,4370,168.33285,0,90.0143967,5.15482948090714,173,0.0129055158442517,,1.8499482955002E-6,,2.50358411596012,,0.000358877643707705,,,,,,,,,,0,250,-83.8019766155854,,-88.1089452154258,,-6.48097534795978E-7,,0.0129055159862062,,,,,,,,,,,,,,,,,,,,,,,,,,,
,30386242.355,4370,166.0578,0,90.0143967,5.15482948090714,173,,0.00635517012338411,,1.16601609950553E-6,,1.23285905725571,,0.000226199057536466,,,,,,,,,0,500,,-83.279832043749,,-75.2462652194733,,3.28848120994614E-7,,0.0063551701976018,,,,,,,,,,,,,,,,,,,,,,,,,,
,30386309.28,4370,163.83185,0,90.0143967,5.15482948090714,173,0.0127863205788352,,1.84484810443282E-6,,2.48046096914728,,0.000357888232137511,,,,,,,,,,0,250,-83.1901447414483,,-88.533753336587,,-6.370753374603E-7,,0.0127863207172811,,,,,,,,,,,,,,,,,,,,,,,,,,,
,30386376.36,4370,161.5956,0,90.0143967,5.15482948090714,173,,0.00630948991529943,,1.16698762236932E-6,,1.22399740157015,,0.000226387523880943,,,,,,,,,0,500,,-83.0393777138009,,-75.3390411042953,,3.44455602862375E-7,,0.00630948999731875,,,,,,,,,,,,,,,,,,,,,,,,,,
,30386444.39,4370,159.3336,0,90.0143967,5.15482948090714,173,0.0126652494471526,,1.84848372098941E-6,,2.45697391697146,,0.000358593508818277,,,,,,,,,,0,250,-82.3351922831532,,-88.7661685202972,,-6.30583718132565E-7,,0.012665249584088,,,,,,,,,,,,,,,,,,,,,,,,,,,
,30386511.905,4370,157.07805,0,90.0143967,5.15482948090714,173,,0.00626261115035316,,1.15919280728981E-6,,1.21490323401632,,0.000224875381347408,,,,,,,,,0,500,,-82.3526433593368,,-75.4696812436544,,3.55192283525673E-7,,0.00626261123821807,,,,,,,,,,,,,,,,,,,,,,,,,,
,30386580.145,4370,154.80675,0,90.0143967,5.15482948090714,173,0.012542273707583,,1.86068327443965E-6,,2.433117383789,,0.000360960132099498,,,,,,,,,,0,250,-82.1354341713276,,-88.3870598506877,,-6.08298803626577E-7,,0.0125422738362602,,,,,,,,,,,,,,,,,,,,,,,,,,,
,30386646.5,4370,152.59325,0,90.0143967,5.15482948090714,173,,0.0062147258248687,,1.14973719980138E-6,,1.20561380061172,,0.00022304105657642,,,,,,,,,0,500,,-81.7111043682413,,-75.5675245512416,,3.64926427019598E-7,,0.00621472591833015,,,,,,,,,,,,,,,,,,,,,,,,,,
,30386715.04,4370,150.3105,0,90.0143967,5.15482948090714,173,0.0124179625432686,,1.88017604471319E-6,,2.40900178765691,,0.000364741590407365,,,,,,,,,,0,250,-80.9883711881278,,-88.849711190908,,-5.93812663729983E-7,,0.0124179626671176,,,,,,,,,,,,,,,,,,,,,,,,,,,
,30386783.465,4370,148.03485,0,90.0143967,5.15482948090714,173,,0.00616674791455296,,1.13871922626707E-6,,1.1963064065468,,0.000220903643340946,,,,,,,,,0,500,,-81.0943500370372,,-75.8170148265772,,3.89896403540239E-7,,0.00616674802207219,,,,,,,,,,,,,,,,,,,,,,,,,,
,30386853.51,4370,145.69965,0,90.0143967,5.15482948090714,173,0.0122865404233579,,1.86552782861787E-6,,2.38350671147685,,0.000361899925058912,,,,,,,,,,0,250,-80.6107610669455,,-88.5028603680957,,-5.68434408669503E-7,,0.0122865405380609,,,,,,,,,,,,,,,,,,,,,,,,,,,
,30386921.765,4370,143.4238,0,90.0143967,5.15482948090714,173,,0.00611708383404996,,1.14205917198039E-6,,1.18667190691916,,0.000221551567260119,,,,,,,,,0,500,,-80.4192800323159,,-75.9036322131299,,3.97284588914703E-7,,0.00611708394658892,,,,,,,,,,,,,,,,,,,,,,,,,,
,30386990.54,4370,141.13245,0,90.0143967,5.15482948090714,173,0.0121541672830986,,1.8692429112732E-6,,2.35782714460445,,0.000362620616774487,,,,,,,,,,0,250,-80.0168836530386,,-88.8913386991213,,-5.50824713722864E-7,,0.0121541673919779,,,,,,,,,,,,,,,,,,,,,,,,,,,
,30387058.96,4370,138.84615,0,90.0143967,5.15482948090714,173,,0.00606697627305375,,1.12787246641913E-6,,1.17695137523466,,0.000218799442076651,,,,,,,,,0,500,,-79.807269814188,,-76.0799307535405,,4.12807812636504E-7,,0.00606697639556258,,,,,,,,,,,,,,,,,,,,,,,,,,
,30387127.35,4370,136.57425,0,90.0143967,5.15482948090714,173,0.0120200221961592,,1.88780158132893E-6,,2.33180383247332,,0.000366220864718341,,,,,,,,,,0,250,-79.0419507538576,,-89.2301241095895,,-5.46449588783979E-7,,0.0120200223045116,,,,,,,,,,,,,,,,,,,,,,,,,,,
,30387194.405,4370,134.3381,0,90.0143967,5.15482948090714,173,,0.00601678584774075,,1.12483251644242E-6,,1.16721476862258,,0.000218209710396001,,,,,,,,,0,500,,-79.1898152526949,,-76.4557923871806,,4.21241141307028E-7,,0.00601678597637034,,,,,,,,,,,,,,,,,,,,,,,,,,
,30387261.97,4370,132.08895,0,90.0143967,5.15482948090714,173,0.0118844381610732,,1.88742663526449E-6,,2.30550137477701,,0.000366148117960339,,,,,,,,,,0,250,-78.737760160985,,-88.670573426402,,-5.22603427912038E-7,,0.011884438261306,,,,,,,,,,,,,,,,,,,,,,,,,,,
,30387327.13,4370,129.92195,0,90.0143967,5.15482948090714,173,,0.0059651358519382,,1.11183801317356E-6,,1.15719501530809,,0.000215688864082582,,,,,,,,,0,500,,-78.759288039511,,-76.8237652802597,,4.41004456325741E-7,,0.00596513599414144,,,,,,,,,,,,,,,,,,,,,,,,,,
,30387397.395,4370,127.5722,0,90.0143967,5.15482948090714,173,0.0117445340988546,,1.91986804936728E-6,,2.27836086024199,,0.000372441524708722,,,,,,,,,,0,250,-77.8942389752118,,-89.3310311082869,,-4.93875232899674E-7,,0.0117445341894368,,,,,,,,,,,,,,,,,,,,,,,,,,,
,30387464.475,4370,125.3399,0,90.0143967,5.15482948090714,173,,0.00591352820928617,,1.1090926091138E-6,,1.14718347842827,,0.000215156272015737,,,,,,,,,0,500,,-77.9474072652157,,-77.3345882389628,,4.57757600580017E-7,,0.00591352836383593,,,,,,,,,,,,,,,,,,,,,,,,,,
,30387533.085,4370,123.0534,0,90.0143967,5.15482948090714,173,0.0115987567491573,,1.92541772800355E-6,,2.25008096622626,,0.00037351811420032,,,,,,,,,,0,250,-77.4620242632139,,-90.5350887641519,,-4.90567538415972E-7,,0.0115987568396534,,,,,,,,,,,,,,,,,,,,,,,,,,,
,30387601.455,4370,120.7757,0,90.0143967,5.15482948090714,173,,0.00586010262196778,,1.10509850100514E-6,,1.13681927268231,,0.000214381440122531,,,,,,,,,0,500,,-77.3287908151485,,-77.6223160696724,,4.66954876092073E-7,,0.00586010278425655,,,,,,,,,,,,,,,,,,,,,,,,,,
,30387671.895,4370,118.42275,0,90.0143967,5.15482948090714,173,0.0114450643888409,,1.96771777227896E-6,,2.22026561144685,,0.000381724027415032,,,,,,,,,,0,250,-76.4656126054169,,-90.4864238121949,,-4.56320273708041E-7,,0.0114450644681942,,,,,,,,,,,,,,,,,,,,,,,,,,,
,30387737.58,4370,116.2383,0,90.0143967,5.15482948090714,173,,0.00580542805617943,,1.11184321632774E-6,,1.12621277371669,,0.000215689865165839,,,,,,,,,0,500,,-76.7643403096344,,-78.0644518773085,,4.83814344358556E-7,,0.00580542823203945,,,,,,,,,,,,,,,,,,,,,,,,,,
,30387808.345,4370,113.8756,0,90.0143967,5.15482948090714,173,0.011289090974607,,1.99693642031556E-6,,2.19000774837882,,0.000387392236696382,,,,,,,,,,0,250,-75.9443955012312,,-90.5772541715028,,-4.52079317057895E-7,,0.0112890910535683,,,,,,,,,,,,,,,,,,,,,,,,,,,
,30387876.44,4370,111.6066,0,90.0143967,5.15482948090714,173,,0.00574790901915253,,1.11108313301798E-6,,1.11505446666438,,0.000215542411282633,,,,,,,,,0,500,,-76.2192355572962,,-78.7203558165002,,4.97528655137479E-7,,0.00574790920698479,,,,,,,,,,,,,,,,,,,,,,,,,,
,30387946.445,4370,109.2719,0,90.0143967,5.15482948090714,173,0.0111246195060817,,2.03139010620458E-6,,2.15810131818222,,0.000394076007315544,,,,,,,,,,0,250,-75.3668262353465,,-91.345871094492,,-4.26322326469197E-7,,0.0111246195773399,,,,,,,,,,,,,,,,,,,,,,,,,,,
,30388013.36,4370,107.0458,0,90.0143967,5.15482948090714,173,,0.00568868428508877,,1.11757238369937E-6,,1.10356526610612,,0.000216801277795741,,,,,,,,,0,500,,-75.4668012954019,,-79.1103920957064,,5.08768004730685E-7,,0.00568868448354814,,,,,,,,,,,,,,,,,,,,,,,,,,
,30388083.775,4370,104.69065,0,90.0143967,5.15482948090714,173,0.0109520605385859,,2.05335799045423E-6,,2.12462596632428,,0.000398337615407787,,,,,,,,,,0,250,-74.6872237351235,,-92.3586269599656,,-4.04348605618676E-7,,0.0109520606036977,,,,,,,,,,,,,,,,,,,,,,,,,,,
,30388149.67,4370,102.49825,0,90.0143967,5.15482948090714,173,,0.00562946410056682,,1.12267997773643E-6,,1.092076948401,,0.000217792112425751,,,,,,,,,0,500,,-74.7817141912401,,-80.4061297100094,,5.21152832341708E-7,,0.00562946431099651,,,,,,,,,,,,,,,,,,,,,,,,,,
,30388218.38,4370,100.20755,0,90.0143967,5.15482948090714,173,0.0107694579770617,,2.16359219241163E-6,,2.0892022230614,,0.000419722292618188,,,,,,,,,,0,250,-73.610859054148,,-95.9412205485162,,-3.89564668960779E-7,,0.010769458038524,,,,,,,,,,,,,,,,,,,,,,,,,,,
,30388292.57,4370,97.72695,0,90.0143967,5.15482948090714,173,,0.00556297652522996,,1.14041715554628E-6,,1.07917880605573,,0.000221232997890872,,,,,,,,,0,500,,-74.1624398182894,,-81.4549323145535,,5.39333859335494E-7,,0.00556297675329148,,,,,,,,,,,,,,,,,,,,,,,,,,
,30388368.71,4370,95.186,0,90.0143967,5.15482948090714,173,0.010544603189066,,2.18464290395789E-6,,2.04558181837073,,0.000423805969907237,,,,,,,,,,0,250,-73.0283392575961,,-94.0417994324893,,-3.55383264944511E-7,,0.0105446032413065,,,,,,,,,,,,,,,,,,,,,,,,,,,
,30388444.805,4370,92.65905,0,90.0143967,5.15482948090714,173,,0.00548902935680953,,1.16282938918829E-6,,1.0648335532374,,0.000225580811085566,,,,,,,,,0,500,,-73.3868606702135,,-82.9690142153248,,5.58528586742543E-7,,0.00548902960468819,,,,,,,,,,,,,,,,,,,,,,,,,,
,30388524.955,4370,89.9837,0,90.0143967,5.15482948090714,173,0.0102666020832676,,2.28842032191506E-6,,1.99165137007603,,0.000443938063678281,,,,,,,,,,0,250,-71.8759079636582,,-98.5643704194548,,-3.26058434748733E-7,,0.0102666021284332,,,,,,,,,,,,,,,,,,,,,,,,,,,
,30388604.54,4370,87.32615,0,90.0143967,5.15482948090714,173,,0.00538762886804722,,1.19423537933138E-6,,1.04516254179541,,0.000231673348628764,,,,,,,,,0,500,,-72.3686388510098,,-85.7434421740867,,5.82027689566152E-7,,0.00538762914228892,,,,,,,,,,,,,,,,,,,,,,,,,,
,30388683.635,4370,84.7008,0,90.0143967,5.15482948090714,173,0.00976893286581863,,2.40399276002009E-6,,1.89510671874479,,0.000466358288982516,,,,,,,,,,0,250,-70.5397466108203,,-100.256696281415,,-2.66964608711117E-7,,0.00976893289763892,,,,,,,,,,,,,,,,,,,,,,,,,,,
,30388762.64,4370,82.06625,0,90.0143967,5.15482948090714,173,,0.00521526581513393,,1.33104799499154E-6,,1.01172527298659,,0.000258214031671981,,,,,,,,,0,500,,-70.3384944431357,,-89.2287454108307,,6.22661603873658E-7,,0.00521526613937766,,,,,,,,,,,,,,,,,,,,,,,,,,
,30388832.25,4370,79.71475,0,90.0143967,5.15482948090714,173,0.00768274539407497,,2.63678065781234E-6,,1.49039987581134,,0.00051151709970056,,,,,,,,,,0,500,-67.5992599315891,,-74.1338298112543,,2.57348648896529E-6,,0.00768274915393012,,,,,,,,,,,,,,,,,,,,,,,,,,,
,30388895.965,4370,77.5854,0,90.0143967,5.15482948090714,173,,0.00363258848108876,,2.39884130534085E-6,,0.704696661251271,,0.000465358283369059,,,,,,,,,0,1250,,-64.9863707568522,,-62.3296596578002,,-7.5559236751283E-7,,0.00363258916658134,,,,,,,,,,,,,,,,,,,,,,,,,,
,30388960.18,4370,75.44515,0,90.0143967,5.15482948090714,173,0.000673005498755831,,1.70176011610984E-5,,0.130560846003748,,0.00330135060833217,,,,,,,,,,0,5000,-59.253336219898,,-28.1954608064644,,4.97329577835188E-7,,0.000673007101681281,,,,,,,,,,,,,,,,,,,,,,,,,,,
,30389022.835,4370,73.3512,0,90.0143967,5.15482948090714,173,,0.000929848165727561,,1.33432381428736E-5,,0.180383918105513,,0.00258849310839591,,,,,,,,,0,2500,,-64.4882806221895,,-33.3212351408557,,-2.49959661460857E-8,,0.000929848168658263,,,,,,,,,,,,,,,,,,,,,,,,,,
,30389081.265,4370,71.41505,0,90.0143967,5.15482948090714,173,0.000177734610392903,,2.24213882830105E-6,,0.0344792426945228,,0.000434952222939609,,,,,,,,,,0,12500,-45.5418451382988,,-34.7231774710479,,3.33189790479057E-7,,0.00017773733467397,,,,,,,,,,,,,,,,,,,,,,,,,,,
,30389137.44,4370,69.54135,0,90.0143967,5.15482948090714,173,,0.000457765296105591,,2.18329008022641E-5,,0.088804391469966,,0.00423548240763226,,,,,,,,,0,5000,,-55.5922999948304,,-22.8882285078426,,1.23075473589486E-7,,0.000457765440431392,,,,,,,,,,,,,,,,,,,,,,,,,,
,30389193.055,4370,67.68935,0,90.0143967,5.15482948090714,173,0.000136945305339237,,2.00387464345005E-6,,0.0265664091515265,,0.000388728479313389,,,,,,,,,,0,12500,-42.188821879783,,-33.7253272759105,,3.13060322994489E-7,,0.000136948426727811,,,,,,,,,,,,,,,,,,,,,,,,,,,
,30389261.405,4370,65.4089,0,90.0143967,5.15482948090714,173,,0.000183101570732929,,9.20430006409664E-6,,0.0355203946371529,,0.00178556688121069,,,,,,,,,0,12500,,-76.9572253785007,,-22.3366152485803,,7.96797295286519E-8,,0.000183101721966195,,,,,,,,,,,,,,,,,,,,,,,,,,
,30389331.865,4370,63.0509,0,90.0143967,5.15482948090714,173,0.000117238827352976,,1.05857607211576E-6,,0.0227434933668835,,0.000205350080879326,,,,,,,,,,0,12500,-40.857129644095,,-39.746797388283,,3.05972172270473E-7,,0.00011724231016327,,,,,,,,,,,,,,,,,,,,,,,,,,,
,30389399.6,4370,60.799,0,90.0143967,5.15482948090714,173,,0.000133743322797577,,6.32146804042216E-7,,0.0259452474376134,,0.000122631790317205,,,,,,,,,0,12500,,-43.7181964452059,,-53.8950576040123,,7.43883184153368E-8,,0.000133743503257579,,,,,,,,,,,,,,,,,,,,,,,,,,
,30389459.91,4370,58.79605,0,90.0143967,5.15482948090714,173,0.000114724970702755,,9.06729177617538E-7,,0.0222558231585194,,0.000175893880632854,,,,,,,,,,0,12500,-41.0133002565126,,-41.9898301401641,,2.95504579981144E-7,,0.000114728290473321,,,,,,,,,,,,,,,,,,,,,,,,,,,
,30389511.05,4370,57.0886,0,90.0143967,5.15482948090714,173,,0.000121019176044172,,5.69530733158401E-7,,0.0234768539728222,,0.000110484703458235,,,,,,,,,0,12500,,-43.4956652739848,,-66.2552897119958,,7.44608795207546E-8,,0.000121019375867253,,,,,,,,,,,,,,,,,,,,,,,,,,
,30389579.335,4370,54.79795,0,90.0143967,5.15482948090714,173,0.000113162667088998,,8.55619787953976E-7,,0.0219528204254271,,0.000165980585536433,,,,,,,,,,0,25000,-41.3503421945658,,-42.2670185528323,,2.68680901124371E-7,,0.000113165449421027,,,,,,,,,,,,,,,,,,,,,,,,,,,
,30389639.48,4370,52.7989,0,90.0143967,5.15482948090714,173,,0.000106324435373633,,5.09920423219385E-7,,0.0206261793978041,,9.89206678764172E-5,,,,,,,,,0,12500,,-43.3484872419138,,-63.0382467453851,,7.99982540944961E-8,,0.000106324697898999,,,,,,,,,,,,,,,,,,,,,,,,,,
,30389700.32,4370,50.78215,0,90.0143967,5.15482948090714,173,0.000113030829125323,,8.18497255522032E-7,,0.0219271718110788,,0.00015877790854417,,,,,,,,,,0,12500,-41.8218359753623,,-42.6861356088814,,2.94478961863535E-7,,0.000113034175303646,,,,,,,,,,,,,,,,,,,,,,,,,,,
,30389774.36,4370,48.3124,0,90.0143967,5.15482948090714,173,,9.91383312113603E-5,,4.8787202992531E-7,,0.0192321826218917,,9.46438151731646E-5,,,,,,,,,0,25000,,-43.4882222061234,,-55.8749425094679,,5.81503829161784E-8,,9.91384799785312E-5,,,,,,,,,,,,,,,,,,,,,,,,,,
,30389830.115,4370,46.447,0,90.0143967,5.15482948090714,173,0.00011233034128651,,8.14622488544351E-7,,0.0217912821811636,,0.000158026462277274,,,,,,,,,,0,12500,-41.9474546819012,,-42.5211678293583,,2.86055846567174E-7,,0.000112333518470119,,,,,,,,,,,,,,,,,,,,,,,,,,,
,30389882.055,4370,44.71265,0,90.0143967,5.15482948090714,173,,9.28906570162585E-5,,4.87209861376094E-7,,0.0180201225062537,,9.45149061535708E-5,,,,,,,,,0,12500,,-43.0240224682501,,-50.733979377159,,8.17492697650288E-8,,9.28909708060944E-5,,,,,,,,,,,,,,,,,,,,,,,,,,
,30389935.97,4370,42.91275,0,90.0143967,5.15482948090714,173,0.000111913333978863,,7.89335362549079E-7,,0.0217103857464852,,0.000153121250681527,,,,,,,,,,0,12500,-42.20763292971,,-42.7062494558626,,2.79306812861449E-7,,0.0001119163742982,,,,,,,,,,,,,,,,,,,,,,,,,,,
,30389996.4,4370,40.90675,0,90.0143967,5.15482948090714,173,,8.87426958597482E-5,,4.22868751979709E-7,,0.0172154477206376,,8.20332054790168E-5,,,,,,,,,0,12500,,-43.224077193823,,-67.2515765429941,,8.19671422035485E-8,,8.87430260696089E-5,,,,,,,,,,,,,,,,,,,,,,,,,,
,30390058.265,4370,38.83975,0,90.0143967,5.15482948090714,173,0.000111690658315128,,7.84938558972493E-7,,0.0216671882606064,,0.000152268215892584,,,,,,,,,,0,12500,-42.1728698061089,,-42.834861817439,,2.82417527908916E-7,,0.000111693772929367,,,,,,,,,,,,,,,,,,,,,,,,,,,
,30390124.155,4370,36.6542,0,90.0143967,5.15482948090714,173,,8.58647192664385E-5,,4.2224780491592E-7,,0.0166571828786395,,8.19130818855402E-5,,,,,,,,,0,25000,,-43.3936817439176,,-51.4387944498988,,6.02940563435766E-8,,8.58649039284916E-5,,,,,,,,,,,,,,,,,,,,,,,,,,
,30390201.665,4370,34.06185,0,90.0143967,5.15482948090714,173,0.000111252509028104,,7.62223493078863E-7,,0.0215822609822613,,0.000147863068574709,,,,,,,,,,0,25000,-42.3419737102549,,-42.8650126564989,,2.52295016079619E-7,,0.000111255004464668,,,,,,,,,,,,,,,,,,,,,,,,,,,
,30390270.945,4370,31.7584,0,90.0143967,5.15482948090714,173,,8.36216427386183E-5,,4.23806194675689E-7,,0.0162220000582229,,8.22150438255407E-5,,,,,,,,,0,12500,,-43.3057626467048,,-51.5574459236745,,7.94848222379413E-8,,8.36219722669353E-5,,,,,,,,,,,,,,,,,,,,,,,,,,
,30390337.65,4370,29.5361,0,90.0143967,5.15482948090714,173,0.000110979755370963,,7.63705814831451E-7,,0.0215293483784019,,0.00014815069243997,,,,,,,,,,0,25000,-42.5010819255185,,-42.5949283621636,,2.4898239912737E-7,,0.000110982191681486,,,,,,,,,,,,,,,,,,,,,,,,,,,
,30390405.535,4370,27.2699,0,90.0143967,5.15482948090714,173,,8.22516216802248E-5,,4.27525075962294E-7,,0.0159562643383246,,8.29368045382776E-5,,,,,,,,,0,25000,,-42.9051466315103,,-50.9317720574171,,6.11646293946992E-8,,8.2251820060999E-5,,,,,,,,,,,,,,,,,,,,,,,,,,
,30390461.14,4370,25.41,0,90.0143967,5.15482948090714,173,0.000111672965587862,,8.01107783038044E-7,,0.0216637559980799,,0.000155405110349585,,,,,,,,,,0,12500,-42.8138467807628,,-41.8884092424629,,2.73495407878019E-7,,0.000111675886982473,,,,,,,,,,,,,,,,,,,,,,,,,,,
,30390528.505,4370,23.1751,0,90.0143967,5.15482948090714,173,,8.14376329292375E-5,,4.33541377380675E-7,,0.0157983177832445,,8.41035509537777E-5,,,,,,,,,0,12500,,-43.1548679411758,,-49.7360166201761,,8.20733090025801E-8,,8.14379936919632E-5,,,,,,,,,,,,,,,,,,,,,,,,,,
,30390582.295,4370,21.3783,0,90.0143967,5.15482948090714,173,0.000112555428463129,,8.26130653638769E-7,,0.0218349474833026,,0.00016025903079242,,,,,,,,,,0,12500,-43.2346758167788,,-41.2530141195167,,2.82488912219463E-7,,0.000112558520710848,,,,,,,,,,,,,,,,,,,,,,,,,,,
,30390650.915,4370,19.09125,0,90.0143967,5.15482948090714,173,,8.10992048954713E-5,,4.63332954888711E-7,,0.0157326651664046,,8.98828812302904E-5,,,,,,,,,0,12500,,-42.9577189372819,,-47.5293003171338,,8.14110411186916E-8,,8.10995613408127E-5,,,,,,,,,,,,,,,,,,,,,,,,,,
,30390705.835,4370,17.2526,0,90.0143967,5.15482948090714,173,0.000113709914074859,,8.99596890929338E-7,,0.0220589094336125,,0.000174510671479809,,,,,,,,,,0,12500,-43.5795168274436,,-40.0930218472329,,2.82153703659988E-7,,0.000113712967668373,,,,,,,,,,,,,,,,,,,,,,,,,,,
,30390758.075,4370,15.51605,0,90.0143967,5.15482948090714,173,,8.11993314074101E-5,,4.62178399445692E-7,,0.0157520889932382,,8.96588894803816E-5,,,,,,,,,0,12500,,-43.276784697916,,-46.8066842980772,,8.32760619350736E-8,,8.11997039112774E-5,,,,,,,,,,,,,,,,,,,,,,,,,,
,30390811.79,4370,13.7303,0,90.0143967,5.15482948090714,173,0.00011463678429379,,9.70575311436338E-7,,0.0222387156259922,,0.000188279828064199,,,,,,,,,,0,12500,-44.1164816658918,,-39.1185740738028,,2.78173986419514E-7,,0.000114639728358376,,,,,,,,,,,,,,,,,,,,,,,,,,,
,30390879.76,4370,11.462,0,90.0143967,5.15482948090714,173,,8.15188934547558E-5,,4.62069634322147E-7,,0.0158140817437154,,8.96378149416252E-5,,,,,,,,,0,12500,,-43.2615646164603,,-47.001578967837,,8.10210990808741E-8,,8.151924467612E-5,,,,,,,,,,,,,,,,,,,,,,,,,,
,30390942.075,4375,9.62985,0,90.0143967,5.15482948090714,173,0.000115984696684022,,1.02805188039646E-6,,0.0225002009879228,,0.000199429662588003,,,,,,,,,,0,12500,-44.5301146702545,,-38.5295297740585,,2.79298029200607E-7,,0.000115987630098532,,,,,,,,,,,,,,,,,,,,,,,,,,,
,30391019.565,4375,9.21505,0,90.0143967,5.15482948090714,173,,8.18848516804198E-5,,4.78033296338827E-7,,0.0158850750207964,,9.27346690628078E-5,,,,,,,,,0,12500,,-43.1400022253546,,-46.39351326622,,7.8131119096351E-8,,8.18851768332489E-5,,,,,,,,,,,,,,,,,,,,,,,,,,
,30391084.585,4375,8.7685,0,90.0143967,5.15482948090714,173,0.000116375559289534,,1.03488203187331E-6,,0.0225760255375326,,0.000200754822680759,,,,,,,,,,0,12500,-44.9611872195588,,-38.3740862262069,,2.74858766555447E-7,,0.000116378390655443,,,,,,,,,,,,,,,,,,,,,,,,,,,
,30391142.695,4375,8.37825,0,90.0143967,5.15482948090714,173,,8.20812725278291E-5,,4.84131698045658E-7,,0.0159231792596637,,9.39176983365313E-5,,,,,,,,,0,12500,,-43.1857314889366,,-46.026459483785,,7.96001840615226E-8,,8.20816092153724E-5,,,,,,,,,,,,,,,,,,,,,,,,,,
,30391201.22,4375,8.0023,0,90.0143967,5.15482948090714,173,0.000116769670922585,,1.03650589969239E-6,,0.0226524803752567,,0.000201069660928397,,,,,,,,,,0,12500,-45.1653364923432,,-38.3390354658058,,2.80619469913252E-7,,0.000116772612253924,,,,,,,,,,,,,,,,,,,,,,,,,,,
,30391254.21,4375,7.6631,0,90.0143967,5.15482948090714,173,,8.22019384326073E-5,,4.77233758157858E-7,,0.0159465875817423,,9.25795468800332E-5,,,,,,,,,0,12500,,-43.4028834083215,,-46.0103125711667,,8.03435616645035E-8,,8.22022809345769E-5,,,,,,,,,,,,,,,,,,,,,,,,,,
,30391313.03,4375,7.29485,0,90.0143967,5.15482948090714,173,0.000117012147148455,,1.02790698445935E-6,,0.0226995190286444,,0.000199401592040728,,,,,,,,,,0,12500,-45.4360179044195,,-38.4223053612589,,2.80723277577018E-7,,0.000117015084556826,,,,,,,,,,,,,,,,,,,,,,,,,,,
,30391383.79,4375,7.0229,0,90.0143967,5.15482948090714,173,,8.22360053460563E-5,,4.77311056200094E-7,,0.0159531963191792,,9.25945767313586E-5,,,,,,,,,0,12500,,-43.5443761560548,,-45.8031278767313,,7.66829118458808E-8,,8.2236317219387E-5,,,,,,,,,,,,,,,,,,,,,,,,,,
,30391597.51,4370,5.15025,0,90.0143967,5.15482948090714,173,0.000118346712277173,,1.00688398728257E-6,,0.0229584151175613,,0.000195323374102091,,,,,,,,,,0,12500,-45.6696607826142,,-38.67922243358,,2.84196725012818E-7,,0.000118349688876335,,,,,,,,,,,,,,,,,,,,,,,,,,,
,30391692.265,4370,5.52145,0,90.0143967,5.15482948090714,173,,8.26659149412677E-5,,4.89010691132239E-7,,0.0160365957043587,,9.48641887090237E-5,,,,,,,,,0,12500,,-43.5851520891523,,-45.3208084867651,,7.97008963864982E-8,,8.26662500941286E-5,,,,,,,,,,,,,,,,,,,,,,,,,,
,30391754.555,4370,9.75765,0,90.0143967,5.15482948090714,173,0.000115914574134218,,1.0293288116642E-6,,0.0224865977148521,,0.000199677412065141,,,,,,,,,,0,12500,-44.6666669908769,,-38.4539244403123,,2.78015427786547E-7,,0.00011591748242735,,,,,,,,,,,,,,,,,,,,,,,,,,,
,30391824.475,4370,14.3933,0,90.0143967,5.15482948090714,173,,8.12863404018002E-5,,4.72075336297434E-7,,0.015768968115534,,9.15788029270175E-5,,,,,,,,,0,12500,,-43.1520046653513,,-46.4815287527612,,8.46105987838999E-8,,8.12867245287836E-5,,,,,,,,,,,,,,,,,,,,,,,,,,
,30391886.55,4370,18.5492,0,90.0143967,5.15482948090714,173,0.000113236570717035,,8.76547671924449E-7,,0.0219670842081425,,0.000170039595756063,,,,,,,,,,0,12500,-43.4326400572389,,-40.4613760623857,,2.75142535696195E-7,,0.000113239486579578,,,,,,,,,,,,,,,,,,,,,,,,,,,
,30391946.085,4370,22.4795,0,90.0143967,5.15482948090714,173,,8.13011078844136E-5,,4.5337297428444E-7,,0.0157718329014884,,8.79506818628603E-5,,,,,,,,,0,12500,,-42.8045877297825,,-48.9564215864387,,8.60262139135014E-8,,8.13015049003789E-5,,,,,,,,,,,,,,,,,,,,,,,,,,
[...]
,30394142.595,4370,168.94465,0,90.0143967,5.15482948090714,173,0.0129999679686273,,1.87546003738583E-6,,2.52190724670332,,0.000363826758004059,,,,,,,,,,0,250,-83.6820745972762,,-87.4587659959679,,-6.95249769396516E-7,,0.0129999681308021,,,,,,,,,,,,,,,,,,,,,,,,,,,
,30394169.13,4370,170.7241,0,90.0143967,5.15482948090714,173,0.0130461948370965,,1.88309821836381E-6,,2.53087497489662,,0.000365308517535588,,,,,,,,,,0,250,-83.985877309186,,-87.2526965501628,,-7.05045883448211E-7,,0.0130461950032826,,,,,,,,,,,,,,,,,,,,,,,,,,,
,30394195.525,4370,172.4773,0,90.0143967,5.15482948090714,173,0.0130924889625122,,1.89923121741651E-6,,2.53985575069038,,0.000368438215407493,,,,,,,,,,0,250,-83.9733920930608,,-87.1319441683253,,-7.04137437069504E-7,,0.0130924891276843,,,,,,,,,,,,,,,,,,,,,,,,,,,
,30394221.54,4370,174.2159,0,90.0143967,5.15482948090714,173,0.013137758059692,,1.88772271404771E-6,,2.54863767746756,,0.000366205645493713,,,,,,,,,,0,250,-84.2990952083659,,-86.7280843322597,,-7.2010618986701E-7,,0.0131377582318455,,,,,,,,,,,,,,,,,,,,,,,,,,,
,30394249.525,4370,176.07705,0,90.0143967,5.15482948090714,173,0.0131859300663985,,1.90279690083573E-6,,2.55798275103605,,0.000369129940941152,,,,,,,,,,0,250,-84.2905459071488,,-86.7320271828987,,-7.26244339835425E-7,,0.0131859302408596,,,,,,,,,,,,,,,,,,,,,,,,,,,
,30394276.08,4370,177.85305,0,90.0143967,5.15482948090714,173,0.0132316830744467,,1.89519768012286E-6,,2.56685855388233,,0.000367655745974969,,,,,,,,,,0,250,-84.8959061208052,,-86.8813345105383,,-7.3393754459521E-7,,0.0132316832520075,,,,,,,,,,,,,,,,,,,,,,,,,,,
,30394303.32,4370,179.6752,0,90.0143967,5.15482948090714,173,0.0132784503381869,,1.90144748618813E-6,,2.57593111627808,,0.000368868169995553,,,,,,,,,,0,250,-84.9672636996019,,-87.0426822921781,,-7.54733904725613E-7,,0.0132784505252914,,,,,,,,,,,,,,,,,,,,,,,,,,,
,30394330.53,4370,181.48435,0,90.0143967,5.15482948090714,173,0.0133249727835298,,1.91646116407791E-6,,2.58495618557461,,0.000371780727082114,,,,,,,,,,0,250,-84.9622241276645,,-86.7980137546226,,-7.62142912684699E-7,,0.0133249729736596,,,,,,,,,,,,,,,,,,,,,,,,,,,
,30394357.47,4370,183.27635,0,90.0143967,5.15482948090714,173,0.0133705842536315,,1.90312454768989E-6,,2.59380453142033,,0.0003691935155752,,,,,,,,,,0,250,-85.398625685291,,-86.5022810520962,,-7.61093003874214E-7,,0.0133705844425911,,,,,,,,,,,,,,,,,,,,,,,,,,,
,30394384.765,4370,185.0987,0,90.0143967,5.15482948090714,173,0.0134174149514963,,1.91411209657657E-6,,2.60288940015298,,0.000371325030617236,,,,,,,,,,0,250,-85.7841674339604,,-86.8452876078329,,-7.57244581328666E-7,,0.0134174151378969,,,,,,,,,,,,,,,,,,,,,,,,,,,
,30394412.39,4370,186.9435,0,90.0143967,5.15482948090714,173,0.0134640068237311,,1.89736222179736E-6,,2.61192793834443,,0.000368075669415606,,,,,,,,,,0,250,-86.0627751265471,,-87.2164557729154,,-7.74971260150731E-7,,0.0134640070182853,,,,,,,,,,,,,,,,,,,,,,,,,,,
,30394439.38,4370,188.74545,0,90.0143967,5.15482948090714,173,0.0135089625743738,,1.92274455927055E-6,,2.6206490791158,,0.000372999677717912,,,,,,,,,,0,250,-85.893297024957,,-86.6669734432637,,-7.73659518861171E-7,,0.0135089627676247,,,,,,,,,,,,,,,,,,,,,,,,,,,
,30394466.94,4370,190.57195,0,90.0143967,5.15482948090714,173,0.013555724748037,,1.90252905585899E-6,,2.62972065507561,,0.000369078007683539,,,,,,,,,,0,250,-86.7381731878539,,-86.7860165325015,,-7.80612359828771E-7,,0.0135557249440984,,,,,,,,,,,,,,,,,,,,,,,,,,,
,30394493.555,4370,192.345,0,90.0143967,5.15482948090714,173,0.0135997281919142,,1.91561645410407E-6,,2.6382570544688,,0.000371616879318488,,,,,,,,,,0,250,-86.2264784891277,,-86.9292967515835,,-7.84973796962759E-7,,0.0135997283895311,,,,,,,,,,,,,,,,,,,,,,,,,,,
,30394520.25,4370,194.13325,0,90.0143967,5.15482948090714,173,0.0136439633929238,,1.93175189648718E-6,,2.64683841348207,,0.000374747051246837,,,,,,,,,,0,250,-86.7893339660165,,-86.6895460200791,,-7.97134998209136E-7,,0.0136439635960505,,,,,,,,,,,,,,,,,,,,,,,,,,,
,30394547.695,4370,195.95585,0,90.0143967,5.15482948090714,173,0.0136898189569542,,1.93777135249485E-6,,2.65573411319232,,0.000375914789314672,,,,,,,,,,0,250,-87.1616956126276,,-86.625812461804,,-7.93593862738657E-7,,0.0136898191576059,,,,,,,,,,,,,,,,,,,,,,,,,,,
,30394574.5,4370,197.7522,0,90.0143967,5.15482948090714,173,0.0137337962246044,,1.93415038590445E-6,,2.66426543501562,,0.000375212349031128,,,,,,,,,,0,250,-86.9901951841701,,-86.8362118358125,,-8.02494371746837E-7,,0.0137337964291251,,,,,,,,,,,,,,,,,,,,,,,,,,,
,30394600.685,4370,199.49825,0,90.0143967,5.15482948090714,173,0.0137462021978357,,1.93713408987336E-6,,2.66667211821851,,0.000375791168821834,,,,,,,,,,0,250,-87.6292849971368,,-86.553342903624,,-7.97999586163874E-7,,0.0137462023998892,,,,,,,,,,,,,,,,,,,,,,,,,,,
,30394627.46,4370,201.2842,0,90.0143967,5.15482948090714,173,0.013790845314962,,1.96289267607346E-6,,2.67533261097774,,0.000380788166889539,,,,,,,,,,0,250,-87.8460929758104,,-86.393991675133,,-8.19137147219328E-7,,0.0137908455271722,,,,,,,,,,,,,,,,,,,,,,,,,,,
,30394655.225,4370,203.12525,0,90.0143967,5.15482948090714,173,0.0138382974691934,,1.95010373900782E-6,,2.68453803999268,,0.000378307201414292,,,,,,,,,,0,250,-88.1084747791141,,-86.7092049469267,,-8.26192119080033E-7,,0.0138382976843345,,,,,,,,,,,,,,,,,,,,,,,,,,,
,30394682.68,4370,204.95815,0,90.0143967,5.15482948090714,173,0.0139100502821586,,1.95835976429622E-6,,2.69845764918314,,0.000379908820740529,,,,,,,,,,0,250,-88.4550506494837,,-86.5661169590217,,-8.53032075600456E-7,,0.013910050510322,,,,,,,,,,,,,,,,,,,,,,,,,,,
,30394709.29,4370,206.7309,0,90.0143967,5.15482948090714,173,0.0138972662027991,,1.95277431676208E-6,,2.695977615533,,0.000378825279979841,,,,,,,,,,0,250,-88.7338094176065,,-85.8630016041321,,-8.50242049101784E-7,,0.0138972664296809,,,,,,,,,,,,,,,,,,,,,,,,,,,
,30394737.39,4370,208.60565,0,90.0143967,5.15482948090714,173,0.0138955657365329,,1.9335878073189E-6,,2.6956477354196,,0.000375103224260422,,,,,,,,,,0,250,-88.8062779145748,,-86.5015368459435,,-8.41322194613305E-7,,0.0138955659587065,,,,,,,,,,,,,,,,,,,,,,,,,,,
,30394764.425,4370,210.40745,0,90.0143967,5.15482948090714,173,0.0139291124532153,,1.95414632806434E-6,,2.70215559446631,,0.000379091443645282,,,,,,,,,,0,250,-88.6593400991746,,-86.6306855765267,,-8.42206566941298E-7,,0.01392911267532,,,,,,,,,,,,,,,,,,,,,,,,,,,
,30394792.14,4370,212.26835,0,90.0143967,5.15482948090714,173,0.0139630051032019,,1.9487108234161E-6,,2.70873056255932,,0.000378036994230724,,,,,,,,,,0,250,-89.5804242927759,,-86.1654960734465,,-8.5008615024921E-7,,0.0139630053289328,,,,,,,,,,,,,,,,,,,,,,,,,,,
,30394819.035,4370,214.0456,0,90.0143967,5.15482948090714,173,0.0139919485590801,,1.94582646530107E-6,,2.71434541714788,,0.000377477450112794,,,,,,,,,,0,250,-89.9802274524769,,-86.4554612166272,,-8.47242430775564E-7,,0.0139919487828394,,,,,,,,,,,,,,,,,,,,,,,,,,,
,30394845.18,4370,215.78785,0,90.0143967,5.15482948090714,173,0.0140277989886658,,1.95986066137422E-6,,2.72130018276127,,0.000380199993870108,,,,,,,,,,0,250,-89.9723400170029,,-86.4225600084445,,-8.55324279640097E-7,,0.0140277992161315,,,,,,,,,,,,,,,,,,,,,,,,,,,
,30394872.165,4370,217.594,0,90.0143967,5.15482948090714,173,0.01406881992196,,1.95650365524308E-6,,2.72925799481523,,0.00037954875997794,,,,,,,,,,0,250,-89.9174561122711,,-86.0795098816633,,-8.6097879667677E-7,,0.0140688201517711,,,,,,,,,,,,,,,,,,,,,,,,,,,
,30394898.46,4370,219.3459,0,90.0143967,5.15482948090714,173,0.0141067654365041,,1.97023468251757E-6,,2.73661919441653,,0.000382212491245806,,,,,,,,,,0,250,-90.8307103969807,,-85.7907188704589,,-8.66737827933161E-7,,0.0141067656687735,,,,,,,,,,,,,,,,,,,,,,,,,,,
,30394924.79,4370,221.0986,0,90.0143967,5.15482948090714,173,0.0141459752194905,,1.95986840804006E-6,,2.74422565454271,,0.000380201505469146,,,,,,,,,,0,250,-90.5128246925701,,-86.1423841338028,,-8.76657984464252E-7,,0.0141459754564485,,,,,,,,,,,,,,,,,,,,,,,,,,,
,30394951.12,4370,222.85335,0,90.0143967,5.15482948090714,173,0.0141859624225784,,1.97167796114828E-6,,2.75198292957727,,0.000382492483715429,,,,,,,,,,0,250,-90.3643881737621,,-86.2706839382677,,-8.78687053269698E-7,,0.0141859626599635,,,,,,,,,,,,,,,,,,,,,,,,,,,
,30394976.4,4370,224.54165,0,90.0143967,5.15482948090714,173,0.0142220808928308,,1.96132311183864E-6,,2.75898969399717,,0.000380483713986985,,,,,,,,,,0,250,-91.1855371896595,,-86.2818461918131,,-8.94835723035852E-7,,0.0142220811383963,,,,,,,,,,,,,,,,,,,,,,,,,,,
,30395004.415,4370,226.41735,0,90.0143967,5.15482948090714,173,0.0142653636563166,,1.96934212852063E-6,,2.76738628803593,,0.000382039353509904,,,,,,,,,,0,250,-91.4551526341278,,-85.7147988731936,,-8.9744174664277E-7,,0.0142653639025651,,,,,,,,,,,,,,,,,,,,,,,,,,,
,30395031.565,4370,228.19985,0,90.0143967,5.15482948090714,173,0.0143108991575389,,1.97580158185932E-6,,2.77621989971241,,0.000383292448095033,,,,,,,,,,0,250,-91.6178385635172,,-86.2198829501598,,-9.10801351470576E-7,,0.0143108994103664,,,,,,,,,,,,,,,,,,,,,,,,,,,
,30395059.3,4370,230.0668,0,90.0143967,5.15482948090714,173,0.0143527602799778,,1.98009062502163E-6,,2.7843407042828,,0.000384124497263336,,,,,,,,,,0,250,-91.148393646094,,-86.3541290196631,,-9.18737486426681E-7,,0.0143527605364801,,,,,,,,,,,,,,,,,,,,,,,,,,,
,30395086.58,4370,231.89385,0,90.0143967,5.15482948090714,173,0.0143927429799789,,1.99295589748072E-6,,2.79209710638843,,0.000386620278059575,,,,,,,,,,0,250,-92.5142171244333,,-86.0475734456116,,-9.31023770514176E-7,,0.0143927432426558,,,,,,,,,,,,,,,,,,,,,,,,,,,
,30395113.25,4370,233.6678,0,90.0143967,5.15482948090714,173,0.0144339115826594,,2.00135411899121E-6,,2.80008356657492,,0.000388249480727432,,,,,,,,,,0,250,-91.3740265358929,,-85.8150294605145,,-9.35398140480908E-7,,0.0144339118470542,,,,,,,,,,,,,,,,,,,,,,,,,,,
,30395140.805,4370,235.5074,0,90.0143967,5.15482948090714,173,0.014482319019184,,2.00925287350221E-6,,2.80947431695991,,0.000389781790546785,,,,,,,,,,0,250,-92.0041497213585,,-85.7024567123637,,-9.49423685842002E-7,,0.0144823192906565,,,,,,,,,,,,,,,,,,,,,,,,,,,
,30395168.37,4370,237.3435,0,90.0143967,5.15482948090714,173,0.0145202821800879,,2.01665378503812E-6,,2.81683894106804,,0.000391217521600925,,,,,,,,,,0,250,-92.7376859160426,,-86.0017009558177,,-9.44843481673394E-7,,0.0145202824482445,,,,,,,,,,,,,,,,,,,,,,,,,,,
,30395195.825,4370,239.1731,0,90.0143967,5.15482948090714,173,0.014556998014037,,2.00860201576527E-6,,2.82396159138112,,0.000389655534239523,,,,,,,,,,0,250,-92.45647265358,,-86.2702891326686,,-9.56481463578354E-7,,0.0145569982881472,,,,,,,,,,,,,,,,,,,,,,,,,,,
,30395222.46,4370,240.94775,0,90.0143967,5.15482948090714,173,0.0145952994038324,,2.01502901188871E-6,,2.83139183007582,,0.000390902332083542,,,,,,,,,,0,250,-93.0495088645649,,-85.9651549200485,,-9.58013870698119E-7,,0.0145952996781,,,,,,,,,,,,,,,,,,,,,,,,,,,
,30395248.475,4370,242.69055,0,90.0143967,5.15482948090714,173,0.0146348047979844,,2.02619204829877E-6,,2.83905563847599,,0.000393067890465734,,,,,,,,,,0,250,-93.818952317751,,-86.2478589175412,,-9.69183031751658E-7,,0.0146348050779267,,,,,,,,,,,,,,,,,,,,,,,,,,,
,30395275.57,4370,244.4891,0,90.0143967,5.15482948090714,173,0.0146763561981519,,2.01512087477403E-6,,2.84711635984455,,0.000390920159112558,,,,,,,,,,0,250,-93.8228109653145,,-86.2958857678576,,-9.70665110145316E-7,,0.0146763564781561,,,,,,,,,,,,,,,,,,,,,,,,,,,
,30395303.33,4370,246.34635,0,90.0143967,5.15482948090714,173,0.0147229273801403,,2.0059355270419E-6,,2.8561508888117,,0.000389138265691938,,,,,,,,,,0,250,-93.5873465945552,,-86.5645238590596,,-9.84982826275063E-7,,0.0147229276675537,,,,,,,,,,,,,,,,,,,,,,,,,,,
,30395331.24,4370,248.211,0,90.0143967,5.15482948090714,173,0.0147744077126765,,2.03033422866557E-6,,2.86613776363033,,0.000393871456729895,,,,,,,,,,0,250,-94.1379155215957,,-86.124390765064,,-1.00506478115913E-6,,0.0147744080108863,,,,,,,,,,,,,,,,,,,,,,,,,,,
,30395357.275,4370,249.93125,0,90.0143967,5.15482948090714,173,0.0148303809692981,,2.03311996859504E-6,,2.87699623892688,,0.000394411876392233,,,,,,,,,,0,250,-94.0005085869126,,-86.3154259065785,,-1.00527470910035E-6,,0.0148303812665065,,,,,,,,,,,,,,,,,,,,,,,,,,,
,30395384.19,4370,251.73055,0,90.0143967,5.15482948090714,173,0.0148680905205808,,2.03495039596605E-6,,2.88431166531879,,0.000394766970253356,,,,,,,,,,0,250,-93.6331699830875,,-85.9051868804594,,-1.0058638197578E-6,,0.0148680908173829,,,,,,,,,,,,,,,,,,,,,,,,,,,
,30395411.615,4370,253.55265,0,90.0143967,5.15482948090714,173,0.0149043071619146,,2.02070266471062E-6,,2.89133747625402,,0.000392003006996296,,,,,,,,,,0,250,-94.6282533133418,,-85.9317080817953,,-1.01497678922735E-6,,0.0149043074633848,,,,,,,,,,,,,,,,,,,,,,,,,,,
,30395439.175,4370,255.40075,0,90.0143967,5.15482948090714,173,0.0149569157413811,,2.04220686738843E-6,,2.90154322493379,,0.000396174684800886,,,,,,,,,,0,250,-94.8184791606071,,-86.2006675425015,,-1.02149844097153E-6,,0.0149569160456638,,,,,,,,,,,,,,,,,,,,,,,,,,,
,30395466.245,4370,257.19775,0,90.0143967,5.15482948090714,173,0.0150077386173994,,2.05763639465141E-6,,2.91140255806603,,0.000399167915161126,,,,,,,,,,0,250,-94.804749751309,,-85.9317813742604,,-1.04946506425846E-6,,0.0150077389374838,,,,,,,,,,,,,,,,,,,,,,,,,,,
,30395493.39,4370,258.99205,0,90.0143967,5.15482948090714,173,0.0150576407060662,,2.05429636160573E-6,,2.92108326416991,,0.000398519974706234,,,,,,,,,,0,250,-95.3006037714472,,-86.0611122833381,,-1.05390191904119E-6,,0.015057641027793,,,,,,,,,,,,,,,,,,,,,,,,,,,
,30395520.48,4370,260.8092,0,90.0143967,5.15482948090714,173,0.0151056354097687,,2.07700374846589E-6,,2.93039394920559,,0.000402925062012646,,,,,,,,,,0,250,-94.4808073150229,,-85.8846397989732,,-1.0682417214232E-6,,0.01510563573926,,,,,,,,,,,,,,,,,,,,,,,,,,,
,30395546.955,4370,262.57585,0,90.0143967,5.15482948090714,173,0.0151442358022117,,2.07274073892295E-6,,2.93788219425764,,0.000402098069376535,,,,,,,,,,0,250,-95.7519951019276,,-86.0419056188419,,-1.06739952790094E-6,,0.0151442361303451,,,,,,,,,,,,,,,,,,,,,,,,,,,
,30395574.54,4370,264.4144,0,90.0143967,5.15482948090714,173,0.0151839362718788,,2.08337557754833E-6,,2.94558384782635,,0.000404161160927109,,,,,,,,,,0,250,-95.2497633367839,,-85.9193590342896,,-1.09458879144666E-6,,0.0151839366160397,,,,,,,,,,,,,,,,,,,,,,,,,,,
,30395601.49,4370,266.2295,0,90.0143967,5.15482948090714,173,0.0152212140359184,,2.10200139992413E-6,,2.95281551111101,,0.000407774451057195,,,,,,,,,,0,250,-94.2174967371412,,-85.755421335673,,-1.095198665174E-6,,0.015221214379619,,,,,,,,,,,,,,,,,,,,,,,,,,,
,30395629.18,4370,268.06185,0,90.0143967,5.15482948090714,173,0.0152610185731123,,2.08084719578786E-6,,2.96053735339554,,0.00040367067783818,,,,,,,,,,0,250,-94.8365926535502,,-86.20153244538,,-1.09341258099968E-6,,0.0152610189147993,,,,,,,,,,,,,,,,,,,,,,,,,,,
,30395656.44,4370,269.8786,0,90.0143967,5.15482948090714,173,0.0154153537510587,,2.11971948329673E-6,,2.99047745654508,,0.000411211658333709,,,,,,,,,,0,250,-95.0271215303905,,-86.1623979828093,,-1.13251090706726E-6,,0.0154153541139488,,,,,,,,,,,,,,,,,,,,,,,,,,,
,30395683.35,4370,271.6672,0,90.0143967,5.15482948090714,173,0.0154520041488382,,2.11973021079242E-6,,2.99758741518557,,0.000411213742262251,,,,,,,,,,0,250,-95.550511001691,,-86.142679099024,,-1.14421501612458E-6,,0.0154520045183891,,,,,,,,,,,,,,,,,,,,,,,,,,,
,30395709.515,4370,273.4154,0,90.0143967,5.15482948090714,173,0.015489864675224,,2.1275793456191E-6,,3.00493213166991,,0.000412736425804093,,,,,,,,,,0,250,-96.8208694679554,,-85.9547295340796,,-1.15890780959466E-6,,0.0154898650534001,,,,,,,,,,,,,,,,,,,,,,,,,,,
,30395736.32,4370,275.19235,0,90.0143967,5.15482948090714,173,0.0155273364707199,,2.11400373679596E-6,,3.01220143678798,,0.000410102850162145,,,,,,,,,,0,250,-95.8107998925542,,-85.9751528936212,,-1.14597559847234E-6,,0.0155273368396105,,,,,,,,,,,,,,,,,,,,,,,,,,,
,30395763.79,4370,277.04655,0,90.0143967,5.15482948090714,173,0.0155665478208115,,2.13326116985602E-6,,3.01980820525249,,0.00041383866878468,,,,,,,,,,0,250,-96.0998838035312,,-86.3242319085859,,-1.16339068804376E-6,,0.0155665482000415,,,,,,,,,,,,,,,,,,,,,,,,,,,
,30395791.04,4370,278.8428,0,90.0143967,5.15482948090714,173,0.0156061798953665,,2.13426199176427E-6,,3.02749659187945,,0.000414032824939456,,,,,,,,,,0,250,-95.6409023583855,,-86.0893136429985,,-1.16723695503294E-6,,0.0156061802761388,,,,,,,,,,,,,,,,,,,,,,,,,,,
,30395818.07,4370,280.6453,0,90.0143967,5.15482948090714,173,0.0156460906524837,,2.12735303214634E-6,,3.03523904138849,,0.00041269253519465,,,,,,,,,,0,250,-94.97550909509,,-86.4436617503377,,-1.18198894623142E-6,,0.0156460910419454,,,,,,,,,,,,,,,,,,,,,,,,,,,
,30395845.015,4370,282.4526,0,90.0143967,5.15482948090714,173,0.0156858904845034,,2.13791820298749E-6,,3.04295997221166,,0.000414742112340026,,,,,,,,,,0,250,-95.1324863703806,,-86.6043450420122,,-1.18550513820558E-6,,0.0156858908752917,,,,,,,,,,,,,,,,,,,,,,,,,,,
,30395871.355,4370,284.1968,0,90.0143967,5.15482948090714,173,0.015721736211284,,2.15386269667265E-6,,3.04991383022885,,0.000417835242487699,,,,,,,,,,0,250,-95.3774926699353,,-86.1888822101897,,-1.19244738169257E-6,,0.0157217366057611,,,,,,,,,,,,,,,,,,,,,,,,,,,
,30395897.86,4370,285.9626,0,90.0143967,5.15482948090714,173,0.0156995016184862,,2.14082569921775E-6,,3.04560045132168,,0.000415306148495162,,,,,,,,,,0,250,-96.3958469417473,,-86.1518295122513,,-1.19683937628521E-6,,0.0156995020164373,,,,,,,,,,,,,,,,,,,,,,,,,,,
,30395925.915,4370,287.84095,0,90.0143967,5.15482948090714,173,0.0157391887544953,,2.14879803503532E-6,,3.05329951995327,,0.000416852732742603,,,,,,,,,,0,250,-95.9826055097601,,-86.1322643857192,,-1.19654334418686E-6,,0.0157391891512466,,,,,,,,,,,,,,,,,,,,,,,,,,,
,30395952.99,4370,289.64195,0,90.0143967,5.15482948090714,173,0.0157183248919138,,2.15698837135967E-6,,3.04925205453516,,0.000418441602699332,,,,,,,,,,0,250,-95.6356554722582,,-85.9775167569379,,-1.18648928848499E-6,,0.0157183252825435,,,,,,,,,,,,,,,,,,,,,,,,,,,
,30395980.575,4370,291.4725,0,90.0143967,5.15482948090714,173,0.0157387453994834,,2.15539014622968E-6,,3.05321351171396,,0.000418131558985286,,,,,,,,,,0,250,-95.6302549191226,,-85.9369206633883,,-1.20095708444213E-6,,0.0157387457991784,,,,,,,,,,,,,,,,,,,,,,,,,,,
,30396007.1,4370,293.24155,0,90.0143967,5.15482948090714,173,0.0157790741192619,,2.14578876551444E-6,,3.06103704390964,,0.000416268957462022,,,,,,,,,,0,250,-95.7462281548242,,-86.4855479561933,,-1.2022167729602E-6,,0.0157790745187722,,,,,,,,,,,,,,,,,,,,,,,,,,,
,30396033.47,4370,295.0174,0,90.0143967,5.15482948090714,173,0.0158096366593221,,2.1609196020715E-6,,3.06696599530833,,0.000419204243015531,,,,,,,,,,0,250,-96.8213824051025,,-86.1683991498347,,-1.21250866181128E-6,,0.0158096370649163,,,,,,,,,,,,,,,,,,,,,,,,,,,
,30396060.27,4370,296.80305,0,90.0143967,5.15482948090714,173,0.0158388404945678,,2.17656722576388E-6,,3.07263136610405,,0.000422239781770167,,,,,,,,,,0,250,-96.6598258823662,,-86.1459492144319,,-1.22470120582444E-6,,0.0158388409075971,,,,,,,,,,,,,,,,,,,,,,,,,,,
,30396086.715,4370,298.54545,0,90.0143967,5.15482948090714,173,0.0158689774901184,,2.14560915144996E-6,,3.07847776453275,,0.000416234120946804,,,,,,,,,,0,250,-94.8701417608605,,-86.4072474786857,,-1.21251522331438E-6,,0.0158689778942002,,,,,,,,,,,,,,,,,,,,,,,,,,,
,30396114.32,4370,300.1504,0,90.0143967,5.15482948090714,173,0.0158991428653585,,2.1837425870316E-6,,3.08432966852364,,0.000423631759972895,,,,,,,,,,0,250,-96.243325916037,,-86.4205303954558,,-1.22883648183883E-6,,0.0158991432796046,,,,,,,,,,,,,,,,,,,,,,,,,,,
,30396140.635,4373,300.1249,0,90.0143967,5.15482948090714,173,0.0159124507068624,,2.16850944415424E-6,,3.08691131091544,,0.000420676631113401,,,,,,,,,,0,250,-95.7526778769915,,-86.4849527918769,,-1.23147265001295E-6,,0.0159124511225397,,,,,,,,,,,,,,,,,,,,,,,,,,,
,30396153.565,4373,299.9821,0,90.0143967,5.15482948090714,173,,0.00759920215698837,,1.12414102789909E-6,,1.47419303654502,,0.000218075640109539,,,,,,,,,0,500,,-88.7798079018939,,-80.6650037863549,,7.56532107780636E-8,,0.00759920216027334,,,,,,,,,,,,,,,,,,,,,,,,,,