File: Data/As Grown/YBCO_Gd_0_12202017_resistivity.dat
[Header]
; AC Transport Data File (default extension .dat)
; Copyright 1998, Quantum Design, Inc. All rights reserved.
TITLE,PPMS_MANG
FILEOPENTIME,30531877.56,12/20/2017,10:32 am
BYAPP,ACTRANSPORT,2.0,1.1
INFO,PPMS AC Transport Option Release 2.2.4. Build 2,APPNAME
INFO,,SAMPLE1_MATERIAL
INFO,,SAMPLE1_COMMENT
INFO,1.0,SAMPLE1_LEAD_SEPARATION
INFO,1.0,SAMPLE1_CROSS_SECTION
INFO,,SAMPLE2_MATERIAL
INFO,,SAMPLE2_COMMENT
INFO,1.0,SAMPLE2_LEAD_SEPARATION
INFO,1.0,SAMPLE2_CROSS_SECTION
DATATYPE,COMMENT,1
DATATYPE,TIME,2
FIELDGROUP,ACResist,2,4,5,6,7,8,9,10,13,14,15,16,53
FIELDGROUP,ACHall,2,4,5,6,7,8,9,10,17,18,19,20,53
FIELDGROUP,ACIVcurve,2,4,5,6,7,8,9,10,53
FIELDGROUP,ACCritCurrent,2,4,5,6,7,8,9,21,22,23,24,53
STARTUPGROUP,All
STARTUPAXIS,X,2
STARTUPAXIS,Y1,3
[Data]
Comment,Time Stamp (sec),Status (code),Temperature (K),Magnetic Field (Oe),Sample Position (deg),Excitation (mA),Frequency (Hz),Volts ch1,Volts ch2,V Std.Dev. ch1,V Std.Dev. ch2,Res. ch1 (ohm-cm),Res. ch2 (ohm-cm),Res. Std.Dev. ch1,Res. Std.Dev. ch2,Hall ch1 (cm^3/coul),Hall ch2 (cm^3/coul),Hall Std.Dev. ch1,Hall Std.Dev. ch2,Crit.Cur. ch1 (mA),Crit.Cur. ch2 (mA),C.Cur. Std.Dev. ch1,C.Cur. Std.Dev. ch2,ACT Status (code),ACT Gain,2nd Harm. ch1 (dB),2nd Harm. ch2 (dB),3rd Harm. ch1 (dB),3rd Harm. ch2 (dB),Quad.Error ch1 (ohm-cm-rad),Quad.Error ch2 (ohm-cm-rad),Drive Signal ch1 (V),Drive Signal ch2 (V),Bridge 1 Resistance (ohms),Bridge 1 Excitation (uA),Bridge 2 Resistance (ohms),Bridge 2 Excitation (uA),Bridge 3 Resistance (ohms),Bridge 3 Excitation (uA),Bridge 4 Resistance (ohms),Bridge 4 Excitation (uA),Signal 1 Vin (V),Signal 2 Vin (V),Digital Inputs (code),Drive 1 Iout (mA),Drive 1 Ipower (watts),Drive 2 Iout (mA),Drive 2 Ipower (watts),Pressure (),Map 20 (),Map 21 (),Map 22 (),Map 23 (),Map 24 (),Map 25 (),Map 26 (),Map 27 (),Map 28 (),Map 29 ()
,30531891.325,4370,299.99,312.857,90.014,0.102153342753992,173,0.000329641822089015,,5.08941307094924E-8,,3.22852003294113,,0.000498458229058383,,,,,,,,,,0,5000,-81.4312224630918,,-79.6954541804461,,-4.01214237972664E-6,,0.000329641905732235,,,,,,,,,,,,,,,,,,,,,,,,,,,
,30531923.085,4370,299.32205,312.857,90.014,0.102153342753992,173,,0.000150304873037783,,2.23536247596755E-8,,1.47169540303249,,0.000218873306794812,,,,,,,,,0,5000,,-84.3375293398309,,-79.7928512365648,,9.41460408970535E-7,,0.000150304883138483,,,,,,,,,,,,,,,,,,,,,,,,,,
,30531957.845,4374,298.48105,312.857,90.014,0.102153342753992,173,0.000329256434167769,,4.90339753187278E-8,,3.22474367814318,,0.000480239535276222,,,,,,,,,,0,5000,-82.4414354319361,,-80.3191525068192,,-4.24370290349576E-6,,0.00032925652785406,,,,,,,,,,,,,,,,,,,,,,,,,,,
,30531991.225,4374,296.98265,312.857,90.014,0.102153342753992,173,,0.000149878070789749,,2.27421247013671E-8,,1.46751547553774,,0.000222677124009332,,,,,,,,,0,5000,,-86.7205563419605,,-79.5750096172168,,9.27740514677972E-7,,0.00014987808062613,,,,,,,,,,,,,,,,,,,,,,,,,,
,30532024.18,4370,293.57505,312.857,90.014,0.102153342753992,173,0.000327728911875282,,4.99578297706529E-8,,3.2097757734946,,0.000489286666673401,,,,,,,,,,0,5000,-80.8870436850813,,-79.7375106924026,,-4.18698196004167E-6,,0.000327729003498975,,,,,,,,,,,,,,,,,,,,,,,,,,,
,30532063.545,4370,291.74105,312.857,90.014,0.102153342753992,173,,0.000148883035667066,,2.63034756961407E-8,,1.45777052724636,,0.000257547331900952,,,,,,,,,0,5000,,-89.3333427992931,,-76.854047324926,,1.01167727082158E-6,,0.000148883047442019,,,,,,,,,,,,,,,,,,,,,,,,,,
,30532104.295,4370,289.5528,312.857,90.014,0.102153342753992,173,0.000325629263698455,,5.03363508944939E-8,,3.18920182599011,,0.000492992350798185,,,,,,,,,,0,5000,-81.597163927095,,-79.990907353991,,-4.21113387037752E-6,,0.000325629356979852,,,,,,,,,,,,,,,,,,,,,,,,,,,
,30532149.05,4370,287.86555,312.857,90.014,0.102153342753992,173,,0.000148188461478439,,2.22474459482416E-8,,1.45096818195951,,0.000217832956331629,,,,,,,,,0,25000,,-86.3184700669793,,-81.7065384501719,,-1.48369641059662E-6,,0.000148188486923066,,,,,,,,,,,,,,,,,,,,,,,,,,
,30532182.45,4370,285.7811,312.857,90.014,0.102153342753992,173,0.000324091137267969,,5.14339173369891E-8,,3.17413017691341,,0.000503740719124175,,,,,,,,,,0,5000,-81.1657717773621,,-79.8234071155162,,-4.18314148966022E-6,,0.000324091229750206,,,,,,,,,,,,,,,,,,,,,,,,,,,
,30532225.95,4370,283.6011,312.857,90.014,0.102153342753992,173,,0.000147492287489335,,2.2556852248623E-8,,1.44415018310866,,0.000220862236119861,,,,,,,,,0,25000,,-85.3351087908643,,-81.880009270041,,-1.51407646008145E-6,,0.000147492314111704,,,,,,,,,,,,,,,,,,,,,,,,,,
,30532259.89,4370,281.8614,312.857,90.014,0.102153342753992,173,0.000322560943755002,,4.7395916549298E-8,,3.15913632887558,,0.000464191713733247,,,,,,,,,,0,5000,-82.1203555948633,,-80.5129636044618,,-4.25110977117099E-6,,0.000322561039720081,,,,,,,,,,,,,,,,,,,,,,,,,,,
,30532304.875,4370,279.63945,312.857,90.014,0.102153342753992,173,,0.0001467632890265,,2.2385230491674E-8,,1.4370107320761,,0.000219181589940323,,,,,,,,,0,25000,,-85.3997957978259,,-82.1135996920406,,-1.45599407834155E-6,,0.000146763313767781,,,,,,,,,,,,,,,,,,,,,,,,,,
,30532339.055,4370,277.9256,312.857,90.014,0.102153342753992,173,0.000320861942924655,,4.84977450443837E-8,,3.14248847539056,,0.000474981726011812,,,,,,,,,,0,5000,-81.3775681154532,,-80.4184132686602,,-4.23249274335826E-6,,0.000320862038554754,,,,,,,,,,,,,,,,,,,,,,,,,,,
,30532378.235,4370,275.96675,312.857,90.014,0.102153342753992,173,,0.000146160235828803,,2.02963328683745E-8,,1.43110473853656,,0.000198728284507433,,,,,,,,,0,25000,,-88.693190035133,,-82.3404617619626,,-1.49618235329259E-6,,0.000146160262062543,,,,,,,,,,,,,,,,,,,,,,,,,,
,30532411.745,4370,274.2966,312.857,90.014,0.102153342753992,173,0.000319250091872561,,4.78738266349498E-8,,3.12669464704802,,0.00046887000905232,,,,,,,,,,0,5000,-81.7475407822739,,-80.2178328731301,,-4.18253700708551E-6,,0.000319250185730048,,,,,,,,,,,,,,,,,,,,,,,,,,,
,30532449.8,4370,272.3951,312.857,90.014,0.102153342753992,173,,0.000145536308123864,,2.53302152642239E-8,,1.42499432198001,,0.00024801653139657,,,,,,,,,0,5000,,-86.9970492114393,,-77.3413825867845,,9.42494099272179E-7,,0.000145536318578438,,,,,,,,,,,,,,,,,,,,,,,,,,
,30532490.915,4370,270.33725,312.857,90.014,0.102153342753992,173,0.000317445022261332,,4.63326367226029E-8,,3.10900764422995,,0.000453774574544051,,,,,,,,,,0,5000,-82.5725138033674,,-79.2244431830107,,-4.13331638799177E-6,,0.000317445114443974,,,,,,,,,,,,,,,,,,,,,,,,,,,
,30532530.515,4370,268.34575,312.857,90.014,0.102153342753992,173,,0.00014483110833342,,2.14500286787688E-8,,1.41808798348979,,0.000210024096149219,,,,,,,,,0,25000,,-86.0048050475042,,-82.0667285300354,,-1.45975932533685E-6,,0.000144831133534611,,,,,,,,,,,,,,,,,,,,,,,,,,
,30532571.19,4370,266.3233,312.857,90.014,0.102153342753992,173,0.000315710613171819,,4.88268892286386E-8,,3.09201309947563,,0.000478201651442861,,,,,,,,,,0,5000,-80.8945628289719,,-80.5983211770237,,-4.1417346090631E-6,,0.00031571070623882,,,,,,,,,,,,,,,,,,,,,,,,,,,
,30532615.7,4370,264.0924,312.857,90.014,0.102153342753992,173,,0.0001440894083904,,2.06495547955771E-8,,1.41082419829343,,0.000202186176675415,,,,,,,,,0,25000,,-86.3448023491946,,-81.3747437454497,,-1.44344301181168E-6,,0.000144089433158211,,,,,,,,,,,,,,,,,,,,,,,,,,
,30532655.7,4370,262.0977,312.857,90.014,0.102153342753992,173,0.000313784090124274,,4.80717593239059E-8,,3.07313623626026,,0.000470804685324687,,,,,,,,,,0,5000,-81.7328029651219,,-79.6412553380357,,-4.21727642370235E-6,,0.000313784187209598,,,,,,,,,,,,,,,,,,,,,,,,,,,
,30532699.41,4370,259.9022,312.857,90.014,0.102153342753992,173,,0.000143398930988015,,2.21639640468707E-8,,1.40406207183514,,0.000217014001417054,,,,,,,,,0,25000,,-84.7559751590246,,-81.4068780042255,,-1.45226897371437E-6,,0.000143398956180361,,,,,,,,,,,,,,,,,,,,,,,,,,
,30532738.32,4370,257.95625,312.857,90.014,0.102153342753992,173,0.000311727046641381,,4.90295342906606E-8,,3.05298060018485,,0.000480183465815571,,,,,,,,,,0,5000,-81.6284972219672,,-80.1640981569129,,-4.05482489014165E-6,,0.000311727136983463,,,,,,,,,,,,,,,,,,,,,,,,,,,
,30532783.38,4370,255.70635,312.857,90.014,0.102153342753992,173,,0.000142684272780856,,2.15220141249554E-8,,1.39706314758982,,0.000210728253590565,,,,,,,,,0,25000,,-87.9333554320114,,-81.2554259642421,,-1.43068719218133E-6,,0.00014268429735247,,,,,,,,,,,,,,,,,,,,,,,,,,
,30532824.45,4370,253.65525,312.857,90.014,0.102153342753992,173,0.000309742581386725,,4.77827150008034E-8,,3.03353622850036,,0.000467971022892674,,,,,,,,,,0,5000,-81.0610530004749,,-79.9540687610083,,-4.14239985867091E-6,,0.00030974267627739,,,,,,,,,,,,,,,,,,,,,,,,,,,
,30532868.095,4370,251.47135,312.857,90.014,0.102153342753992,173,,0.00014195481637377,,2.05768425609025E-8,,1.38991931425245,,0.000201473587494591,,,,,,,,,0,25000,,-87.039432141929,,-82.4816812684902,,-1.40293122193941E-6,,0.000141954840122644,,,,,,,,,,,,,,,,,,,,,,,,,,
,30532907.96,4370,249.47325,312.857,90.014,0.102153342753992,173,0.000308087845752269,,4.78311727688042E-8,,3.01732273231225,,0.000468444453088148,,,,,,,,,,0,5000,-81.3083182747028,,-79.765148775161,,-4.03973078833763E-6,,0.000308087936482215,,,,,,,,,,,,,,,,,,,,,,,,,,,
,30532951.5,4370,247.29495,312.857,90.014,0.102153342753992,173,,0.000141532075330775,,2.05711228947013E-8,,1.3857792637556,,0.000201417456517908,,,,,,,,,0,25000,,-87.98591539544,,-82.8707528705288,,-1.41937013837682E-6,,0.000141532099712074,,,,,,,,,,,,,,,,,,,,,,,,,,
,30532990.35,4370,245.36175,312.857,90.014,0.102153342753992,173,0.000303924185125198,,4.55596713884908E-8,,2.97652654246187,,0.000446195259091668,,,,,,,,,,0,5000,-82.5359282521729,,-78.6995242425252,,-4.01948243557408E-6,,0.000303924276178432,,,,,,,,,,,,,,,,,,,,,,,,,,,
,30533035.42,4370,243.1032,312.857,90.014,0.102153342753992,173,,0.000141661063668839,,1.93595638846163E-8,,1.38704249099061,,0.000189554790370991,,,,,,,,,0,25000,,-86.6928258249415,,-82.2579794511071,,-1.39926971596564E-6,,0.000141661087342901,,,,,,,,,,,,,,,,,,,,,,,,,,
,30533074.72,4370,241.1351,312.857,90.014,0.102153342753992,173,0.000301100352641085,,4.65505781328022E-8,,2.94885848440964,,0.000455897922506311,,,,,,,,,,0,5000,-81.9562605284914,,-79.585578419053,,-4.02647027045708E-6,,0.000301100444868088,,,,,,,,,,,,,,,,,,,,,,,,,,,
,30533118.05,4370,238.9799,312.857,90.014,0.102153342753992,173,,0.000141093648679624,,1.93323605418144E-8,,1.38148560414736,,0.000189288273536281,,,,,,,,,0,25000,,-86.9127485268903,,-82.4289864023458,,-1.41749372240124E-6,,0.000141093673072062,,,,,,,,,,,,,,,,,,,,,,,,,,
,30533157.03,4370,237.0205,312.857,90.014,0.102153342753992,173,0.000298982029043992,,4.54720810840334E-8,,2.92810319244544,,0.000445334137577784,,,,,,,,,,0,5000,-82.6854278520395,,-80.0335083571211,,-4.0444827486072E-6,,0.000298982122757297,,,,,,,,,,,,,,,,,,,,,,,,,,,
,30533199.735,4370,234.8925,312.857,90.014,0.102153342753992,173,,0.000140435569944978,,2.10894133065899E-8,,1.37504082838253,,0.000206491840159679,,,,,,,,,0,25000,,-88.3865270663261,,-82.1547088204047,,-1.42042361544784E-6,,0.000140435594553133,,,,,,,,,,,,,,,,,,,,,,,,,,
,30533239.005,4370,232.925,312.857,90.014,0.102153342753992,173,0.000296867285064965,,4.51938262185058E-8,,2.90738310449733,,0.00044260763745413,,,,,,,,,,0,5000,-82.9547707090357,,-79.832987306806,,-3.91267262215915E-6,,0.000296867373394319,,,,,,,,,,,,,,,,,,,,,,,,,,,
,30533282.315,4370,230.7571,312.857,90.014,0.102153342753992,173,,0.000139661832931885,,2.04513402099759E-8,,1.36746339026252,,0.000200244071877763,,,,,,,,,0,25000,,-85.3993583588306,,-82.0364637195938,,-1.41350043917975E-6,,0.000139661857435748,,,,,,,,,,,,,,,,,,,,,,,,,,
,30533321.1,4370,228.8325,312.857,90.014,0.102153342753992,173,0.000295229022620799,,4.60367246463497E-8,,2.89133163349005,,0.000450861489566334,,,,,,,,,,0,5000,-81.8336919441658,,-78.7977775046536,,-3.97687341957942E-6,,0.000295229114378993,,,,,,,,,,,,,,,,,,,,,,,,,,,
,30533365.71,4370,226.591,312.857,90.014,0.102153342753992,173,,0.000138814602572816,,2.11155256536157E-8,,1.35916622989283,,0.000206747011999506,,,,,,,,,0,25000,,-87.0253874324239,,-83.0169341420099,,-1.4126656174551E-6,,0.000138814627197122,,,,,,,,,,,,,,,,,,,,,,,,,,
,30533404.2,4370,224.65935,312.857,90.014,0.102153342753992,173,0.00029313727007246,,4.34278990028977E-8,,2.87083704273106,,0.000425310586050427,,,,,,,,,,0,5000,-82.6596946165313,,-79.2964249797425,,-3.8594668493832E-6,,0.000293137357109469,,,,,,,,,,,,,,,,,,,,,,,,,,,
,30533441.54,4370,222.79345,312.857,90.014,0.102153342753992,173,,0.000138217822724102,,2.18257385114125E-8,,1.35332181298618,,0.000213700705627697,,,,,,,,,0,5000,,-85.5534068169806,,-77.6729780039011,,8.16507913908068E-7,,0.000138217830985949,,,,,,,,,,,,,,,,,,,,,,,,,,
,30533479.74,4370,220.89315,312.857,90.014,0.102153342753992,173,0.000291183159031538,,4.5722995734804E-8,,2.85169115277881,,0.000447786277306596,,,,,,,,,,0,5000,-82.4224696523039,,-80.1019174535579,,-3.8782508176172E-6,,0.000291183247507624,,,,,,,,,,,,,,,,,,,,,,,,,,,
,30533524.26,4370,218.6652,312.857,90.014,0.102153342753992,173,,0.000137479832090911,,2.11290219347431E-8,,1.34609449734025,,0.000206878745537742,,,,,,,,,0,25000,,-84.8438290403254,,-82.5698415265336,,-1.38732628399839E-6,,0.000137479856070329,,,,,,,,,,,,,,,,,,,,,,,,,,
,30533565.52,4370,216.6026,312.857,90.014,0.102153342753992,173,0.000288978359844087,,4.35690711815225E-8,,2.83008921740246,,0.000426690493502008,,,,,,,,,,0,5000,-82.239757370545,,-80.176238312512,,-3.95646755412566E-6,,0.000288978452627482,,,,,,,,,,,,,,,,,,,,,,,,,,,
,30533604.195,4370,214.66735,312.857,90.014,0.102153342753992,173,,0.000136797362460211,,2.11690528175158E-8,,1.33941092609021,,0.000207270507616802,,,,,,,,,0,5000,,-86.9791195760612,,-78.3259702699768,,8.51341064901014E-7,,0.000136797371535278,,,,,,,,,,,,,,,,,,,,,,,,,,
,30533643.55,4370,212.7082,312.857,90.014,0.102153342753992,173,0.000287290332375488,,4.24436149065207E-8,,2.8135505464409,,0.000415667377332492,,,,,,,,,,0,5000,-81.6737743236696,,-80.3977897707302,,-3.85982857508158E-6,,0.000287290421200523,,,,,,,,,,,,,,,,,,,,,,,,,,,
,30533687.37,4370,210.50905,312.857,90.014,0.102153342753992,173,,0.000134913472700513,,1.97658559112315E-8,,1.32096166091677,,0.00019353095282308,,,,,,,,,0,25000,,-83.7186279048187,,-81.5352649852205,,-1.41700576812808E-6,,0.000134913498192771,,,,,,,,,,,,,,,,,,,,,,,,,,
,30533725.69,4370,208.6025,312.857,90.014,0.102153342753992,173,0.000286081340365069,,4.45177835971277E-8,,2.80170533958316,,0.000435979758487424,,,,,,,,,,0,5000,-84.8070435702418,,-80.6337357240107,,-3.83197671962305E-6,,0.000286081428282818,,,,,,,,,,,,,,,,,,,,,,,,,,,
,30533769.645,4370,206.4066,312.857,90.014,0.102153342753992,173,,0.000135006993759292,,2.01723487070738E-8,,1.321877526716,,0.000197511023418831,,,,,,,,,0,25000,,-86.7755698973292,,-81.6948977748327,,-1.3999132740944E-6,,0.000135007018623028,,,,,,,,,,,,,,,,,,,,,,,,,,
,30533807.645,4370,204.5109,312.857,90.014,0.102153342753992,173,0.000283906588262401,,4.43233733335938E-8,,2.78039811991395,,0.000434074419082049,,,,,,,,,,0,5000,-83.4805572001608,,-79.6038784317778,,-3.73387436476249E-6,,0.000283906672375629,,,,,,,,,,,,,,,,,,,,,,,,,,,
,30533851.35,4370,202.3133,312.857,90.014,0.102153342753992,173,,0.00013352782223147,,1.91428004952086E-8,,1.3073918073663,,0.000187430124079938,,,,,,,,,0,25000,,-87.0954434425111,,-83.0283195157424,,-1.32930475573514E-6,,0.000133527844898664,,,,,,,,,,,,,,,,,,,,,,,,,,
,30533889.625,4370,200.39465,312.857,90.014,0.102153342753992,173,0.000283487958920602,,4.34455443002486E-8,,2.77629659827926,,0.000425477264048854,,,,,,,,,,0,5000,-84.3015813453529,,-79.5228786109196,,-3.72645595551719E-6,,0.00028348804282365,,,,,,,,,,,,,,,,,,,,,,,,,,,
,30533932.805,4370,198.22915,312.857,90.014,0.102153342753992,173,,0.000132478938956425,,1.7709877389307E-8,,1.29711999566855,,0.000173399878907952,,,,,,,,,0,25000,,-88.5047629487799,,-81.9978046803023,,-1.3539079855053E-6,,0.000132478962656617,,,,,,,,,,,,,,,,,,,,,,,,,,
,30533971.31,4370,196.3213,312.857,90.014,0.102153342753992,173,0.000281273516845326,,4.43931672933611E-8,,2.75460068387815,,0.000434756214752837,,,,,,,,,,0,5000,-81.6746764865319,,-79.7446743958918,,-3.86220615860979E-6,,0.000281273607682251,,,,,,,,,,,,,,,,,,,,,,,,,,,
,30534014.755,4370,194.1454,312.857,90.014,0.102153342753992,173,,0.000131762406996601,,1.86111279834788E-8,,1.29010294988149,,0.000182223955500762,,,,,,,,,0,25000,,-88.8790082648186,,-82.0918731165073,,-1.31926941708879E-6,,0.00013176242962198,,,,,,,,,,,,,,,,,,,,,,,,,,
,30534054.805,4370,192.141,312.857,90.014,0.102153342753992,173,0.000278913107205272,,4.32308392510237E-8,,2.7314748156548,,0.000423371688460323,,,,,,,,,,0,5000,-84.5278311478483,,-80.2697695810989,,-3.69732692389452E-6,,0.000278913191156519,,,,,,,,,,,,,,,,,,,,,,,,,,,
,30534099.45,4370,189.91195,312.857,90.014,0.102153342753992,173,,0.000131069056591184,,1.8784504626577E-8,,1.28331293691295,,0.000183921317272405,,,,,,,,,0,25000,,-86.3168953001464,,-82.0934300832384,,-1.331134173787E-6,,0.000131069079747203,,,,,,,,,,,,,,,,,,,,,,,,,,
,30534138.125,4370,187.9742,312.857,90.014,0.102153342753992,173,0.000276617145441471,,4.09957553422104E-8,,2.70898052522608,,0.000401481508325705,,,,,,,,,,0,5000,-83.8284547030548,,-80.2589888987261,,-3.70133706188085E-6,,0.000276617230273244,,,,,,,,,,,,,,,,,,,,,,,,,,,
,30534181.375,4370,185.80705,312.857,90.014,0.102153342753992,173,,0.000130294603164503,,1.87052196698668E-8,,1.27572869488282,,0.000183144819149971,,,,,,,,,0,25000,,-85.6730563323327,,-81.8134393764118,,-1.27991965591453E-6,,0.000130294624700222,,,,,,,,,,,,,,,,,,,,,,,,,,
,30534220.5,4370,183.85935,312.857,90.014,0.102153342753992,173,0.000274332808210489,,3.95494518764987E-8,,2.68660027724446,,0.000387316188537973,,,,,,,,,,0,5000,-84.4656078655336,,-80.1952143573959,,-3.56353112994066E-6,,0.000274332887497809,,,,,,,,,,,,,,,,,,,,,,,,,,,
,30534264.185,4370,181.66195,312.857,90.014,0.102153342753992,173,,0.000129518685824654,,2.0020655243007E-8,,1.26813013430326,,0.000196024163072338,,,,,,,,,0,25000,,-85.9711353937177,,-80.3424022680556,,-1.27755694883E-6,,0.000129518707409477,,,,,,,,,,,,,,,,,,,,,,,,,,
,30534303.93,4370,179.68315,312.857,90.014,0.102153342753992,173,0.000272078627704011,,4.13285498924841E-8,,2.66451563224857,,0.000404737907236389,,,,,,,,,,0,5000,-84.2970494848654,,-79.3762563756836,,-3.59148154525575E-6,,0.000272078708907226,,,,,,,,,,,,,,,,,,,,,,,,,,,
,30534347.33,4370,177.5033,312.857,90.014,0.102153342753992,173,,0.000128759586893987,,1.8038982488244E-8,,1.26069629348729,,0.000176621217053884,,,,,,,,,0,25000,,-84.3239853895023,,-82.5298025338446,,-1.20589020042855E-6,,0.000128759606238435,,,,,,,,,,,,,,,,,,,,,,,,,,
,30534385.9,4370,175.5866,312.857,90.014,0.102153342753992,173,0.000269768478852391,,4.22264098702434E-8,,2.64188280875942,,0.000413529382211845,,,,,,,,,,0,5000,-83.0794834079222,,-79.4312705734684,,-3.5938292569997E-6,,0.000269768560858092,,,,,,,,,,,,,,,,,,,,,,,,,,,
,30534430.165,4370,173.3794,312.857,90.014,0.102153342753992,173,,0.000127987471715171,,1.8394298152742E-8,,1.25313500209734,,0.00018009992792853,,,,,,,,,0,25000,,-87.3126335116617,,-82.3935761473274,,-1.35457654431243E-6,,0.000127987496271307,,,,,,,,,,,,,,,,,,,,,,,,,,
,30534469.205,4370,171.41895,312.857,90.014,0.102153342753992,173,0.000267514847819972,,4.06206692124489E-8,,2.61980384804617,,0.000397802793878781,,,,,,,,,,0,5000,-83.6642022784317,,-79.6497655024284,,-3.52484670689817E-6,,0.00026751492737231,,,,,,,,,,,,,,,,,,,,,,,,,,,
,30534513.71,4370,169.19225,312.857,90.014,0.102153342753992,173,,0.00012715587124503,,1.87736850647944E-8,,1.24499119325769,,0.000183814310119812,,,,,,,,,0,25000,,-86.239222336364,,-81.3410201514247,,-1.24209327713294E-6,,0.000127155892027272,,,,,,,,,,,,,,,,,,,,,,,,,,
,30534553.25,4370,167.20965,312.857,90.014,0.102153342753992,173,0.00026506178669748,,3.75289792639116E-8,,2.59577122749681,,0.000367524183205684,,,,,,,,,,0,5000,-84.6791017382727,,-80.5992278120854,,-3.42841629697842E-6,,0.000265061862653177,,,,,,,,,,,,,,,,,,,,,,,,,,,
,30534596.955,4370,165.0264,312.857,90.014,0.102153342753992,173,,0.000126378452291271,,1.8850228460161E-8,,1.23737799874268,,0.00018456353461522,,,,,,,,,0,25000,,-83.6380089288872,,-82.1657744299134,,-1.28240404087459E-6,,0.000126378474580606,,,,,,,,,,,,,,,,,,,,,,,,,,
,30534635.46,4370,163.1073,312.857,90.014,0.102153342753992,173,0.000262725878890888,,3.87925798697702E-8,,2.57288652072898,,0.000379897397171045,,,,,,,,,,0,5000,-82.7058657120614,,-80.7491058841037,,-3.37973834863033E-6,,0.000262725953361287,,,,,,,,,,,,,,,,,,,,,,,,,,,
,30534678.935,4370,160.93265,312.857,90.014,0.102153342753992,173,,0.000125577183162176,,1.84464239313141E-8,,1.22953126008208,,0.000180609648765546,,,,,,,,,0,25000,,-89.3783755448476,,-82.2242996451534,,-1.26086225392246E-6,,0.000125577204846453,,,,,,,,,,,,,,,,,,,,,,,,,,
,30534718.47,4370,158.9552,312.857,90.014,0.102153342753992,173,0.000260350257014351,,3.98765241604643E-8,,2.54961290206755,,0.000390511118869489,,,,,,,,,,0,5000,-83.239672003471,,-79.6010603143212,,-3.43557080698411E-6,,0.000260350334667696,,,,,,,,,,,,,,,,,,,,,,,,,,,
,30534762.095,4370,156.7751,312.857,90.014,0.102153342753992,173,,0.000124727419562812,,1.79063157291066E-8,,1.22120964102995,,0.000175321206938134,,,,,,,,,0,25000,,-88.326938066774,,-82.8185731603842,,-1.23423898863897E-6,,0.000124727440482586,,,,,,,,,,,,,,,,,,,,,,,,,,
,30534800.61,4370,154.85505,312.857,90.014,0.102153342753992,173,0.000258017160476807,,4.05983015277151E-8,,2.52675605863347,,0.000397578110392053,,,,,,,,,,0,5000,-83.5056122968421,,-78.2927555618857,,-3.32869052553131E-6,,0.000258017234032895,,,,,,,,,,,,,,,,,,,,,,,,,,,
,30534844.205,4370,152.67085,312.857,90.014,0.102153342753992,173,,0.000123831649421851,,1.89982193643527E-8,,1.21243750905145,,0.000186011812614119,,,,,,,,,0,25000,,-83.9174182083768,,-83.226069503186,,-1.27681889893035E-6,,0.000123831671971893,,,,,,,,,,,,,,,,,,,,,,,,,,
,30534884.095,4370,150.67825,312.857,90.014,0.102153342753992,173,0.000255763995692175,,3.93748717370807E-8,,2.50468244051952,,0.000385595801289811,,,,,,,,,,0,5000,-83.3027311345147,,-79.4334867565853,,-3.23217414715518E-6,,0.000255764065655505,,,,,,,,,,,,,,,,,,,,,,,,,,,
,30534927.735,4370,148.4941,312.857,90.014,0.102153342753992,173,,0.000122885730671669,,1.78924609101971E-8,,1.20317430533272,,0.000175185071914772,,,,,,,,,0,25000,,-87.1057405135892,,-83.4427174297124,,-1.22450298989918E-6,,0.000122885751571301,,,,,,,,,,,,,,,,,,,,,,,,,,
,30534966.31,4370,146.57165,312.857,90.014,0.102153342753992,173,0.000253321183379977,,3.59488411418333E-8,,2.48075106704312,,0.000352043601936651,,,,,,,,,,0,5000,-84.715821666165,,-80.2236558248352,,-3.18701535547525E-6,,0.000253321252057904,,,,,,,,,,,,,,,,,,,,,,,,,,,
,30535009.345,4370,144.4199,312.857,90.014,0.102153342753992,173,,0.000122042644795954,,1.72454996704019E-8,,1.19491814659042,,0.000168850462158622,,,,,,,,,0,25000,,-88.2771165355192,,-81.7666850494203,,-1.21984779610214E-6,,0.000122042665680262,,,,,,,,,,,,,,,,,,,,,,,,,,
,30535048.235,4370,142.4765,312.857,90.014,0.102153342753992,173,0.000250801143236428,,3.87986836928025E-8,,2.4560633026201,,0.000379950409764185,,,,,,,,,,0,5000,-83.0203400982561,,-79.0849962796943,,-3.16940001648963E-6,,0.000250801211839723,,,,,,,,,,,,,,,,,,,,,,,,,,,
,30535091.4,4370,140.31315,312.857,90.014,0.102153342753992,173,,0.000121165257805004,,1.65597473806628E-8,,1.1863261064713,,0.000162136058759172,,,,,,,,,0,25000,,-86.6053633993747,,-82.4514749519922,,-1.19538683715179E-6,,0.00012116527800537,,,,,,,,,,,,,,,,,,,,,,,,,,
,30535131.55,4370,138.30445,312.857,90.014,0.102153342753992,173,0.00024814769915065,,3.63824911064553E-8,,2.43006883718627,,0.00035628754195774,,,,,,,,,,0,5000,-82.9348766267114,,-79.959636180181,,-3.12939425038244E-6,,0.000248147766748158,,,,,,,,,,,,,,,,,,,,,,,,,,,
,30535174.97,4370,136.1318,312.857,90.014,0.102153342753992,173,,0.00012027149518307,,1.79921954198616E-8,,1.1775737268752,,0.000176160885532834,,,,,,,,,0,25000,,-84.7136905740298,,-80.0712862707811,,-1.18441068192438E-6,,0.000120271515161545,,,,,,,,,,,,,,,,,,,,,,,,,,
,30535214.745,4370,134.15455,312.857,90.014,0.102153342753992,173,0.000245578611045204,,3.8432302372054E-8,,2.40490096141318,,0.000376359549304971,,,,,,,,,,0,5000,-82.9797185540693,,-79.0859590801353,,-3.11993630256803E-6,,0.000245578678937624,,,,,,,,,,,,,,,,,,,,,,,,,,,
,30535258.445,4370,131.96045,312.857,90.014,0.102153342753992,173,,0.000119399632949169,,1.84628841790558E-8,,1.16903583446049,,0.000180769145979461,,,,,,,,,0,25000,,-82.8279593608188,,-81.3395940339614,,-1.1674345290314E-6,,0.000119399652500777,,,,,,,,,,,,,,,,,,,,,,,,,,
,30535299.11,4370,129.9299,312.857,90.014,0.102153342753992,173,0.00024270713969228,,3.76012543624105E-8,,2.37677103975224,,0.000368219694059105,,,,,,,,,,0,5000,-82.6271189450546,,-79.1364033594033,,-3.02018583062104E-6,,0.000242707204065488,,,,,,,,,,,,,,,,,,,,,,,,,,,
,30535343.195,4370,127.72385,312.857,90.014,0.102153342753992,173,,0.000118470191885433,,1.70774403612459E-8,,1.1599341138474,,0.000167204103432004,,,,,,,,,0,25000,,-88.6544341279802,,-84.7945091596157,,-1.19194948308148E-6,,0.000118470212426689,,,,,,,,,,,,,,,,,,,,,,,,,,
,30535381.97,4370,125.7797,312.857,90.014,0.102153342753992,173,0.000239939032032057,,3.70395556409004E-8,,2.34965393277408,,0.000362717620329853,,,,,,,,,,0,5000,-85.0234748306499,,-79.2633622025749,,-2.97108367408042E-6,,0.000239939095047826,,,,,,,,,,,,,,,,,,,,,,,,,,,
,30535425.145,4370,123.62325,312.857,90.014,0.102153342753992,173,,0.000117515182636334,,1.73652005520123E-8,,1.150582038443,,0.000170021302637336,,,,,,,,,0,25000,,-86.8722621347314,,-84.0493595724974,,-1.17434712546034E-6,,0.000117515202737414,,,,,,,,,,,,,,,,,,,,,,,,,,
,30535463.805,4370,121.7058,312.857,90.014,0.102153342753992,173,0.000237171263923318,,3.72660576547285E-8,,2.32254037627525,,0.000364934185449211,,,,,,,,,,0,5000,-83.0945256855459,,-79.0906055872074,,-2.85987184513241E-6,,0.000237171322991208,,,,,,,,,,,,,,,,,,,,,,,,,,,
,30535507.29,4370,119.5177,312.857,90.014,0.102153342753992,173,,0.000116567180951472,,1.72062820559468E-8,,1.14129861206936,,0.000168465105513225,,,,,,,,,0,25000,,-85.0623917109498,,-83.4085193601514,,-1.17039945396661E-6,,0.000116567201080014,,,,,,,,,,,,,,,,,,,,,,,,,,
,30535547.07,4370,117.51975,312.857,90.014,0.102153342753992,173,0.000234199287597557,,3.57544232247174E-8,,2.29342660872631,,0.000350129692074225,,,,,,,,,,0,5000,-85.0020764262395,,-78.3521803737894,,-2.87409397653651E-6,,0.000234199348011438,,,,,,,,,,,,,,,,,,,,,,,,,,,
,30535591.875,4370,115.29285,312.857,90.014,0.102153342753992,173,,0.00011558403322879,,1.79513839266131E-8,,1.1316710414353,,0.000175760070522415,,,,,,,,,0,25000,,-85.8745519909356,,-81.459338269841,,-1.16117668532381E-6,,0.00011558405320988,,,,,,,,,,,,,,,,,,,,,,,,,,
,30535630.28,4370,113.36795,312.857,90.014,0.102153342753992,173,0.000231063372981722,,3.48749667544015E-8,,2.26270716602294,,0.000341515909590898,,,,,,,,,,0,5000,-82.7466080885203,,-80.0296640991138,,-2.75341296103047E-6,,0.000231063429181161,,,,,,,,,,,,,,,,,,,,,,,,,,,
,30535673.915,4370,111.18885,312.857,90.014,0.102153342753992,173,,0.000114630945587263,,1.67402330925382E-8,,1.12233786407944,,0.000163901590629987,,,,,,,,,0,25000,,-85.5347975067789,,-81.175206160139,,-1.13160291595492E-6,,0.000114630964721301,,,,,,,,,,,,,,,,,,,,,,,,,,
,30535712.585,4370,109.249,312.857,90.014,0.102153342753992,173,0.000227900976227985,,3.36578700297493E-8,,2.23172859546449,,0.000329595833872757,,,,,,,,,,0,5000,-84.8159147929869,,-79.5121618556478,,-2.74808647947871E-6,,0.000227901032987018,,,,,,,,,,,,,,,,,,,,,,,,,,,
,30535756.17,4370,107.07285,312.857,90.014,0.102153342753992,173,,0.000113622068932404,,1.74421567997912E-8,,1.11245839785043,,0.000170773781715234,,,,,,,,,0,25000,,-86.5162119981751,,-81.5167671070794,,-1.15101111146367E-6,,0.000113622088904182,,,,,,,,,,,,,,,,,,,,,,,,,,
,30535794.89,4370,105.1318,312.857,90.014,0.102153342753992,173,0.000224541123029302,,3.29234916428122E-8,,2.19881607886474,,0.000322402792670607,,,,,,,,,,0,5000,-84.5453055068937,,-79.1744942484255,,-2.67987770295465E-6,,0.000224541177813391,,,,,,,,,,,,,,,,,,,,,,,,,,,
,30535837.6,4370,103.0101,312.857,90.014,0.102153342753992,173,,0.000112605933033711,,1.74540997559844E-8,,1.10250787526162,,0.000170890454696263,,,,,,,,,0,25000,,-82.7870167722346,,-82.1643661694306,,-1.13335586980196E-6,,0.000112605952572233,,,,,,,,,,,,,,,,,,,,,,,,,,
,30535876.345,4370,101.0714,312.857,90.014,0.102153342753992,173,0.00022107608369003,,3.21524809843625E-8,,2.16487352371053,,0.000314851053582566,,,,,,,,,,0,5000,-82.8856282986285,,-80.131246556412,,-2.63465827025689E-6,,0.000221076137470823,,,,,,,,,,,,,,,,,,,,,,,,,,,
,30535921.145,4370,98.81715,312.857,90.014,0.102153342753992,173,,0.000111491055732886,,1.71663369823922E-8,,1.09159046108147,,0.000168072735426312,,,,,,,,,0,25000,,-83.2394012932786,,-81.3301652743138,,-1.07592275531861E-6,,0.000111491073517423,,,,,,,,,,,,,,,,,,,,,,,,,,
,30535962.97,4370,96.71815,312.857,90.014,0.102153342753992,173,0.000217085388977719,,3.37602082693728E-8,,2.12578223093029,,0.000330592648835678,,,,,,,,,,0,5000,-84.3037749349636,,-78.9205466750117,,-2.5593346244671E-6,,0.000217085440660269,,,,,,,,,,,,,,,,,,,,,,,,,,,
,30536009.445,4370,94.4018,312.857,90.014,0.102153342753992,173,,0.000110265288026127,,1.65708710411E-8,,1.07958719671575,,0.000162242330466191,,,,,,,,,0,25000,,-84.5014366380815,,-81.9474332089833,,-1.07556023167189E-6,,0.00011026530599625,,,,,,,,,,,,,,,,,,,,,,,,,,
,30536050.58,4370,92.34385,312.857,90.014,0.102153342753992,173,0.000212608731860052,,3.21998085869769E-8,,2.08193119395313,,0.000315310517247472,,,,,,,,,,0,5000,-83.8675437504466,,-79.1258808965695,,-2.56572885940802E-6,,0.000212608784894835,,,,,,,,,,,,,,,,,,,,,,,,,,,
,30536097.86,4370,89.98635,312.857,90.014,0.102153342753992,173,,0.000108856038555066,,1.57272835311343E-8,,1.0657872513292,,0.000153982597071214,,,,,,,,,0,25000,,-84.2453189766027,,-82.0084729044693,,-1.06766875577208E-6,,0.000108856056491699,,,,,,,,,,,,,,,,,,,,,,,,,,
,30536140.21,4370,87.86685,312.857,90.014,0.102153342753992,173,0.000206140138671974,,3.16610624050138E-8,,2.01856920852635,,0.000310031959394029,,,,,,,,,,0,5000,-84.5966130282883,,-79.0687843840016,,-2.37882943128448E-6,,0.000206140185692169,,,,,,,,,,,,,,,,,,,,,,,,,,,
,30536187.15,4370,85.51265,312.857,90.014,0.102153342753992,173,,0.000106898875124634,,1.6855826651421E-8,,1.04662200538973,,0.000165031449513925,,,,,,,,,0,25000,,-82.4163909336673,,-80.3061534302476,,-1.02518390294197E-6,,0.000106898891964972,,,,,,,,,,,,,,,,,,,,,,,,,,
,30536228.41,4370,83.46405,312.857,90.014,0.102153342753992,173,0.000195666925441726,,3.0346015671117E-8,,1.91598325559626,,0.000297150096350214,,,,,,,,,,0,5000,-84.0142958439933,,-78.7757219925349,,-2.16142885581578E-6,,0.000195666966338105,,,,,,,,,,,,,,,,,,,,,,,,,,,
,30536275.45,4370,81.11125,312.857,90.014,0.102153342753992,173,,0.000103360782485577,,1.4580933988345E-8,,1.01197601814326,,0.000142757753750556,,,,,,,,,0,25000,,-86.5648000562773,,-81.8784669937413,,-1.00402217667599E-6,,0.000103360799190759,,,,,,,,,,,,,,,,,,,,,,,,,,
,30536316.09,4370,78.9963,312.857,90.014,0.102153342753992,173,0.000138125199192447,,2.22089365718221E-8,,1.35241472810671,,0.000217452616895203,,,,,,,,,,0,5000,-88.481435983837,,-77.7559752533007,,-1.59866971471062E-6,,0.000138125230885565,,,,,,,,,,,,,,,,,,,,,,,,,,,
,30536367.16,4370,76.475,312.857,90.014,0.102153342753992,173,,4.14335192725697E-5,,9.27528776552303E-9,,0.405626297017162,,9.08032996363827E-5,,,,,,,,,0,25000,,-84.2820071161979,,-74.4084428246924,,-3.11654673123266E-7,,4.143352328785E-5,,,,,,,,,,,,,,,,,,,,,,,,,,
,30536412.945,4370,74.17275,312.857,90.014,0.102153342753992,173,8.509153168726E-6,,1.00372059770518E-8,,0.0832989016981987,,9.82558508009829E-5,,,,,,,,,,0,125000,-81.6387069260102,,-56.7838757297888,,-8.45825953369337E-7,,8.50929717865356E-6,,,,,,,,,,,,,,,,,,,,,,,,,,,
,30536453.165,4370,72.1801,312.857,90.014,0.102153342753992,173,,8.01768432347496E-6,,1.03956201403338E-7,,0.0784876937899804,,0.00101766021227172,,,,,,,,,0,125000,,-59.6547113057204,,-34.4784079581843,,1.38539812485431E-7,,8.01768842382148E-6,,,,,,,,,,,,,,,,,,,,,,,,,,
,30536495.195,4370,70.0697,312.857,90.014,0.102153342753992,173,5.6052864256312E-6,,9.24653634629696E-9,,0.0548717562936692,,9.05145862235301E-5,,,,,,,,,,0,125000,-64.0651665120309,,-54.8978215592967,,-6.98826501076833E-7,,5.60543565543766E-6,,,,,,,,,,,,,,,,,,,,,,,,,,,
,30536535.41,4370,68.0834,312.857,90.014,0.102153342753992,173,,2.50017581712756E-6,,5.520388240549E-9,,0.0244748246212615,,5.40398364406393E-5,,,,,,,,,0,125000,,-68.5029196776787,,-63.8357851136706,,1.97342878039952E-7,,2.50020249741365E-6,,,,,,,,,,,,,,,,,,,,,,,,,,
,30536580.91,4370,65.8027,312.857,90.014,0.102153342753992,173,5.17909969553097E-6,,5.54150153163015E-9,,0.0506996599160643,,5.42457730726289E-5,,,,,,,,,,0,25000,-75.6425337555857,,-71.0524530361324,,-6.66786922552646E-7,,5.17924673507436E-6,,,,,,,,,,,,,,,,,,,,,,,,,,,
,30536623.91,4370,63.64175,312.857,90.014,0.102153342753992,173,,2.23033306467554E-6,,6.04962571268918E-9,,0.0218332599820888,,5.92201773515364E-5,,,,,,,,,0,125000,,-74.3728285992828,,-60.231528785308,,2.26409257382825E-7,,2.23037243194013E-6,,,,,,,,,,,,,,,,,,,,,,,,,,
,30536666.65,4370,61.5035,312.857,90.014,0.102153342753992,173,4.94635591069766E-6,,7.7072817005409E-9,,0.0484212488866246,,7.54461168953931E-5,,,,,,,,,,0,125000,-71.5153273045903,,-78.6945118275782,,-7.01576467547022E-7,,4.94652635308798E-6,,,,,,,,,,,,,,,,,,,,,,,,,,,
,30536708.235,4370,59.42715,312.857,90.014,0.102153342753992,173,,1.9647982316142E-6,,5.15776836372284E-9,,0.0192338688236278,,5.04898321042552E-5,,,,,,,,,0,125000,,-71.0578800535298,,-69.8782628841995,,1.85053774242795E-7,,1.96482808510155E-6,,,,,,,,,,,,,,,,,,,,,,,,,,
,30536749.26,4370,57.38935,312.857,90.014,0.102153342753992,173,4.84860001784304E-6,,8.43196161102717E-9,,0.0474642824320953,,8.25408798762189E-5,,,,,,,,,,0,125000,-65.1317966997495,,-63.1255499078067,,-5.6462160871175E-7,,4.8487126374538E-6,,,,,,,,,,,,,,,,,,,,,,,,,,,
,30536793,4370,55.21085,312.857,90.014,0.102153342753992,173,,1.63983448078499E-6,,5.94606746286944E-9,,0.0160527149750494,,5.82057083021559E-5,,,,,,,,,0,125000,,-58.829553754455,,-53.2694214411206,,2.14556833733708E-7,,1.63988256458212E-6,,,,,,,,,,,,,,,,,,,,,,,,,,
,30536837.9,4370,52.966,312.857,90.014,0.102153342753992,173,4.78697405467602E-6,,4.93122525301476E-9,,0.0468610045761481,,4.8271801738188E-5,,,,,,,,,,0,25000,-81.618777686537,,-71.9482982434954,,-6.04263057249713E-7,,4.78710470350503E-6,,,,,,,,,,,,,,,,,,,,,,,,,,,
,30536881.25,4370,50.79485,312.857,90.014,0.102153342753992,173,,1.52472296902003E-6,,4.99007714643065E-9,,0.0149258594806457,,4.88465118338116E-5,,,,,,,,,0,125000,,-65.0265230052925,,-67.7180189658247,,2.62871214531317E-7,,1.52480059453599E-6,,,,,,,,,,,,,,,,,,,,,,,,,,
,30536928.84,4370,48.41415,312.857,90.014,0.102153342753992,173,4.73788916104195E-6,,6.932163710284E-9,,0.0463804956643962,,6.78591481196856E-5,,,,,,,,,,0,25000,-67.3342949793059,,-70.5790480062195,,-5.73422629251478E-7,,4.73800803308996E-6,,,,,,,,,,,,,,,,,,,,,,,,,,,
,30536970.925,4370,46.3032,312.857,90.014,0.102153342753992,173,,1.52781051779632E-6,,5.23760200556155E-9,,0.0149560842658791,,5.12701242380784E-5,,,,,,,,,0,125000,,-55.5857349008109,,-61.6492357968199,,2.27767651857641E-7,,1.52786867811288E-6,,,,,,,,,,,,,,,,,,,,,,,,,,
,30537018.835,4370,43.8933,312.857,90.014,0.102153342753992,173,4.70324409578865E-6,,5.62212796143869E-9,,0.046041343243169,,5.50349811786905E-5,,,,,,,,,,0,25000,-66.4759196154368,,-66.6389018924184,,-6.06516398116687E-7,,4.7033780640202E-6,,,,,,,,,,,,,,,,,,,,,,,,,,,
,30537061.525,4370,41.7826,312.857,90.014,0.102153342753992,173,,1.50280376038995E-6,,5.74385051119835E-9,,0.0147112868871098,,5.62256349557342E-5,,,,,,,,,0,125000,,-56.8427238626474,,-59.8795618332484,,2.28197227650978E-7,,1.5028631117005E-6,,,,,,,,,,,,,,,,,,,,,,,,,,
,30537107.11,4370,39.4833,312.857,90.014,0.102153342753992,173,4.68613262188681E-6,,6.05310420158122E-9,,0.0458738331717127,,5.92532239318877E-5,,,,,,,,,,0,25000,-65.7930360975,,-68.9387355322568,,-7.00477748830058E-7,,4.68631196563287E-6,,,,,,,,,,,,,,,,,,,,,,,,,,,
,30537148.515,4370,37.4161,312.857,90.014,0.102153342753992,173,,1.47528328192701E-6,,5.46331116526795E-9,,0.0144418820877402,,5.34794768671957E-5,,,,,,,,,0,125000,,-66.6759286273379,,-69.3152103789763,,2.24074311278782E-7,,1.47534157548635E-6,,,,,,,,,,,,,,,,,,,,,,,,,,
,30537190.76,4370,35.3272,312.857,90.014,0.102153342753992,173,4.65042055467228E-6,,7.34403573104423E-9,,0.0455242355570619,,7.18902515272125E-5,,,,,,,,,,0,125000,-64.7009424167942,,-71.580054316731,,-6.64994236023608E-7,,4.65058343039713E-6,,,,,,,,,,,,,,,,,,,,,,,,,,,
,30537232.805,4370,33.2408,312.857,90.014,0.102153342753992,173,,1.43939179350025E-6,,5.50290020848882E-9,,0.0140905314258539,,5.38663748322098E-5,,,,,,,,,0,125000,,-57.5067326936315,,-60.8453156219372,,2.48883098686646E-7,,1.43946550259931E-6,,,,,,,,,,,,,,,,,,,,,,,,,,
,30537278.165,4370,30.96875,312.857,90.014,0.102153342753992,173,4.61955772887735E-6,,7.48207170855532E-9,,0.0452221088517614,,7.32419755070441E-5,,,,,,,,,,0,25000,-75.3411870954638,,-66.7807656262607,,-5.92305635142857E-7,,4.61968780741627E-6,,,,,,,,,,,,,,,,,,,,,,,,,,,
,30537321.89,4370,28.78015,312.857,90.014,0.102153342753992,173,,1.40980236986773E-6,,5.25795681668766E-9,,0.0138008732640558,,5.14689430521634E-5,,,,,,,,,0,125000,,-57.6530394154004,,-60.0162272023925,,2.31726914422996E-7,,1.40986760853902E-6,,,,,,,,,,,,,,,,,,,,,,,,,,
Incorrect Gain Setting. Readback Voltage Exceeds Maximum!,30537336.545,4370,28.05865,312.857,90.014,,,,,,,,,,,,,,,,,,,1,,,,,,,,,,,,,,,,,,,,,,,,,,,,,,,,,,,
,30537349.295,4370,27.4213,312.857,90.014,0.102153342753992,173,,1.41093352593762E-6,,4.50299820651453E-9,,0.013811946429186,,4.40770553069182E-5,,,,,,,,,0,125000,,-80.7172099055432,,-60.6145607294399,,3.16944373400051E-7,,1.41105547015382E-6,,,,,,,,,,,,,,,,,,,,,,,,,,
,30537379.86,4370,25.9094,312.857,90.014,0.102153342753992,173,,1.40792946742203E-6,,4.93141106580356E-9,,0.0137825389612013,,4.82734163132493E-5,,,,,,,,,0,125000,,-64.0305571380424,,-57.793796881126,,1.75063070442777E-7,,1.40796675145368E-6,,,,,,,,,,,,,,,,,,,,,,,,,,
,30537407.42,4370,24.5312,312.857,90.014,0.102153342753992,173,,1.40877797634486E-6,,5.38435920928122E-9,,0.0137908452238034,,5.27041777755742E-5,,,,,,,,,0,125000,,-67.3023904491047,,-57.8874078487699,,3.15532189871935E-7,,1.40889902126452E-6,,,,,,,,,,,,,,,,,,,,,,,,,,
,30537434.77,4370,23.15235,312.857,90.014,0.102153342753992,173,,1.4112172717518E-6,,5.62770175615727E-9,,0.0138147240867929,,5.50860694544711E-5,,,,,,,,,0,125000,,-57.1032553188092,,-61.0623023652564,,3.17375431899021E-7,,1.41133952329508E-6,,,,,,,,,,,,,,,,,,,,,,,,,,
,30537462.11,4370,21.80015,312.857,90.014,0.102153342753992,173,,1.40778699982036E-6,,4.93055650519331E-9,,0.0137811443107997,,4.82644897014411E-5,,,,,,,,,0,125000,,-63.7431983906508,,-58.8825559690479,,2.09996890808482E-7,,1.40784065367612E-6,,,,,,,,,,,,,,,,,,,,,,,,,,
,30537489.735,4370,20.4329,312.857,90.014,0.102153342753992,173,,1.41764600096515E-6,,5.51793501944347E-9,,0.0138776564998486,,5.40139970748551E-5,,,,,,,,,0,125000,,-60.3618223811839,,-71.5113195443078,,2.24182360201056E-7,,1.41770672298514E-6,,,,,,,,,,,,,,,,,,,,,,,,,,
,30537518.21,4370,19.00755,312.857,90.014,0.102153342753992,173,,1.41001673927673E-6,,5.42827885755395E-9,,0.013802971778951,,5.31357805073682E-5,,,,,,,,,0,125000,,-68.1797768757829,,-57.6291368538314,,2.50178531962158E-7,,1.41009276919728E-6,,,,,,,,,,,,,,,,,,,,,,,,,,
,30537546.025,4370,17.6269,312.857,90.014,0.102153342753992,173,,1.4106726396798E-6,,4.63385954839904E-9,,0.0138093925494044,,4.53597115389569E-5,,,,,,,,,0,125000,,-71.8794805040966,,-63.3000965544484,,2.36540136612602E-7,,1.41074057465489E-6,,,,,,,,,,,,,,,,,,,,,,,,,,
[...]
,30538409.265,4375,7.33165,312.857,90.014,0.102153342753992,173,,1.43461723972174E-6,,5.62370161868322E-9,,0.0140437921402465,,5.50474370365312E-5,,,,,,,,,0,125000,,-55.9347478102181,,-70.5257717855737,,3.04518510129921E-7,,1.43472795180533E-6,,,,,,,,,,,,,,,,,,,,,,,,,,
,30538441.06,4375,7.24705,312.857,90.014,0.102153342753992,173,,1.43635112546478E-6,,5.18354837232336E-9,,0.0140607655757436,,5.07401116258819E-5,,,,,,,,,0,125000,,-66.2702567967575,,-68.588605467634,,2.58465463245286E-7,,1.43643078775941E-6,,,,,,,,,,,,,,,,,,,,,,,,,,
,30538474.97,4375,7.15965,312.857,90.014,0.102153342753992,173,,1.4361569525841E-6,,5.13415021401991E-9,,0.0140588647694844,,5.02561543652461E-5,,,,,,,,,0,125000,,-60.5964752834358,,-61.1217605401676,,2.76974954828392E-7,,1.43624844512656E-6,,,,,,,,,,,,,,,,,,,,,,,,,,
,30538509.455,4375,7.06965,312.857,90.014,0.102153342753992,173,,1.4332418764144E-6,,5.66134528306763E-9,,0.0140303283694256,,5.5416100386994E-5,,,,,,,,,0,125000,,-64.8433721876253,,-65.2960550231706,,2.97406593566811E-7,,1.43334757912305E-6,,,,,,,,,,,,,,,,,,,,,,,,,,
,30538544.325,4375,7.0932,312.857,90.014,0.102153342753992,173,,1.44118721391017E-6,,4.82247378320932E-9,,0.0141081072396453,,4.7206172826529E-5,,,,,,,,,0,125000,,-60.1836337353924,,-64.012416354012,,2.32954161091888E-7,,1.44125170968446E-6,,,,,,,,,,,,,,,,,,,,,,,,,,
,30538595.01,4375,7.018,312.857,90.014,0.102153342753992,173,,1.43696016504605E-6,,5.57566309194924E-9,,0.0140667276145489,,5.45785745283712E-5,,,,,,,,,0,125000,,-56.3671292657872,,-58.6185297771775,,2.50936829032731E-7,,1.437035222387E-6,,,,,,,,,,,,,,,,,,,,,,,,,,
,30538661.015,4375,7.01635,312.857,90.014,0.102153342753992,173,,1.44151303344251E-6,,4.68722247698954E-9,,0.0141112967675221,,4.58827387742812E-5,,,,,,,,,0,125000,,-74.5859022952078,,-63.5355106782707,,2.01857485000843E-7,,1.44156144892716E-6,,,,,,,,,,,,,,,,,,,,,,,,,,
,30538746.485,4374,5.61115,312.857,90.014,0.102153342753992,173,,1.44705458563899E-6,,5.58242467912034E-9,,0.014165544391167,,5.46456884361568E-5,,,,,,,,,0,125000,,-55.5269165261465,,-64.9853164715073,,2.07708480979084E-7,,1.44710565216528E-6,,,,,,,,,,,,,,,,,,,,,,,,,,
,30538778.345,4370,5.01275,312.857,90.014,0.102153342753992,173,,1.45498507121446E-6,,5.09722852204416E-9,,0.0142431778754721,,4.9895738266078E-5,,,,,,,,,0,125000,,-61.2316770997244,,-60.6297152453178,,2.32612931150954E-7,,1.45504876837873E-6,,,,,,,,,,,,,,,,,,,,,,,,,,
,30538807.43,4373,4.9994,312.857,90.014,0.102153342753992,173,,1.45742746866863E-6,,5.58247538206618E-9,,0.0142670871084637,,5.46461947202461E-5,,,,,,,,,0,125000,,-61.1884377917392,,-59.0284950712621,,2.08702505719371E-7,,1.45747865820351E-6,,,,,,,,,,,,,,,,,,,,,,,,,,
,30538871.095,4374,6.3227,312.857,90.014,0.102153342753992,173,,1.44947306525566E-6,,4.97285215345437E-9,,0.014189219485968,,4.86768586265317E-5,,,,,,,,,0,125000,,-57.8568782702582,,-62.8556605429066,,2.97626696053182E-7,,1.44957773914714E-6,,,,,,,,,,,,,,,,,,,,,,,,,,
,30538899.375,4374,10.78425,312.857,90.014,0.102153342753992,173,,1.42155452670801E-6,,5.0435054073968E-9,,0.013915918021235,,4.93699957221203E-5,,,,,,,,,0,125000,,-56.0660724605492,,-58.386193997154,,2.19532941213447E-7,,1.42161259612066E-6,,,,,,,,,,,,,,,,,,,,,,,,,,
,30538927.42,4374,16.46245,312.857,90.014,0.102153342753992,173,,1.42316914264098E-6,,5.17858177293457E-9,,0.0139317238945039,,5.06920077784564E-5,,,,,,,,,0,125000,,-58.5137406266466,,-65.3442844900021,,2.31520171295179E-7,,1.42323365333926E-6,,,,,,,,,,,,,,,,,,,,,,,,,,
,30538955.605,4370,22.17855,312.857,90.014,0.102153342753992,173,,1.40875696236255E-6,,5.92490282244614E-9,,0.0137906395127603,,5.79967506861565E-5,,,,,,,,,0,125000,,-56.942533578159,,-57.9559972176365,,2.62872422127996E-7,,1.40884097825836E-6,,,,,,,,,,,,,,,,,,,,,,,,,,
,30538982.82,4370,27.61635,312.857,90.014,0.102153342753992,173,,1.4126925551711E-6,,4.69206969809755E-9,,0.0138291659993,,4.59310227119041E-5,,,,,,,,,0,125000,,-58.3135862352919,,-64.4945097524791,,1.33794343378382E-7,,1.41271425942927E-6,,,,,,,,,,,,,,,,,,,,,,,,,,
,30539011.72,4370,33.3423,312.857,90.014,0.102153342753992,173,,1.43867147459501E-6,,5.35437844080278E-9,,0.0140834800462264,,5.24118375824316E-5,,,,,,,,,0,125000,,-61.3509838509576,,-60.7987261193159,,2.79261467168717E-7,,1.43876432136902E-6,,,,,,,,,,,,,,,,,,,,,,,,,,
,30539040.175,4370,39.05595,312.857,90.014,0.102153342753992,173,,1.48458174795063E-6,,5.04949186294693E-9,,0.0145329070787762,,4.94294035917784E-5,,,,,,,,,0,125000,,-57.1411982577497,,-62.0268947443549,,1.7793819944008E-7,,1.48461827792416E-6,,,,,,,,,,,,,,,,,,,,,,,,,,
,30539067.56,4370,44.54475,312.857,90.014,0.102153342753992,173,,1.52054545887742E-6,,5.85964688322047E-9,,0.0148849647921244,,5.73587414062427E-5,,,,,,,,,0,125000,,-55.7337095558712,,-70.1364238237042,,2.50789743437325E-7,,1.52061630734326E-6,,,,,,,,,,,,,,,,,,,,,,,,,,
,30539097.9,4370,50.6057,312.857,90.014,0.102153342753992,173,,1.53003408032507E-6,,5.67206785301772E-9,,0.014977851274366,,5.55226621010717E-5,,,,,,,,,0,125000,,-68.5120348736705,,-62.0245660380448,,2.48021450336301E-7,,1.5301029436586E-6,,,,,,,,,,,,,,,,,,,,,,,,,,
,30539125.9,4370,56.26245,312.857,90.014,0.102153342753992,173,,1.62009073046632E-6,,5.79047453917447E-9,,0.0158594384177967,,5.66822286169837E-5,,,,,,,,,0,125000,,-64.7568926706297,,-57.3253270319309,,2.35416765743007E-7,,1.62014932377484E-6,,,,,,,,,,,,,,,,,,,,,,,,,,
,30539153.195,4370,61.7038,312.857,90.014,0.102153342753992,173,,2.0019623020325E-6,,4.73641210378357E-9,,0.0195976776769176,,4.63642847568727E-5,,,,,,,,,0,125000,,-66.7077648704019,,-63.9298815315987,,2.80788316105725E-7,,2.00202975720966E-6,,,,,,,,,,,,,,,,,,,,,,,,,,
,30539180.375,4370,67.12465,312.857,90.014,0.102153342753992,173,,2.31445099643893E-6,,4.96805581820402E-9,,0.0226567132356671,,4.86324489353258E-5,,,,,,,,,0,125000,,-65.5814797565309,,-64.2777401865864,,2.58022023264494E-7,,2.31450026630418E-6,,,,,,,,,,,,,,,,,,,,,,,,,,
,30539208.205,4370,72.69975,312.857,90.014,0.102153342753992,173,,3.33901062175657E-6,,2.23934412164039E-8,,0.0326864219502447,,0.000219212841399672,,,,,,,,,0,125000,,-77.7170821397564,,-40.3900365614926,,2.57610509615533E-7,,3.33904466473685E-6,,,,,,,,,,,,,,,,,,,,,,,,,,
,30539241.74,4370,79.4488,312.857,90.014,0.102153342753992,173,,5.49568136534715E-5,,1.38753263211029E-8,,0.538027646740824,,0.000135839547609505,,,,,,,,,0,25000,,-75.0584368896243,,-72.902125687059,,-3.30893936956699E-7,,5.49568170660016E-5,,,,,,,,,,,,,,,,,,,,,,,,,,
,30539273.005,4370,85.6879,312.857,90.014,0.102153342753992,173,,0.000105361186479885,,1.54669171714971E-8,,1.03156448549907,,0.000151432611189975,,,,,,,,,0,25000,,-85.0376126614645,,-83.6893278378855,,-1.07925945165136E-6,,0.000105361205416026,,,,,,,,,,,,,,,,,,,,,,,,,,
,30539304.95,4370,92.0804,312.857,90.014,0.102153342753992,173,,0.000108589844328237,,1.63634425049381E-8,,1.06318057545046,,0.000160211035582766,,,,,,,,,0,25000,,-85.0969796616945,,-83.5414659669777,,-1.05357736563231E-6,,0.000108589861837346,,,,,,,,,,,,,,,,,,,,,,,,,,
,30539336.345,4370,98.39405,312.857,90.014,0.102153342753992,173,,0.000110557294689273,,1.71093246274625E-8,,1.08244665227856,,0.000167514299930276,,,,,,,,,0,25000,,-83.3071138186132,,-82.2525106621329,,-1.13506371808669E-6,,0.000110557314649867,,,,,,,,,,,,,,,,,,,,,,,,,,
,30539364.265,4370,103.90755,312.857,90.014,0.102153342753992,173,,0.000112058474488102,,1.68575321169572E-8,,1.09714689361111,,0.000165049416739916,,,,,,,,,0,25000,,-84.5334895585447,,-81.7630292550772,,-1.11581475532115E-6,,0.000112058493519027,,,,,,,,,,,,,,,,,,,,,,,,,,
,30539391.455,4370,109.3779,312.857,90.014,0.102153342753992,173,,0.000113399825968767,,1.76481843164671E-8,,1.11028207846839,,0.00017279091545523,,,,,,,,,0,25000,,-84.3833435656756,,-82.2936283025538,,-1.07613507346031E-6,,0.000113399843460852,,,,,,,,,,,,,,,,,,,,,,,,,,
,30539418.825,4370,114.8165,312.857,90.014,0.102153342753992,173,,0.000114707201759549,,1.67052223406538E-8,,1.12308460699968,,0.0001635588261686,,,,,,,,,0,25000,,-83.0553864060668,,-81.0870167903822,,-1.06965544161725E-6,,0.000114707218844649,,,,,,,,,,,,,,,,,,,,,,,,,,
,30539446.46,4370,120.39105,312.857,90.014,0.102153342753992,173,,0.000115988952303449,,1.76361188110814E-8,,1.1356362478197,,0.000172673449377212,,,,,,,,,0,25000,,-84.3703183659906,,-81.7101486570382,,-1.13912869942579E-6,,0.000115988971465825,,,,,,,,,,,,,,,,,,,,,,,,,,
,30539474.1,4370,125.8973,312.857,90.014,0.102153342753992,173,,0.000117158475259601,,1.87988513685485E-8,,1.14708893326695,,0.000184057969154942,,,,,,,,,0,25000,,-83.8577401027787,,-81.4951865960878,,-1.11366560597665E-6,,0.000117158493392043,,,,,,,,,,,,,,,,,,,,,,,,,,
,30539501.325,4370,131.3782,312.857,90.014,0.102153342753992,173,,0.000118045000694016,,1.79749582215214E-8,,1.15577036021601,,0.000175991529113684,,,,,,,,,0,25000,,-86.005091146156,,-80.7804679877346,,-1.21377467573792E-6,,0.000118045022071123,,,,,,,,,,,,,,,,,,,,,,,,,,
,30539528.94,4370,136.9002,312.857,90.014,0.102153342753992,173,,0.000119243587437281,,1.79492681066738E-8,,1.16750772864768,,0.000175740314292142,,,,,,,,,0,25000,,-86.5287223747754,,-81.9799286314618,,-1.21140671855722E-6,,0.000119243608517024,,,,,,,,,,,,,,,,,,,,,,,,,,
,30539557,4370,142.4743,312.857,90.014,0.102153342753992,173,,0.000120415743902007,,1.80198303016346E-8,,1.17898631462564,,0.000176431491101193,,,,,,,,,0,25000,,-87.0842376032314,,-82.5377258112318,,-1.27328981138336E-6,,0.000120415766963725,,,,,,,,,,,,,,,,,,,,,,,,,,
,30539584.48,4370,147.98985,312.857,90.014,0.102153342753992,173,,0.000121602065534232,,1.95080108962528E-8,,1.19060365686101,,0.000191002551831329,,,,,,,,,0,25000,,-84.9244648548074,,-80.5090271287011,,-1.26219105598121E-6,,0.000121602087974583,,,,,,,,,,,,,,,,,,,,,,,,,,
,30539612.245,4370,153.5137,312.857,90.014,0.102153342753992,173,,0.000122561766432498,,1.87156233636368E-8,,1.20000179072231,,0.000183244565538931,,,,,,,,,0,25000,,-84.6886679693194,,-82.4782410162002,,-1.23551496302566E-6,,0.000122561787765963,,,,,,,,,,,,,,,,,,,,,,,,,,
,30539639.595,4370,159.0063,312.857,90.014,0.102153342753992,173,,0.000123664118342033,,1.77534242736483E-8,,1.21079690691217,,0.000173823966677302,,,,,,,,,0,25000,,-84.6970832669355,,-81.576896827396,,-1.22480467366512E-6,,0.00012366413912035,,,,,,,,,,,,,,,,,,,,,,,,,,
,30539667.92,4370,164.676,312.857,90.014,0.102153342753992,173,,0.000124881326233511,,1.83213346039504E-8,,1.222716826503,,0.000179384707602058,,,,,,,,,0,25000,,-84.127134103381,,-82.4720708759021,,-1.2610852871322E-6,,0.00012488134804633,,,,,,,,,,,,,,,,,,,,,,,,,,
,30539695.125,4370,170.12525,312.857,90.014,0.102153342753992,173,,0.000126215208981515,,1.86070213260868E-8,,1.23577937380698,,0.000182182233312047,,,,,,,,,0,25000,,-85.5818954380392,,-81.754390875869,,-1.35099705458275E-6,,0.00012621523375103,,,,,,,,,,,,,,,,,,,,,,,,,,
,30539723.005,4370,175.72595,312.857,90.014,0.102153342753992,173,,0.000127371351761496,,2.10448393931926E-8,,1.24710137787577,,0.000206051386387974,,,,,,,,,0,25000,,-82.0913576246297,,-81.3835492920727,,-1.28674621785518E-6,,0.000127371374027098,,,,,,,,,,,,,,,,,,,,,,,,,,
,30539750.345,4370,181.1867,312.857,90.014,0.102153342753992,173,,0.000128285567301072,,1.82447078932859E-8,,1.25605423753481,,0.000178635362438919,,,,,,,,,0,25000,,-85.4150592013031,,-82.1065890193337,,-1.27073909243404E-6,,0.000128285588861401,,,,,,,,,,,,,,,,,,,,,,,,,,
,30539777.535,4370,186.6008,312.857,90.014,0.102153342753992,173,,0.000129398261623748,,1.79738710486169E-8,,1.26695082136074,,0.000175983868734173,,,,,,,,,0,25000,,-89.4650323618944,,-82.270558402037,,-1.31038974308429E-6,,0.000129398284353407,,,,,,,,,,,,,,,,,,,,,,,,,,
,30539805.28,4370,191.96325,312.857,90.014,0.102153342753992,173,,0.000130272899163865,,1.99851220288118E-8,,1.27551614730731,,0.000195676468671329,,,,,,,,,0,25000,,-86.9653609186194,,-83.6511341106727,,-1.39150931749737E-6,,0.000130272924622701,,,,,,,,,,,,,,,,,,,,,,,,,,
,30539832.795,4370,197.16515,312.857,90.014,0.102153342753992,173,,0.000131407680793427,,1.93802831937184E-8,,1.28662909781653,,0.000189754750383671,,,,,,,,,0,25000,,-87.7437217024566,,-83.5909822872102,,-1.36574472620626E-6,,0.000131407705106436,,,,,,,,,,,,,,,,,,,,,,,,,,
,30539853.97,4374,201.07295,312.857,90.014,0.102153342753992,173,,0.000132075831974122,,2.06108609396882E-8,,1.29317233996831,,0.000201803716629721,,,,,,,,,0,5000,,-84.8084112722912,,-79.5889870527764,,7.57265109283429E-7,,0.00013207583941104,,,,,,,,,,,,,,,,,,,,,,,,,,
,30539881.625,4374,206.1492,312.857,90.014,0.102153342753992,173,,0.000132748065826767,,1.97057617777912E-8,,1.2997555771315,,0.000192941938262879,,,,,,,,,0,25000,,-84.2883718823216,,-82.9946247451104,,-1.3668341566563E-6,,0.000132748089932694,,,,,,,,,,,,,,,,,,,,,,,,,,
,30539909.015,4374,211.04035,312.857,90.014,0.102153342753992,173,,0.000133653748524057,,2.06896160839062E-8,,1.30862501745261,,0.000202575272682875,,,,,,,,,0,25000,,-86.9148329092296,,-81.300305254122,,-1.3392721487601E-6,,0.000133653771510773,,,,,,,,,,,,,,,,,,,,,,,,,,
,30539936.62,4374,215.877,312.857,90.014,0.102153342753992,173,,0.000135415217949784,,1.92677356230993E-8,,1.32587533062737,,0.000188653910386774,,,,,,,,,0,25000,,-86.5579314642578,,-82.6177458103695,,-1.43992052824663E-6,,0.000135415244175657,,,,,,,,,,,,,,,,,,,,,,,,,,
,30539964.135,4374,220.6071,312.857,90.014,0.102153342753992,173,,0.00013557845893887,,2.03616904035208E-8,,1.32747397675541,,0.00019936507194994,,,,,,,,,0,25000,,-86.8608311100286,,-81.3237790865049,,-1.39652677696926E-6,,0.000135578483578163,,,,,,,,,,,,,,,,,,,,,,,,,,
,30539991.7,4374,225.24875,312.857,90.014,0.102153342753992,173,,0.000136677321569116,,2.07509443647059E-8,,1.33823534134456,,0.00020317666218816,,,,,,,,,0,25000,,-86.088904320263,,-82.2407382555788,,-1.41829441471256E-6,,0.00013667734677818,,,,,,,,,,,,,,,,,,,,,,,,,,
,30540018.57,4374,229.6926,312.857,90.014,0.102153342753992,173,,0.000137776743708324,,2.03185031337588E-8,,1.34900222064765,,0.000198942871607491,,,,,,,,,0,25000,,-86.8824074804305,,-82.5430433534852,,-1.39508022225471E-6,,0.000137776767904283,,,,,,,,,,,,,,,,,,,,,,,,,,
,30540046.2,4374,234.26905,312.857,90.014,0.102153342753992,173,,0.000138472142830046,,1.99388365333655E-8,,1.35581243322089,,0.000195225676185445,,,,,,,,,0,25000,,-85.4848774936307,,-83.053775809253,,-1.40382442187462E-6,,0.000138472167207232,,,,,,,,,,,,,,,,,,,,,,,,,,
,30540067.49,4374,237.7152,312.857,90.014,0.102153342753992,173,,0.000139102864688355,,2.30886003025104E-8,,1.36198925786791,,0.000226065965406824,,,,,,,,,0,5000,,-86.095146782374,,-77.2495808794445,,8.87907336864617E-7,,0.000139102874396128,,,,,,,,,,,,,,,,,,,,,,,,,,
,30540089.625,4374,241.2659,312.857,90.014,0.102153342753992,173,,0.000140263472087187,,2.33176341867547E-8,,1.37335542104466,,0.000228308889682995,,,,,,,,,0,5000,,-84.5032906319701,,-77.5888025105591,,7.90225661023031E-7,,0.000140263479712858,,,,,,,,,,,,,,,,,,,,,,,,,,
,30540111.285,4374,244.66435,312.857,90.014,0.102153342753992,173,,0.000141087471934054,,2.38550554676816E-8,,1.38142511324133,,0.000233571203407473,,,,,,,,,0,5000,,-87.5328110044851,,-76.8922320956003,,8.59636005839999E-7,,0.000141087480905474,,,,,,,,,,,,,,,,,,,,,,,,,,
,30540133.315,4374,248.1536,312.857,90.014,0.102153342753992,173,,0.000141005256644176,,2.35861374583132E-8,,1.38061995190482,,0.000230938129782371,,,,,,,,,0,5000,,-84.054585659303,,-77.0663573084168,,7.79469105828012E-7,,0.000141005264024628,,,,,,,,,,,,,,,,,,,,,,,,,,
,30540160.85,4374,252.3809,312.857,90.014,0.102153342753992,173,,0.000141306188636123,,1.9685700159819E-8,,1.38356707870229,,0.000192747973356431,,,,,,,,,0,25000,,-83.9014890288736,,-82.9543652861449,,-1.48898452258376E-6,,0.000141306215510573,,,,,,,,,,,,,,,,,,,,,,,,,,
,30540181.94,4374,255.62675,312.857,90.014,0.102153342753992,173,,0.000141963523074359,,2.31585883766042E-8,,1.39000458206337,,0.00022675220531087,,,,,,,,,0,5000,,-86.2175156357275,,-76.8841718140835,,8.60709430890208E-7,,0.000141963532012697,,,,,,,,,,,,,,,,,,,,,,,,,,
,30540204.275,4374,259.0057,312.857,90.014,0.102153342753992,173,,0.000142510227463368,,2.27724534216524E-8,,1.39535865673842,,0.0002229716321612,,,,,,,,,0,5000,,-91.2135147166076,,-77.1494896877078,,8.63858417865644E-7,,0.000142510236432689,,,,,,,,,,,,,,,,,,,,,,,,,,
,30540225.845,4374,262.2392,312.857,90.014,0.102153342753992,173,,0.000143103577847937,,2.37099233398936E-8,,1.40116956248383,,0.000232150874146515,,,,,,,,,0,5000,,-87.3586325825671,,-76.7622691405444,,8.94193511034651E-7,,0.0001431035874184,,,,,,,,,,,,,,,,,,,,,,,,,,
,30540247.185,4374,265.4206,312.857,90.014,0.102153342753992,173,,0.000143665514240297,,2.22135591689137E-8,,1.40667282856146,,0.000217499712934674,,,,,,,,,0,5000,,-88.1672844614388,,-79.8784664779616,,8.78804133579425E-7,,0.000143665523448016,,,,,,,,,,,,,,,,,,,,,,,,,,
,30540269.225,4374,268.70505,312.857,90.014,0.102153342753992,173,,0.00014422167228859,,2.18864207950986E-8,,1.41211951411555,,0.000214296780050627,,,,,,,,,0,5000,,-86.2873410843805,,-78.6538251531447,,8.67184652476773E-7,,0.000144221681219857,,,,,,,,,,,,,,,,,,,,,,,,,,
,30540290.975,4374,271.86645,312.857,90.014,0.102153342753992,173,,0.000144759020494613,,2.25121750043081E-8,,1.41738199570481,,0.000220423911967591,,,,,,,,,0,5000,,-87.7173143661645,,-77.7330897401416,,8.63615020823048E-7,,0.000144759029319622,,,,,,,,,,,,,,,,,,,,,,,,,,
,30540312.195,4374,274.93405,312.857,90.014,0.102153342753992,173,,0.000145272520456642,,2.41291124390814E-8,,1.42241092909649,,0.000236256044935814,,,,,,,,,0,5000,,-88.2091559030877,,-77.1052709961899,,8.72755730626883E-7,,0.000145272529437593,,,,,,,,,,,,,,,,,,,,,,,,,,
,30540334.075,4374,278.077,312.857,90.014,0.102153342753992,173,,0.000145824937058942,,2.30102088683581E-8,,1.42782099905605,,0.000225300679824697,,,,,,,,,0,5000,,-89.4607753416792,,-78.4939966203008,,8.60631675109216E-7,,0.000145824945759023,,,,,,,,,,,,,,,,,,,,,,,,,,
,30540355.515,4374,281.18005,312.857,90.014,0.102153342753992,173,,0.000146347138083943,,2.41082161092266E-8,,1.43293516217035,,0.000236051821658252,,,,,,,,,0,5000,,-86.0157331907796,,-77.8966166967268,,8.55270403997605E-7,,0.000146347146645309,,,,,,,,,,,,,,,,,,,,,,,,,,
,30540377.555,4374,284.2893,312.857,90.014,0.102153342753992,173,,0.000146912551224013,,2.30697552237139E-8,,1.43847253108124,,0.000225884086345524,,,,,,,,,0,5000,,-88.6696120619101,,-77.6295007508828,,8.2261961075676E-7,,0.000146912559113698,,,,,,,,,,,,,,,,,,,,,,,,,,
,30540399.635,4374,287.41485,312.857,90.014,0.102153342753992,173,,0.000147457454028702,,2.2492961370581E-8,,1.44380904103919,,0.000220236673997091,,,,,,,,,0,5000,,-88.960816783748,,-77.618293496691,,8.2831468563648E-7,,0.000147457461998446,,,,,,,,,,,,,,,,,,,,,,,,,,
,30540420.935,4374,290.36575,312.857,90.014,0.102153342753992,173,,0.000147983618630925,,2.22199267398367E-8,,1.44896204650287,,0.00021756346382693,,,,,,,,,0,5000,,-90.7370341256736,,-77.8167587989219,,8.60147440917081E-7,,0.00014798362719445,,,,,,,,,,,,,,,,,,,,,,,,,,
,30540442.845,4374,293.43765,312.857,90.014,0.102153342753992,173,,0.000148505738947231,,2.52798514328539E-8,,1.4540754521604,,0.000247524503478397,,,,,,,,,0,5000,,-89.1594821112875,,-76.9664275304316,,8.58912447033057E-7,,0.000148505747456162,,,,,,,,,,,,,,,,,,,,,,,,,,
,30540464.74,4374,296.44635,312.857,90.014,0.102153342753992,173,,0.000149064553048004,,2.31525335892825E-8,,1.45954822865839,,0.000226695325141323,,,,,,,,,0,5000,,-86.7858918230144,,-78.5076026449636,,8.91206563123502E-7,,0.000149064562174473,,,,,,,,,,,,,,,,,,,,,,,,,,
,30540486.66,4370,299.45615,312.857,90.014,0.102153342753992,173,,0.000149584648829754,,2.36088193454374E-8,,1.46464182338418,,0.000231163174188856,,,,,,,,,0,5000,,-85.799567205101,,-77.4693933632968,,8.65020724341356E-7,,0.000149584657397891,,,,,,,,,,,,,,,,,,,,,,,,,,
,30540508.265,4374,301.3973,312.857,90.014,0.102153342753992,173,,0.000150067550841625,,2.42222506239091E-8,,1.46937116538367,,0.000237169686964735,,,,,,,,,0,5000,,-89.7292384855907,,-77.6302389260146,,9.74512449317218E-7,,0.000150067561681104,,,,,,,,,,,,,,,,,,,,,,,,,,