File: Data/Gd (3 nm)/20171026-YBCO-Gd3nm.dc.dat
[Header]
TITLE,MPMS DC Measurement
BYAPP,MPMS Measurement,2.1,Summary
FILEOPENTIME, 1509065902.606000 10/26/2017, 5:58:22 PM

INFO, APPNAME, MPMS MultiVu Application, Revision 1.61,  Build 082

INFO, NAME, YBCO Gd 3nm
INFO, WEIGHT, 59.410
INFO, AREA, 1.000
INFO, LENGTH, 1.000
INFO, SHAPE, with substrate
INFO, COMMENT, H in plane
INFO, SEQUENCE FILE: 20171025-YBCO-Ta-500C.seq


INFO, BACKGROUND DATA FILE:, None


STARTUPAXIS,X,4,LINEAR,AUTO,0.000000,0.000000
STARTUPAXIS,Y1,5,LINEAR,AUTO,0.000000,0.000000


STARTUPGROUP,Longitudinal
FIELDGROUP,Longitudinal,1,2,3,4,5,6,7,8,9,15,16,17,18,27,28
FIELDGROUP,Transverse,1,2,3,4,10,11,12,13,14,19,20,21,22,27,28

PLOT_APPEARANCE,ALL,HORZ_GRID_ON,VERT_GRID_ON,MARKERS_AND_LINES

[Data]
Time,Comment,Field (Oe),Temperature (K),Long Moment (emu),Long Scan Std Dev,Long Algorithm,Long Reg Fit,Long Percent Error (%),Trans Moment (emu),Trans Scan Std Dev,Trans Algorithm,Trans Reg Fit,Trans Percent Error (%),Long Moment [w/o ABS] (emu),Long Scan Std Dev [w/o ABS],Long Reg Fit [w/o ABS],Long Percent Error [w/o ABS] (%),Trans Moment [w/o ABS] (emu),Trans Scan Std Dev [w/o ABS],Trans Reg Fit [w/o ABS],Trans Percent Error [w/o ABS] (%),Points per Scan,Scans per Measurement,Scan Length (cm),Delta Temp (K),Rot Position (deg),Error,EC Comp. Running,Using ABS,
1509065902.606,,1.000000e+001,1.998659e+000,-5.935386e-005,3.501116e-007,3,4.737661e-001,5.898716e-001,,,,,,,,,,,,,,48,2,6.000000e+000,1.753092e-003,0.000000e+000,0,,0,
1509066168.136,,1.000000e+001,3.996103e+000,-5.920765e-005,4.751553e-008,3,4.685254e-001,8.025234e-002,,,,,,,,,,,,,,48,2,6.000000e+000,2.042198e-002,0.000000e+000,0,,0,
1509066321.686,,1.000000e+001,6.005588e+000,-5.941845e-005,2.704406e-008,3,4.727870e-001,4.551458e-002,,,,,,,,,,,,,,48,2,6.000000e+000,2.667332e-002,0.000000e+000,0,,0,
1509066519.457,,1.000000e+001,8.014754e+000,-5.926343e-005,8.809062e-008,3,4.725216e-001,1.486425e-001,,,,,,,,,,,,,,48,2,6.000000e+000,3.993988e-002,0.000000e+000,0,,0,
1509066672.547,,1.000000e+001,9.992153e+000,-5.912963e-005,6.663389e-008,3,4.712512e-001,1.126912e-001,,,,,,,,,,,,,,48,2,6.000000e+000,5.072594e-003,0.000000e+000,0,,0,
1509066824.897,,1.000000e+001,1.199368e+001,-5.902885e-005,1.129790e-007,3,4.725412e-001,1.913962e-001,,,,,,,,,,,,,,48,2,6.000000e+000,6.830215e-003,0.000000e+000,0,,0,
1509066961.397,,1.000000e+001,1.400430e+001,-5.891318e-005,2.141556e-008,3,4.731504e-001,3.635105e-002,,,,,,,,,,,,,,48,2,6.000000e+000,6.119728e-003,0.000000e+000,0,,0,
1509067110.398,,1.000000e+001,1.599232e+001,-5.877893e-005,2.096538e-008,3,4.722179e-001,3.566819e-002,,,,,,,,,,,,,,48,2,6.000000e+000,6.539345e-003,0.000000e+000,0,,0,
1509067252.818,,1.000000e+001,1.799149e+001,-5.862485e-005,5.180893e-009,3,4.732371e-001,8.837367e-003,,,,,,,,,,,,,,48,2,6.000000e+000,4.961014e-003,0.000000e+000,0,,0,
1509067400.558,,1.000000e+001,1.999498e+001,-5.847134e-005,4.863454e-008,3,4.711990e-001,8.317672e-002,,,,,,,,,,,,,,48,2,6.000000e+000,5.081177e-003,0.000000e+000,0,,0,
1509067538.778,,1.000000e+001,2.199151e+001,-5.823281e-005,1.557664e-007,3,4.721150e-001,2.674890e-001,,,,,,,,,,,,,,48,2,6.000000e+000,4.291534e-003,0.000000e+000,0,,0,
1509067685.638,,1.000000e+001,2.399168e+001,-5.792082e-005,1.078032e-007,3,4.710197e-001,1.861217e-001,,,,,,,,,,,,,,48,2,6.000000e+000,8.699417e-003,0.000000e+000,0,,0,
1509067843.549,,1.000000e+001,2.600348e+001,-5.765710e-005,1.115924e-008,3,4.721585e-001,1.935450e-002,,,,,,,,,,,,,,48,2,6.000000e+000,3.370285e-003,0.000000e+000,0,,0,
1509067990.849,,1.000000e+001,2.799883e+001,-5.730325e-005,1.408128e-007,3,4.705520e-001,2.457326e-001,,,,,,,,,,,,,,48,2,6.000000e+000,2.910614e-003,0.000000e+000,0,,0,
1509068136.729,,1.000000e+001,3.000153e+001,-5.685401e-005,2.316739e-008,3,4.701989e-001,4.074891e-002,,,,,,,,,,,,,,48,2,6.000000e+000,6.639481e-003,0.000000e+000,0,,0,
1509068284.969,,1.000000e+001,3.200438e+001,-5.650984e-005,3.210919e-008,3,4.717409e-001,5.682052e-002,,,,,,,,,,,,,,48,2,6.000000e+000,1.250076e-002,0.000000e+000,0,,0,
1509068451.499,,1.000000e+001,3.400085e+001,-5.590781e-005,6.153018e-008,3,4.690467e-001,1.100565e-001,,,,,,,,,,,,,,48,2,6.000000e+000,8.419037e-003,0.000000e+000,0,,0,
1509068619.310,,1.000000e+001,3.600559e+001,-5.554320e-005,6.508787e-008,3,4.683746e-001,1.171842e-001,,,,,,,,,,,,,,48,2,6.000000e+000,3.120422e-003,0.000000e+000,0,,0,
1509068780.240,,1.000000e+001,3.800681e+001,-5.498130e-005,8.926108e-008,3,4.674447e-001,1.623481e-001,,,,,,,,,,,,,,48,2,6.000000e+000,8.666992e-003,0.000000e+000,0,,0,
1509068955.630,,1.000000e+001,4.000246e+001,-5.453834e-005,2.575013e-009,3,4.682627e-001,4.721474e-003,,,,,,,,,,,,,,48,2,6.000000e+000,1.334000e-002,0.000000e+000,0,,0,
1509069132.560,,1.000000e+001,4.200793e+001,-5.398558e-005,4.613927e-008,3,4.658648e-001,8.546593e-002,,,,,,,,,,,,,,48,2,6.000000e+000,1.668930e-002,0.000000e+000,0,,0,
1509069318.781,,1.000000e+001,4.401146e+001,-5.325168e-005,1.271557e-008,3,4.667566e-001,2.387825e-002,,,,,,,,,,,,,,48,2,6.000000e+000,1.594162e-002,0.000000e+000,0,,0,
1509069485.521,,1.000000e+001,4.601728e+001,-5.268964e-005,3.854543e-008,3,4.665855e-001,7.315562e-002,,,,,,,,,,,,,,48,2,6.000000e+000,1.736069e-002,0.000000e+000,0,,0,
1509069640.061,,1.000000e+001,4.802679e+001,-5.186349e-005,1.874537e-008,3,4.647623e-001,3.614366e-002,,,,,,,,,,,,,,48,2,6.000000e+000,2.153015e-002,0.000000e+000,0,,0,
1509069788.921,,1.000000e+001,5.004460e+001,-5.097849e-005,1.234797e-007,3,4.656005e-001,2.422192e-001,,,,,,,,,,,,,,48,2,6.000000e+000,1.975250e-002,0.000000e+000,0,,0,
1509069940.722,,1.000000e+001,5.205075e+001,-4.981150e-005,3.007182e-008,3,4.628229e-001,6.037124e-002,,,,,,,,,,,,,,48,2,6.000000e+000,3.374100e-002,0.000000e+000,0,,0,
1509070108.592,,1.000000e+001,5.403664e+001,-4.784951e-005,3.929402e-008,3,4.575566e-001,8.212000e-002,,,,,,,,,,,,,,48,2,6.000000e+000,3.749847e-002,0.000000e+000,0,,0,
1509070264.812,,1.000000e+001,5.606016e+001,-4.515011e-005,2.286899e-008,3,4.481037e-001,5.065101e-002,,,,,,,,,,,,,,48,2,6.000000e+000,2.729797e-002,0.000000e+000,0,,0,
1509070415.852,,1.000000e+001,5.806451e+001,-4.131423e-005,4.933939e-008,3,4.360727e-001,1.194247e-001,,,,,,,,,,,,,,48,2,6.000000e+000,2.153015e-002,0.000000e+000,0,,0,
1509070572.362,,1.000000e+001,6.006486e+001,-3.699822e-005,9.869164e-008,3,4.196058e-001,2.667470e-001,,,,,,,,,,,,,,48,2,6.000000e+000,3.940964e-002,0.000000e+000,0,,0,
1509070734.193,,1.000000e+001,6.205429e+001,-3.211799e-005,8.920191e-008,3,3.983707e-001,2.777319e-001,,,,,,,,,,,,,,48,2,6.000000e+000,2.619934e-002,0.000000e+000,0,,0,
1509070887.203,,1.000000e+001,6.408324e+001,-2.702253e-005,6.545058e-008,3,3.761458e-001,2.422075e-001,,,,,,,,,,,,,,48,2,6.000000e+000,5.009460e-002,0.000000e+000,0,,0,
1509071039.733,,1.000000e+001,6.608330e+001,-1.949640e-005,7.254408e-008,3,3.142868e-001,3.720897e-001,,,,,,,,,,,,,,48,2,6.000000e+000,6.290436e-002,0.000000e+000,0,,0,
1509071197.723,,1.000000e+001,6.807128e+001,-1.157511e-005,3.428419e-009,3,1.835644e-001,2.961888e-002,,,,,,,,,,,,,,48,2,6.000000e+000,4.989624e-002,0.000000e+000,0,,0,
1509071358.453,,1.000000e+001,7.008503e+001,-5.673801e-006,9.276570e-008,3,0.000000e+000,1.634983e+000,,,,,,,,,,,,,,48,2,6.000000e+000,5.267334e-002,0.000000e+000,0,,0,
1509071522.304,,1.000000e+001,7.208172e+001,-1.040238e-006,8.893141e-008,3,0.000000e+000,8.549145e+000,,,,,,,,,,,,,,48,2,6.000000e+000,6.005859e-002,0.000000e+000,0,,0,
1509071684.674,,1.000000e+001,7.409504e+001,1.053957e-006,2.400779e-007,3,6.964522e-003,2.277873e+001,,,,,,,,,,,,,,48,2,6.000000e+000,4.129791e-002,0.000000e+000,0,,0,
1509071851.744,,1.000000e+001,7.609195e+001,5.918745e-007,3.973459e-007,2,2.227714e-001,6.713347e+001,,,,,,,,,,,,,,48,2,6.000000e+000,7.652283e-002,0.000000e+000,0,,0,
1509072020.674,,1.000000e+001,7.808762e+001,7.221339e-007,2.209874e-008,3,4.379159e-001,3.060200e+000,,,,,,,,,,,,,,48,2,6.000000e+000,9.097290e-002,0.000000e+000,0,,0,
1509072198.615,,1.000000e+001,8.009082e+001,4.477665e-007,4.217465e-007,2,2.692777e-001,9.418893e+001,,,,,,,,,,,,,,48,2,6.000000e+000,6.999969e-002,0.000000e+000,0,,0,
1509072360.365,,1.000000e+001,8.210179e+001,7.599356e-007,2.355269e-008,3,5.055002e-001,3.099301e+000,,,,,,,,,,,,,,48,2,6.000000e+000,7.908630e-002,0.000000e+000,0,,0,
1509072523.845,,1.000000e+001,8.411198e+001,7.340598e-007,6.014552e-008,3,4.629934e-001,8.193546e+000,,,,,,,,,,,,,,48,2,6.000000e+000,7.038116e-002,0.000000e+000,0,,0,
1509072686.995,,1.000000e+001,8.611745e+001,7.186540e-007,4.880352e-008,3,4.240615e-001,6.790962e+000,,,,,,,,,,,,,,48,2,6.000000e+000,8.940887e-002,0.000000e+000,0,,0,
1509072850.866,,1.000000e+001,8.809669e+001,7.420917e-007,7.907197e-008,3,4.788316e-001,1.065528e+001,,,,,,,,,,,,,,48,2,6.000000e+000,1.165085e-001,0.000000e+000,0,,0,
1509073016.566,,1.000000e+001,9.011333e+001,7.205977e-007,1.464840e-007,3,5.007146e-001,2.032813e+001,,,,,,,,,,,,,,48,2,6.000000e+000,6.951904e-002,0.000000e+000,0,,0,
1509073204.586,,1.000000e+001,9.208372e+001,6.639013e-007,4.203278e-008,3,4.270994e-001,6.331178e+000,,,,,,,,,,,,,,48,2,6.000000e+000,9.414673e-002,0.000000e+000,0,,0,
1509073389.286,,1.000000e+001,9.409405e+001,3.736039e-008,8.329798e-007,3,1.075298e-001,2.229580e+003,,,,,,,,,,,,,,48,2,6.000000e+000,3.392792e-002,0.000000e+000,0,,0,
1509073567.407,,1.000000e+001,9.612550e+001,4.664851e-007,2.707037e-007,2,5.035230e-002,5.803051e+001,,,,,,,,,,,,,,48,2,6.000000e+000,8.641815e-002,0.000000e+000,0,,0,
1509073744.947,,1.000000e+001,9.811922e+001,-6.619385e-008,1.074106e-006,3,2.050494e-001,1.622668e+003,,,,,,,,,,,,,,48,2,6.000000e+000,6.127167e-002,0.000000e+000,0,,0,