File: Data/Gd (3 nm)/YBCO_Gd_3_12192017_resistivity.dat
[Header]
; AC Transport Data File (default extension .dat)
; Copyright 1998, Quantum Design, Inc. All rights reserved.
TITLE,PPMS_MANG
FILEOPENTIME,30468088.70,12/19/2017,4:49 pm
BYAPP,ACTRANSPORT,2.0,1.1
INFO,PPMS AC Transport Option Release 2.2.4. Build 2,APPNAME
INFO,,SAMPLE1_MATERIAL
INFO,,SAMPLE1_COMMENT
INFO,1.0,SAMPLE1_LEAD_SEPARATION
INFO,1.0,SAMPLE1_CROSS_SECTION
INFO,,SAMPLE2_MATERIAL
INFO,,SAMPLE2_COMMENT
INFO,1.0,SAMPLE2_LEAD_SEPARATION
INFO,1.0,SAMPLE2_CROSS_SECTION
DATATYPE,COMMENT,1
DATATYPE,TIME,2
FIELDGROUP,ACResist,2,4,5,6,7,8,9,10,13,14,15,16,53
FIELDGROUP,ACHall,2,4,5,6,7,8,9,10,17,18,19,20,53
FIELDGROUP,ACIVcurve,2,4,5,6,7,8,9,10,53
FIELDGROUP,ACCritCurrent,2,4,5,6,7,8,9,21,22,23,24,53
STARTUPGROUP,All
STARTUPAXIS,X,2
STARTUPAXIS,Y1,3
[Data]
Comment,Time Stamp (sec),Status (code),Temperature (K),Magnetic Field (Oe),Sample Position (deg),Excitation (mA),Frequency (Hz),Volts ch1,Volts ch2,V Std.Dev. ch1,V Std.Dev. ch2,Res. ch1 (ohm-cm),Res. ch2 (ohm-cm),Res. Std.Dev. ch1,Res. Std.Dev. ch2,Hall ch1 (cm^3/coul),Hall ch2 (cm^3/coul),Hall Std.Dev. ch1,Hall Std.Dev. ch2,Crit.Cur. ch1 (mA),Crit.Cur. ch2 (mA),C.Cur. Std.Dev. ch1,C.Cur. Std.Dev. ch2,ACT Status (code),ACT Gain,2nd Harm. ch1 (dB),2nd Harm. ch2 (dB),3rd Harm. ch1 (dB),3rd Harm. ch2 (dB),Quad.Error ch1 (ohm-cm-rad),Quad.Error ch2 (ohm-cm-rad),Drive Signal ch1 (V),Drive Signal ch2 (V),Bridge 1 Resistance (ohms),Bridge 1 Excitation (uA),Bridge 2 Resistance (ohms),Bridge 2 Excitation (uA),Bridge 3 Resistance (ohms),Bridge 3 Excitation (uA),Bridge 4 Resistance (ohms),Bridge 4 Excitation (uA),Signal 1 Vin (V),Signal 2 Vin (V),Digital Inputs (code),Drive 1 Iout (mA),Drive 1 Ipower (watts),Drive 2 Iout (mA),Drive 2 Ipower (watts),Pressure (),Map 20 (),Map 21 (),Map 22 (),Map 23 (),Map 24 (),Map 25 (),Map 26 (),Map 27 (),Map 28 (),Map 29 ()
,30468186.045,4370,299.9919,0,90.014,0.102153342753992,173,0.00236112302734767,,3.36256760475349E-7,,23.114068714359,,0.00329176488348344,,,,,,,,,,0,1250,-87.8200772920842,,-82.2824278528423,,3.47155583082696E-7,,0.0023611230274351,,,,,,,,,,,,,,,,,,,,,,,,,,,
,30468308.33,4374,294.24845,0,90.014,0.102153342753992,173,0.00235120230859609,,3.52218694129448E-7,,23.0169481397387,,0.00344802290595009,,,,,,,,,,0,1250,-88.3804056369701,,-82.9024436967972,,-1.57049801908129E-7,,0.00235120230861406,,,,,,,,,,,,,,,,,,,,,,,,,,,
,30468427.435,4374,276.8773,0,90.014,0.102153342753992,173,0.00230910986497303,,3.43408208048182E-7,,22.6048771734389,,0.00336177177139559,,,,,,,,,,0,1250,-86.9265344527045,,-83.6827370806786,,9.31222683300963E-7,,0.00230910986561629,,,,,,,,,,,,,,,,,,,,,,,,,,,
,30468545.25,4374,257.4697,0,90.014,0.102153342753992,173,0.0022599991409801,,3.3921564363033E-7,,22.1241000293342,,0.00332072729070987,,,,,,,,,,0,1250,-88.8444342906092,,-81.7122473301754,,1.63876055938625E-6,,0.00225999914301547,,,,,,,,,,,,,,,,,,,,,,,,,,,
,30468667.495,4374,236.99545,0,90.014,0.102153342753992,173,0.00220746260048646,,3.40708722114603E-7,,21.6097858451417,,0.00333534190234002,,,,,,,,,,0,1250,-86.8710850576524,,-81.2240299774413,,2.0819250963138E-6,,0.00220746260384969,,,,,,,,,,,,,,,,,,,,,,,,,,,
,30468783.905,4374,217.926,0,90.014,0.102153342753992,173,0.00215766454019728,,3.34177593036597E-7,,21.1222809196931,,0.00327140426736191,,,,,,,,,,0,1250,-87.1406760783238,,-82.9053388354452,,2.22433348609897E-6,,0.00215766454412496,,,,,,,,,,,,,,,,,,,,,,,,,,,
,30468903.77,4374,199.2789,0,90.014,0.102153342753992,173,0.00210758488232497,,3.28200368709779E-7,,20.6320197511677,,0.00321288908927435,,,,,,,,,,0,1250,-87.8587231497789,,-81.9484147223537,,2.50761454225559E-6,,0.00210758488743539,,,,,,,,,,,,,,,,,,,,,,,,,,,
,30469021.665,4374,182.1743,0,90.014,0.102153342753992,173,0.00206000483834998,,2.99187726265848E-7,,20.1662293300697,,0.00292887092472549,,,,,,,,,,0,1250,-89.3612970159978,,-82.817502910676,,3.19001890316362E-6,,0.00206000484681131,,,,,,,,,,,,,,,,,,,,,,,,,,,
,30469140.785,4374,165.9079,0,90.014,0.102153342753992,173,0.0020136345951862,,2.99170749112877E-7,,19.7122828270391,,0.00292870335209449,,,,,,,,,,0,1250,-86.4931200451399,,-81.6492675507168,,3.5431601024713E-6,,0.00201363460586497,,,,,,,,,,,,,,,,,,,,,,,,,,,
,30469258.48,4374,150.65875,0,90.014,0.102153342753992,173,0.00196875930990015,,3.08733658131144E-7,,19.2729717808131,,0.00302231715603661,,,,,,,,,,0,1250,-86.7445550257854,,-80.933614344622,,4.021773022794E-6,,0.00196875932397238,,,,,,,,,,,,,,,,,,,,,,,,,,,
,30469377.83,4374,136.0354,0,90.014,0.102153342753992,173,0.00192432855846111,,3.02963440613357E-7,,18.8380129353498,,0.00296582885556596,,,,,,,,,,0,1250,-89.2485468371843,,-81.8845963550935,,4.21669991872781E-6,,0.00192432857428768,,,,,,,,,,,,,,,,,,,,,,,,,,,
,30469496.18,4374,122.2407,0,90.014,0.102153342753992,173,0.00188078341113392,,2.97322611261086E-7,,18.4117241702693,,0.00291060725194438,,,,,,,,,,0,1250,-86.9475725939096,,-80.4588886159748,,5.22405082544529E-6,,0.00188078343598793,,,,,,,,,,,,,,,,,,,,,,,,,,,
,30469610.42,4374,109.46045,0,90.014,0.102153342753992,173,0.00183887229889495,,2.83122447747236E-7,,18.0014322791624,,0.00277159513791225,,,,,,,,,,0,1250,-85.7333343993662,,-80.9466694401098,,4.26558294307757E-6,,0.00183887231584323,,,,,,,,,,,,,,,,,,,,,,,,,,,
,30469719.59,4374,97.61755,0,90.014,0.102153342753992,173,0.00179839033983777,,2.7916602307756E-7,,17.6051315174805,,0.0027328629930315,,,,,,,,,,0,2500,-86.190126776925,,-81.9261758174816,,-7.45665048816227E-6,,0.00179839039279486,,,,,,,,,,,,,,,,,,,,,,,,,,,
,30469819.485,4374,86.82985,0,90.014,0.102153342753992,173,0.00175648582808969,,2.65683179066631E-7,,17.1949049256924,,0.00260087317553959,,,,,,,,,,0,2500,-86.4654881323395,,-81.8703647074801,,-7.18444295084434E-6,,0.00175648587842375,,,,,,,,,,,,,,,,,,,,,,,,,,,
,30469916.85,4374,76.3949,0,90.014,0.102153342753992,173,0.00161572457163466,,2.51264326975252E-7,,15.816917175556,,0.00245971807776485,,,,,,,,,,0,2500,-86.5450121471817,,-81.8026844441935,,-6.53619238303718E-6,,0.0016157246169247,,,,,,,,,,,,,,,,,,,,,,,,,,,
,30470010.74,4374,66.22465,0,90.014,0.102153342753992,173,0.00123249016718626,,2.05653851747892E-7,,12.0652490620443,,0.00201321268867615,,,,,,,,,,0,2500,-77.5759022017693,,-83.9527523550986,,-5.93820590939993E-6,,0.00123249021619206,,,,,,,,,,,,,,,,,,,,,,,,,,,
,30470569.775,4449,72.99935,136.4025,90.014,0.102153342753992,173,0.00133670623921562,,2.00617353848641E-7,,13.0854680377336,,0.00196391084352359,,,,,,,,,,0,2500,-83.7996464957099,,-97.9492305382118,,-6.10517419452926E-6,,0.0013367062869774,,,,,,,,,,,,,,,,,,,,,,,,,,,
,30470662.355,4449,72.9994,43.638,90.014,0.102153342753992,173,0.00134343808103314,,1.98011459758448E-7,,13.15136920185,,0.00193840100099166,,,,,,,,,,0,2500,-83.817098491415,,-97.9221219781475,,-6.11570587194876E-6,,0.00134343812871969,,,,,,,,,,,,,,,,,,,,,,,,,,,
,30470756.615,4449,72.9996,-50.588,90.014,0.102153342753992,173,0.00134919850690665,,1.93274797028525E-7,,13.2077607257598,,0.00189203232417156,,,,,,,,,,0,2500,-84.1887643298936,,-91.3520374403288,,-6.00725167733336E-6,,0.00134919855272044,,,,,,,,,,,,,,,,,,,,,,,,,,,
,30470895.33,4449,73.00005,121.376,90.014,0.102153342753992,173,0.00133830004240823,,1.91865636676837E-7,,13.1010705256051,,0.00187823737243585,,,,,,,,,,0,2500,-83.9037799721515,,-98.8163269224151,,-5.8532725753655E-6,,0.00133830008625771,,,,,,,,,,,,,,,,,,,,,,,,,,,
,30470991.455,4449,73.00005,217.9205,90.014,0.102153342753992,173,0.00133039890285493,,1.85601341619087E-7,,13.0237225652282,,0.00181691392750684,,,,,,,,,,0,2500,-84.2541409977706,,-90.9056695136262,,-6.03664950110123E-6,,0.00133039894977195,,,,,,,,,,,,,,,,,,,,,,,,,,,
,30471085.54,4449,72.99965,311.9445,90.014,0.102153342753992,173,0.00132106171061701,,2.021225661165E-7,,12.9323164276042,,0.00197864556284788,,,,,,,,,,0,2500,-82.7876844551689,,-82.4136998001631,,-5.93010436828791E-6,,0.00132106175621251,,,,,,,,,,,,,,,,,,,,,,,,,,,
,30471182.12,4449,72.99985,408.5065,90.014,0.102153342753992,173,0.00132962454686246,,1.87071716048083E-7,,13.0161420319437,,0.00183130790668688,,,,,,,,,,0,2500,-83.4717846913923,,-92.969588310482,,-5.84679620000035E-6,,0.00132962459090044,,,,,,,,,,,,,,,,,,,,,,,,,,,
,30471513.89,4417,73.0002,329.518,90.014,0.102153342753992,173,0.00132250858808742,,1.88982814848007E-7,,12.9464805860864,,0.00185001615903075,,,,,,,,,,0,2500,-84.0638113841939,,-83.3335695110318,,-5.96011119279482E-6,,0.00132250863409514,,,,,,,,,,,,,,,,,,,,,,,,,,,
,30471645.855,4417,72.9999,320.691,90.014,0.102153342753992,173,0.00132158251534339,,2.06807356902777E-7,,12.9374148279625,,0.00202450655825046,,,,,,,,,,0,2500,-82.343816158996,,-82.8811921674057,,-6.05324422303919E-6,,0.00132158256283343,,,,,,,,,,,,,,,,,,,,,,,,,,,
,30471779.585,4417,72.9998,310.618,90.014,0.102153342753992,173,0.00131981699316267,,1.97566537900595E-7,,12.9201313081523,,0.00193404504971166,,,,,,,,,,0,2500,-83.4204181789718,,-83.0306901134336,,-5.97542216065533E-6,,0.00131981703950138,,,,,,,,,,,,,,,,,,,,,,,,,,,
,30475503.6,4370,6.60835,312.857,90.014,0.102153342753992,173,0.00109226714197672,,4.5217493316018E-7,,10.6925448824901,,0.00442648181152527,,,,,,,,,,0,2500,-84.2916759493183,,-64.8376089362273,,-4.33201176056355E-6,,0.0010922671714054,,,,,,,,,,,,,,,,,,,,,,,,,,,
,30475611.71,4370,10.2082,312.857,90.014,0.102153342753992,173,,1.01147949280547E-7,,5.03091016821225E-9,,0.000990158146823245,,4.06249253903979E-5,,,,,,,,,0,125000,,-35.7810713558098,,-41.3780954767422,,1.18427305917996E-6,,1.22619220616924E-7,,,,,,,,,,,,,,,,,,,,,,,,,,
,30475720.67,4370,13.83895,312.857,90.014,0.102153342753992,173,0.00108882040011383,,2.12026184741688E-7,,10.6588032763419,,0.00207559054350878,,,,,,,,,,0,2500,-79.7810495738341,,-76.4520970439478,,-4.51425486965226E-6,,0.00108882043217182,,,,,,,,,,,,,,,,,,,,,,,,,,,
,30475828.595,4370,17.43755,312.857,90.014,0.102153342753992,173,,1.00858961261937E-7,,5.25334500844879E-9,,0.000987329183052079,,4.27422127814052E-5,,,,,,,,,0,125000,,-38.0840299924998,,-43.8866227346893,,1.15289873396215E-6,,1.21350311506075E-7,,,,,,,,,,,,,,,,,,,,,,,,,,
,30475936.41,4370,21.04345,312.857,90.014,0.102153342753992,173,0.0010908052658258,,1.90123742242097E-7,,10.6782339615469,,0.00186118073253121,,,,,,,,,,0,2500,-76.9404533319292,,-90.702109698657,,-4.43974645048454E-6,,0.00109080529677786,,,,,,,,,,,,,,,,,,,,,,,,,,,
,30476042.265,4370,24.5769,312.857,90.014,0.102153342753992,173,,1.02457834462924E-7,,5.5404339855055E-9,,0.00100298088512226,,4.46073858431391E-5,,,,,,,,,0,125000,,-38.1242202189609,,-55.6111830072258,,1.21068193042752E-6,,1.24574647846091E-7,,,,,,,,,,,,,,,,,,,,,,,,,,
,30476149.085,4370,28.1351,312.857,90.014,0.102153342753992,173,0.00109612712349001,,1.90071802783464E-7,,10.7303318682179,,0.00186067238008733,,,,,,,,,,0,2500,-76.9722638933011,,-85.4091791082568,,-4.50139125216465E-6,,0.00109612715515308,,,,,,,,,,,,,,,,,,,,,,,,,,,
,30476257.4,4370,31.7452,312.857,90.014,0.102153342753992,173,,1.07968620984157E-7,,4.93198901738652E-9,,0.00105692712029892,,4.04031197826049E-5,,,,,,,,,0,125000,,-45.3398858931064,,-50.9083483953119,,1.20673748820504E-6,,1.29018575237265E-7,,,,,,,,,,,,,,,,,,,,,,,,,,
,30476365.085,4370,35.33255,312.857,90.014,0.102153342753992,173,0.00110541414664183,,2.01176563937387E-7,,10.8212464637212,,0.00196938054156369,,,,,,,,,,0,2500,-75.7757165761032,,-85.0344520764099,,-4.80057773199435E-6,,0.00110541418235122,,,,,,,,,,,,,,,,,,,,,,,,,,,
,30476472.06,4370,38.8945,312.857,90.014,0.102153342753992,173,,1.13332052886066E-7,,4.7815503566145E-9,,0.00110943087131819,,4.01186911436593E-5,,,,,,,,,0,125000,,-40.9389887037241,,-65.8517003963339,,1.16381362530763E-6,,1.32227633234467E-7,,,,,,,,,,,,,,,,,,,,,,,,,,
,30476579.01,4370,42.4669,312.857,90.014,0.102153342753992,173,0.0011205353112926,,1.94931769761767E-7,,10.9692739731275,,0.00190824859171841,,,,,,,,,,0,2500,-76.1440958621707,,-90.141483461806,,-4.49123935855827E-6,,0.00112053534212641,,,,,,,,,,,,,,,,,,,,,,,,,,,
,30476686.35,4370,46.03775,312.857,90.014,0.102153342753992,173,,1.18963579906446E-7,,5.00046894852992E-9,,0.00116455906214766,,4.21750759586135E-5,,,,,,,,,0,125000,,-53.8666959621249,,-35.3068385261744,,1.19750015306958E-6,,1.38075422429896E-7,,,,,,,,,,,,,,,,,,,,,,,,,,
,30476793.69,4370,49.62385,312.857,90.014,0.102153342753992,173,0.00114072016977092,,2.31735794815285E-7,,11.1668722047233,,0.00226853525643501,,,,,,,,,,0,2500,-78.0164864853521,,-74.186554719517,,-4.93951460731902E-6,,0.00114072020640708,,,,,,,,,,,,,,,,,,,,,,,,,,,
,30476902.07,4370,53.23455,312.857,90.014,0.102153342753992,173,,1.2251133657769E-7,,5.00272622491931E-9,,0.00119928879153742,,4.22644237131864E-5,,,,,,,,,0,125000,,-37.4698711196774,,-42.1231897042509,,1.22523134737397E-6,,1.41956590474086E-7,,,,,,,,,,,,,,,,,,,,,,,,,,
,30477008.61,4370,56.78295,312.857,90.014,0.102153342753992,173,0.00117289415922034,,2.00208839347715E-7,,11.4818373450719,,0.00195990850946349,,,,,,,,,,0,2500,-76.0085671878794,,-97.6871759293227,,-5.45211932322575E-6,,0.00117289420263059,,,,,,,,,,,,,,,,,,,,,,,,,,,
,30477115.07,4370,60.32735,312.857,90.014,0.102153342753992,173,,1.26698252932943E-7,,5.37558195147554E-9,,0.00124027538874489,,4.63003193451787E-5,,,,,,,,,0,125000,,-44.7335033430111,,-40.9636149451918,,1.16922960639817E-6,,1.43999049874601E-7,,,,,,,,,,,,,,,,,,,,,,,,,,
,30477224.32,4370,63.9752,312.857,90.014,0.102153342753992,173,0.00121082427551498,,2.09187940317576E-7,,11.8531519713548,,0.00204780859358291,,,,,,,,,,0,2500,-76.8898154938291,,-84.1594065351143,,-5.58749654112781E-6,,0.00121082431967953,,,,,,,,,,,,,,,,,,,,,,,,,,,
,30477332.645,4370,67.5879,312.857,90.014,0.102153342753992,173,,1.27488220049252E-7,,5.10827185110591E-9,,0.00124800854161841,,4.35528351117545E-5,,,,,,,,,0,125000,,-46.0559906045275,,-46.4231773718504,,1.22886633881024E-6,,1.46377770510937E-7,,,,,,,,,,,,,,,,,,,,,,,,,,
,30477438.09,4370,71.10185,312.857,90.014,0.102153342753992,173,0.00126625179898203,,1.99876608705168E-7,,12.3957569405885,,0.00195665804040874,,,,,,,,,,0,2500,-79.3956166202775,,-92.1424143541804,,-6.02120296586264E-6,,0.00126625184802389,,,,,,,,,,,,,,,,,,,,,,,,,,,
,30477546.025,4370,74.6981,312.857,90.014,0.102153342753992,173,,1.21678564299333E-7,,5.19093484804672E-9,,0.00119113661012591,,4.35086934469332E-5,,,,,,,,,0,125000,,-35.4872423007393,,-49.1945296488683,,1.25437229164366E-6,,1.42112117106626E-7,,,,,,,,,,,,,,,,,,,,,,,,,,
,30477654.015,4370,78.30105,312.857,90.014,0.102153342753992,173,0.00164473054740334,,2.52114303168296E-7,,16.1008719735008,,0.00246803952689247,,,,,,,,,,0,2500,-85.4476354083443,,-81.7365408943838,,-6.71574834550948E-6,,0.00164473059437268,,,,,,,,,,,,,,,,,,,,,,,,,,,
,30477768.22,4370,82.10865,312.857,90.014,0.102153342753992,173,,1.42851099734662E-7,,5.59370871959352E-9,,0.00139839897888711,,4.83496155114942E-5,,,,,,,,,0,125000,,-46.5444288858316,,-34.9963251466241,,1.29757958227083E-6,,1.61784876237783E-7,,,,,,,,,,,,,,,,,,,,,,,,,,
,30477887.91,4370,86.0996,312.857,90.014,0.102153342753992,173,0.00174680938305023,,2.58395336070065E-7,,17.1001768681695,,0.00252952947782803,,,,,,,,,,0,2500,-88.1388684609684,,-82.4755018931293,,-7.01721250731985E-6,,0.00174680943133433,,,,,,,,,,,,,,,,,,,,,,,,,,,
,30478007.67,4370,90.095,312.857,90.014,0.102153342753992,173,,1.48253545059976E-7,,5.4655775639645E-9,,0.00145128464593761,,4.74649766868059E-5,,,,,,,,,0,125000,,-37.9464324883357,,-37.8321703014354,,1.31771462824253E-6,,1.67114983582572E-7,,,,,,,,,,,,,,,,,,,,,,,,,,
,30478128.32,4370,94.1158,312.857,90.014,0.102153342753992,173,0.00178084097887884,,2.69927914902778E-7,,17.4333310118453,,0.00264242715445997,,,,,,,,,,0,2500,-86.8217255013312,,-82.0198854180541,,-7.13740195442973E-6,,0.00178084102787653,,,,,,,,,,,,,,,,,,,,,,,,,,,
,30478249.665,4370,98.1641,312.857,90.014,0.102153342753992,173,,1.51034741301201E-7,,5.00671833127389E-9,,0.00147851035788016,,4.3623978995703E-5,,,,,,,,,0,125000,,-43.0635133809242,,-40.2523791649046,,1.32151601548066E-6,,1.69688439298627E-7,,,,,,,,,,,,,,,,,,,,,,,,,,
,30478362.83,4370,101.92985,312.857,90.014,0.102153342753992,173,0.00180850168271437,,2.73374547804737E-7,,17.7041171334611,,0.00267616830385564,,,,,,,,,,0,2500,-87.0475455655427,,-81.9461812805705,,-7.2951801770349E-6,,0.00180850173311936,,,,,,,,,,,,,,,,,,,,,,,,,,,
,30478476.035,4370,105.70055,312.857,90.014,0.102153342753992,173,,1.54585809316423E-7,,5.38424020284385E-9,,0.00151327250603485,,4.69858699727806E-5,,,,,,,,,0,125000,,-44.9856889773937,,-43.5559172704736,,1.34251100913237E-6,,1.73410062845941E-7,,,,,,,,,,,,,,,,,,,,,,,,,,
,30478597.73,4370,109.7602,312.857,90.014,0.102153342753992,173,0.00183467775208376,,2.90918001017335E-7,,17.9603694762576,,0.00284790869655323,,,,,,,,,,0,1250,-87.4147540732682,,-80.5880475819384,,4.75175131002627E-6,,0.00183467777316363,,,,,,,,,,,,,,,,,,,,,,,,,,,
,30478715.085,4370,113.66825,312.857,90.014,0.102153342753992,173,,1.57614265080722E-7,,4.9412717821555E-9,,0.00154291869375674,,4.29968893148844E-5,,,,,,,,,0,125000,,-40.3236486753163,,-47.3566031082962,,1.38783893057159E-6,,1.77314701716833E-7,,,,,,,,,,,,,,,,,,,,,,,,,,
,30478836.375,4370,117.7136,312.857,90.014,0.102153342753992,173,0.00186065045456131,,2.87842110349224E-7,,18.2146310796063,,0.00281779834768657,,,,,,,,,,0,1250,-85.4314596823303,,-80.4038976401956,,5.2940531944417E-6,,0.00186065048036206,,,,,,,,,,,,,,,,,,,,,,,,,,,
,30478954.74,4370,121.6704,312.857,90.014,0.102153342753992,173,,1.61611485920775E-7,,6.0698020784002E-9,,0.00158204832610267,,5.34074665273835E-5,,,,,,,,,0,125000,,-54.2667331711581,,-34.2832740975359,,1.3464060447106E-6,,1.79801081052664E-7,,,,,,,,,,,,,,,,,,,,,,,,,,
,30479075.305,4370,125.67985,312.857,90.014,0.102153342753992,173,0.00188599911583632,,3.09061800134767E-7,,18.4627837163171,,0.00302552692664425,,,,,,,,,,0,1250,-86.5107220811207,,-80.9621664669871,,4.76061125779315E-6,,0.00188599913641912,,,,,,,,,,,,,,,,,,,,,,,,,,,
,30479194.325,4370,129.6492,312.857,90.014,0.102153342753992,173,,1.59911514957426E-7,,6.03441916818605E-9,,0.00156540695408835,,5.25614663524607E-5,,,,,,,,,0,125000,,-43.3674239874965,,-44.3871469440967,,1.401357325817E-6,,1.79719524307377E-7,,,,,,,,,,,,,,,,,,,,,,,,,,
,30479316.165,4370,133.71295,312.857,90.014,0.102153342753992,173,0.00191098743223705,,2.93963760619854E-7,,18.7074088541058,,0.00287772704933997,,,,,,,,,,0,1250,-87.1819961137562,,-79.7418724634922,,3.6043208727127E-6,,0.00191098744388124,,,,,,,,,,,,,,,,,,,,,,,,,,,
,30479435.93,4370,137.6941,312.857,90.014,0.102153342753992,173,,1.64758961803724E-7,,4.64200399519156E-9,,0.00161285962734399,,4.06250908020465E-5,,,,,,,,,0,125000,,-39.4743625548144,,-45.9299391323222,,1.41078341517586E-6,,1.84292531684307E-7,,,,,,,,,,,,,,,,,,,,,,,,,,
,30479558.585,4370,141.7866,312.857,90.014,0.102153342753992,173,0.00193568060005361,,3.06003177623697E-7,,18.9491447324429,,0.0029955863854266,,,,,,,,,,0,1250,-88.0474432516244,,-82.1101890644783,,4.31364378572466E-6,,0.00193568061651913,,,,,,,,,,,,,,,,,,,,,,,,,,,
,30479675.905,4370,145.69805,312.857,90.014,0.102153342753992,173,,1.70105713448561E-7,,5.62262013858212E-9,,0.00166520010072873,,4.90954838759681E-5,,,,,,,,,0,125000,,-49.5127266099854,,-38.9776806942832,,1.47298444408317E-6,,1.90705679666584E-7,,,,,,,,,,,,,,,,,,,,,,,,,,
,30479794.77,4370,149.65525,312.857,90.014,0.102153342753992,173,0.00195925526743204,,3.00331357933902E-7,,19.1799310676849,,0.00294006340054827,,,,,,,,,,0,1250,-89.8286133194124,,-81.8584422967512,,3.87164572243352E-6,,0.00195925528053655,,,,,,,,,,,,,,,,,,,,,,,,,,,
,30479912.555,4370,153.5787,312.857,90.014,0.102153342753992,173,,1.73224321170097E-7,,5.49557671050821E-9,,0.0016957288062591,,4.8477497789596E-5,,,,,,,,,0,125000,,-52.0964494949659,,-42.2454927477545,,1.42405656811247E-6,,1.92233678715475E-7,,,,,,,,,,,,,,,,,,,,,,,,,,
,30480031.315,4370,157.53745,312.857,90.014,0.102153342753992,173,0.00198245293377582,,3.07060679641758E-7,,19.4070268246274,,0.00300594011735449,,,,,,,,,,0,1250,-88.3377553824727,,-80.940249563016,,4.03057112720524E-6,,0.00198245294781205,,,,,,,,,,,,,,,,,,,,,,,,,,,
,30480148.54,4370,161.4416,312.857,90.014,0.102153342753992,173,,1.71796732231137E-7,,5.31420730590956E-9,,0.00168175383847299,,4.6335365016355E-5,,,,,,,,,0,125000,,-43.1976438661461,,-40.6581316406277,,1.49814296874692E-6,,1.92880503520369E-7,,,,,,,,,,,,,,,,,,,,,,,,,,
,30480269.485,4370,165.46715,312.857,90.014,0.102153342753992,173,0.00200546202045738,,3.05106185746664E-7,,19.6322765682782,,0.00298680749390139,,,,,,,,,,0,1250,-87.051534418905,,-80.8314334527518,,3.419800522502E-6,,0.00200546203044605,,,,,,,,,,,,,,,,,,,,,,,,,,,
,30480390.04,4370,169.4889,312.857,90.014,0.102153342753992,173,,1.78797539858135E-7,,6.0490223037097E-9,,0.00175028621443073,,5.36486405891355E-5,,,,,,,,,0,125000,,-44.6468384393162,,-35.3148598562028,,1.42723587142402E-6,,1.97349275446714E-7,,,,,,,,,,,,,,,,,,,,,,,,,,
,30480508.89,4370,173.4466,312.857,90.014,0.102153342753992,173,0.00202826603779093,,2.98969629833293E-7,,19.8555188685287,,0.00292673495025905,,,,,,,,,,0,1250,-90.7650699580197,,-82.4221709004183,,3.18330627984834E-6,,0.00202826604634853,,,,,,,,,,,,,,,,,,,,,,,,,,,
,30480626.9,4370,177.37685,312.857,90.014,0.102153342753992,173,,1.72260791408481E-7,,5.194020035824E-9,,0.00168629661116331,,4.54845812944254E-5,,,,,,,,,0,125000,,-44.6422876431075,,-41.8235905628475,,1.47041770691387E-6,,1.9256324089319E-7,,,,,,,,,,,,,,,,,,,,,,,,,,
,30480746.735,4370,181.37335,312.857,90.014,0.102153342753992,173,0.00205058910088339,,3.17600772482522E-7,,20.0740529168893,,0.00310912346372073,,,,,,,,,,0,1250,-85.5841396170183,,-81.5080249211606,,3.11826051602045E-6,,0.00205058910900545,,,,,,,,,,,,,,,,,,,,,,,,,,,
,30480865.65,4370,185.33665,312.857,90.014,0.102153342753992,173,,1.83448693784362E-7,,4.965779986938E-9,,0.00179581733770063,,4.38913897122675E-5,,,,,,,,,0,125000,,-46.3189322141367,,-50.3896532501084,,1.49207991817039E-6,,2.03175015742499E-7,,,,,,,,,,,,,,,,,,,,,,,,,,
,30480987.375,4370,189.3897,312.857,90.014,0.102153342753992,173,0.00207281358636271,,3.14432382631949E-7,,20.291622026987,,0.00307810749958977,,,,,,,,,,0,1250,-88.482739480113,,-81.4337282975512,,2.50632329818666E-6,,0.00207281359155351,,,,,,,,,,,,,,,,,,,,,,,,,,,
,30481106.74,4370,193.36545,312.857,90.014,0.102153342753992,173,,1.77807183767761E-7,,5.93565549386825E-9,,0.00174059141061055,,5.22326169363445E-5,,,,,,,,,0,125000,,-39.0024385821338,,-35.5281910396398,,1.48052392995722E-6,,1.97798838636812E-7,,,,,,,,,,,,,,,,,,,,,,,,,,
,30481225.945,4370,197.3367,312.857,90.014,0.102153342753992,173,0.00209459698716817,,3.15799730805463E-7,,20.5048731837341,,0.00309149371341753,,,,,,,,,,0,1250,-87.6393309681938,,-82.1493517244155,,2.32363120106214E-6,,0.00209459699158341,,,,,,,,,,,,,,,,,,,,,,,,,,,
,30481343.025,4370,201.2363,312.857,90.014,0.102153342753992,173,,1.82352396034698E-7,,5.29996096266724E-9,,0.0017850854485744,,4.61776760937213E-5,,,,,,,,,0,125000,,-42.468938712219,,-55.6848910444487,,1.59576277547336E-6,,2.04880019801517E-7,,,,,,,,,,,,,,,,,,,,,,,,,,
,30481462.86,4370,205.22865,312.857,90.014,0.102153342753992,173,0.00211584976570655,,3.25242676944731E-7,,20.7129298420861,,0.00318393528813878,,,,,,,,,,0,1250,-88.0406449274968,,-82.6088203251322,,2.47393173659976E-6,,0.00211584977066118,,,,,,,,,,,,,,,,,,,,,,,,,,,
,30481581.59,4370,209.18745,312.857,90.014,0.102153342753992,173,,1.8947470685963E-7,,6.03045632120861E-9,,0.00185480724706101,,5.31025919254253E-5,,,,,,,,,0,125000,,-49.9991671431887,,-46.7473341427713,,1.57213319379164E-6,,2.10636311375737E-7,,,,,,,,,,,,,,,,,,,,,,,,,,
,30481700.775,4370,213.1572,312.857,90.014,0.102153342753992,173,0.00213695192007227,,3.23559112924797E-7,,20.9195120352452,,0.00316745486117989,,,,,,,,,,0,1250,-90.6778961685719,,-82.2929323915111,,1.944842755351E-6,,0.00213695192310403,,,,,,,,,,,,,,,,,,,,,,,,,,,
,30481818.985,4370,217.09845,312.857,90.014,0.102153342753992,173,,1.89047587201176E-7,,5.52443778687462E-9,,0.00185062608285939,,4.8150287444829E-5,,,,,,,,,0,125000,,-46.8870128963882,,-50.7310384021116,,1.65157597839721E-6,,2.12328299664639E-7,,,,,,,,,,,,,,,,,,,,,,,,,,
,30481938.245,4370,221.0726,312.857,90.014,0.102153342753992,173,0.00215770444560784,,3.09027624422829E-7,,21.1226715789739,,0.00302520070280173,,,,,,,,,,0,1250,-87.6177757053437,,-82.681315780851,,2.43359773625672E-6,,0.00215770445030923,,,,,,,,,,,,,,,,,,,,,,,,,,,
,30482056.62,4370,225.0132,312.857,90.014,0.102153342753992,173,,1.94326863579171E-7,,6.47251367053376E-9,,0.00190230603044579,,5.70246485783025E-5,,,,,,,,,0,125000,,-38.623280896578,,-50.9191825100643,,1.60802976703077E-6,,2.15918941976332E-7,,,,,,,,,,,,,,,,,,,,,,,,,,
,30482175.22,4370,228.9652,312.857,90.014,0.102153342753992,173,0.00217839663220839,,3.26549201926489E-7,,21.325240511731,,0.00319672742771998,,,,,,,,,,0,1250,-88.1639263279332,,-82.1893957918171,,1.7114984320753E-6,,0.00217839663451162,,,,,,,,,,,,,,,,,,,,,,,,,,,
,30482293.24,4370,232.9084,312.857,90.014,0.102153342753992,173,,1.94166295069947E-7,,5.30824585810552E-9,,0.00190073419150235,,4.68262700937427E-5,,,,,,,,,0,125000,,-41.3065964281172,,-43.1955297968405,,1.59599121422905E-6,,2.15468034912952E-7,,,,,,,,,,,,,,,,,,,,,,,,,,
,30482413.165,4370,236.8919,312.857,90.014,0.102153342753992,173,0.0021988974153744,,3.43551582356396E-7,,21.5259357584973,,0.0033631715766556,,,,,,,,,,0,1250,-87.8906962160069,,-80.7722511008335,,1.26091912542339E-6,,0.00219889741661289,,,,,,,,,,,,,,,,,,,,,,,,,,,
,30482531.5,4370,240.8326,312.857,90.014,0.102153342753992,173,,1.91570408746223E-7,,5.86736552669971E-9,,0.0018753225138371,,5.19528526065501E-5,,,,,,,,,0,125000,,-42.1588788793872,,-41.3996414202503,,1.54305374095525E-6,,2.11792079107979E-7,,,,,,,,,,,,,,,,,,,,,,,,,,
,30482650.56,4370,244.8058,312.857,90.014,0.102153342753992,173,0.0022188536459304,,3.43704820945037E-7,,21.7213001122166,,0.00336467237171158,,,,,,,,,,0,1250,-85.4288067012775,,-81.4669345324448,,1.57330873419927E-6,,0.00221885364784122,,,,,,,,,,,,,,,,,,,,,,,,,,,
,30482768.84,4370,248.74465,312.857,90.014,0.102153342753992,173,,2.01154534239247E-7,,5.56413355215744E-9,,0.00196914353675592,,4.91143291113858E-5,,,,,,,,,0,125000,,-42.8770025957661,,-47.4230694689476,,1.64791448351024E-6,,2.23083116884877E-7,,,,,,,,,,,,,,,,,,,,,,,,,,
,30482886.945,4370,252.683,312.857,90.014,0.102153342753992,173,0.00223897624903279,,3.50227742739049E-7,,21.9182932734239,,0.00342852871957077,,,,,,,,,,0,1250,-85.8363093718876,,-81.5644448057025,,1.46091849101803E-6,,0.00223897625066555,,,,,,,,,,,,,,,,,,,,,,,,,,,
,30483003.885,4370,256.57725,312.857,90.014,0.102153342753992,173,,2.02548019499754E-7,,5.35266014770988E-9,,0.00198278465766994,,4.74972668480059E-5,,,,,,,,,0,125000,,-44.3757666969478,,-46.4560981653244,,1.61213429053865E-6,,2.23448066023741E-7,,,,,,,,,,,,,,,,,,,,,,,,,,
,30483122.21,4370,260.5369,312.857,90.014,0.102153342753992,173,0.00225914347190119,,3.45134045058348E-7,,22.1157233267565,,0.00337866503113632,,,,,,,,,,0,1250,-85.1460284308293,,-84.0697137618999,,9.52131009502138E-7,,0.00225914347258853,,,,,,,,,,,,,,,,,,,,,,,,,,,
,30483239.7,4370,264.44975,312.857,90.014,0.102153342753992,173,,2.04416474171328E-7,,6.5084890442654E-9,,0.00200107535434523,,5.74709144211319E-5,,,,,,,,,0,125000,,-43.4587520231211,,-36.9309814815101,,1.6713914076641E-6,,2.26618580053714E-7,,,,,,,,,,,,,,,,,,,,,,,,,,
,30483359.715,4370,268.46005,312.857,90.014,0.102153342753992,173,0.00227947165803647,,3.46307096602186E-7,,22.3147292356007,,0.00339014923140978,,,,,,,,,,0,1250,-88.5994914702652,,-80.8244781974568,,1.17750711826659E-6,,0.00227947165907834,,,,,,,,,,,,,,,,,,,,,,,,,,,
,30483479.415,4370,272.42215,312.857,90.014,0.102153342753992,173,,2.08113857938188E-7,,5.97506806340429E-9,,0.00203726982379773,,5.30741205124338E-5,,,,,,,,,0,125000,,-42.5048508292809,,-40.6678025860944,,1.64698445315923E-6,,2.29355206326204E-7,,,,,,,,,,,,,,,,,,,,,,,,,,
,30483599.235,4370,276.4366,312.857,90.014,0.102153342753992,173,0.00230008515711647,,3.50070209290427E-7,,22.5165283429774,,0.00342698867628983,,,,,,,,,,0,1250,-86.9766182535853,,-81.0532831113815,,7.86709481285641E-7,,0.00230008515757737,,,,,,,,,,,,,,,,,,,,,,,,,,,
,30483718.055,4370,280.4037,312.857,90.014,0.102153342753992,173,,2.1261474772252E-7,,5.8159985288076E-9,,0.00208132998364966,,5.17939295578101E-5,,,,,,,,,0,125000,,-52.5987896556424,,-46.1782529886209,,1.65804094561879E-6,,2.33714881767341E-7,,,,,,,,,,,,,,,,,,,,,,,,,,
,30483838.16,4370,284.41145,312.857,90.014,0.102153342753992,173,0.00232107027627301,,3.55944635613823E-7,,22.7219655702212,,0.00348449671601446,,,,,,,,,,0,1250,-89.7982792845717,,-81.7867841473221,,6.2847238413961E-8,,0.00232107027627592,,,,,,,,,,,,,,,,,,,,,,,,,,,
,30483955.79,4370,288.34305,312.857,90.014,0.102153342753992,173,,2.14435247518052E-7,,5.59485437749486E-9,,0.00209915124046819,,4.99575342138089E-5,,,,,,,,,0,125000,,-46.4000794842545,,-56.1897928699652,,1.6462513794294E-6,,2.35088574558007E-7,,,,,,,,,,,,,,,,,,,,,,,,,,
,30484076.43,4370,292.3519,312.857,90.014,0.102153342753992,173,0.00234267723545511,,3.40295172409623E-7,,22.9334904923166,,0.00333129804769916,,,,,,,,,,0,1250,-86.9391023458489,,-82.0479891740788,,2.69154803694936E-7,,0.00234267723550808,,,,,,,,,,,,,,,,,,,,,,,,,,,
,30484193.515,4370,296.2665,312.857,90.014,0.102153342753992,173,,2.12310224026179E-7,,5.2591120285549E-9,,0.00207834893690859,,4.64940310926128E-5,,,,,,,,,0,125000,,-40.2736036423753,,-50.8399312643041,,1.72482504296829E-6,,2.35089744570823E-7,,,,,,,,,,,,,,,,,,,,,,,,,,
,30484312.45,4370,300.15725,312.857,90.014,0.102153342753992,173,0.00236497829672759,,3.39714712389704E-7,,23.1518105392219,,0.00332561642043658,,,,,,,,,,0,1250,-85.1284035063514,,-82.7321587177107,,6.63164094180574E-7,,0.00236497829704611,,,,,,,,,,,,,,,,,,,,,,,,,,,
,30484450.595,4370,297.85875,312.857,90.014,0.102153342753992,173,,2.13599791184602E-7,,6.24630682000456E-9,,0.00209097278203742,,5.5439686083256E-5,,,,,,,,,0,125000,,-42.3215583767416,,-37.6181566090035,,1.6979352452781E-6,,2.35586787581558E-7,,,,,,,,,,,,,,,,,,,,,,,,,,
,30484572.32,4370,293.70005,312.857,90.014,0.102153342753992,173,0.00235345572614856,,3.51800542621846E-7,,23.0390083549381,,0.00344392951636294,,,,,,,,,,0,1250,-87.057921804312,,-82.1570453657559,,-4.69445507600107E-9,,0.00235345572614858,,,,,,,,,,,,,,,,,,,,,,,,,,,
,30484694.555,4370,289.68875,312.857,90.014,0.102153342753992,173,,2.11256518445687E-7,,6.81937891760979E-9,,0.00206803399059027,,6.01576577742479E-5,,,,,,,,,0,125000,,-46.1740782873926,,-40.4487145634925,,1.73630735168439E-6,,2.34429130357013E-7,,,,,,,,,,,,,,,,,,,,,,,,,,
,30484818.645,4370,285.54185,312.857,90.014,0.102153342753992,173,0.00233331636464796,,3.45774402279657E-7,,22.84185067865,,0.00338493630098958,,,,,,,,,,0,1250,-87.2200483515894,,-82.1967423873386,,6.28474720087575E-7,,0.00233331636493791,,,,,,,,,,,,,,,,,,,,,,,,,,,
,30484939.555,4370,281.5093,312.857,90.014,0.102153342753992,173,,2.12524436592374E-7,,6.62661724822745E-9,,0.00208044590893388,,5.87550157949697E-5,,,,,,,,,0,125000,,-45.0375270431691,,-37.0156921225041,,1.69908362537836E-6,,2.34640712075611E-7,,,,,,,,,,,,,,,,,,,,,,,,,,
,30485061.07,4370,277.46075,312.857,90.014,0.102153342753992,173,0.00231296151431736,,3.60688638092217E-7,,22.6425835196854,,0.00353093752819451,,,,,,,,,,0,1250,-88.7532993550054,,-81.4722953684457,,4.06383225782748E-7,,0.00231296151443966,,,,,,,,,,,,,,,,,,,,,,,,,,,
,30485179.645,4370,273.49565,312.857,90.014,0.102153342753992,173,,2.12494463209445E-7,,6.19788568034276E-9,,0.00208015249316169,,5.53166599170328E-5,,,,,,,,,0,125000,,-43.4268019170477,,-39.6914529542644,,1.63581569845013E-6,,2.33068073336914E-7,,,,,,,,,,,,,,,,,,,,,,,,,,
,30485298.775,4370,269.5321,312.857,90.014,0.102153342753992,173,0.00229283472102332,,3.37637742291081E-7,,22.4455490432641,,0.00330528163789501,,,,,,,,,,0,1250,-84.7937038929022,,-82.6348415861379,,7.3251451256013E-7,,0.00229283472142416,,,,,,,,,,,,,,,,,,,,,,,,,,,
,30485415.195,4370,265.63355,312.857,90.014,0.102153342753992,173,,2.09118242284483E-7,,6.89241860275664E-9,,0.00204710195405198,,6.10782378162425E-5,,,,,,,,,0,125000,,-43.143447901084,,-38.4897383559266,,1.67695187832565E-6,,2.31006723414263E-7,,,,,,,,,,,,,,,,,,,,,,,,,,
,30485534.86,4370,261.6458,312.857,90.014,0.102153342753992,173,0.00227274690350014,,3.22807596475026E-7,,22.2488962063583,,0.00316010229414869,,,,,,,,,,0,1250,-87.6232561282053,,-82.4641375386883,,1.42360597468521E-6,,0.00227274690502753,,,,,,,,,,,,,,,,,,,,,,,,,,,
,30485653.15,4370,257.6956,312.857,90.014,0.102153342753992,173,,2.03740204424218E-7,,6.03058113938531E-9,,0.00199445520721227,,5.30149341153908E-5,,,,,,,,,0,125000,,-46.9845964243925,,-57.5970826421976,,1.70527718234653E-6,,2.26874260180801E-7,,,,,,,,,,,,,,,,,,,,,,,,,,
,30485772.29,4370,253.7311,312.857,90.014,0.102153342753992,173,0.0022525095575839,,3.33802833509209E-7,,22.0507796185823,,0.0032677387275295,,,,,,,,,,0,1250,-88.294410303064,,-81.7042132928903,,9.6681218359832E-7,,0.00225250955829468,,,,,,,,,,,,,,,,,,,,,,,,,,,
,30485889.43,4370,249.8352,312.857,90.014,0.102153342753992,173,,1.96501684596477E-7,,6.17932705518847E-9,,0.00192359581135276,,5.43276932510028E-5,,,,,,,,,0,125000,,-40.2126696553878,,-49.738286951724,,1.64388886641365E-6,,2.18793159235045E-7,,,,,,,,,,,,,,,,,,,,,,,,,,
,30486007.93,4370,245.87435,312.857,90.014,0.102153342753992,173,0.00223244653479876,,3.41174628244396E-7,,21.8543696737311,,0.00333990369985067,,,,,,,,,,0,1250,-85.9608154163663,,-81.2146116880755,,1.72866580860103E-6,,0.00223244653709153,,,,,,,,,,,,,,,,,,,,,,,,,,,
,30486124.915,4370,241.98245,312.857,90.014,0.102153342753992,173,,1.91090539687957E-7,,4.6095879311923E-9,,0.00187062497463334,,4.0147964026855E-5,,,,,,,,,0,125000,,-50.1830867074034,,-52.8286025724202,,1.67515575504217E-6,,2.14775780437806E-7,,,,,,,,,,,,,,,,,,,,,,,,,,
,30486244.44,4370,237.9929,312.857,90.014,0.102153342753992,173,0.00221222713541685,,3.43826365653405E-7,,21.6564289375373,,0.00336586200019152,,,,,,,,,,0,1250,-88.8582867330596,,-81.3866809728294,,1.19676862351999E-6,,0.0022122271365258,,,,,,,,,,,,,,,,,,,,,,,,,,,
,30486361.525,4370,234.1047,312.857,90.014,0.102153342753992,173,,1.97185653398639E-7,,6.30627040811829E-9,,0.0019302913260142,,5.59313632415071E-5,,,,,,,,,0,125000,,-41.4338785985495,,-41.2007033174037,,1.57382991776338E-6,,2.17640664607601E-7,,,,,,,,,,,,,,,,,,,,,,,,,,
,30486479.95,4370,230.1504,312.857,90.014,0.102153342753992,173,0.0021920326102656,,3.28242857947391E-7,,21.4587317919917,,0.00321330777983237,,,,,,,,,,0,1250,-89.2245144437603,,-82.5736132628151,,2.10418766584792E-6,,0.00219203261372533,,,,,,,,,,,,,,,,,,,,,,,,,,,
,30486596.54,4370,226.26385,312.857,90.014,0.102153342753992,173,,1.87783890290165E-7,,5.49604348767665E-9,,0.00183825548794974,,4.85643188730279E-5,,,,,,,,,0,125000,,-48.7873808583573,,-47.4624600681738,,1.52971313358778E-6,,2.08036112472756E-7,,,,,,,,,,,,,,,,,,,,,,,,,,
,30486717.915,4370,222.2235,312.857,90.014,0.102153342753992,173,0.00217164138338355,,3.23169766723838E-7,,21.2591090890755,,0.00316364449714643,,,,,,,,,,0,1250,-91.0572769964981,,-81.0924423846857,,2.26101173861892E-6,,0.00217164138741572,,,,,,,,,,,,,,,,,,,,,,,,,,,
,30486834.98,4370,218.32145,312.857,90.014,0.102153342753992,173,,1.9560748007184E-7,,5.49002137966545E-9,,0.00191484225494492,,4.88555293613911E-5,,,,,,,,,0,125000,,-39.9630114739411,,-52.0386623510161,,1.53181843790631E-6,,2.15175744808163E-7,,,,,,,,,,,,,,,,,,,,,,,,,,
,30486954.915,4370,214.3223,312.857,90.014,0.102153342753992,173,0.00215066656713678,,3.21244481019127E-7,,21.0537733441649,,0.00314479639656691,,,,,,,,,,0,1250,-88.50890786374,,-81.997794206567,,2.88814721292217E-6,,0.00215066657378011,,,,,,,,,,,,,,,,,,,,,,,,,,,
,30487072.57,4370,210.4029,312.857,90.014,0.102153342753992,173,,1.85894292080697E-7,,5.99338363833336E-9,,0.0018197578136438,,5.25713411759406E-5,,,,,,,,,0,125000,,-35.8294556217547,,-52.1555431624325,,1.57365656683566E-6,,2.07461070272512E-7,,,,,,,,,,,,,,,,,,,,,,,,,,
,30487194.125,4370,206.3593,312.857,90.014,0.102153342753992,173,0.00212944621498044,,3.13047301451193E-7,,20.8460339815205,,0.003064550126453,,,,,,,,,,0,1250,-88.8604773778003,,-81.893235322386,,2.58577404862654E-6,,0.00212944622035862,,,,,,,,,,,,,,,,,,,,,,,,,,,
,30487315.99,4370,202.2985,312.857,90.014,0.102153342753992,173,,1.8479010337434E-7,,5.9372001985399E-9,,0.00180894867820491,,5.20426261023733E-5,,,,,,,,,0,125000,,-45.7973188967811,,-40.473489305595,,1.56977604404696E-6,,2.06371031897195E-7,,,,,,,,,,,,,,,,,,,,,,,,,,
,30487434.71,4370,198.3357,312.857,90.014,0.102153342753992,173,0.00210771236344979,,3.07298142311341E-7,,20.6332677431931,,0.00300826855447747,,,,,,,,,,0,1250,-89.5588966887554,,-81.4411233601917,,3.03012127605223E-6,,0.00210771237091135,,,,,,,,,,,,,,,,,,,,,,,,,,,
,30487552.3,4370,194.4129,312.857,90.014,0.102153342753992,173,,1.80997273170821E-7,,5.71824208688563E-9,,0.00177181986604555,,5.0250850939165E-5,,,,,,,,,0,125000,,-41.2394633058939,,-49.9470040763895,,1.51777100696662E-6,,2.01622355423741E-7,,,,,,,,,,,,,,,,,,,,,,,,,,
,30487670.89,4370,190.4686,312.857,90.014,0.102153342753992,173,0.00208616217208278,,3.14085534320367E-7,,20.4222995611537,,0.00307471247174069,,,,,,,,,,0,1250,-87.089118297111,,-81.0299335147473,,2.89370040004484E-6,,0.00208616217895789,,,,,,,,,,,,,,,,,,,,,,,,,,,
,30487789.4,4370,186.52305,312.857,90.014,0.102153342753992,173,,1.80530372262062E-7,,5.83048589036054E-9,,0.00176724927493077,,5.15320151055101E-5,,,,,,,,,0,125000,,-48.1078236033036,,-44.4211271235781,,1.46870019589352E-6,,1.99951854029709E-7,,,,,,,,,,,,,,,,,,,,,,,,,,
,30487908.555,4370,182.5524,312.857,90.014,0.102153342753992,173,0.00206418094209217,,3.24785949462649E-7,,20.2071117695261,,0.00317946253047633,,,,,,,,,,0,1250,-90.1138516084027,,-81.857989245547,,2.7846374139591E-6,,0.00206418094852659,,,,,,,,,,,,,,,,,,,,,,,,,,,
,30488025.165,4370,178.66405,312.857,90.014,0.102153342753992,173,,1.78408820242928E-7,,6.23358215589849E-9,,0.00174648095645281,,5.48646804234208E-5,,,,,,,,,0,125000,,-39.0552714274751,,-51.6084818590992,,1.48407042780546E-6,,1.98430619512246E-7,,,,,,,,,,,,,,,,,,,,,,,,,,
,30488144.53,4370,174.6902,312.857,90.014,0.102153342753992,173,0.00204207781186869,,2.95908607704617E-7,,19.9907307179086,,0.00289676976598975,,,,,,,,,,0,1250,-88.9183472910167,,-81.4354458118173,,3.42572263438713E-6,,0.00204207782171225,,,,,,,,,,,,,,,,,,,,,,,,,,,
,30488261.07,4370,170.80345,312.857,90.014,0.102153342753992,173,,1.72602224419653E-7,,5.03304469145521E-9,,0.00168963897057847,,4.41563823666198E-5,,,,,,,,,0,125000,,-43.3128278448827,,-40.4433759568592,,1.45967107857822E-6,,1.92588885129649E-7,,,,,,,,,,,,,,,,,,,,,,,,,,
,30488378.785,4370,166.88185,312.857,90.014,0.102153342753992,173,0.00201972015793223,,3.23172948607054E-7,,19.7718580764676,,0.00316367077663218,,,,,,,,,,0,1250,-88.3487913140899,,-80.8597252300034,,3.5275981212173E-6,,0.00201972016848551,,,,,,,,,,,,,,,,,,,,,,,,,,,
,30488497.265,4370,162.93875,312.857,90.014,0.102153342753992,173,,1.75993731849827E-7,,6.0662078126032E-9,,0.00172283914889481,,5.35363109585208E-5,,,,,,,,,0,125000,,-44.0310875366922,,-41.2441575457656,,1.44320150517108E-6,,1.95215174855468E-7,,,,,,,,,,,,,,,,,,,,,,,,,,
,30488616.335,4370,158.96535,312.857,90.014,0.102153342753992,173,0.00199671346682971,,2.9915757083022E-7,,19.5466317196451,,0.00292857384074234,,,,,,,,,,0,1250,-86.3221021711887,,-81.1117067306855,,3.82452681767359E-6,,0.0019967134793773,,,,,,,,,,,,,,,,,,,,,,,,,,,
,30488733.595,4370,155.0553,312.857,90.014,0.102153342753992,173,,1.71317004482653E-7,,4.89881500635443E-9,,0.00167705768285768,,4.2812996489847E-5,,,,,,,,,0,125000,,-43.0145567352793,,-42.8117368503226,,1.47708406645019E-6,,1.91894892132894E-7,,,,,,,,,,,,,,,,,,,,,,,,,,
,30488852.4,4370,151.10305,312.857,90.014,0.102153342753992,173,0.0019735699604064,,2.81602469622084E-7,,19.3200661009389,,0.00275671924586546,,,,,,,,,,0,1250,-88.6206498018413,,-82.7835372797366,,3.79028858442955E-6,,0.00197356997287485,,,,,,,,,,,,,,,,,,,,,,,,,,,
,30488970.155,4370,147.1832,312.857,90.014,0.102153342753992,173,,1.6680571858052E-7,,4.66735249997589E-9,,0.00163289575866059,,4.07285722414307E-5,,,,,,,,,0,125000,,-64.3695994621341,,-43.2522883557249,,1.44886745990076E-6,,1.87124165713618E-7,,,,,,,,,,,,,,,,,,,,,,,,,,
,30489088.345,4370,143.23895,312.857,90.014,0.102153342753992,173,0.0019499650023281,,3.07273686322857E-7,,19.0889831653476,,0.00300802433773129,,,,,,,,,,0,1250,-85.2032602667609,,-81.9306395993316,,3.92203507009024E-6,,0.00194996501584001,,,,,,,,,,,,,,,,,,,,,,,,,,,
,30489206.85,4370,139.29755,312.857,90.014,0.102153342753992,173,,1.71516443786013E-7,,5.77184322684924E-9,,0.00167901003605583,,5.07250727273131E-5,,,,,,,,,0,125000,,-48.3524180319191,,-40.6938339501836,,1.43780319565347E-6,,1.9104916333028E-7,,,,,,,,,,,,,,,,,,,,,,,,,,
,30489327.165,4370,135.2873,312.857,90.014,0.102153342753992,173,0.00192560433670283,,2.91602693899675E-7,,18.8505022759761,,0.0028546140447539,,,,,,,,,,0,1250,-88.0146828899106,,-82.12929179841,,4.89513235237349E-6,,0.00192560435801768,,,,,,,,,,,,,,,,,,,,,,,,,,,
,30489444.545,4370,131.37255,312.857,90.014,0.102153342753992,173,,1.67711382314727E-7,,5.75805161501216E-9,,0.00164176149092197,,5.07814832688302E-5,,,,,,,,,0,125000,,-42.7957346219781,,-51.368815214739,,1.38037427778722E-6,,1.86157370674332E-7,,,,,,,,,,,,,,,,,,,,,,,,,,
,30489563.835,4370,127.39685,312.857,90.014,0.102153342753992,173,0.00190099786907372,,2.947654953424E-7,,18.6096152054019,,0.00288557523991839,,,,,,,,,,0,1250,-90.9707693695553,,-80.7124042508931,,4.8838554477837E-6,,0.0019009978905651,,,,,,,,,,,,,,,,,,,,,,,,,,,
,30489680.52,4370,123.50625,312.857,90.014,0.102153342753992,173,,1.59854048551908E-7,,5.715046034532E-9,,0.00156484440340327,,5.03056400058154E-5,,,,,,,,,0,125000,,-44.2248014085686,,-38.199953802397,,1.32905711954587E-6,,1.77776444177942E-7,,,,,,,,,,,,,,,,,,,,,,,,,,
,30489800.99,4370,119.49115,312.857,90.014,0.102153342753992,173,0.00187582054511524,,2.96485902230849E-7,,18.3631398131411,,0.00290241624408943,,,,,,,,,,0,1250,-86.8146217099863,,-81.7734171245281,,4.52022030743022E-6,,0.00187582056377252,,,,,,,,,,,,,,,,,,,,,,,,,,,
,30489918.525,4370,115.57185,312.857,90.014,0.102153342753992,173,,1.61358475797773E-7,,4.70985236684276E-9,,0.00157957155698123,,4.12968391006025E-5,,,,,,,,,0,125000,,-43.2091267295434,,-43.3818522903494,,1.36862314453599E-6,,1.80148142043564E-7,,,,,,,,,,,,,,,,,,,,,,,,,,
,30490038,4370,111.59205,312.857,90.014,0.102153342753992,173,0.00184995263376233,,2.82759632845528E-7,,18.1099039919632,,0.00276804369960254,,,,,,,,,,0,1250,-92.005732903791,,-80.5386812732929,,5.27025868484617E-6,,0.00184995265947953,,,,,,,,,,,,,,,,,,,,,,,,,,,
,30490156.24,4370,107.6428,312.857,90.014,0.102153342753992,173,,1.57494087310935E-7,,5.86750179544583E-9,,0.00154174224839453,,5.13024901939633E-5,,,,,,,,,0,125000,,-43.5071466268808,,-39.8382390627629,,1.35481092770267E-6,,1.763301425792E-7,,,,,,,,,,,,,,,,,,,,,,,,,,
,30490275.64,4370,103.6768,312.857,90.014,0.102153342753992,173,0.00182332438825898,,2.66096728920705E-7,,17.849224962022,,0.00260492336676185,,,,,,,,,,0,1250,-89.9058796393293,,-82.1736894357307,,5.42430878854909E-6,,0.00182332441589944,,,,,,,,,,,,,,,,,,,,,,,,,,,
,30490385.475,4370,100.01055,312.857,90.014,0.102153342753992,173,,1.52972890254401E-7,,4.61811115259375E-9,,0.00149748330365477,,4.00294890275221E-5,,,,,,,,,0,125000,,-45.0619510204712,,-40.0447295577206,,1.37170670187613E-6,,1.7276124460835E-7,,,,,,,,,,,,,,,,,,,,,,,,,,
,30490498.995,4370,96.2178,312.857,90.014,0.102153342753992,173,0.00179740657413318,,2.71771978770497E-7,,17.5955008833979,,0.00266047984467225,,,,,,,,,,0,2500,-88.6837461698032,,-81.6684882839821,,-7.14348921080638E-6,,0.00179740662276212,,,,,,,,,,,,,,,,,,,,,,,,,,,
,30490614.18,4370,92.37625,312.857,90.014,0.102153342753992,173,,1.51346065988101E-7,,5.40908520385921E-9,,0.00148155798039583,,4.70663553286913E-5,,,,,,,,,0,125000,,-43.3185231457852,,-44.0889507508588,,1.33281442406529E-6,,1.70267557248764E-7,,,,,,,,,,,,,,,,,,,,,,,,,,
,30490728.085,4370,88.5818,312.857,90.014,0.102153342753992,173,0.0017680792505229,,2.64425731954331E-7,,17.3083993566323,,0.00258856385340868,,,,,,,,,,0,2500,-86.9009122239032,,-82.5736029610751,,-7.22681466624978E-6,,0.00176807930111848,,,,,,,,,,,,,,,,,,,,,,,,,,,
,30490842.625,4370,84.76585,312.857,90.014,0.102153342753992,173,,1.47187326224688E-7,,5.68846023038514E-9,,0.0014408472067234,,4.92772277245848E-5,,,,,,,,,0,125000,,-42.2671751724889,,-38.5607267113191,,1.32354130262686E-6,,1.66328391672457E-7,,,,,,,,,,,,,,,,,,,,,,,,,,
,30490954.875,4370,81.02015,312.857,90.014,0.102153342753992,173,0.00172195641561838,,2.66654984046543E-7,,16.8568775472795,,0.0026103856378165,,,,,,,,,,0,2500,-86.5108511978694,,-82.1359357362409,,-6.7174329769363E-6,,0.00172195646050376,,,,,,,,,,,,,,,,,,,,,,,,,,,
,30491062.84,4370,77.4284,312.857,90.014,0.102153342753992,173,,1.34227238058368E-7,,6.0663055489188E-9,,0.00131397819528093,,5.16889458186468E-5,,,,,,,,,0,125000,,-40.52903372503,,-39.0797340759924,,1.29714162682183E-6,,1.54210790933088E-7,,,,,,,,,,,,,,,,,,,,,,,,,,
,30491169.66,4370,73.8777,312.857,90.014,0.102153342753992,173,0.00138594804323481,,1.90044567969462E-7,,13.5675194124577,,0.00186041122139137,,,,,,,,,,0,2500,-84.5569572161083,,-88.8135435348477,,-5.64465406180653E-6,,0.00138594808261231,,,,,,,,,,,,,,,,,,,,,,,,,,,
,30491275.96,4370,70.32485,312.857,90.014,0.102153342753992,173,,1.26548535058664E-7,,4.46252368397271E-9,,0.00123880976924735,,3.79698205970242E-5,,,,,,,,,0,125000,,-40.4172679460926,,-46.7200214934088,,1.23007501955399E-6,,1.45595050181415E-7,,,,,,,,,,,,,,,,,,,,,,,,,,
,30491383.83,4370,66.7399,312.857,90.014,0.102153342753992,173,0.00123109031246158,,2.08960391830501E-7,,12.0515452560888,,0.00204558146419491,,,,,,,,,,0,2500,-77.7876038226094,,-83.2561885952476,,-5.77607682417845E-6,,0.00123109035888065,,,,,,,,,,,,,,,,,,,,,,,,,,,
,30491490.565,4370,63.1701,312.857,90.014,0.102153342753992,173,,1.25136213087366E-7,,5.50161573243114E-9,,0.00122498425493868,,4.63525156852307E-5,,,,,,,,,0,125000,,-37.3957089865617,,-45.8951069431534,,1.26483069343789E-6,,1.45394323249179E-7,,,,,,,,,,,,,,,,,,,,,,,,,,
,30491596.805,4370,59.6408,312.857,90.014,0.102153342753992,173,0.00118710870482483,,1.99628813524355E-7,,11.6209897637612,,0.00195423073683971,,,,,,,,,,0,2500,-77.1576763957905,,-87.9366741254471,,-5.31249016783164E-6,,0.00118710874554656,,,,,,,,,,,,,,,,,,,,,,,,,,,
,30491704.655,4370,56.0393,312.857,90.014,0.102153342753992,173,,1.2449899490883E-7,,5.69483141034767E-9,,0.0012187463933199,,4.857924058437E-5,,,,,,,,,0,125000,,-43.5890855708077,,-37.9768543369828,,1.19744877198393E-6,,1.42870805686476E-7,,,,,,,,,,,,,,,,,,,,,,,,,,
,30491812.465,4370,52.43555,312.857,90.014,0.102153342753992,173,0.00115156332586677,,2.80850593322375E-7,,11.2730205408038,,0.0027493359167534,,,,,,,,,,0,2500,-77.7538321619935,,-71.6510758097352,,-4.8248629385376E-6,,0.00115156336049279,,,,,,,,,,,,,,,,,,,,,,,,,,,
,30491918.935,4370,48.8956,312.857,90.014,0.102153342753992,173,,1.22681214742501E-7,,4.44046636701042E-9,,0.00120095176430375,,3.74793454253289E-5,,,,,,,,,0,125000,,-44.6811667178842,,-38.0885022359646,,1.23140759693382E-6,,1.42285993986135E-7,,,,,,,,,,,,,,,,,,,,,,,,,,
,30492024.53,4370,45.3833,312.857,90.014,0.102153342753992,173,0.00112760094428684,,1.9169883311133E-7,,11.0384424739178,,0.00187660048548201,,,,,,,,,,0,2500,-77.1022885983497,,-93.6254726035843,,-4.66885003537361E-6,,0.0011276009773988,,,,,,,,,,,,,,,,,,,,,,,,,,,
,30492131.48,4370,41.80965,312.857,90.014,0.102153342753992,173,,1.15918104445459E-7,,4.74760550972534E-9,,0.00113474626849147,,3.97017524727713E-5,,,,,,,,,0,125000,,-36.6035355103569,,-36.5231992306118,,1.205230119111E-6,,1.35694958053179E-7,,,,,,,,,,,,,,,,,,,,,,,,,,
,30492238.005,4370,38.2665,312.857,90.014,0.102153342753992,173,0.00111099801185012,,1.9194803787016E-7,,10.8759092889098,,0.0018790397086019,,,,,,,,,,0,2500,-77.0159240087992,,-85.1413637192655,,-4.83117818313338E-6,,0.00111099804783444,,,,,,,,,,,,,,,,,,,,,,,,,,,
,30492346.675,4370,34.63545,312.857,90.014,0.102153342753992,173,,1.13386122037687E-7,,5.19566444682935E-9,,0.00110996016549949,,4.34769137334403E-5,,,,,,,,,0,125000,,-39.8865075085597,,-40.2978215603918,,1.176064664873E-6,,1.32644662973095E-7,,,,,,,,,,,,,,,,,,,,,,,,,,
,30492452.905,4370,31.0901,312.857,90.014,0.102153342753992,173,0.00109890645439518,,1.98382306949381E-7,,10.7575399115554,,0.00194202655987133,,,,,,,,,,0,2500,-76.765765123744,,-83.8755574618223,,-4.58032465000841E-6,,0.00109890648709552,,,,,,,,,,,,,,,,,,,,,,,,,,,
,30492559.515,4370,27.5407,312.857,90.014,0.102153342753992,173,,1.04458195534374E-7,,4.61048637269268E-9,,0.00102256283550582,,3.74670569095335E-5,,,,,,,,,0,125000,,-48.6012986946554,,-36.0290014175061,,1.19864554565813E-6,,1.25830860686631E-7,,,,,,,,,,,,,,,,,,,,,,,,,,
,30492669.915,4370,23.8636,312.857,90.014,0.102153342753992,173,0.00109224955816876,,1.82060938165968E-7,,10.6923727471904,,0.0017822514448201,,,,,,,,,,0,2500,-77.6223084247135,,-86.1762662289112,,-4.64963158223303E-6,,0.00109224959207157,,,,,,,,,,,,,,,,,,,,,,,,,,,
,30492776.905,4370,20.29005,312.857,90.014,0.102153342753992,173,,1.05124704783304E-7,,4.64549371959103E-9,,0.00102908743313021,,3.76830136317967E-5,,,,,,,,,0,125000,,-42.8720520342557,,-38.3180459706894,,1.21333669249401E-6,,1.26864036253262E-7,,,,,,,,,,,,,,,,,,,,,,,,,,
,30492884.235,4370,16.72285,312.857,90.014,0.102153342753992,173,0.00108914418991904,,1.84478357810865E-7,,10.6619729908641,,0.0018059162634071,,,,,,,,,,0,2500,-79.1937731914334,,-85.0103739939035,,-4.69515021236934E-6,,0.00108914422458746,,,,,,,,,,,,,,,,,,,,,,,,,,,
,30492991.635,4370,13.14615,312.857,90.014,0.102153342753992,173,,9.9859083479234E-8,,5.28865727490771E-9,,0.000977541171663129,,4.30525440401733E-5,,,,,,,,,0,125000,,-43.3291371445681,,-38.3666077812892,,1.13949392843905E-6,,1.20083036770461E-7,,,,,,,,,,,,,,,,,,,,,,,,,,
,30493100.275,4375,9.6221,312.857,90.014,0.102153342753992,173,0.00109016996460984,,3.07305722674816E-7,,10.6720147306782,,0.00300831173227857,,,,,,,,,,0,2500,-85.7362017395153,,-69.1879071720814,,-4.70187216071022E-6,,0.00109016999934489,,,,,,,,,,,,,,,,,,,,,,,,,,,
,30493232.725,4375,8.9003,312.857,90.014,0.102153342753992,173,,1.01389946109133E-7,,5.40151522336101E-9,,0.000992527104071527,,4.44289557515394E-5,,,,,,,,,0,125000,,-47.7731378112811,,-37.6788559630294,,1.11786335802944E-6,,1.20667933143016E-7,,,,,,,,,,,,,,,,,,,,,,,,,,
,30493343.38,4375,8.151,312.857,90.014,0.102153342753992,173,0.00109111754092098,,3.5578073805114E-7,,10.6812909538542,,0.00348284883251556,,,,,,,,,,0,2500,-91.8404631677259,,-67.1753655679014,,-4.78851070711707E-6,,0.00109111757691661,,,,,,,,,,,,,,,,,,,,,,,,,,,
,30493457.95,4375,7.42795,312.857,90.014,0.102153342753992,173,,1.00502682863759E-7,,5.5021359421784E-9,,0.000983841499774505,,4.44384747745879E-5,,,,,,,,,0,125000,,-43.1691712248892,,-35.60629373012,,1.17602427761144E-6,,1.21814029504261E-7,,,,,,,,,,,,,,,,,,,,,,,,,,
,30493603.32,4375,7.0353,312.857,90.014,0.102153342753992,173,0.00109210128306467,,3.96739381788472E-7,,10.6909212197689,,0.00388380586267982,,,,,,,,,,0,2500,-96.0513391131615,,-66.0470926877457,,-4.24320141987773E-6,,0.00109210131130338,,,,,,,,,,,,,,,,,,,,,,,,,,,
,30493794.97,4373,4.99345,312.857,90.014,0.102153342753992,173,,1.025811186032E-7,,5.83955896652535E-9,,0.00100418773919758,,4.75068856039927E-5,,,,,,,,,0,125000,,-47.7306115933734,,-39.6015500439148,,1.17297350462882E-6,,1.23435022985662E-7,,,,,,,,,,,,,,,,,,,,,,,,,,