File: Data/Gd (3 nm)/YBCO_Gd_3_12202017_resistivity.dat
[Header]
; AC Transport Data File (default extension .dat)
; Copyright 1998, Quantum Design, Inc. All rights reserved.
TITLE,PPMS_MANG
FILEOPENTIME,30562855.11,12/20/2017,7:09 pm
BYAPP,ACTRANSPORT,2.0,1.1
INFO,PPMS AC Transport Option Release 2.2.4. Build 2,APPNAME
INFO,,SAMPLE1_MATERIAL
INFO,,SAMPLE1_COMMENT
INFO,1.0,SAMPLE1_LEAD_SEPARATION
INFO,1.0,SAMPLE1_CROSS_SECTION
INFO,,SAMPLE2_MATERIAL
INFO,,SAMPLE2_COMMENT
INFO,1.0,SAMPLE2_LEAD_SEPARATION
INFO,1.0,SAMPLE2_CROSS_SECTION
DATATYPE,COMMENT,1
DATATYPE,TIME,2
FIELDGROUP,ACResist,2,4,5,6,7,8,9,10,13,14,15,16,53
FIELDGROUP,ACHall,2,4,5,6,7,8,9,10,17,18,19,20,53
FIELDGROUP,ACIVcurve,2,4,5,6,7,8,9,10,53
FIELDGROUP,ACCritCurrent,2,4,5,6,7,8,9,21,22,23,24,53
STARTUPGROUP,All
STARTUPAXIS,X,2
STARTUPAXIS,Y1,3
[Data]
Comment,Time Stamp (sec),Status (code),Temperature (K),Magnetic Field (Oe),Sample Position (deg),Excitation (mA),Frequency (Hz),Volts ch1,Volts ch2,V Std.Dev. ch1,V Std.Dev. ch2,Res. ch1 (ohm-cm),Res. ch2 (ohm-cm),Res. Std.Dev. ch1,Res. Std.Dev. ch2,Hall ch1 (cm^3/coul),Hall ch2 (cm^3/coul),Hall Std.Dev. ch1,Hall Std.Dev. ch2,Crit.Cur. ch1 (mA),Crit.Cur. ch2 (mA),C.Cur. Std.Dev. ch1,C.Cur. Std.Dev. ch2,ACT Status (code),ACT Gain,2nd Harm. ch1 (dB),2nd Harm. ch2 (dB),3rd Harm. ch1 (dB),3rd Harm. ch2 (dB),Quad.Error ch1 (ohm-cm-rad),Quad.Error ch2 (ohm-cm-rad),Drive Signal ch1 (V),Drive Signal ch2 (V),Bridge 1 Resistance (ohms),Bridge 1 Excitation (uA),Bridge 2 Resistance (ohms),Bridge 2 Excitation (uA),Bridge 3 Resistance (ohms),Bridge 3 Excitation (uA),Bridge 4 Resistance (ohms),Bridge 4 Excitation (uA),Signal 1 Vin (V),Signal 2 Vin (V),Digital Inputs (code),Drive 1 Iout (mA),Drive 1 Ipower (watts),Drive 2 Iout (mA),Drive 2 Ipower (watts),Pressure (),Map 20 (),Map 21 (),Map 22 (),Map 23 (),Map 24 (),Map 25 (),Map 26 (),Map 27 (),Map 28 (),Map 29 ()
,30562881.575,4370,300.00355,312.857,90.014,0.102153342753992,173,0.00428354214513538,,3.24370989111508E-6,,42.202330468554,,0.0319576864449744,,,,,,,,,,0,1000,-59.2859524587312,,-81.07033051431,,3.95817788080087E-5,,0.00428354277161648,,,,,,,,,,,,,,,,,,,,,,,,,,,
,30562937.775,4374,298.4331,312.857,90.014,0.102153342753992,173,0.00427246068941531,,3.13766720940322E-6,,42.0924529236359,,0.0309124172084947,,,,,,,,,,0,1000,-59.5691543966137,,-80.6012267720279,,4.20983937051759E-5,,0.00427246139993051,,,,,,,,,,,,,,,,,,,,,,,,,,,
,30562994.68,4374,295.62795,312.857,90.014,0.102153342753992,173,0.00426131453722225,,3.13871463400893E-6,,41.9819375751267,,0.0309222189030608,,,,,,,,,,0,1000,-59.5362991094807,,-80.7297815408171,,4.10025772062433E-5,,0.00426131521299258,,,,,,,,,,,,,,,,,,,,,,,,,,,
,30563047.565,4370,291.94105,312.857,90.014,0.102153342753992,173,0.00423702011043639,,3.06238046339631E-6,,41.7410684350871,,0.0301690828904346,,,,,,,,,,0,1000,-59.7071664716228,,-80.6578966127292,,4.20611915214878E-5,,0.004237020825629,,,,,,,,,,,,,,,,,,,,,,,,,,,
,30563104.165,4370,289.676,312.857,90.014,0.102153342753992,173,0.00422346063386573,,3.0430150964134E-6,,41.606639507779,,0.0299776940794745,,,,,,,,,,0,1000,-59.735617479468,,-80.6996880230035,,4.18512412030567E-5,,0.00422346134420959,,,,,,,,,,,,,,,,,,,,,,,,,,,
,30563153.4,4370,286.7536,312.857,90.014,0.102153342753992,173,0.00421006545538111,,3.03211776659498E-6,,41.4738448123851,,0.0298697405419798,,,,,,,,,,0,1000,-59.7389070369324,,-81.2853314611483,,3.942370745674E-5,,0.00421006608771504,,,,,,,,,,,,,,,,,,,,,,,,,,,
,30563202.27,4370,284.27615,312.857,90.014,0.102153342753992,173,0.00419955589612169,,3.05084967831513E-6,,41.369660787809,,0.0300537961221413,,,,,,,,,,0,1000,-59.6586020344638,,-81.0259188788686,,3.99880285271342E-5,,0.00419955654831602,,,,,,,,,,,,,,,,,,,,,,,,,,,
,30563245.37,4370,282.08475,312.857,90.014,0.102153342753992,173,0.00419013510950467,,3.11290037271765E-6,,41.276272848769,,0.0306646211505226,,,,,,,,,,0,1000,-59.4548874138815,,-81.9600227852109,,3.93734456607726E-5,,0.00419013574322731,,,,,,,,,,,,,,,,,,,,,,,,,,,
,30563288.97,4370,279.9197,312.857,90.014,0.102153342753992,173,0.00415900559731513,,2.8017106013752E-6,,40.9677058437907,,0.0275978535119838,,,,,,,,,,0,1000,-60.3538014536461,,-79.793354356924,,5.01155117144498E-5,,0.00415900663168345,,,,,,,,,,,,,,,,,,,,,,,,,,,
,30563332.595,4370,277.74325,312.857,90.014,0.102153342753992,173,0.00413733253489152,,2.84791784079181E-6,,40.7528916344035,,0.0280520963910076,,,,,,,,,,0,1000,-60.1683246034063,,-79.1908176957021,,5.57371657767984E-5,,0.00413733382103583,,,,,,,,,,,,,,,,,,,,,,,,,,,
,30563376.045,4370,275.55895,312.857,90.014,0.102153342753992,173,0.00414737396728468,,2.9222061235442E-6,,40.8524163176862,,0.0287842769820257,,,,,,,,,,0,1000,-59.9425264736765,,-81.0298516817675,,4.11222174976021E-5,,0.00414737466567828,,,,,,,,,,,,,,,,,,,,,,,,,,,
,30563425.7,4370,273.0766,312.857,90.014,0.102153342753992,173,0.00414385991827569,,3.14034596298493E-6,,40.8175868202614,,0.0309328337547011,,,,,,,,,,0,1000,-59.2760752624423,,-81.5360808443292,,3.31313202930316E-5,,0.00414386037200081,,,,,,,,,,,,,,,,,,,,,,,,,,,
,30563474.695,4370,270.6287,312.857,90.014,0.102153342753992,173,0.00410762922785282,,2.74762354529666E-6,,40.4585077622083,,0.0270629884610848,,,,,,,,,,0,1000,-60.4249653894253,,-79.5031020014567,,4.81275579635903E-5,,0.00410763019371864,,,,,,,,,,,,,,,,,,,,,,,,,,,
,30563518.65,4370,268.431,312.857,90.014,0.102153342753992,173,0.00408499825761039,,2.7483439153661E-6,,40.2342341157223,,0.0270691617157798,,,,,,,,,,0,1000,-60.369975932479,,-79.4339947995664,,5.47938407713611E-5,,0.00408499951651255,,,,,,,,,,,,,,,,,,,,,,,,,,,
,30563561.635,4370,266.27895,312.857,90.014,0.102153342753992,173,0.00407297022638309,,2.73237160878877E-6,,40.1150421423925,,0.0269113601533078,,,,,,,,,,0,1000,-60.3991028649235,,-79.148539199697,,5.44707947500831E-5,,0.00407297147415888,,,,,,,,,,,,,,,,,,,,,,,,,,,
,30563606.25,4370,264.04835,312.857,90.014,0.102153342753992,173,0.00409333045468819,,3.05125225236065E-6,,40.3168046846999,,0.0300529677338341,,,,,,,,,,0,1000,-59.4206085670719,,-81.8630433946972,,3.21809266228362E-5,,0.00409333088804008,,,,,,,,,,,,,,,,,,,,,,,,,,,
,30563649.75,4370,261.87175,312.857,90.014,0.102153342753992,173,0.00408183202603893,,3.08063436284291E-6,,40.2028578742669,,0.0303418398150333,,,,,,,,,,0,1000,-59.3121536398604,,-81.7753306182867,,3.06563949055274E-5,,0.00408183242041218,,,,,,,,,,,,,,,,,,,,,,,,,,,
,30563692.96,4370,259.724,312.857,90.014,0.102153342753992,173,0.00406886394452714,,3.03666306212667E-6,,40.0743518608259,,0.0299081740772147,,,,,,,,,,0,1000,-59.4105068874119,,-81.6786799763862,,3.19907135668093E-5,,0.00406886437534639,,,,,,,,,,,,,,,,,,,,,,,,,,,
,30563736.445,4370,257.5318,312.857,90.014,0.102153342753992,173,0.00405540252267694,,2.98929998591242E-6,,39.9409624315352,,0.029441098666256,,,,,,,,,,0,1000,-59.5268348102343,,-81.3941863793232,,3.18729842687648E-5,,0.00405540295175064,,,,,,,,,,,,,,,,,,,,,,,,,,,
,30563779.985,4370,255.36375,312.857,90.014,0.102153342753992,173,0.0040450704690149,,3.02657865219862E-6,,39.8385856166524,,0.0298077870341146,,,,,,,,,,0,1000,-59.3889853368189,,-81.6837238769305,,3.29249337713488E-5,,0.00404507092804814,,,,,,,,,,,,,,,,,,,,,,,,,,,
,30563824.54,4370,253.1323,312.857,90.014,0.102153342753992,173,0.00403115038320198,,2.98593635116255E-6,,39.7006612320442,,0.0294068999223423,,,,,,,,,,0,1000,-59.4784170472012,,-82.3255749224708,,3.05309825050156E-5,,0.00403115077927291,,,,,,,,,,,,,,,,,,,,,,,,,,,
,30563867.785,4370,250.97785,312.857,90.014,0.102153342753992,173,0.00401733037758826,,2.93554868837143E-6,,39.5637341766561,,0.0289100584447787,,,,,,,,,,0,1000,-59.5995452802315,,-81.8089400993595,,3.11510882089468E-5,,0.00401733079132997,,,,,,,,,,,,,,,,,,,,,,,,,,,
,30563912.425,4370,248.7467,312.857,90.014,0.102153342753992,173,0.00399633887497845,,2.75440324935336E-6,,39.3557636115148,,0.0271252341750927,,,,,,,,,,0,1000,-60.1339297446767,,-80.930864224985,,3.63308064176942E-5,,0.0039963394407071,,,,,,,,,,,,,,,,,,,,,,,,,,,
,30563956.795,4370,246.52365,312.857,90.014,0.102153342753992,173,0.00399216538979068,,2.93253316679712E-6,,39.3144169157599,,0.0288792694349131,,,,,,,,,,0,1000,-59.5482258808476,,-82.1240542367775,,3.06211442512672E-5,,0.00399216579209502,,,,,,,,,,,,,,,,,,,,,,,,,,,
,30563999.905,4370,244.3691,312.857,90.014,0.102153342753992,173,0.00394799069562769,,2.54294460195093E-6,,38.8768102266737,,0.0250409778721225,,,,,,,,,,0,1000,-60.7672334991413,,-79.5343953962685,,4.99060903178654E-5,,0.00394799177619382,,,,,,,,,,,,,,,,,,,,,,,,,,,
,30564042.675,4370,242.2319,312.857,90.014,0.102153342753992,173,0.00393268217332002,,2.53599401440697E-6,,38.7251733331066,,0.0249719592847728,,,,,,,,,,0,1000,-60.7558687787511,,-79.3678524134394,,5.13396707077118E-5,,0.00393268332130889,,,,,,,,,,,,,,,,,,,,,,,,,,,
,30564085.11,4370,240.10855,312.857,90.014,0.102153342753992,173,0.00395337498201256,,2.90989877535795E-6,,38.9301453438755,,0.0286546993729937,,,,,,,,,,0,1000,-59.5321518736693,,-82.0970845814856,,2.92782397507642E-5,,0.00395337535341293,,,,,,,,,,,,,,,,,,,,,,,,,,,
,30564129.595,4370,237.8911,312.857,90.014,0.102153342753992,173,0.00393922930781768,,2.84804707597411E-6,,38.7900244046668,,0.0280450302125522,,,,,,,,,,0,1000,-59.6933916532568,,-82.0587515161128,,2.95256577510941E-5,,0.00393922968687799,,,,,,,,,,,,,,,,,,,,,,,,,,,
,30564172.985,4370,235.6977,312.857,90.014,0.102153342753992,173,0.00392531449231843,,2.83003409142563E-6,,38.6521960596568,,0.027867072111305,,,,,,,,,,0,1000,-59.7204247743661,,-82.0419362070154,,2.94413687133473E-5,,0.00392531487055363,,,,,,,,,,,,,,,,,,,,,,,,,,,
,30564216.43,4370,233.53405,312.857,90.014,0.102153342753992,173,0.00391134868072273,,2.80913545430429E-6,,38.5138683818462,,0.0276607051771071,,,,,,,,,,0,1000,-59.7542994442147,,-82.0524079155543,,2.93738624507374E-5,,0.00391134905856974,,,,,,,,,,,,,,,,,,,,,,,,,,,
,30564259.825,4370,231.36845,312.857,90.014,0.102153342753992,173,0.00389865399291629,,2.81962983779644E-6,,38.3881358831211,,0.0277635111252597,,,,,,,,,,0,1000,-59.6885407934893,,-82.1927605412109,,2.84134734074869E-5,,0.00389865434761073,,,,,,,,,,,,,,,,,,,,,,,,,,,
,30564303.295,4370,229.19495,312.857,90.014,0.102153342753992,173,0.00388431604397392,,2.78562149779983E-6,,38.246133732106,,0.0274280571080232,,,,,,,,,,0,1000,-59.7679144496598,,-82.1941100448282,,2.88289701448777E-5,,0.00388431641046559,,,,,,,,,,,,,,,,,,,,,,,,,,,
,30564347.64,4370,226.97205,312.857,90.014,0.102153342753992,173,0.00386880652721503,,2.73446027676498E-6,,38.0925353303615,,0.0269236814276923,,,,,,,,,,0,1000,-59.8988885702064,,-81.9424703022172,,2.93354647952244E-5,,0.00386880690821886,,,,,,,,,,,,,,,,,,,,,,,,,,,
,30564392.39,4370,224.7413,312.857,90.014,0.102153342753992,173,0.00385582888518845,,2.76069418908267E-6,,37.964016831265,,0.0271814528953766,,,,,,,,,,0,1000,-59.78257040799,,-82.3725040748903,,2.79680152704898E-5,,0.00385582923266537,,,,,,,,,,,,,,,,,,,,,,,,,,,
,30564435.505,4370,222.5776,312.857,90.014,0.102153342753992,173,0.00384094706281755,,2.71147929435401E-6,,37.8166472651148,,0.0266962925700228,,,,,,,,,,0,1000,-59.9086785821877,,-82.2295037605812,,2.82578595298975E-5,,0.00384094741890824,,,,,,,,,,,,,,,,,,,,,,,,,,,
,30564479.11,4370,220.39785,312.857,90.014,0.102153342753992,173,0.00382718721699141,,2.70900173846778E-6,,37.6803941059638,,0.02667134846545,,,,,,,,,,0,1000,-59.8820427544646,,-82.289529686332,,2.7810732871021E-5,,0.00382718756314239,,,,,,,,,,,,,,,,,,,,,,,,,,,
,30564523.525,4370,218.1753,312.857,90.014,0.102153342753992,173,0.00381131028725141,,2.65494011529591E-6,,37.5231840901009,,0.0261384641138186,,,,,,,,,,0,1000,-60.0284306141248,,-82.3993028579063,,2.84746147423123E-5,,0.00381131065163753,,,,,,,,,,,,,,,,,,,,,,,,,,,
,30564572.265,4370,215.7541,312.857,90.014,0.102153342753992,173,0.00379546336309838,,2.6511714047369E-6,,37.3662786564919,,0.0261007394233934,,,,,,,,,,0,1000,-60.0029234842441,,-82.4522337970918,,2.80144277677359E-5,,0.00379546371727437,,,,,,,,,,,,,,,,,,,,,,,,,,,
,30564618.96,4370,213.4105,312.857,90.014,0.102153342753992,173,0.00378043802689573,,2.6442160299273E-6,,37.2175149214553,,0.0260316767615694,,,,,,,,,,0,1000,-59.9921685189851,,-82.3275632758927,,2.73399322867678E-5,,0.00378043836556295,,,,,,,,,,,,,,,,,,,,,,,,,,,
,30564664.625,4370,211.13215,312.857,90.014,0.102153342753992,173,0.00376502799224648,,2.62313999928607E-6,,37.0649493124248,,0.025823590863959,,,,,,,,,,0,1000,-60.0257297956485,,-82.2767742235784,,2.71343092982199E-5,,0.00376502832720401,,,,,,,,,,,,,,,,,,,,,,,,,,,
,30564713.575,4370,208.68715,312.857,90.014,0.102153342753992,173,0.0037162962828541,,2.27165008398654E-6,,36.5825320277553,,0.0223616961444247,,,,,,,,,,0,1000,-61.2480787847654,,-79.4896765139886,,4.79464857327524E-5,,0.00371629734240934,,,,,,,,,,,,,,,,,,,,,,,,,,,
,30564759.91,4370,206.35825,312.857,90.014,0.102153342753992,173,0.00371848610507397,,2.30517855247585E-6,,36.6042085561722,,0.0226918215777178,,,,,,,,,,0,1000,-61.0890266798516,,-81.5437639759369,,3.56151735134241E-5,,0.00371848668935848,,,,,,,,,,,,,,,,,,,,,,,,,,,
,30564808.06,4370,203.96315,312.857,90.014,0.102153342753992,173,0.00371528212230878,,2.55263719300538E-6,,36.5724931424293,,0.0251276471040611,,,,,,,,,,0,1000,-60.1494362898527,,-82.1490888291461,,2.65644558848178E-5,,0.00371528244764353,,,,,,,,,,,,,,,,,,,,,,,,,,,
,30564853.375,4370,201.6975,312.857,90.014,0.102153342753992,173,0.00369832230073339,,2.51219445670968E-6,,36.4046172463132,,0.0247289073718873,,,,,,,,,,0,1000,-60.2544472716672,,-82.9234830525793,,2.64929327213967E-5,,0.00369832262580252,,,,,,,,,,,,,,,,,,,,,,,,,,,
,30564909.85,4370,198.88155,312.857,90.014,0.102153342753992,173,0.00367912623102925,,2.50802569776183E-6,,36.2146162785753,,0.024687160700332,,,,,,,,,,0,1000,-60.2214311917879,,-82.7078948993302,,2.59824517719902E-5,,0.00367912654532318,,,,,,,,,,,,,,,,,,,,,,,,,,,
,30564957.61,4370,196.4937,312.857,90.014,0.102153342753992,173,0.00366172490902981,,2.47614021982413E-6,,36.0423890232118,,0.0243726668664536,,,,,,,,,,0,1000,-60.2938803781239,,-82.5182438668754,,2.60127486423617E-5,,0.00366172522555421,,,,,,,,,,,,,,,,,,,,,,,,,,,
,30564999.16,4370,194.40325,312.857,90.014,0.102153342753992,173,0.0036471952479526,,5.52100477427302E-7,,35.704457838708,,0.00540482377406864,,,,,,,,,,0,1250,-85.4076045082629,,-81.3484079005569,,-1.58070808571598E-5,,0.00364719536529765,,,,,,,,,,,,,,,,,,,,,,,,,,,
,30565040.6,4370,192.33635,312.857,90.014,0.102153342753992,173,0.00363200393523444,,5.44881355359797E-7,,35.5557360230675,,0.00533415088144041,,,,,,,,,,0,1250,-85.0143034385403,,-81.5019055949135,,-1.59819525129241E-5,,0.00363200405569192,,,,,,,,,,,,,,,,,,,,,,,,,,,
,30565083.04,4370,190.2074,312.857,90.014,0.102153342753992,173,0.00361632899158914,,5.51919417563928E-7,,35.4022795446949,,0.00540304958992958,,,,,,,,,,0,1250,-84.9223072932988,,-81.5282125167875,,-1.57110543770172E-5,,0.00361632910850223,,,,,,,,,,,,,,,,,,,,,,,,,,,
,30565124.235,4370,188.146,312.857,90.014,0.102153342753992,173,0.00360087653305779,,5.66592430259922E-7,,35.2510012258756,,0.00554669110331351,,,,,,,,,,0,1250,-85.7294217442637,,-80.9097561300274,,-1.53740298006854E-5,,0.00360087664548919,,,,,,,,,,,,,,,,,,,,,,,,,,,
,30565165.21,4370,186.1086,312.857,90.014,0.102153342753992,173,0.00358548560080235,,5.45462280921862E-7,,35.1003252913,,0.00533983538159418,,,,,,,,,,0,1250,-85.5440506776912,,-81.3147152530037,,-1.56292996310893E-5,,0.00358548571749714,,,,,,,,,,,,,,,,,,,,,,,,,,,
,30565206.405,4370,184.0451,312.857,90.014,0.102153342753992,173,0.00356995212549209,,5.57320086617055E-7,,34.9482539197257,,0.00545591722002812,,,,,,,,,,0,1250,-85.0209458176717,,-82.0094350658653,,-1.54580092841189E-5,,0.00356995224013974,,,,,,,,,,,,,,,,,,,,,,,,,,,
,30565247.575,4370,181.99385,312.857,90.014,0.102153342753992,173,0.00355455686459631,,5.6054016012012E-7,,34.7975357023656,,0.00548743947268817,,,,,,,,,,0,1250,-84.4986692190742,,-81.8037421673357,,-1.49080717583494E-5,,0.00355455697169346,,,,,,,,,,,,,,,,,,,,,,,,,,,
,30565287.55,4370,179.9891,312.857,90.014,0.102153342753992,173,0.00353905498255038,,5.25239618913253E-7,,34.6457737209516,,0.00514186203037547,,,,,,,,,,0,1250,-83.7193300172947,,-81.9382246331131,,-1.48387678870347E-5,,0.00353905508911887,,,,,,,,,,,,,,,,,,,,,,,,,,,
,30565326.415,4370,178.04765,312.857,90.014,0.102153342753992,173,0.00352410684342387,,5.2685727702857E-7,,34.4994328761911,,0.00515769740999023,,,,,,,,,,0,1250,-85.0561892652021,,-81.7432317553455,,-1.44760451845855E-5,,0.00352410694527626,,,,,,,,,,,,,,,,,,,,,,,,,,,
,30565367.25,4370,176.002,312.857,90.014,0.102153342753992,173,0.00350829417976846,,5.4568294685639E-7,,34.3446284675565,,0.00534199144739745,,,,,,,,,,0,1250,-83.2740657115058,,-81.4022545275668,,-1.47520477990797E-5,,0.00350829428601849,,,,,,,,,,,,,,,,,,,,,,,,,,,
,30565407.29,4370,174.0039,312.857,90.014,0.102153342753992,173,0.00349254476702527,,5.37894205769202E-7,,34.1904433282733,,0.00526574234125801,,,,,,,,,,0,1250,-83.4844815291499,,-82.0828604357272,,-1.39213250628904E-5,,0.00349254486207253,,,,,,,,,,,,,,,,,,,,,,,,,,,
,30565445.98,4370,172.0737,312.857,90.014,0.102153342753992,173,0.00347723136680132,,5.34908817954274E-7,,34.0405267540171,,0.00523651591797212,,,,,,,,,,0,1250,-83.551409127332,,-82.3882778216609,,-1.42773540956715E-5,,0.00347723146721255,,,,,,,,,,,,,,,,,,,,,,,,,,,
,30565486.845,4370,170.02475,312.857,90.014,0.102153342753992,173,0.0034608147733587,,5.35130723610436E-7,,33.8798100859713,,0.0052386874293457,,,,,,,,,,0,1250,-83.9418132285637,,-81.2097216584524,,-1.30062756431078E-5,,0.00346081485708231,,,,,,,,,,,,,,,,,,,,,,,,,,,
,30565525.675,4370,168.0749,312.857,90.014,0.102153342753992,173,0.00344537304648256,,5.25608051934457E-7,,33.7286373044917,,0.00514546397608362,,,,,,,,,,0,1250,-83.9969212459871,,-81.539471956517,,-1.33099769863818E-5,,0.00344537313455474,,,,,,,,,,,,,,,,,,,,,,,,,,,
,30565566.725,4370,166.0262,312.857,90.014,0.102153342753992,173,0.00342878583294512,,5.43866313897101E-7,,33.566250389112,,0.00532420316477396,,,,,,,,,,0,1250,-82.6996121494801,,-81.3012052677655,,-1.35367447731564E-5,,0.00342878592448463,,,,,,,,,,,,,,,,,,,,,,,,,,,
,30565607.93,4370,163.96155,312.857,90.014,0.102153342753992,173,0.003411833783306,,5.33034202915128E-7,,33.400291826469,,0.00521816085434719,,,,,,,,,,0,1250,-84.3404594688052,,-81.1609464711834,,-1.29785494811165E-5,,0.00341183386786988,,,,,,,,,,,,,,,,,,,,,,,,,,,
,30565647.645,4370,161.98815,312.857,90.014,0.102153342753992,173,0.00339540783378163,,5.54370377479421E-7,,33.2394837760369,,0.00542703132594334,,,,,,,,,,0,1250,-83.362099736189,,-81.8565170762397,,-1.33763919053307E-5,,0.00339540792404394,,,,,,,,,,,,,,,,,,,,,,,,,,,
,30565688.85,4370,159.9246,312.857,90.014,0.102153342753992,173,0.0033780550454368,,5.10956477502171E-7,,33.069602144154,,0.00500202832673385,,,,,,,,,,0,1250,-83.3823334267758,,-82.4210359542868,,-1.25179340328983E-5,,0.0033780551248914,,,,,,,,,,,,,,,,,,,,,,,,,,,
,30565729.825,4370,157.8721,312.857,90.014,0.102153342753992,173,0.00336089080359254,,5.33517795987655E-7,,32.9015664176105,,0.00522289231661026,,,,,,,,,,0,1250,-82.5662315903286,,-81.7351466718012,,-1.2924201486126E-5,,0.00336089088872075,,,,,,,,,,,,,,,,,,,,,,,,,,,
,30565769.455,4370,155.89105,312.857,90.014,0.102153342753992,173,0.00334393119373054,,5.00702820226278E-7,,32.7355340692061,,0.00490164804996002,,,,,,,,,,0,1250,-83.1870032011511,,-81.2046604615133,,-1.28582445017616E-5,,0.00334393127841943,,,,,,,,,,,,,,,,,,,,,,,,,,,
,30565810.715,4370,153.8356,312.857,90.014,0.102153342753992,173,0.0033262663465884,,5.26084430116311E-7,,32.5625976011807,,0.0051501213143689,,,,,,,,,,0,1250,-82.2919898334214,,-82.0163773693327,,-1.21777364723198E-5,,0.00332626642295379,,,,,,,,,,,,,,,,,,,,,,,,,,,
,30565851.695,4370,151.7885,312.857,90.014,0.102153342753992,173,0.00330843881892431,,5.40506052037119E-7,,32.3880685754341,,0.00529130131158675,,,,,,,,,,0,1250,-81.5207366625162,,-81.8728416875673,,-1.23368735010351E-5,,0.00330843889772093,,,,,,,,,,,,,,,,,,,,,,,,,,,
,30565892.67,4370,149.737,312.857,90.014,0.102153342753992,173,0.00329051942173301,,5.18634819909966E-7,,32.2126402231391,,0.00507719127187571,,,,,,,,,,0,1250,-82.0834053862196,,-81.5794981936048,,-1.18798231599644E-5,,0.00329051949519723,,,,,,,,,,,,,,,,,,,,,,,,,,,
,30565934.175,4370,147.6609,312.857,90.014,0.102153342753992,173,0.00327214046796271,,5.1731812090936E-7,,32.0327129432582,,0.00506430048014033,,,,,,,,,,0,1250,-81.8280254080447,,-80.9258285134935,,-1.10628401982659E-5,,0.00327214053202785,,,,,,,,,,,,,,,,,,,,,,,,,,,
,30565975.05,4370,145.6154,312.857,90.014,0.102153342753992,173,0.00325388521954728,,5.26702599381001E-7,,31.8539967869647,,0.00515616914558992,,,,,,,,,,0,1250,-81.5956323417554,,-80.943993653515,,-1.11269905960757E-5,,0.00325388528472117,,,,,,,,,,,,,,,,,,,,,,,,,,,
,30566015.86,4370,143.5761,312.857,90.014,0.102153342753992,173,0.00323553754253394,,5.20993644598387E-7,,31.6743758349617,,0.00510028023819451,,,,,,,,,,0,1250,-81.0596420738037,,-80.7583958058784,,-1.08612527225881E-5,,0.00323553760498414,,,,,,,,,,,,,,,,,,,,,,,,,,,
,30566055.975,4370,141.57015,312.857,90.014,0.102153342753992,173,0.00321697635275028,,5.33161251846876E-7,,31.4926646933893,,0.00521939434860804,,,,,,,,,,0,1250,-81.0277941592235,,-80.9637324217466,,-1.10083161640737E-5,,0.00321697641727325,,,,,,,,,,,,,,,,,,,,,,,,,,,
,30566097.255,4370,139.50415,312.857,90.014,0.102153342753992,173,0.00319808748528187,,5.11653529815412E-7,,31.3077457086001,,0.00500884304870841,,,,,,,,,,0,1250,-81.3206076779081,,-80.8647340492011,,-1.11338851774813E-5,,0.00319808755167506,,,,,,,,,,,,,,,,,,,,,,,,,,,
,30566138.175,4370,137.4614,312.857,90.014,0.102153342753992,173,0.00317909306211162,,5.18638032137652E-7,,31.1217934216226,,0.00507721701623547,,,,,,,,,,0,1250,-80.9142501911659,,-81.4408383488564,,-1.05701349302846E-5,,0.00317909312230909,,,,,,,,,,,,,,,,,,,,,,,,,,,
,30566178.29,4370,135.4527,312.857,90.014,0.102153342753992,173,0.00316031069041673,,5.2888951235115E-7,,30.9379171540239,,0.00517757310336272,,,,,,,,,,0,1250,-80.700421082357,,-80.8700975103257,,-1.01268029826661E-5,,0.00316031074599888,,,,,,,,,,,,,,,,,,,,,,,,,,,
,30566219.26,4370,133.40675,312.857,90.014,0.102153342753992,173,0.00314076404447585,,5.15126152109124E-7,,30.746558843932,,0.00504283545473259,,,,,,,,,,0,1250,-80.183500397198,,-81.8487733476218,,-9.8980695532391E-6,,0.00314076409790597,,,,,,,,,,,,,,,,,,,,,,,,,,,
,30566259.24,4370,131.40415,312.857,90.014,0.102153342753992,173,0.00312152341010741,,5.07817275064123E-7,,30.5581964084882,,0.00497128411961824,,,,,,,,,,0,1250,-80.1773366656654,,-80.8431967099317,,-1.00103143250882E-5,,0.00312152346509304,,,,,,,,,,,,,,,,,,,,,,,,,,,
,30566298.985,4370,129.41105,312.857,90.014,0.102153342753992,173,0.00310231326557976,,4.95592294340665E-7,,30.3701325363383,,0.0048516065779145,,,,,,,,,,0,1250,-80.4215697776722,,-81.5784994956093,,-9.00213462110001E-6,,0.00310231331032283,,,,,,,,,,,,,,,,,,,,,,,,,,,
,30566340.43,4370,127.34255,312.857,90.014,0.102153342753992,173,0.00308190404078133,,5.09383795461053E-7,,30.1703299632559,,0.00498661761495096,,,,,,,,,,0,1250,-80.5775391786082,,-81.4117190125247,,-8.69742191913555E-6,,0.00308190408282323,,,,,,,,,,,,,,,,,,,,,,,,,,,
,30566381.215,4370,125.3082,312.857,90.014,0.102153342753992,173,0.00306170007078131,,4.81599216542186E-7,,29.9725368782662,,0.00471461924337702,,,,,,,,,,0,1250,-80.4081133858869,,-80.9260396615266,,-8.86325337503956E-6,,0.00306170011472981,,,,,,,,,,,,,,,,,,,,,,,,,,,
,30566421.01,4370,123.31555,312.857,90.014,0.102153342753992,173,0.00304151381037087,,4.96411524811956E-7,,29.7749172475334,,0.00485962347390763,,,,,,,,,,0,1250,-79.2239053689585,,-81.4250328012068,,-7.71526805080833E-6,,0.00304151384389308,,,,,,,,,,,,,,,,,,,,,,,,,,,
,30566462.3,4370,121.2545,312.857,90.014,0.102153342753992,173,0.00302039553277591,,5.11645286686422E-7,,29.5681734330486,,0.0050087533893289,,,,,,,,,,0,1250,-78.9967323350159,,-81.4220361054281,,-8.61965849929366E-6,,0.00302039557491031,,,,,,,,,,,,,,,,,,,,,,,,,,,
,30566503.16,4370,119.20815,312.857,90.014,0.102153342753992,173,0.0029994568719876,,4.78066122434176E-7,,29.3631881191827,,0.00468002905186186,,,,,,,,,,0,1250,-79.4910949980537,,-80.5922924411422,,-8.3364820003204E-6,,0.00299945691167416,,,,,,,,,,,,,,,,,,,,,,,,,,,
,30566544.435,4370,117.1549,312.857,90.014,0.102153342753992,173,0.00297801970954641,,5.01611456505911E-7,,29.1533226634401,,0.00491052507938548,,,,,,,,,,0,1250,-79.1027410358969,,-80.8137098305754,,-7.81652123881508E-6,,0.00297801974468788,,,,,,,,,,,,,,,,,,,,,,,,,,,
,30566585.18,4370,115.11185,312.857,90.014,0.102153342753992,173,0.00295654800537995,,4.90115105848583E-7,,28.9431191424191,,0.00479798052169336,,,,,,,,,,0,1250,-78.555879052763,,-81.1263312998372,,-7.60606844910837E-6,,0.00295654803889624,,,,,,,,,,,,,,,,,,,,,,,,,,,
,30566626.06,4370,113.06985,312.857,90.014,0.102153342753992,173,0.00293455116337011,,5.0019186435645E-7,,28.7277747256859,,0.00489662583873654,,,,,,,,,,0,1250,-78.6010248601079,,-80.440942757307,,-7.17656762653776E-6,,0.00293455119343173,,,,,,,,,,,,,,,,,,,,,,,,,,,
,30566667.065,4370,111.0133,312.857,90.014,0.102153342753992,173,0.00291223614947067,,5.04281408487575E-7,,28.509315571511,,0.00493665928934581,,,,,,,,,,0,1250,-77.7369655447244,,-80.9709675914414,,-7.68241802860296E-6,,0.00291223618418347,,,,,,,,,,,,,,,,,,,,,,,,,,,
,30566709.165,4370,108.9087,312.857,90.014,0.102153342753992,173,0.00288920033411143,,4.94148846368882E-7,,28.2838000305091,,0.00483746552376344,,,,,,,,,,0,1250,-77.7217684237074,,-80.6012342111383,,-7.19572622794533E-6,,0.00288920036480816,,,,,,,,,,,,,,,,,,,,,,,,,,,
,30566752.66,4370,106.72875,312.857,90.014,0.102153342753992,173,0.00286485957738134,,4.9468837021681E-7,,28.0455095160286,,0.00484274599549235,,,,,,,,,,0,1250,-77.5681424708973,,-81.1695310638693,,-7.15851280009086E-6,,0.0028648596080195,,,,,,,,,,,,,,,,,,,,,,,,,,,
,30566801.805,4370,104.2951,312.857,90.014,0.102153342753992,173,0.00283665073889971,,4.99049399813405E-7,,27.7693515009601,,0.00488543685795892,,,,,,,,,,0,1250,-77.212606105731,,-80.7125310502613,,-6.5557777173728E-6,,0.00283665076485124,,,,,,,,,,,,,,,,,,,,,,,,,,,
,30566858.68,4370,101.4438,312.857,90.014,0.102153342753992,173,0.00280307034629222,,5.101047277484E-7,,27.4406074166809,,0.00499366114188986,,,,,,,,,,0,1250,-76.1632862878667,,-79.8134174281399,,-5.98418025914922E-6,,0.00280307036817466,,,,,,,,,,,,,,,,,,,,,,,,,,,
,30566909.055,4370,98.9099,312.857,90.014,0.102153342753992,173,0.00277224509535988,,5.10559549136902E-7,,27.1388357128443,,0.00499811206029772,,,,,,,,,,0,1250,-75.9711409941875,,-81.3110971514583,,-5.10344988659543E-6,,0.00277224511145212,,,,,,,,,,,,,,,,,,,,,,,,,,,
,30566957.805,4370,96.48135,312.857,90.014,0.102153342753992,173,0.0027417210960239,,5.13193386723011E-7,,26.8400133741358,,0.00502389439762513,,,,,,,,,,0,1250,-76.2212673642236,,-80.3104154284889,,-5.89306908814539E-6,,0.00274172111771993,,,,,,,,,,,,,,,,,,,,,,,,,,,
,30567013.32,4370,93.69735,312.857,90.014,0.102153342753992,173,0.00270486277567974,,5.19991443266687E-7,,26.4791798587621,,0.0050904419246662,,,,,,,,,,0,1250,-75.5593334092729,,-79.4771698656668,,-4.9028470580323E-6,,0.00270486279090175,,,,,,,,,,,,,,,,,,,,,,,,,,,
,30567061.58,4370,91.2792,312.857,90.014,0.102153342753992,173,0.00267050476630244,,5.06154907299645E-7,,26.1428239894819,,0.00495498781762372,,,,,,,,,,0,1250,-75.3897271946856,,-80.6387225063555,,-4.65992650013112E-6,,0.00267050478023033,,,,,,,,,,,,,,,,,,,,,,,,,,,
,30567112.325,4370,88.74755,312.857,90.014,0.102153342753992,173,0.00262769945350518,,5.24976833023909E-7,,25.7237715698059,,0.00513924225459711,,,,,,,,,,0,1250,-74.9382503108329,,-78.9589930035492,,-4.5157025199971E-6,,0.00262769946679734,,,,,,,,,,,,,,,,,,,,,,,,,,,
,30567162.885,4370,86.2263,312.857,90.014,0.102153342753992,173,0.00257251638569539,,5.38720450140348E-7,,25.1835448158514,,0.00527378197701902,,,,,,,,,,0,1250,-74.5620006830273,,-78.4654457816187,,-3.7301678907414E-6,,0.00257251639495983,,,,,,,,,,,,,,,,,,,,,,,,,,,
,30567218.84,4370,83.43,312.857,90.014,0.102153342753992,173,0.0024944590734486,,5.1936002856914E-7,,24.4193866547847,,0.00508424990976383,,,,,,,,,,0,1250,-73.8610878081013,,-79.6275078313598,,-3.0075688608398E-6,,0.00249445907965979,,,,,,,,,,,,,,,,,,,,,,,,,,,
,30567282.06,4370,80.2695,312.857,90.014,0.102153342753992,173,0.00232933115738265,,5.60571375742482E-7,,22.8028368294614,,0.00548767725339725,,,,,,,,,,0,1250,-71.9837402864541,,-78.5951729026961,,-1.0351830296071E-6,,0.00232933115817064,,,,,,,,,,,,,,,,,,,,,,,,,,,
,30567340.65,4370,77.29615,312.857,90.014,0.102153342753992,173,0.00190230062088281,,5.35206109128683E-7,,18.6223686000695,,0.00523934297296566,,,,,,,,,,0,1250,-69.7564311079396,,-77.5725429762003,,3.27868584541644E-6,,0.00190230063056204,,,,,,,,,,,,,,,,,,,,,,,,,,,
,30567395.33,4370,74.5522,312.857,90.014,0.102153342753992,173,0.00113092214181485,,4.33012973109587E-7,,11.0709550992053,,0.00423890101046673,,,,,,,,,,0,2500,-65.8012032583509,,-84.4590955359897,,-5.19059007161421E-6,,0.00113092218262058,,,,,,,,,,,,,,,,,,,,,,,,,,,
,30567449.07,4370,71.87985,312.857,90.014,0.102153342753992,173,0.000537740887530565,,5.90159295904474E-7,,5.26828473067315,,0.00578183149899627,,,,,,,,,,0,5000,-59.0854134371852,,-58.0365915758559,,5.44286984508568E-7,,0.000537740888474198,,,,,,,,,,,,,,,,,,,,,,,,,,,
,30567504.755,4370,69.08705,312.857,90.014,0.102153342753992,173,0.000430529496653458,,4.48301695978592E-7,,4.21725182036518,,0.0043913394027515,,,,,,,,,,0,5000,-56.4529444114692,,-68.1041177500269,,2.05446172093609E-7,,0.000430529496821383,,,,,,,,,,,,,,,,,,,,,,,,,,,
,30567560.58,4370,66.299,312.857,90.014,0.102153342753992,173,0.00040191190826473,,4.68867782775385E-7,,3.93675993812292,,0.00459259819089117,,,,,,,,,,0,5000,-55.2691683115096,,-94.317166617529,,1.90787615131147E-7,,0.000401911908419858,,,,,,,,,,,,,,,,,,,,,,,,,,,
,30567615.13,4370,63.57935,312.857,90.014,0.102153342753992,173,0.00038471575287449,,4.7875592503494E-7,,3.76822540382565,,0.00468933289967135,,,,,,,,,,0,5000,-54.8295984576652,,-68.3471146147859,,3.0737296730064E-7,,0.000384715753295132,,,,,,,,,,,,,,,,,,,,,,,,,,,
,30567669.64,4370,60.84445,312.857,90.014,0.102153342753992,173,0.000372302785777378,,5.41738911714766E-7,,3.6465748916637,,0.00530614217328483,,,,,,,,,,0,5000,-54.6123922086032,,-58.733207356005,,1.35998274528514E-7,,0.00037230278586247,,,,,,,,,,,,,,,,,,,,,,,,,,,
,30567724.135,4370,58.12445,312.857,90.014,0.102153342753992,173,0.000362825298036468,,6.6602231555316E-7,,3.55369592624453,,0.00652336207164512,,,,,,,,,,0,5000,-54.4896550831284,,-53.8903722526935,,2.36656993731787E-7,,0.000362825298300868,,,,,,,,,,,,,,,,,,,,,,,,,,,
,30567775.74,4370,55.54375,312.857,90.014,0.102153342753992,173,0.000355851120068936,,8.23675224386115E-7,,3.48535096654033,,0.00806741099108108,,,,,,,,,,0,5000,-54.4208287891393,,-50.7285913369549,,2.37850573727422E-7,,0.000355851120341245,,,,,,,,,,,,,,,,,,,,,,,,,,,
,30567830.445,4370,52.81045,312.857,90.014,0.102153342753992,173,0.000348145964730652,,1.03520031845807E-6,,3.40984429207014,,0.0101390573182978,,,,,,,,,,0,5000,-54.5088864295706,,-47.8931379378718,,3.32208781156458E-7,,0.000348145965273629,,,,,,,,,,,,,,,,,,,,,,,,,,,
,30567885.475,4370,50.059,312.857,90.014,0.102153342753992,173,0.000342451208148787,,1.16415915639056E-6,,3.35403963831238,,0.0114020212479849,,,,,,,,,,0,5000,-54.3615006877843,,-46.5490552449574,,2.69029613896541E-7,,0.000342451208510798,,,,,,,,,,,,,,,,,,,,,,,,,,,
,30567939.85,4370,47.33875,312.857,90.014,0.102153342753992,173,0.000337930668982483,,1.22119129302955E-6,,3.30974217440421,,0.011960525301049,,,,,,,,,,0,5000,-54.0873182249529,,-45.8504679389001,,3.89340557107986E-7,,0.00033793066975082,,,,,,,,,,,,,,,,,,,,,,,,,,,
,30567991.495,4370,44.7722,312.857,90.014,0.102153342753992,173,0.00033515443564856,,1.2361953654453E-6,,3.28253773016574,,0.01210742716029,,,,,,,,,,0,5000,-53.957126304825,,-45.6510941811559,,4.37935368504493E-7,,0.000335154436628717,,,,,,,,,,,,,,,,,,,,,,,,,,,
,30568040.42,4370,42.3257,312.857,90.014,0.102153342753992,173,0.000332261202311801,,1.20194108324016E-6,,3.25418703732204,,0.0117718862472636,,,,,,,,,,0,5000,-54.1125053828065,,-45.7305484405858,,4.92360409349178E-7,,0.000332261203561505,,,,,,,,,,,,,,,,,,,,,,,,,,,
,30568088.305,4370,39.936,312.857,90.014,0.102153342753992,173,0.000329749003810561,,1.11643473154218E-6,,3.22957029031523,,0.0109343906571933,,,,,,,,,,0,5000,-54.0699991216664,,-46.368816298362,,4.88966220712595E-7,,0.000329749005052484,,,,,,,,,,,,,,,,,,,,,,,,,,,
,30568140.75,4370,37.31835,312.857,90.014,0.102153342753992,173,0.000327341080766748,,9.49433810940477E-7,,3.20597550002236,,0.00929874589555369,,,,,,,,,,0,5000,-54.1358063133762,,-47.9628710132092,,3.37493952218462E-7,,0.000327341081362756,,,,,,,,,,,,,,,,,,,,,,,,,,,
,30568195.5,4370,34.581,312.857,90.014,0.102153342753992,173,0.000324833709833764,,7.66229072827855E-7,,3.18140641871389,,0.0075044122951182,,,,,,,,,,0,5000,-54.4523077346575,,-50.214062002753,,3.39255129555243E-7,,0.000324833710440657,,,,,,,,,,,,,,,,,,,,,,,,,,,
,30568250.16,4370,31.86805,312.857,90.014,0.102153342753992,173,0.000322987079906159,,5.7554820660183E-7,,3.16331188582581,,0.00563687711533156,,,,,,,,,,0,5000,-55.067118557682,,-53.6761772936635,,3.44051137365692E-7,,0.000322987080533901,,,,,,,,,,,,,,,,,,,,,,,,,,,
,30568305.005,4370,29.12865,312.857,90.014,0.102153342753992,173,0.000322065104666434,,4.35187166178166E-7,,3.15427778426266,,0.00426218546171265,,,,,,,,,,0,5000,-55.3930040496495,,-58.5825146243435,,3.89434129259516E-7,,0.000322065105473009,,,,,,,,,,,,,,,,,,,,,,,,,,,
,30568360.12,4370,26.37175,312.857,90.014,0.102153342753992,173,0.000322271558636201,,5.09128261296085E-7,,3.15630074980174,,0.00498635969311602,,,,,,,,,,0,5000,-52.7890861053733,,-63.5367718047176,,3.16385434794561E-7,,0.000322271559168225,,,,,,,,,,,,,,,,,,,,,,,,,,,
,30568414.475,4370,23.69075,312.857,90.014,0.102153342753992,173,0.000322284239269284,,4.40042332815462E-7,,3.15642500264206,,0.00430973795842527,,,,,,,,,,0,5000,-53.934662832612,,-70.0068755993942,,3.05562473891096E-7,,0.000322284239765513,,,,,,,,,,,,,,,,,,,,,,,,,,,
,30568469.58,4370,20.938,312.857,90.014,0.102153342753992,173,0.000323514007736824,,4.38877404902784E-7,,3.16847507203151,,0.00429833664508982,,,,,,,,,,0,5000,-53.9026369159931,,-71.5782226300459,,3.28597461793484E-7,,0.000323514008308507,,,,,,,,,,,,,,,,,,,,,,,,,,,
,30568526.52,4370,18.1114,312.857,90.014,0.102153342753992,173,0.000324907521157814,,4.4107696793547E-7,,3.18212967421911,,0.00431988801150067,,,,,,,,,,0,5000,-53.9101636956892,,-70.6564127217412,,3.49763668864306E-7,,0.000324907521802741,,,,,,,,,,,,,,,,,,,,,,,,,,,
,30568581.3,4370,15.3868,312.857,90.014,0.102153342753992,173,0.000326366980680423,,4.1434142354431E-7,,3.19643052256662,,0.00405805013898319,,,,,,,,,,0,5000,-54.5666721656423,,-69.5540214318865,,2.80107870818406E-7,,0.000326366981092202,,,,,,,,,,,,,,,,,,,,,,,,,,,
,30568637.195,4370,12.66385,312.857,90.014,0.102153342753992,173,0.000328139265646778,,3.70658103047408E-7,,3.213796746482,,0.00363022633869696,,,,,,,,,,0,5000,-55.5475636186748,,-71.1486865398723,,1.94835447834377E-7,,0.00032813926584493,,,,,,,,,,,,,,,,,,,,,,,,,,,
,30568691.14,4370,9.986,312.857,90.014,0.102153342753992,173,0.000330319585275949,,3.17398933839586E-7,,3.23516133689951,,0.00310861602917639,,,,,,,,,,0,5000,-56.9454513666066,,-84.32713364897,,3.14189516646458E-7,,0.000330319585787831,,,,,,,,,,,,,,,,,,,,,,,,,,,
,30568784.34,4375,9.50655,312.857,90.014,0.102153342753992,173,0.000329518937540974,,3.22875957051729E-7,,3.22731590637426,,0.00316225438427125,,,,,,,,,,0,5000,-57.2130785183647,,-67.9196046682162,,6.54414225378596E-7,,0.000329518939767078,,,,,,,,,,,,,,,,,,,,,,,,,,,
,30568844.475,4375,9.27265,312.857,90.014,0.102153342753992,173,0.000329988849610679,,3.03507068088823E-7,,3.23192050401906,,0.00297255713943801,,,,,,,,,,0,5000,-57.7241924166609,,-69.2123998845329,,6.0383344652757E-7,,0.000329988851503265,,,,,,,,,,,,,,,,,,,,,,,,,,,
,30568893.78,4375,9.0626,312.857,90.014,0.102153342753992,173,0.000329881678559713,,3.01485989234423E-7,,3.23087035045198,,0.00295276215782779,,,,,,,,,,0,5000,-57.8768267090994,,-68.3459026401398,,6.60190413480875E-7,,0.000329881680822797,,,,,,,,,,,,,,,,,,,,,,,,,,,
,30568942.735,4375,8.8414,312.857,90.014,0.102153342753992,173,0.000330352468415196,,2.93484772725992E-7,,3.23548355439206,,0.0028744000462285,,,,,,,,,,0,5000,-57.949616628913,,-71.5055994050084,,5.86988307705064E-7,,0.000330352470201691,,,,,,,,,,,,,,,,,,,,,,,,,,,
,30568993.28,4375,8.6453,312.857,90.014,0.102153342753992,173,0.000330844948746968,,2.7899696321818E-7,,3.24030930721788,,0.00273250794779735,,,,,,,,,,0,5000,-58.2556901618973,,-83.3172783066051,,5.74041558996622E-7,,0.000330844950452982,,,,,,,,,,,,,,,,,,,,,,,,,,,
,30569051.405,4375,8.4228,312.857,90.014,0.102153342753992,173,0.000330624040194578,,2.68023949000008E-7,,3.23814465122137,,0.00262503691449442,,,,,,,,,,0,5000,-58.8617110240377,,-71.1108955171999,,6.92598246853068E-7,,0.000330624042679706,,,,,,,,,,,,,,,,,,,,,,,,,,,
,30569105.915,4375,8.23005,312.857,90.014,0.102153342753992,173,0.000330919551591589,,2.7021148258626E-7,,3.24104033172776,,0.00264646287442004,,,,,,,,,,0,5000,-58.6334987806016,,-74.4515126410023,,6.30829978097945E-7,,0.000330919553651378,,,,,,,,,,,,,,,,,,,,,,,,,,,
,30569159.18,4375,8.045,312.857,90.014,0.102153342753992,173,0.000331034346855174,,2.4026150596904E-7,,3.24216519734733,,0.00235313191757623,,,,,,,,,,0,5000,-59.889528191162,,-71.277859646582,,6.73088177304059E-7,,0.000331034349199356,,,,,,,,,,,,,,,,,,,,,,,,,,,
,30569219.51,4375,7.8425,312.857,90.014,0.102153342753992,173,0.000331528119947117,,2.52243285726016E-7,,3.24700362763172,,0.0024704838251523,,,,,,,,,,0,5000,-59.2425451578937,,-76.6164377916417,,6.79054821899228E-7,,0.00033152812232949,,,,,,,,,,,,,,,,,,,,,,,,,,,
,30569275.445,4375,7.67155,312.857,90.014,0.102153342753992,173,0.000331378956571439,,2.33537284040955E-7,,3.24554199074337,,0.00228727576987041,,,,,,,,,,0,5000,-60.1564117251151,,-71.0106540564265,,5.63066437673102E-7,,0.000331378958210196,,,,,,,,,,,,,,,,,,,,,,,,,,,
,30569333.785,4375,7.4938,312.857,90.014,0.102153342753992,173,0.000331669025986077,,2.43887929631652E-7,,3.24838435230775,,0.00238865153944434,,,,,,,,,,0,5000,-59.5732208996539,,-76.8001615271797,,6.25379990170538E-7,,0.000331669028005854,,,,,,,,,,,,,,,,,,,,,,,,,,,
,30569390.04,4375,7.34405,312.857,90.014,0.102153342753992,173,0.000331713117434998,,2.56250399791623E-7,,3.24881640027956,,0.00250973040386968,,,,,,,,,,0,5000,-59.1565575734061,,-74.8345403990703,,6.35404292136196E-7,,0.000331713119519768,,,,,,,,,,,,,,,,,,,,,,,,,,,
,30569443.555,4375,7.1926,312.857,90.014,0.102153342753992,173,0.000331888830887422,,2.57776275356143E-7,,3.25053820048161,,0.00252467557103232,,,,,,,,,,0,5000,-59.0645445006619,,-76.589301910315,,7.10799560774708E-7,,0.000331888833494909,,,,,,,,,,,,,,,,,,,,,,,,,,,
,30569509.5,4375,7.0248,312.857,90.014,0.102153342753992,173,0.000332281446123019,,2.37569155202982E-7,,3.25438540487294,,0.00232676725522642,,,,,,,,,,0,5000,-59.8357819885974,,-76.2474052331486,,4.98642035931024E-7,,0.000332281447404736,,,,,,,,,,,,,,,,,,,,,,,,,,,
,30569739.775,4374,6.89005,312.857,90.014,0.102153342753992,173,0.000332166555323033,,2.15283007420943E-7,,3.2532595989095,,0.00210849495612529,,,,,,,,,,0,5000,-60.7524151560786,,-76.0474509787402,,5.97541751304234E-7,,0.000332166557164233,,,,,,,,,,,,,,,,,,,,,,,,,,,
,30569786.36,4370,5.08,312.857,90.014,0.102153342753992,173,0.000335265063980875,,2.19852348124939E-7,,3.28362177820998,,0.00215325732556534,,,,,,,,,,0,5000,-61.3225058180019,,-68.5877503070891,,5.45263484029494E-7,,0.00033526506549983,,,,,,,,,,,,,,,,,,,,,,,,,,,
,30569826.26,4373,4.9996,312.857,90.014,0.102153342753992,173,,1.90356116876417E-7,,4.58817904980012E-9,,0.00186343555517888,,3.68132332137219E-5,,,,,,,,,0,25000,,-48.6584845404497,,-42.9619495881209,,2.27327985311979E-6,,2.32247353153906E-7,,,,,,,,,,,,,,,,,,,,,,,,,,