File: Data/Ta (20 nm)/20170810-YBCO-Ta (0.260 cm^2).rso.dat
[Header]
TITLE,MPMS RSO Measurement
BYAPP,MPMS Measurement,1.1,Summary
FILEOPENTIME, 1502427141.516000 8/10/2017, 9:52:21 PM

INFO, APPNAME, MPMS MultiVu Application, Revision 1.61,  Build 082

INFO, NAME, YBCO Ta
INFO, WEIGHT, 70.860
INFO, AREA, 1.000
INFO, LENGTH, 1.000
INFO, SHAPE, 1
INFO, COMMENT, mass includes substrate
INFO, SEQUENCE FILE: 20170810-YBCO-Ta.seq


INFO, BACKGROUND DATA FILE:, None


STARTUPAXIS,X,4,LINEAR,AUTO,0.000000,0.000000
STARTUPAXIS,Y1,5,LINEAR,AUTO,0.000000,0.000000


STARTUPGROUP,Longitudinal
FIELDGROUP,Longitudinal,1,2,3,4,5,6,7,8,9,10,11,19,20,21,22,23,35
FIELDGROUP,Transverse,1,2,3,4,12,13,14,15,16,17,18,24,25,26,27,28,35

PLOT_APPEARANCE,ALL,HORZ_GRID_ON,VERT_GRID_ON,MARKERS_AND_LINES

[Data]
Time,Comment,Field (Oe),Temperature (K),Long Moment (emu),Long Scan Std Dev,Long Offset (cm),Long Offset Std Dev,Long Algorithm,Long Reg Fit,Long Reg Factor,Trans Moment (emu),Trans Scan Std Dev,Trans Offset (cm),Trans Offset Std Dev,Trans Algorithm,Trans Reg Fit,Trans Reg Factor,Long Moment [w/o ABS] (emu),Long Scan Std Dev [w/o ABS],Long Offset [w/o ABS] (cm),Long Offset Std Dev [w/o ABS],Long Reg Fit [w/o ABS],Trans Moment [w/o ABS] (emu),Trans Scan Std Dev [w/o ABS],Trans Offset [w/o ABS] (cm),Trans Offset Std Dev [w/o ABS],Trans Reg Fit [w/o ABS],RSO Position (deg),Amplitude (cm),Frequency,Cycles to Average,Scans per Measurement,Delta Temp (K),Error,EC Comp. Running,Using ABS,
1502427141.513,,1.000000e+001,2.002128e+000,-1.754054e-004,2.519272e-006,-3.554962e-003,1.109115e-002,3,6.860180e-001,1.825000e+000,,,,,,,,,,,,,,,,,,0,4.000000e+000,5.000000e-001,3,2,2.942801e-003,0,,0,
1502427366.491,,1.000000e+001,7.006363e+000,-1.699344e-004,2.955218e-008,-1.144774e-002,7.458952e-004,3,7.951088e-001,1.825000e+000,,,,,,,,,,,,,,,,,,0,4.000000e+000,5.000000e-001,3,2,5.159378e-003,0,,0,
1502427557.243,,1.000000e+001,1.199394e+001,-1.611485e-004,1.473716e-005,2.657696e-002,5.759002e-002,3,7.400663e-001,1.825000e+000,,,,,,,,,,,,,,,,,,0,4.000000e+000,5.000000e-001,3,2,4.429817e-003,0,,0,
1502427728.443,,1.000000e+001,1.698486e+001,-1.589092e-004,4.972124e-006,-2.160970e-002,1.340610e-002,3,7.563232e-001,1.825000e+000,,,,,,,,,,,,,,,,,,0,4.000000e+000,5.000000e-001,3,2,7.379532e-003,0,,0,
1502427898.705,,1.000000e+001,2.197428e+001,-1.566644e-004,2.740780e-007,-1.272078e-002,1.809397e-004,3,7.956464e-001,1.825000e+000,,,,,,,,,,,,,,,,,,0,4.000000e+000,5.000000e-001,3,2,1.405907e-002,0,,0,
1502428088.904,,1.000000e+001,2.699790e+001,-1.340042e-004,2.560442e-006,-2.011520e-002,1.104380e-002,3,7.429625e-001,1.825000e+000,,,,,,,,,,,,,,,,,,0,4.000000e+000,5.000000e-001,3,2,9.117126e-004,0,,0,
1502428279.877,,1.000000e+001,3.199846e+001,-1.089615e-004,7.130787e-006,-8.443882e-002,6.788419e-002,3,5.791504e-001,1.825000e+000,,,,,,,,,,,,,,,,,,0,4.000000e+000,5.000000e-001,3,2,1.258850e-003,0,,0,
1502428493.869,,1.000000e+001,3.699948e+001,-1.189499e-004,1.360938e-005,1.610434e-002,4.443320e-002,3,6.864789e-001,1.825000e+000,,,,,,,,,,,,,,,,,,0,4.000000e+000,5.000000e-001,3,2,1.651764e-003,0,,0,
1502428782.191,,1.000000e+001,4.200191e+001,-1.123834e-004,2.096271e-006,-2.916436e-002,2.269886e-003,3,7.786749e-001,1.825000e+000,,,,,,,,,,,,,,,,,,0,4.000000e+000,5.000000e-001,3,2,2.090454e-003,0,,0,
1502429035.763,,1.000000e+001,4.699721e+001,-8.889246e-005,4.341969e-007,-4.400121e-002,1.419690e-004,3,7.971849e-001,1.825000e+000,,,,,,,,,,,,,,,,,,0,4.000000e+000,5.000000e-001,3,2,3.101349e-003,0,,0,
1502429237.608,,1.000000e+001,5.202947e+001,-6.677182e-005,1.279523e-005,-4.284341e-002,8.256126e-002,3,5.955507e-001,1.825000e+000,,,,,,,,,,,,,,,,,,0,4.000000e+000,5.000000e-001,3,2,2.122116e-002,0,,0,
1502429451.241,,1.000000e+001,5.703482e+001,-4.481052e-005,2.584916e-007,-1.048849e-001,1.126364e-003,3,7.916737e-001,1.825000e+000,,,,,,,,,,,,,,,,,,0,4.000000e+000,5.000000e-001,3,2,1.782990e-002,0,,0,
1502429685.325,,1.000000e+001,6.203434e+001,-2.788887e-005,1.675314e-006,-1.384268e-001,3.435622e-003,3,7.451000e-001,1.825000e+000,,,,,,,,,,,,,,,,,,0,4.000000e+000,5.000000e-001,3,2,2.093887e-002,0,,0,
1502429970.360,,1.000000e+001,6.702679e+001,-4.352170e-006,1.587597e-005,-3.101249e-001,4.385829e-001,3,0.000000e+000,1.825000e+000,,,,,,,,,,,,,,,,,,0,4.000000e+000,5.000000e-001,3,2,5.855560e-002,0,,0,
1502430257.607,,1.000000e+001,7.200881e+001,8.111387e-006,1.646931e-005,4.465160e-001,8.937790e-001,3,3.998747e-001,1.825000e+000,,,,,,,,,,,,,,,,,,0,4.000000e+000,5.000000e-001,3,2,2.075195e-002,0,,0,
1502430480.297,,1.000000e+001,7.707447e+001,1.479625e-005,6.480676e-007,0.000000e+000,0.000000e+000,3,0.000000e+000,1.825000e+000,,,,,,,,,,,,,,,,,,0,4.000000e+000,5.000000e-001,3,2,4.440308e-002,0,,0,
1502430705.782,,1.000000e+001,8.208926e+001,-9.187843e-008,1.147747e-007,9.891264e-001,1.550145e-001,3,0.000000e+000,1.825000e+000,,,,,,,,,,,,,,,,,,0,4.000000e+000,5.000000e-001,3,2,6.441498e-002,0,,0,
1502430932.273,,1.000000e+001,8.711311e+001,-1.183546e-005,1.654555e-005,-1.125693e-002,1.501776e+000,3,0.000000e+000,1.825000e+000,,,,,,,,,,,,,,,,,,0,4.000000e+000,5.000000e-001,3,2,4.892731e-002,0,,0,
1502431630.722,,1.000000e+001,9.713233e+001,-2.127481e-005,7.855459e-008,1.078122e+000,6.768700e-003,3,0.000000e+000,1.825000e+000,,,,,,,,,,,,,,,,,,0,4.000000e+000,5.000000e-001,3,2,4.806519e-002,0,,0,
1502435401.987,,1.000000e+001,2.005828e+000,-1.517021e-004,2.021933e-005,-5.833129e-002,1.151998e-002,3,6.792969e-001,1.825000e+000,,,,,,,,,,,,,,,,,,0,4.000000e+000,5.000000e-001,3,2,7.839203e-004,0,,0,
1502435728.882,,1.000000e+001,2.999019e+000,-1.634256e-004,4.135341e-006,-2.008700e-003,9.793004e-003,3,6.921667e-001,1.825000e+000,,,,,,,,,,,,,,,,,,0,4.000000e+000,5.000000e-001,3,2,3.010988e-003,0,,0,
1502436019.613,,1.000000e+001,4.012888e+000,-1.500673e-004,2.772431e-006,-3.636023e-002,2.700703e-002,3,7.636155e-001,1.825000e+000,,,,,,,,,,,,,,,,,,0,4.000000e+000,5.000000e-001,3,2,9.587765e-003,0,,0,
1502436710.351,,1.000000e+001,5.002316e+000,-1.704803e-004,3.838597e-005,-2.374001e-002,7.397717e-002,3,7.003577e-001,1.825000e+000,,,,,,,,,,,,,,,,,,0,4.000000e+000,5.000000e-001,3,2,8.544922e-003,0,,0,
1502436851.595,,1.000000e+001,6.004630e+000,-1.543213e-004,7.799029e-006,-6.722322e-003,3.511544e-003,3,7.832611e-001,1.825000e+000,,,,,,,,,,,,,,,,,,0,4.000000e+000,5.000000e-001,3,2,5.996227e-003,0,,0,
1502436992.542,,1.000000e+001,7.004849e+000,-1.593661e-004,1.112837e-007,-9.812682e-003,1.799736e-004,3,7.963121e-001,1.825000e+000,,,,,,,,,,,,,,,,,,0,4.000000e+000,5.000000e-001,3,2,5.382061e-003,0,,0,
1502437133.514,,1.000000e+001,8.006827e+000,-1.656811e-004,9.868475e-006,-3.145859e-003,8.672711e-003,3,7.584072e-001,1.825000e+000,,,,,,,,,,,,,,,,,,0,4.000000e+000,5.000000e-001,3,2,3.682137e-003,0,,0,
1502437272.501,,1.000000e+001,9.005321e+000,-1.579927e-004,2.264261e-007,-9.613745e-003,2.348317e-004,3,7.964176e-001,1.825000e+000,,,,,,,,,,,,,,,,,,0,4.000000e+000,5.000000e-001,3,2,3.620148e-003,0,,0,
1502437409.195,,1.000000e+001,1.000242e+001,-1.834007e-004,3.027160e-005,-1.128485e-002,1.185482e-003,3,6.577744e-001,1.825000e+000,,,,,,,,,,,,,,,,,,0,4.000000e+000,5.000000e-001,3,2,3.000259e-003,0,,0,
1502437540.450,,1.000000e+001,1.098733e+001,-1.498032e-004,1.517520e-005,5.456737e-002,1.980152e-002,3,7.169589e-001,1.825000e+000,,,,,,,,,,,,,,,,,,0,4.000000e+000,5.000000e-001,3,2,1.097965e-002,0,,0,
1502437685.397,,1.000000e+001,1.199613e+001,-1.661305e-004,1.462686e-005,-6.736144e-003,4.177847e-003,3,7.971358e-001,1.825000e+000,,,,,,,,,,,,,,,,,,0,4.000000e+000,5.000000e-001,3,2,5.410194e-003,0,,0,
1502437830.068,,1.000000e+001,1.300524e+001,-1.656238e-004,1.490256e-005,-2.820463e-002,2.612226e-002,3,8.092925e-001,1.825000e+000,,,,,,,,,,,,,,,,,,0,4.000000e+000,5.000000e-001,3,2,7.705688e-004,0,,0,
1502437965.493,,1.000000e+001,1.400728e+001,-1.737373e-004,5.285213e-005,-1.916248e-001,2.146258e-001,3,5.504846e-001,1.825000e+000,,,,,,,,,,,,,,,,,,0,4.000000e+000,5.000000e-001,3,2,2.399445e-003,0,,0,
1502438099.258,,1.000000e+001,1.499879e+001,-1.573546e-004,5.240152e-006,1.859408e-002,4.051800e-002,3,7.627876e-001,1.825000e+000,,,,,,,,,,,,,,,,,,0,4.000000e+000,5.000000e-001,3,2,7.450104e-003,0,,0,
1502438239.512,,1.000000e+001,1.600069e+001,-1.446485e-004,1.190560e-005,4.032481e-003,2.092367e-002,3,7.220699e-001,1.825000e+000,,,,,,,,,,,,,,,,,,0,4.000000e+000,5.000000e-001,3,2,4.580498e-003,0,,0,
1502438379.033,,1.000000e+001,1.699982e+001,-1.522555e-004,1.033503e-007,-1.061672e-002,4.872703e-005,3,7.965897e-001,1.825000e+000,,,,,,,,,,,,,,,,,,0,4.000000e+000,5.000000e-001,3,2,8.131027e-003,0,,0,
1502438517.484,,1.000000e+001,1.800066e+001,-1.559013e-004,2.139710e-005,5.561269e-002,3.223901e-002,3,7.287902e-001,1.825000e+000,,,,,,,,,,,,,,,,,,0,4.000000e+000,5.000000e-001,3,2,5.788803e-003,0,,0,
1502438662.627,,1.000000e+001,1.899986e+001,-1.505614e-004,8.489057e-009,-1.145788e-002,1.912900e-004,3,7.958499e-001,1.825000e+000,,,,,,,,,,,,,,,,,,0,4.000000e+000,5.000000e-001,3,2,7.358551e-003,0,,0,
1502438810.079,,1.000000e+001,1.999969e+001,-1.494509e-004,5.065648e-008,-1.130915e-002,2.962258e-004,3,7.962944e-001,1.825000e+000,,,,,,,,,,,,,,,,,,0,4.000000e+000,5.000000e-001,3,2,5.079269e-003,0,,0,
1502438946.600,,1.000000e+001,2.099772e+001,-1.629877e-004,9.477793e-007,-6.473478e-003,2.015250e-002,3,7.600175e-001,1.825000e+000,,,,,,,,,,,,,,,,,,0,4.000000e+000,5.000000e-001,3,2,7.829666e-003,0,,0,
1502439075.541,,1.000000e+001,2.199646e+001,-1.546354e-004,1.023468e-005,-6.492248e-002,7.582515e-002,3,6.234696e-001,1.825000e+000,,,,,,,,,,,,,,,,,,0,4.000000e+000,5.000000e-001,3,2,4.899979e-003,0,,0,
1502439208.987,,1.000000e+001,2.299560e+001,-1.425191e-004,1.936415e-005,-3.121009e-002,7.150222e-002,3,6.694425e-001,1.825000e+000,,,,,,,,,,,,,,,,,,0,4.000000e+000,5.000000e-001,3,2,2.000809e-003,0,,0,
1502439340.202,,1.000000e+001,2.399649e+001,-1.259869e-004,5.204807e-006,7.672302e-003,9.656025e-003,3,6.967425e-001,1.825000e+000,,,,,,,,,,,,,,,,,,0,4.000000e+000,5.000000e-001,3,2,5.071640e-003,0,,0,
1502439472.394,,1.000000e+001,2.499878e+001,-1.483736e-004,6.851405e-006,-1.074288e-002,1.116411e-003,3,7.659653e-001,1.825000e+000,,,,,,,,,,,,,,,,,,0,4.000000e+000,5.000000e-001,3,2,1.332092e-002,0,,0,
1502439606.381,,1.000000e+001,2.600320e+001,-1.440454e-004,2.279634e-006,1.581925e-002,3.950248e-002,3,7.924500e-001,1.825000e+000,,,,,,,,,,,,,,,,,,0,4.000000e+000,5.000000e-001,3,2,8.506775e-004,0,,0,
1502439872.114,,1.000000e+001,2.700152e+001,-1.398684e-004,2.801986e-005,-6.873672e-002,7.154612e-003,3,6.473167e-001,1.825000e+000,,,,,,,,,,,,,,,,,,0,4.000000e+000,5.000000e-001,3,2,9.098053e-004,0,,0,
1502440042.670,,1.000000e+001,2.800290e+001,-1.499008e-004,1.596620e-005,-1.248514e-002,1.522631e-003,3,7.739920e-001,1.825000e+000,,,,,,,,,,,,,,,,,,0,4.000000e+000,5.000000e-001,3,2,4.850388e-003,0,,0,
1502440183.140,,1.000000e+001,2.900566e+001,-1.502423e-004,1.759199e-006,-3.988457e-002,6.094440e-002,3,7.021909e-001,1.825000e+000,,,,,,,,,,,,,,,,,,0,4.000000e+000,5.000000e-001,3,2,2.079010e-003,0,,0,
1502440326.588,,1.000000e+001,3.000401e+001,-1.375243e-004,1.677817e-006,1.776971e-002,4.177284e-002,3,7.892047e-001,1.825000e+000,,,,,,,,,,,,,,,,,,0,4.000000e+000,5.000000e-001,3,2,1.110077e-003,0,,0,
1502440467.495,,1.000000e+001,3.100528e+001,-1.266056e-004,1.144075e-005,-1.190507e-002,7.229173e-004,3,6.873031e-001,1.825000e+000,,,,,,,,,,,,,,,,,,0,4.000000e+000,5.000000e-001,3,2,3.540039e-003,0,,0,
1502440677.519,,1.000000e+001,3.200409e+001,-1.078155e-004,3.521577e-005,6.035576e-002,1.020378e-001,3,4.827587e-001,1.825000e+000,,,,,,,,,,,,,,,,,,0,4.000000e+000,5.000000e-001,3,2,3.757477e-003,0,,0,
1502440826.743,,1.000000e+001,3.300529e+001,-1.453447e-004,2.985265e-007,1.171869e-002,6.629166e-004,3,6.960803e-001,1.825000e+000,,,,,,,,,,,,,,,,,,0,4.000000e+000,5.000000e-001,3,2,3.978729e-003,0,,0,
1502440964.956,,1.000000e+001,3.401108e+001,-1.436972e-004,1.819162e-005,7.492121e-002,1.958290e-003,3,6.781886e-001,1.825000e+000,,,,,,,,,,,,,,,,,,0,4.000000e+000,5.000000e-001,3,2,5.611420e-003,0,,0,
1502441143.421,,1.000000e+001,3.500692e+001,-1.331190e-004,3.058425e-006,-1.239146e-002,5.682379e-003,3,7.283610e-001,1.825000e+000,,,,,,,,,,,,,,,,,,0,4.000000e+000,5.000000e-001,3,2,1.038361e-002,0,,0,
1502441760.966,,1.000000e+001,3.700731e+001,-1.121850e-004,1.595507e-005,-4.442355e-002,2.351027e-002,3,7.480172e-001,1.825000e+000,,,,,,,,,,,,,,,,,,0,4.000000e+000,5.000000e-001,3,2,3.311157e-003,0,,0,
1502441957.320,,1.000000e+001,3.800436e+001,-1.283535e-004,1.729090e-005,-7.050341e-003,1.454300e-002,3,6.979936e-001,1.825000e+000,,,,,,,,,,,,,,,,,,0,4.000000e+000,5.000000e-001,3,2,6.931305e-003,0,,0,
1502442108.527,,1.000000e+001,3.901381e+001,-1.077226e-004,8.815724e-006,-1.281636e-002,7.238452e-003,3,7.185767e-001,1.825000e+000,,,,,,,,,,,,,,,,,,0,4.000000e+000,5.000000e-001,3,2,3.650665e-003,0,,0,
1502442249.761,,1.000000e+001,4.001743e+001,-1.172710e-004,7.620703e-006,-1.103595e-002,3.823971e-002,3,7.533331e-001,1.825000e+000,,,,,,,,,,,,,,,,,,0,4.000000e+000,5.000000e-001,3,2,1.525116e-002,0,,0,
1502442440.325,,1.000000e+001,4.100938e+001,-1.146735e-004,1.088194e-005,-1.354451e-002,1.357716e-002,3,7.393603e-001,1.825000e+000,,,,,,,,,,,,,,,,,,0,4.000000e+000,5.000000e-001,3,2,1.196289e-002,0,,0,
1502442713.342,,1.000000e+001,4.200140e+001,-1.010449e-004,2.187500e-005,1.389562e-002,1.027583e-002,3,7.169713e-001,1.825000e+000,,,,,,,,,,,,,,,,,,0,4.000000e+000,5.000000e-001,3,2,4.169464e-003,0,,0,
1502442903.553,,1.000000e+001,4.300556e+001,-9.201925e-005,1.211869e-005,-6.053783e-004,3.887932e-002,3,6.628627e-001,1.825000e+000,,,,,,,,,,,,,,,,,,0,4.000000e+000,5.000000e-001,3,2,6.542206e-003,0,,0,
1502443139.735,,1.000000e+001,4.400551e+001,-9.674566e-005,1.024217e-006,-3.145237e-002,5.942192e-004,3,7.974591e-001,1.825000e+000,,,,,,,,,,,,,,,,,,0,4.000000e+000,5.000000e-001,3,2,6.832123e-003,0,,0,
1502443286.430,,1.000000e+001,4.502220e+001,-1.016505e-004,1.159342e-005,-3.952184e-002,8.222231e-003,3,6.924056e-001,1.825000e+000,,,,,,,,,,,,,,,,,,0,4.000000e+000,5.000000e-001,3,2,7.129669e-003,0,,0,
1502443432.926,,1.000000e+001,4.602199e+001,-7.783134e-005,1.035669e-005,-1.185475e-002,3.196292e-002,3,5.320961e-001,1.825000e+000,,,,,,,,,,,,,,,,,,0,4.000000e+000,5.000000e-001,3,2,9.922028e-003,0,,0,
1502443577.168,,1.000000e+001,4.702355e+001,-9.984939e-005,1.931959e-005,-2.343481e-002,2.432710e-002,3,6.967062e-001,1.825000e+000,,,,,,,,,,,,,,,,,,0,4.000000e+000,5.000000e-001,3,2,1.757050e-002,0,,0,
1502443723.617,,1.000000e+001,4.802346e+001,-7.274449e-005,1.282291e-005,-1.855581e-002,3.781608e-002,3,6.193249e-001,1.825000e+000,,,,,,,,,,,,,,,,,,0,4.000000e+000,5.000000e-001,3,2,6.458282e-003,0,,0,
1502443868.589,,1.000000e+001,4.902440e+001,-7.393645e-005,3.069342e-006,-2.308321e-001,3.642552e-003,3,4.358867e-001,1.825000e+000,,,,,,,,,,,,,,,,,,0,4.000000e+000,5.000000e-001,3,2,1.229095e-002,0,,0,
1502444017.285,,1.000000e+001,5.002188e+001,-8.082799e-005,6.112199e-006,-4.516672e-002,1.657257e-002,3,6.789271e-001,1.825000e+000,,,,,,,,,,,,,,,,,,0,4.000000e+000,5.000000e-001,3,2,5.790710e-003,0,,0,
1502444615.576,,1.000000e+001,5.202292e+001,-6.945118e-005,8.254917e-006,-5.367363e-002,1.800910e-002,3,6.971084e-001,1.825000e+000,,,,,,,,,,,,,,,,,,0,4.000000e+000,5.000000e-001,3,2,1.996994e-002,0,,0,
1502444760.683,,1.000000e+001,5.303493e+001,-5.900932e-005,5.810729e-007,-7.475525e-002,1.030770e-003,3,7.950107e-001,1.825000e+000,,,,,,,,,,,,,,,,,,0,4.000000e+000,5.000000e-001,3,2,1.552963e-002,0,,0,
1502444948.677,,1.000000e+001,5.401988e+001,-6.178547e-005,1.024364e-005,-1.281118e-001,6.512491e-002,3,6.075278e-001,1.825000e+000,,,,,,,,,,,,,,,,,,0,4.000000e+000,5.000000e-001,3,2,1.739883e-002,0,,0,
1502445102.144,,1.000000e+001,5.503135e+001,-4.381240e-005,3.423916e-005,9.594898e-001,1.791031e-001,3,0.000000e+000,1.825000e+000,,,,,,,,,,,,,,,,,,0,4.000000e+000,5.000000e-001,3,2,1.110077e-002,0,,0,
1502445272.483,,1.000000e+001,5.603109e+001,-3.575824e-005,2.767055e-006,-2.642027e-001,4.526579e-002,3,1.184945e-001,1.825000e+000,,,,,,,,,,,,,,,,,,0,4.000000e+000,5.000000e-001,3,2,3.876877e-002,0,,0,
1502445415.426,,1.000000e+001,5.704151e+001,-4.687502e-005,6.068724e-006,-3.049606e-002,1.033566e-001,3,6.059827e-001,1.825000e+000,,,,,,,,,,,,,,,,,,0,4.000000e+000,5.000000e-001,3,2,1.634979e-002,0,,0,
1502445629.065,,1.000000e+001,5.800694e+001,-2.399655e-005,2.057218e-005,-4.771878e-001,5.211039e-001,3,3.965608e-001,1.825000e+000,,,,,,,,,,,,,,,,,,0,4.000000e+000,5.000000e-001,3,2,6.149292e-003,0,,0,
1502445783.173,,1.000000e+001,5.903413e+001,-3.734264e-005,1.654557e-006,-1.157318e-001,2.508765e-003,3,7.331313e-001,1.825000e+000,,,,,,,,,,,,,,,,,,0,4.000000e+000,5.000000e-001,3,2,2.541351e-002,0,,0,
1502445955.419,,1.000000e+001,6.002434e+001,-1.072120e-005,1.382818e-005,4.485019e-001,6.342775e-001,3,0.000000e+000,1.825000e+000,,,,,,,,,,,,,,,,,,0,4.000000e+000,5.000000e-001,3,2,1.476288e-002,0,,0,
1502446125.256,,1.000000e+001,6.102591e+001,-2.215808e-005,9.265009e-006,4.535058e-001,8.282478e-001,3,3.948280e-001,1.825000e+000,,,,,,,,,,,,,,,,,,0,4.000000e+000,5.000000e-001,3,2,8.460999e-003,0,,0,
1502446408.321,,1.000000e+001,6.199857e+001,4.546241e-005,2.710646e-006,7.360095e-002,1.671403e+000,3,1.018447e-001,1.825000e+000,,,,,,,,,,,,,,,,,,0,4.000000e+000,5.000000e-001,3,2,1.221085e-002,0,,0,
1502446631.235,,1.000000e+001,6.301223e+001,-2.903940e-005,8.201837e-008,1.987409e-001,4.339435e-001,3,1.730331e-001,1.825000e+000,,,,,,,,,,,,,,,,,,0,4.000000e+000,5.000000e-001,3,2,1.977921e-002,0,,0,
1502446991.706,,1.000000e+001,6.402592e+001,-4.979608e-005,0.000000e+000,5.764571e-002,0.000000e+000,3,3.074262e-001,1.825000e+000,,,,,,,,,,,,,,,,,,0,4.000000e+000,5.000000e-001,3,1,1.110840e-002,1,,0,
1502447354.273,,1.000000e+001,6.500391e+001,-1.926358e-005,2.981580e-006,-7.888420e-002,1.115591e-001,3,3.941553e-001,1.825000e+000,,,,,,,,,,,,,,,,,,0,4.000000e+000,5.000000e-001,3,2,1.907349e-003,0,,0,
1502447511.405,,1.000000e+001,6.604715e+001,-2.670697e-005,1.658632e-005,-3.213098e-001,2.258627e-001,3,4.913203e-001,1.825000e+000,,,,,,,,,,,,,,,,,,0,4.000000e+000,5.000000e-001,3,2,2.946472e-002,0,,0,
1502447727.455,,1.000000e+001,6.702780e+001,-3.441558e-006,1.776068e-005,3.070838e-001,1.177178e+000,3,0.000000e+000,1.825000e+000,,,,,,,,,,,,,,,,,,0,4.000000e+000,5.000000e-001,3,2,5.047607e-002,0,,0,
1502447878.423,,1.000000e+001,6.805595e+001,-3.044737e-005,2.863354e-005,4.448095e-001,8.636456e-001,3,3.943121e-001,1.825000e+000,,,,,,,,,,,,,,,,,,0,4.000000e+000,5.000000e-001,3,2,2.700806e-002,0,,0,
1502448062.638,,1.000000e+001,6.903941e+001,-2.577155e-005,2.197263e-005,6.858071e-001,5.580459e-001,3,1.618680e-001,1.825000e+000,,,,,,,,,,,,,,,,,,0,4.000000e+000,5.000000e-001,3,2,5.335999e-002,0,,0,
1502448213.554,,1.000000e+001,7.005190e+001,-1.126734e-005,6.699871e-006,3.313479e-001,7.149259e-001,3,3.969615e-001,1.825000e+000,,,,,,,,,,,,,,,,,,0,4.000000e+000,5.000000e-001,3,2,3.287506e-002,0,,0,
1502448436.742,,1.000000e+001,7.102028e+001,-3.010559e-005,1.664989e-005,-1.040454e+000,8.955316e-002,3,0.000000e+000,1.825000e+000,,,,,,,,,,,,,,,,,,0,4.000000e+000,5.000000e-001,3,2,1.797485e-002,0,,0,
1502448683.652,,1.000000e+001,7.201054e+001,-2.318367e-005,8.277186e-006,2.199877e-001,1.326636e-001,3,0.000000e+000,1.825000e+000,,,,,,,,,,,,,,,,,,0,4.000000e+000,5.000000e-001,3,2,9.208679e-003,0,,0,
1502448876.538,,1.000000e+001,7.303108e+001,4.465938e-006,5.954565e-006,0.000000e+000,0.000000e+000,3,0.000000e+000,1.825000e+000,,,,,,,,,,,,,,,,,,0,4.000000e+000,5.000000e-001,3,2,3.074646e-002,0,,0,
1502449091.807,,1.000000e+001,7.403112e+001,3.373562e-006,7.372290e-006,-8.775233e-002,1.241005e-001,3,3.813125e-001,1.825000e+000,,,,,,,,,,,,,,,,,,0,4.000000e+000,5.000000e-001,3,2,5.337524e-002,0,,0,
1502449246.220,,1.000000e+001,7.505654e+001,-8.406245e-006,1.032528e-005,-9.821738e-002,1.389004e-001,3,3.917457e-001,1.825000e+000,,,,,,,,,,,,,,,,,,0,4.000000e+000,5.000000e-001,3,2,2.487946e-002,0,,0,
1502449393.665,,1.000000e+001,7.606309e+001,-6.438781e-007,5.987948e-008,-2.260410e-001,1.039473e-002,3,7.176241e-001,1.825000e+000,,,,,,,,,,,,,,,,,,0,4.000000e+000,5.000000e-001,3,2,3.060150e-002,0,,0,
1502449582.383,,1.000000e+001,7.703793e+001,-1.916770e-006,3.641548e-006,5.499728e-001,7.777790e-001,3,0.000000e+000,1.825000e+000,,,,,,,,,,,,,,,,,,0,4.000000e+000,5.000000e-001,3,2,3.131866e-002,0,,0,
1502449773.917,,1.000000e+001,7.804668e+001,-3.017371e-005,1.887512e-005,-1.963613e-001,1.452630e+000,3,7.826968e-002,1.825000e+000,,,,,,,,,,,,,,,,,,0,4.000000e+000,5.000000e-001,3,2,6.414795e-002,0,,0,
1502449959.037,,1.000000e+001,7.903039e+001,1.018745e-005,5.001272e-006,1.329454e-001,1.880132e-001,3,0.000000e+000,1.825000e+000,,,,,,,,,,,,,,,,,,0,4.000000e+000,5.000000e-001,3,2,1.913452e-002,0,,0,
1502450150.718,,1.000000e+001,8.004732e+001,-5.396972e-005,8.611297e-005,1.147461e+000,7.042073e-002,3,1.372557e-001,1.825000e+000,,,,,,,,,,,,,,,,,,0,4.000000e+000,5.000000e-001,3,2,6.153870e-002,0,,0,
1502450309.169,,1.000000e+001,8.106238e+001,2.331669e-005,1.743856e-005,5.415149e-001,7.658177e-001,3,0.000000e+000,1.825000e+000,,,,,,,,,,,,,,,,,,0,4.000000e+000,5.000000e-001,3,2,3.723145e-002,0,,0,
1502450649.744,,1.000000e+001,8.206731e+001,1.009280e-007,0.000000e+000,-1.074843e+000,0.000000e+000,3,0.000000e+000,1.825000e+000,,,,,,,,,,,,,,,,,,0,4.000000e+000,5.000000e-001,3,1,1.464081e-002,1,,0,
1502450957.013,,1.000000e+001,8.303146e+001,-1.308271e-005,1.845258e-005,0.000000e+000,0.000000e+000,3,0.000000e+000,1.825000e+000,,,,,,,,,,,,,,,,,,0,4.000000e+000,5.000000e-001,3,2,2.990723e-003,0,,0,
1502451111.888,,1.000000e+001,8.406908e+001,-1.365443e-006,6.853254e-006,-3.624338e-001,2.065324e+000,3,0.000000e+000,1.825000e+000,,,,,,,,,,,,,,,,,,0,4.000000e+000,5.000000e-001,3,2,2.750397e-002,0,,0,
1502451264.160,,1.000000e+001,8.507033e+001,6.052344e-006,8.707715e-006,-1.409400e+000,6.855264e-001,3,0.000000e+000,1.825000e+000,,,,,,,,,,,,,,,,,,0,4.000000e+000,5.000000e-001,3,2,3.435516e-002,0,,0,
1502451480.941,,1.000000e+001,8.601929e+001,2.173502e-005,1.075237e-005,-3.570334e-001,1.342908e-001,3,5.876481e-003,1.825000e+000,,,,,,,,,,,,,,,,,,0,4.000000e+000,5.000000e-001,3,2,6.370544e-003,0,,0,
1502451631.666,,1.000000e+001,8.708458e+001,2.245225e-005,3.426822e-005,-1.115071e+000,7.781185e-002,3,1.523653e-001,1.825000e+000,,,,,,,,,,,,,,,,,,0,4.000000e+000,5.000000e-001,3,2,5.213928e-002,0,,0,
1502451793.158,,1.000000e+001,8.806506e+001,4.669104e-006,4.541350e-005,-3.290522e-002,1.551967e+000,3,1.245166e-001,1.825000e+000,,,,,,,,,,,,,,,,,,0,4.000000e+000,5.000000e-001,3,2,3.659058e-002,0,,0,
1502451948.127,,1.000000e+001,8.907448e+001,-1.915981e-006,2.748820e-006,9.155496e-001,1.294783e+000,3,0.000000e+000,1.825000e+000,,,,,,,,,,,,,,,,,,0,4.000000e+000,5.000000e-001,3,2,3.059387e-002,0,,0,
1502452105.996,,1.000000e+001,9.006560e+001,-1.091978e-005,1.539052e-005,5.209591e-001,7.367475e-001,3,0.000000e+000,1.825000e+000,,,,,,,,,,,,,,,,,,0,4.000000e+000,5.000000e-001,3,2,1.734924e-002,0,,0,
1502452316.510,,1.000000e+001,9.104594e+001,1.967372e-005,3.887478e-005,-1.606704e-001,2.272222e-001,3,0.000000e+000,1.825000e+000,,,,,,,,,,,,,,,,,,0,4.000000e+000,5.000000e-001,3,2,9.212494e-002,0,,0,
1502452471.000,,1.000000e+001,9.208379e+001,8.018432e-006,4.986134e-005,-1.130396e+000,8.008255e-002,3,1.473830e-001,1.825000e+000,,,,,,,,,,,,,,,,,,0,4.000000e+000,5.000000e-001,3,2,5.068970e-002,0,,0,
1502452712.088,,1.000000e+001,9.301497e+001,-1.701230e-006,2.256109e-006,1.046796e+000,4.809596e-002,3,0.000000e+000,1.825000e+000,,,,,,,,,,,,,,,,,,0,4.000000e+000,5.000000e-001,3,2,1.475525e-002,0,,0,
1502453042.317,,1.000000e+001,9.408472e+001,-1.327293e-005,0.000000e+000,3.451153e-001,0.000000e+000,3,0.000000e+000,1.825000e+000,,,,,,,,,,,,,,,,,,0,4.000000e+000,5.000000e-001,3,1,1.884460e-002,1,,0,
1502453343.152,,1.000000e+001,9.504814e+001,-2.658255e-005,1.410015e-006,2.184397e-002,1.568115e+000,3,0.000000e+000,1.825000e+000,,,,,,,,,,,,,,,,,,0,4.000000e+000,5.000000e-001,3,2,2.305603e-002,0,,0,
1502453497.536,,1.000000e+001,9.608932e+001,7.914266e-006,1.114434e-005,-5.470875e-001,7.736986e-001,3,0.000000e+000,1.825000e+000,,,,,,,,,,,,,,,,,,0,4.000000e+000,5.000000e-001,3,2,4.708862e-002,0,,0,
1502453711.273,,1.000000e+001,9.489362e+001,-5.293292e-007,3.118551e-006,5.498946e-001,7.776684e-001,3,0.000000e+000,1.825000e+000,,,,,,,,,,,,,,,,,,0,4.000000e+000,5.000000e-001,3,2,2.684021e-002,0,,0,
1502453924.403,,1.000000e+001,9.396608e+001,1.732743e-006,2.497864e-006,4.887990e-001,6.912662e-001,3,0.000000e+000,1.825000e+000,,,,,,,,,,,,,,,,,,0,4.000000e+000,5.000000e-001,3,2,8.277893e-002,0,,0,
1502454226.077,,1.000000e+001,9.303158e+001,1.071732e-005,1.477660e-005,-4.582687e-001,6.480898e-001,3,0.000000e+000,1.825000e+000,,,,,,,,,,,,,,,,,,0,4.000000e+000,5.000000e-001,3,2,1.475525e-002,0,,0,
1502454399.548,,1.000000e+001,9.181931e+001,1.422687e-005,2.014477e-005,-1.938194e-002,1.513235e+000,3,0.000000e+000,1.825000e+000,,,,,,,,,,,,,,,,,,0,4.000000e+000,5.000000e-001,3,2,8.283997e-002,0,,0,
1502454552.295,,1.000000e+001,9.089645e+001,5.699967e-006,2.763668e-006,5.499991e-001,7.778161e-001,3,0.000000e+000,1.825000e+000,,,,,,,,,,,,,,,,,,0,4.000000e+000,5.000000e-001,3,2,3.887177e-002,0,,0,
1502454704.278,,1.000000e+001,8.985950e+001,-9.106921e-006,4.164969e-005,2.894836e-001,1.220835e+000,3,1.518028e-001,1.825000e+000,,,,,,,,,,,,,,,,,,0,4.000000e+000,5.000000e-001,3,2,3.112030e-002,0,,0,
1502454861.501,,1.000000e+001,8.886079e+001,-5.523229e-006,5.062059e-006,5.493203e-001,7.768562e-001,3,0.000000e+000,1.825000e+000,,,,,,,,,,,,,,,,,,0,4.000000e+000,5.000000e-001,3,2,8.799744e-002,0,,0,
1502455013.447,,1.000000e+001,8.789156e+001,1.420775e-005,6.435177e-006,1.609868e-001,1.330306e+000,3,0.000000e+000,1.825000e+000,,,,,,,,,,,,,,,,,,0,4.000000e+000,5.000000e-001,3,2,6.631470e-002,0,,0,
1502455220.758,,1.000000e+001,8.693736e+001,1.600333e-006,1.536470e-005,-2.499997e-001,7.226426e-001,3,0.000000e+000,1.825000e+000,,,,,,,,,,,,,,,,,,0,4.000000e+000,5.000000e-001,3,2,1.722031e-001,0,,0,
1502456100.114,,1.000000e+001,8.504222e+001,8.411522e-006,2.431744e-005,8.630586e-002,1.220549e-001,3,0.000000e+000,1.825000e+000,,,,,,,,,,,,,,,,,,0,4.000000e+000,5.000000e-001,3,2,3.433990e-002,0,,0,
1502456287.568,,1.000000e+001,8.390050e+001,-7.779319e-006,1.107646e-005,9.593988e-001,1.356795e+000,3,0.000000e+000,1.825000e+000,,,,,,,,,,,,,,,,,,0,4.000000e+000,5.000000e-001,3,2,9.140015e-002,0,,0,
1502456449.833,,1.000000e+001,8.290983e+001,-2.160468e-005,8.556705e-006,1.064366e+000,9.901618e-002,3,0.000000e+000,1.825000e+000,,,,,,,,,,,,,,,,,,0,4.000000e+000,5.000000e-001,3,2,6.261444e-002,0,,0,
1502456839.632,,1.000000e+001,8.201173e+001,2.070426e-005,1.641125e-005,-1.573075e-001,9.092054e-001,3,0.000000e+000,1.825000e+000,,,,,,,,,,,,,,,,,,0,4.000000e+000,5.000000e-001,3,2,1.755524e-002,0,,0,
1502457098.293,,1.000000e+001,8.106166e+001,6.202980e-006,8.061903e-007,0.000000e+000,0.000000e+000,3,0.000000e+000,1.825000e+000,,,,,,,,,,,,,,,,,,0,4.000000e+000,5.000000e-001,3,2,3.435516e-002,0,,0,
1502457396.165,,1.000000e+001,8.003543e+001,2.830016e-006,4.053802e-006,0.000000e+000,0.000000e+000,3,0.000000e+000,1.825000e+000,,,,,,,,,,,,,,,,,,0,4.000000e+000,5.000000e-001,3,2,2.796936e-002,0,,0,
1502457557.389,,1.000000e+001,7.887013e+001,1.215338e-005,1.756117e-005,-5.423241e-001,7.669621e-001,3,0.000000e+000,1.825000e+000,,,,,,,,,,,,,,,,,,0,4.000000e+000,5.000000e-001,3,2,1.170959e-001,0,,0,
1502458349.516,,1.000000e+001,7.704118e+001,1.994462e-005,0.000000e+000,-1.078978e+000,0.000000e+000,3,0.000000e+000,1.825000e+000,,,,,,,,,,,,,,,,,,0,4.000000e+000,5.000000e-001,3,1,3.131866e-002,1,,0,
1502458757.637,,1.000000e+001,7.605289e+001,-1.904675e-005,2.940538e-005,1.132460e+000,4.593829e-002,3,1.614014e-001,1.825000e+000,,,,,,,,,,,,,,,,,,0,4.000000e+000,5.000000e-001,3,2,1.784515e-002,0,,0,
1502458999.545,,1.000000e+001,7.505282e+001,-3.355453e-006,7.055519e-006,1.065884e+000,4.702046e-002,3,0.000000e+000,1.825000e+000,,,,,,,,,,,,,,,,,,0,4.000000e+000,5.000000e-001,3,2,4.972076e-002,0,,0,
1502459350.608,,1.000000e+001,7.198116e+001,-9.608440e-005,1.127787e-004,-5.473660e-001,7.740924e-001,3,1.974004e-002,1.825000e+000,,,,,,,,,,,,,,,,,,0,4.000000e+000,5.000000e-001,3,2,5.299377e-002,0,,0,
1502459586.310,,1.000000e+001,6.709853e+001,4.023298e-006,5.530313e-006,3.589375e-001,5.076143e-001,3,0.000000e+000,1.825000e+000,,,,,,,,,,,,,,,,,,0,4.000000e+000,5.000000e-001,3,2,2.629089e-002,0,,0,
1502459801.787,,1.000000e+001,6.208805e+001,2.928635e-005,8.390856e-006,-2.042423e-001,3.640915e-001,3,1.415087e-001,1.825000e+000,,,,,,,,,,,,,,,,,,0,4.000000e+000,5.000000e-001,3,2,1.224899e-002,0,,0,
1502460059.745,,1.000000e+001,5.705712e+001,2.396328e-007,8.893383e-008,0.000000e+000,0.000000e+000,3,0.000000e+000,1.825000e+000,,,,,,,,,,,,,,,,,,0,4.000000e+000,5.000000e-001,3,2,2.080917e-002,0,,0,
1502460455.048,,1.000000e+001,5.204602e+001,-1.174240e-004,0.000000e+000,1.159831e+000,0.000000e+000,3,3.161095e-001,1.825000e+000,,,,,,,,,,,,,,,,,,0,4.000000e+000,5.000000e-001,3,1,1.374054e-002,1,,0,
1502460796.794,,1.000000e+001,4.702330e+001,-1.541298e-005,2.783906e-005,-4.759949e-001,6.731585e-001,3,0.000000e+000,1.825000e+000,,,,,,,,,,,,,,,,,,0,4.000000e+000,5.000000e-001,3,2,1.029968e-003,0,,0,
1502461172.846,,1.000000e+001,4.199858e+001,2.548370e-006,1.127179e-005,-5.024117e-001,7.105174e-001,3,0.000000e+000,1.825000e+000,,,,,,,,,,,,,,,,,,0,4.000000e+000,5.000000e-001,3,2,9.170532e-003,0,,0,
1502461708.045,,1.000000e+001,3.700072e+001,2.010821e-005,0.000000e+000,4.433968e-001,0.000000e+000,3,0.000000e+000,1.825000e+000,,,,,,,,,,,,,,,,,,0,4.000000e+000,5.000000e-001,3,1,0.000000e+000,1,,0,
1502462085.604,,1.000000e+001,3.199846e+001,-2.203933e-005,3.060818e-005,-9.299815e-002,1.402641e+000,3,0.000000e+000,1.825000e+000,,,,,,,,,,,,,,,,,,0,4.000000e+000,5.000000e-001,3,2,3.738403e-003,0,,0,
1502462288.241,,1.000000e+001,2.698839e+001,2.026940e-005,2.919663e-005,5.531167e-001,7.822251e-001,3,0.000000e+000,1.825000e+000,,,,,,,,,,,,,,,,,,0,4.000000e+000,5.000000e-001,3,2,3.620148e-003,0,,0,
1502462550.562,,1.000000e+001,2.199126e+001,-3.321504e-005,4.772847e-005,-3.088355e-001,2.142567e+000,3,1.495258e-001,1.825000e+000,,,,,,,,,,,,,,,,,,0,4.000000e+000,5.000000e-001,3,2,2.264023e-002,0,,0,