File: Data/Ta (20 nm) Annealed 500 C/20171025-YBCO-Ta-500C.dc.dat
[Header]
TITLE,MPMS DC Measurement
BYAPP,MPMS Measurement,2.1,Summary
FILEOPENTIME, 1508963932.733000 10/25/2017, 1:38:52 PM

INFO, APPNAME, MPMS MultiVu Application, Revision 1.61,  Build 082

INFO, NAME, YBCO Ta20nm annealed 500C
INFO, WEIGHT, 55.700
INFO, AREA, 1.000
INFO, LENGTH, 1.000
INFO, SHAPE, with substrate
INFO, COMMENT, H in plane
INFO, SEQUENCE FILE: 20171025-YBCO-Ta-500C.seq


INFO, BACKGROUND DATA FILE:, None


STARTUPAXIS,X,4,LINEAR,AUTO,0.000000,0.000000
STARTUPAXIS,Y1,5,LINEAR,AUTO,0.000000,0.000000


STARTUPGROUP,Longitudinal
FIELDGROUP,Longitudinal,1,2,3,4,5,6,7,8,9,15,16,17,18,27,28
FIELDGROUP,Transverse,1,2,3,4,10,11,12,13,14,19,20,21,22,27,28

PLOT_APPEARANCE,ALL,HORZ_GRID_ON,VERT_GRID_ON,MARKERS_AND_LINES

[Data]
Time,Comment,Field (Oe),Temperature (K),Long Moment (emu),Long Scan Std Dev,Long Algorithm,Long Reg Fit,Long Percent Error (%),Trans Moment (emu),Trans Scan Std Dev,Trans Algorithm,Trans Reg Fit,Trans Percent Error (%),Long Moment [w/o ABS] (emu),Long Scan Std Dev [w/o ABS],Long Reg Fit [w/o ABS],Long Percent Error [w/o ABS] (%),Trans Moment [w/o ABS] (emu),Trans Scan Std Dev [w/o ABS],Trans Reg Fit [w/o ABS],Trans Percent Error [w/o ABS] (%),Points per Scan,Scans per Measurement,Scan Length (cm),Delta Temp (K),Rot Position (deg),Error,EC Comp. Running,Using ABS,
1508963932.733,,1.000000e+001,1.999960e+000,9.409948e-007,1.149566e-007,3,6.340712e-001,1.221650e+001,,,,,,,,,,,,,,48,2,6.000000e+000,1.986861e-003,0.000000e+000,0,,0,
1508964784.124,,1.000000e+001,4.004642e+000,8.483164e-007,7.708029e-008,3,6.240985e-001,9.086267e+000,,,,,,,,,,,,,,48,2,6.000000e+000,1.167297e-002,0.000000e+000,0,,0,
1508964973.055,,1.000000e+001,5.998962e+000,7.146108e-007,7.058630e-008,3,4.599293e-001,9.877586e+000,,,,,,,,,,,,,,48,2,6.000000e+000,1.287794e-002,0.000000e+000,0,,0,
1508965103.165,,1.000000e+001,8.003508e+000,8.380608e-007,3.020209e-008,3,5.372238e-001,3.603806e+000,,,,,,,,,,,,,,48,2,6.000000e+000,9.811401e-003,0.000000e+000,0,,0,
1508965235.155,,1.000000e+001,1.000540e+001,7.504576e-007,5.217153e-008,3,4.286220e-001,6.951962e+000,,,,,,,,,,,,,,48,2,6.000000e+000,1.320839e-002,0.000000e+000,0,,0,
1508965492.605,,1.000000e+001,1.199426e+001,6.474413e-007,1.088833e-007,3,3.880315e-001,1.681748e+001,,,,,,,,,,,,,,48,2,6.000000e+000,7.240295e-003,0.000000e+000,0,,0,
1508965631.805,,1.000000e+001,1.400060e+001,7.296541e-007,1.141432e-007,3,5.493665e-001,1.564347e+001,,,,,,,,,,,,,,48,2,6.000000e+000,7.169724e-003,0.000000e+000,0,,0,
1508965774.016,,1.000000e+001,1.599200e+001,7.685022e-007,5.478472e-008,3,5.978659e-001,7.128766e+000,,,,,,,,,,,,,,48,2,6.000000e+000,5.220413e-003,0.000000e+000,0,,0,
1508965917.376,,1.000000e+001,1.799211e+001,6.813594e-007,3.396802e-008,3,5.328108e-001,4.985331e+000,,,,,,,,,,,,,,48,2,6.000000e+000,5.790710e-003,0.000000e+000,0,,0,
1508966067.636,,1.000000e+001,1.999143e+001,8.426949e-007,9.598946e-008,3,5.698093e-001,1.139077e+001,,,,,,,,,,,,,,48,2,6.000000e+000,7.110596e-003,0.000000e+000,0,,0,
1508966202.476,,1.000000e+001,2.199044e+001,8.106774e-007,2.994227e-008,3,5.801471e-001,3.693488e+000,,,,,,,,,,,,,,48,2,6.000000e+000,6.731033e-003,0.000000e+000,0,,0,
1508966356.796,,1.000000e+001,2.398914e+001,8.329375e-007,1.163304e-007,3,5.633927e-001,1.396628e+001,,,,,,,,,,,,,,48,2,6.000000e+000,9.418488e-003,0.000000e+000,0,,0,
1508966499.467,,1.000000e+001,2.600115e+001,6.908787e-007,2.514355e-008,3,5.267809e-001,3.639358e+000,,,,,,,,,,,,,,48,2,6.000000e+000,4.219055e-003,0.000000e+000,0,,0,
1508966641.687,,1.000000e+001,2.800028e+001,7.779802e-007,2.208041e-008,3,5.499510e-001,2.838172e+000,,,,,,,,,,,,,,48,2,6.000000e+000,3.879547e-003,0.000000e+000,0,,0,
1508966797.997,,1.000000e+001,3.000098e+001,7.425649e-007,4.836857e-008,3,5.710672e-001,6.513717e+000,,,,,,,,,,,,,,48,2,6.000000e+000,4.428864e-003,0.000000e+000,0,,0,
1508966951.067,,1.000000e+001,3.200313e+001,6.768690e-007,1.373795e-008,3,5.968819e-001,2.029632e+000,,,,,,,,,,,,,,48,2,6.000000e+000,7.499695e-003,0.000000e+000,0,,0,
1508967109.218,,1.000000e+001,3.400154e+001,7.667442e-007,4.457905e-008,3,6.319685e-001,5.814071e+000,,,,,,,,,,,,,,48,2,6.000000e+000,4.219055e-003,0.000000e+000,0,,0,
1508967265.538,,1.000000e+001,3.600519e+001,7.729196e-007,1.537603e-008,3,6.247228e-001,1.989344e+000,,,,,,,,,,,,,,48,2,6.000000e+000,6.259918e-003,0.000000e+000,0,,0,
1508967434.628,,1.000000e+001,3.800421e+001,7.987920e-007,1.864303e-008,3,6.098066e-001,2.333903e+000,,,,,,,,,,,,,,48,2,6.000000e+000,1.905823e-002,0.000000e+000,0,,0,
1508967615.548,,1.000000e+001,4.000055e+001,7.070928e-007,4.438961e-008,3,5.878911e-001,6.277763e+000,,,,,,,,,,,,,,48,2,6.000000e+000,7.610321e-003,0.000000e+000,0,,0,
1508967794.599,,1.000000e+001,4.200845e+001,6.528659e-007,2.964411e-008,3,5.328126e-001,4.540612e+000,,,,,,,,,,,,,,48,2,6.000000e+000,1.667786e-002,0.000000e+000,0,,0,
1508967965.849,,1.000000e+001,4.401545e+001,6.705907e-007,1.573533e-008,3,4.968498e-001,2.346488e+000,,,,,,,,,,,,,,48,2,6.000000e+000,2.278137e-002,0.000000e+000,0,,0,
1508968129.629,,1.000000e+001,4.602162e+001,6.901789e-007,3.001104e-008,3,5.462449e-001,4.348300e+000,,,,,,,,,,,,,,48,2,6.000000e+000,1.240158e-002,0.000000e+000,0,,0,
1508968280.979,,1.000000e+001,4.802760e+001,7.180407e-007,5.355280e-008,3,5.984601e-001,7.458185e+000,,,,,,,,,,,,,,48,2,6.000000e+000,2.153015e-002,0.000000e+000,0,,0,
1508968442.319,,1.000000e+001,5.003299e+001,6.985440e-007,1.811058e-008,3,5.122223e-001,2.592618e+000,,,,,,,,,,,,,,48,2,6.000000e+000,2.787018e-002,0.000000e+000,0,,0,
1508968601.990,,1.000000e+001,5.204607e+001,7.141099e-007,4.809120e-008,3,5.714890e-001,6.734425e+000,,,,,,,,,,,,,,48,2,6.000000e+000,3.371811e-002,0.000000e+000,0,,0,
1508968751.280,,1.000000e+001,5.405640e+001,6.778555e-007,8.181604e-009,3,5.782745e-001,1.206983e+000,,,,,,,,,,,,,,48,2,6.000000e+000,3.485107e-002,0.000000e+000,0,,0,
1508968905.260,,1.000000e+001,5.605801e+001,6.372172e-007,2.435228e-008,3,5.465281e-001,3.821661e+000,,,,,,,,,,,,,,48,2,6.000000e+000,2.729797e-002,0.000000e+000,0,,0,
1508969062.950,,1.000000e+001,5.806220e+001,7.397360e-007,5.313715e-008,3,6.315825e-001,7.183259e+000,,,,,,,,,,,,,,48,2,6.000000e+000,2.922058e-002,0.000000e+000,0,,0,
1508969214.480,,1.000000e+001,6.007348e+001,6.302495e-007,4.086236e-008,3,6.204296e-001,6.483521e+000,,,,,,,,,,,,,,48,2,6.000000e+000,4.104996e-002,0.000000e+000,0,,0,
1508969372.531,,1.000000e+001,6.206521e+001,7.278625e-007,5.317779e-008,3,6.121984e-001,7.306022e+000,,,,,,,,,,,,,,48,2,6.000000e+000,4.893112e-002,0.000000e+000,0,,0,
1508969527.771,,1.000000e+001,6.407720e+001,7.360639e-007,3.679979e-008,3,6.095144e-001,4.999537e+000,,,,,,,,,,,,,,48,2,6.000000e+000,5.008698e-002,0.000000e+000,0,,0,
1508969694.631,,1.000000e+001,6.606953e+001,7.014041e-007,1.967080e-008,3,5.796077e-001,2.804489e+000,,,,,,,,,,,,,,48,2,6.000000e+000,4.716492e-002,0.000000e+000,0,,0,
1508969849.241,,1.000000e+001,6.807960e+001,6.688304e-007,4.272854e-008,3,5.150294e-001,6.388546e+000,,,,,,,,,,,,,,48,2,6.000000e+000,4.367065e-002,0.000000e+000,0,,0,
1508970001.712,,1.000000e+001,7.009489e+001,7.042987e-007,1.489330e-008,3,5.742970e-001,2.114628e+000,,,,,,,,,,,,,,48,2,6.000000e+000,2.633667e-002,0.000000e+000,0,,0,
1508970162.042,,1.000000e+001,7.208345e+001,6.785240e-007,3.581121e-008,3,6.104982e-001,5.277811e+000,,,,,,,,,,,,,,48,2,6.000000e+000,6.005859e-002,0.000000e+000,0,,0,
1508970321.222,,1.000000e+001,7.409018e+001,7.087248e-007,5.480241e-008,3,5.545208e-001,7.732537e+000,,,,,,,,,,,,,,48,2,6.000000e+000,5.584717e-002,0.000000e+000,0,,0,
1508970477.822,,1.000000e+001,7.611491e+001,7.113290e-007,2.005984e-008,3,6.323204e-001,2.820051e+000,,,,,,,,,,,,,,48,2,6.000000e+000,6.636047e-002,0.000000e+000,0,,0,
1508970646.063,,1.000000e+001,7.808961e+001,6.883769e-007,9.046426e-009,3,6.420654e-001,1.314168e+000,,,,,,,,,,,,,,48,2,6.000000e+000,7.225037e-002,0.000000e+000,0,,0,
1508970814.073,,1.000000e+001,8.008872e+001,7.569008e-007,3.901571e-008,3,6.118141e-001,5.154666e+000,,,,,,,,,,,,,,48,2,6.000000e+000,6.721497e-002,0.000000e+000,0,,0,
1508970979.223,,1.000000e+001,8.209154e+001,6.587039e-007,1.474128e-009,3,5.572703e-001,2.237923e-001,,,,,,,,,,,,,,48,2,6.000000e+000,2.635956e-002,0.000000e+000,0,,0,
1508971147.933,,1.000000e+001,8.411732e+001,6.273956e-007,5.453291e-009,3,5.142221e-001,8.691949e-001,,,,,,,,,,,,,,48,2,6.000000e+000,4.590607e-002,0.000000e+000,0,,0,
1508971310.313,,1.000000e+001,8.610945e+001,6.128688e-007,1.572838e-008,3,5.534730e-001,2.566353e+000,,,,,,,,,,,,,,48,2,6.000000e+000,6.385040e-002,0.000000e+000,0,,0,
1508971478.324,,1.000000e+001,8.810500e+001,5.801373e-007,1.214412e-007,3,4.361116e-001,2.093318e+001,,,,,,,,,,,,,,48,2,6.000000e+000,8.989716e-002,0.000000e+000,0,,0,
1508971646.624,,1.000000e+001,9.011856e+001,6.625696e-007,1.115273e-008,3,5.093064e-001,1.683254e+000,,,,,,,,,,,,,,48,2,6.000000e+000,1.042938e-001,0.000000e+000,0,,0,
1508971814.764,,1.000000e+001,9.210272e+001,7.056789e-007,3.850472e-008,3,5.995183e-001,5.456408e+000,,,,,,,,,,,,,,48,2,6.000000e+000,7.609558e-002,0.000000e+000,0,,0,
1508971973.844,,1.000000e+001,9.413556e+001,6.519880e-007,1.279025e-008,3,5.885826e-001,1.961731e+000,,,,,,,,,,,,,,48,2,6.000000e+000,6.041718e-002,0.000000e+000,0,,0,
1508972134.075,,1.000000e+001,9.614416e+001,6.571155e-007,8.902807e-008,3,6.044538e-001,1.354831e+001,,,,,,,,,,,,,,48,2,6.000000e+000,5.500793e-002,0.000000e+000,0,,0,
1508972305.535,,1.000000e+001,9.813351e+001,6.282734e-007,2.165914e-009,3,5.486330e-001,3.447407e-001,,,,,,,,,,,,,,48,2,6.000000e+000,1.021576e-001,0.000000e+000,0,,0,
1508981505.368,,1.000000e+001,2.001731e+000,-4.461643e-008,6.329319e-009,3,0.000000e+000,1.418607e+001,,,,,,,,,,,,,,48,2,6.000000e+000,7.345080e-003,0.000000e+000,0,,0,
1508981781.578,,1.000000e+001,4.004023e+000,-6.351731e-008,5.658424e-008,3,0.000000e+000,8.908475e+001,,,,,,,,,,,,,,48,2,6.000000e+000,1.763725e-002,0.000000e+000,0,,0,
1508981935.308,,1.000000e+001,6.003730e+000,-8.866305e-008,1.078871e-007,3,0.000000e+000,1.216822e+002,,,,,,,,,,,,,,48,2,6.000000e+000,1.878214e-002,0.000000e+000,0,,0,
1508982105.039,,1.000000e+001,8.027409e+000,-5.379814e-008,4.532561e-009,3,0.000000e+000,8.425125e+000,,,,,,,,,,,,,,48,2,6.000000e+000,1.069627e-001,0.000000e+000,0,,0,
1508982239.489,,1.000000e+001,9.999376e+000,-5.409903e-008,2.031858e-008,3,0.000000e+000,3.755812e+001,,,,,,,,,,,,,,48,2,6.000000e+000,2.384377e-002,0.000000e+000,0,,0,
1508982381.969,,1.000000e+001,1.199586e+001,-5.835172e-008,5.249525e-009,3,0.000000e+000,8.996349e+000,,,,,,,,,,,,,,48,2,6.000000e+000,1.530933e-002,0.000000e+000,0,,0,
1508982526.909,,1.000000e+001,1.400245e+001,-7.502514e-008,1.020330e-008,3,0.000000e+000,1.359983e+001,,,,,,,,,,,,,,48,2,6.000000e+000,8.709908e-003,0.000000e+000,0,,0,
1508982670.629,,1.000000e+001,1.599183e+001,-4.788394e-008,2.387509e-008,2,0.000000e+000,4.986034e+001,,,,,,,,,,,,,,48,2,6.000000e+000,3.919601e-003,0.000000e+000,0,,0,
1508982809.450,,1.000000e+001,1.799129e+001,-5.181234e-008,1.316036e-007,3,0.000000e+000,2.540004e+002,,,,,,,,,,,,,,48,2,6.000000e+000,7.431030e-003,0.000000e+000,0,,0,
1508982950.570,,1.000000e+001,1.999371e+001,-6.087532e-008,3.557596e-008,3,0.000000e+000,5.844069e+001,,,,,,,,,,,,,,48,2,6.000000e+000,2.031326e-003,0.000000e+000,0,,0,
1508983098.160,,1.000000e+001,2.199090e+001,-1.484147e-007,8.608266e-008,3,0.000000e+000,5.800145e+001,,,,,,,,,,,,,,48,2,6.000000e+000,3.669739e-003,0.000000e+000,0,,0,
1508983242.640,,1.000000e+001,2.399223e+001,-6.711505e-008,7.476127e-009,2,0.000000e+000,1.113927e+001,,,,,,,,,,,,,,48,2,6.000000e+000,5.081177e-003,0.000000e+000,0,,0,
1508983425.300,,1.000000e+001,2.600010e+001,-1.475981e-008,3.570024e-008,3,0.000000e+000,2.418747e+002,,,,,,,,,,,,,,48,2,6.000000e+000,1.012039e-002,0.000000e+000,0,,0,
1508983574.551,,1.000000e+001,2.799955e+001,1.528677e-008,2.066761e-007,3,0.000000e+000,1.351993e+003,,,,,,,,,,,,,,48,2,6.000000e+000,3.879547e-003,0.000000e+000,0,,0,
1508983722.651,,1.000000e+001,3.000181e+001,-2.932157e-008,3.552185e-008,3,0.000000e+000,1.211458e+002,,,,,,,,,,,,,,48,2,6.000000e+000,5.529404e-003,0.000000e+000,0,,0,
1508983879.931,,1.000000e+001,3.200438e+001,-7.115519e-008,5.038261e-008,3,0.000000e+000,7.080666e+001,,,,,,,,,,,,,,48,2,6.000000e+000,3.749847e-003,0.000000e+000,0,,0,
1508984036.971,,1.000000e+001,3.400576e+001,-1.202153e-008,3.046098e-008,3,0.000000e+000,2.533868e+002,,,,,,,,,,,,,,48,2,6.000000e+000,9.830475e-003,0.000000e+000,0,,0,
1508984195.481,,1.000000e+001,3.600714e+001,-5.226523e-008,8.682213e-008,3,0.000000e+000,1.661183e+002,,,,,,,,,,,,,,48,2,6.000000e+000,1.094818e-002,0.000000e+000,0,,0,
1508984365.742,,1.000000e+001,3.800854e+001,-4.062255e-008,2.695410e-008,2,0.000000e+000,6.635256e+001,,,,,,,,,,,,,,48,2,6.000000e+000,6.938934e-003,0.000000e+000,0,,0,
1508984539.282,,1.000000e+001,4.000437e+001,-2.867132e-009,1.187430e-007,3,0.000000e+000,4.141524e+003,,,,,,,,,,,,,,48,2,6.000000e+000,9.529114e-003,0.000000e+000,0,,0,
1508984705.402,,1.000000e+001,4.201418e+001,-1.945023e-008,5.940681e-009,3,0.000000e+000,3.054299e+001,,,,,,,,,,,,,,48,2,6.000000e+000,1.042175e-002,0.000000e+000,0,,0,
1508984877.422,,1.000000e+001,4.400919e+001,-9.017872e-008,6.735928e-009,3,0.000000e+000,7.469532e+000,,,,,,,,,,,,,,48,2,6.000000e+000,1.821136e-002,0.000000e+000,0,,0,
1508985047.843,,1.000000e+001,4.601914e+001,-8.821808e-008,3.303211e-008,3,0.000000e+000,3.744370e+001,,,,,,,,,,,,,,48,2,6.000000e+000,1.984024e-002,0.000000e+000,0,,0,
1508985208.323,,1.000000e+001,4.802303e+001,9.608824e-008,1.348997e-008,3,0.000000e+000,1.403915e+001,,,,,,,,,,,,,,48,2,6.000000e+000,1.937103e-002,0.000000e+000,0,,0,
1508985363.773,,1.000000e+001,5.004227e+001,8.235824e-009,1.556647e-008,3,0.000000e+000,1.890093e+002,,,,,,,,,,,,,,48,2,6.000000e+000,1.742172e-002,0.000000e+000,0,,0,
1508985525.063,,1.000000e+001,5.203951e+001,-4.179128e-008,7.067442e-008,3,0.000000e+000,1.691129e+002,,,,,,,,,,,,,,48,2,6.000000e+000,4.496002e-002,0.000000e+000,0,,0,
1508985682.404,,1.000000e+001,5.405171e+001,-1.247399e-007,1.400551e-008,3,0.000000e+000,1.122777e+001,,,,,,,,,,,,,,48,2,6.000000e+000,2.545929e-002,0.000000e+000,0,,0,
1508985853.244,,1.000000e+001,5.604507e+001,-6.228937e-008,1.211239e-008,2,0.000000e+000,1.944536e+001,,,,,,,,,,,,,,48,2,6.000000e+000,2.585983e-002,0.000000e+000,0,,0,
1508986004.734,,1.000000e+001,5.805914e+001,-6.606658e-008,6.313644e-008,3,0.000000e+000,9.556487e+001,,,,,,,,,,,,,,48,2,6.000000e+000,3.844070e-002,0.000000e+000,0,,0,
1508986156.144,,1.000000e+001,6.007307e+001,-3.766534e-008,1.631896e-008,3,0.000000e+000,4.332621e+001,,,,,,,,,,,,,,48,2,6.000000e+000,4.269028e-002,0.000000e+000,0,,0,
1508986311.344,,1.000000e+001,6.206129e+001,-7.234165e-008,1.849622e-008,3,0.000000e+000,2.556787e+001,,,,,,,,,,,,,,48,2,6.000000e+000,5.592346e-002,0.000000e+000,0,,0,
1508986472.235,,1.000000e+001,6.407720e+001,8.143936e-008,1.029957e-007,3,0.000000e+000,1.264692e+002,,,,,,,,,,,,,,48,2,6.000000e+000,2.412415e-002,0.000000e+000,0,,0,
1508986630.035,,1.000000e+001,6.608132e+001,-7.473665e-008,2.440966e-008,3,0.000000e+000,3.266090e+001,,,,,,,,,,,,,,48,2,6.000000e+000,2.948761e-002,0.000000e+000,0,,0,
1508986784.935,,1.000000e+001,6.808427e+001,-7.803472e-008,1.237981e-007,3,0.000000e+000,1.586449e+002,,,,,,,,,,,,,,48,2,6.000000e+000,4.159546e-002,0.000000e+000,0,,0,
1508986954.835,,1.000000e+001,7.006529e+001,7.789962e-009,3.675541e-008,3,0.000000e+000,4.718304e+002,,,,,,,,,,,,,,48,2,6.000000e+000,4.608917e-002,0.000000e+000,0,,0,
1508987115.326,,1.000000e+001,7.207594e+001,-7.434942e-008,6.478345e-008,3,0.000000e+000,8.713377e+001,,,,,,,,,,,,,,48,2,6.000000e+000,5.773926e-002,0.000000e+000,0,,0,
1508987271.566,,1.000000e+001,7.409563e+001,-4.379655e-008,4.799082e-008,3,0.000000e+000,1.095767e+002,,,,,,,,,,,,,,48,2,6.000000e+000,5.101013e-002,0.000000e+000,0,,0,
1508987434.476,,1.000000e+001,7.609131e+001,-1.443866e-009,1.173148e-008,3,0.000000e+000,8.125048e+002,,,,,,,,,,,,,,48,2,6.000000e+000,7.398224e-002,0.000000e+000,0,,0,
1508987597.216,,1.000000e+001,7.810633e+001,3.183225e-008,5.519041e-009,3,0.000000e+000,1.733789e+001,,,,,,,,,,,,,,48,2,6.000000e+000,5.354309e-002,0.000000e+000,0,,0,
1508987761.056,,1.000000e+001,8.011813e+001,-8.681071e-008,5.247784e-008,3,0.000000e+000,6.045088e+001,,,,,,,,,,,,,,48,2,6.000000e+000,3.643036e-002,0.000000e+000,0,,0,
1508987930.267,,1.000000e+001,8.211279e+001,-2.571114e-009,3.050326e-008,2,0.000000e+000,1.186383e+003,,,,,,,,,,,,,,48,2,6.000000e+000,6.739044e-002,0.000000e+000,0,,0,
1508988091.197,,1.000000e+001,8.412038e+001,-1.314064e-007,1.990185e-008,3,0.000000e+000,1.514527e+001,,,,,,,,,,,,,,48,2,6.000000e+000,5.203247e-002,0.000000e+000,0,,0,
1508988254.717,,1.000000e+001,8.612622e+001,-2.427107e-008,4.714240e-008,2,0.000000e+000,1.942329e+002,,,,,,,,,,,,,,48,2,6.000000e+000,3.194427e-002,0.000000e+000,0,,0,
1508988418.237,,1.000000e+001,8.813998e+001,-1.098761e-007,4.785770e-008,2,0.000000e+000,4.355606e+001,,,,,,,,,,,,,,48,2,6.000000e+000,6.664276e-002,0.000000e+000,0,,0,
1508988586.188,,1.000000e+001,9.012637e+001,-1.089361e-007,1.674777e-008,3,0.000000e+000,1.537393e+001,,,,,,,,,,,,,,48,2,6.000000e+000,6.604004e-002,0.000000e+000,0,,0,
1508988749.378,,1.000000e+001,9.211903e+001,-1.113115e-007,1.616755e-008,3,0.000000e+000,1.452460e+001,,,,,,,,,,,,,,48,2,6.000000e+000,7.608032e-002,0.000000e+000,0,,0,
1508988916.408,,1.000000e+001,9.414594e+001,-9.464006e-008,4.354010e-009,3,0.000000e+000,4.600599e+000,,,,,,,,,,,,,,48,2,6.000000e+000,6.421661e-002,0.000000e+000,0,,0,
1508989093.368,,1.000000e+001,9.610193e+001,-2.642579e-010,4.591234e-008,3,0.000000e+000,1.737406e+004,,,,,,,,,,,,,,48,2,6.000000e+000,5.104065e-002,0.000000e+000,0,,0,
1508989265.869,,1.000000e+001,9.812536e+001,-1.018055e-007,9.105820e-008,2,0.000000e+000,8.944330e+001,,,,,,,,,,,,,,48,2,6.000000e+000,1.102753e-001,0.000000e+000,0,,0,