File: Data/YT Group/RVC64b (0 nm Ta)/20170509-RVC64b.dc.raw
[Header]
TITLE,MPMS DC Measurement
BYAPP,MPMS Measurement,2.1,Raw with ABS
FILEOPENTIME, 1494378536.853000 5/9/2017, 6:08:56 PM

INFO, APPNAME, MPMS MultiVu Application, Revision 1.61,  Build 082

INFO, NAME, RVC64B
INFO, WEIGHT, 1.000
INFO, AREA, 1.000
INFO, LENGTH, 1.000
INFO, SHAPE, film on substrate
INFO, COMMENT, H in plane
INFO, SEQUENCE FILE: 20170509-RVC64b.seq


INFO, BACKGROUND DATA FILE:, None


STARTUPAXIS,X,8,LINEAR,AUTO,0.000000,0.000000
STARTUPAXIS,Y1,10,LINEAR,AUTO,0.000000,0.000000


STARTUPGROUP,Longitudinal
FIELDGROUP,Longitudinal,1,3,4,5,6,8,9,10,11,12,13,14,15,16,17,18,19,20,21,22,23
FIELDGROUP,Transverse,1,3,4,5,6,8,9,24,25,26,27,28,29,30,31,32,33,34,35,36,37

PLOT_APPEARANCE,ALL,HORZ_GRID_ON,VERT_GRID_ON,MARKERS_ONLY

[Data]
Time,Comment,Field (Oe),Start Temperature (K),End Temperature (K),Scan,Rejected,Position (cm),Rot Position (deg),Long Voltage,Long Average Voltage,Long Detrended Voltage,Long Demeaned Voltage,Long Regression Fit,Long Detrended Fit,Long Demeaned Fit,Long Scaled Response,Long Avg. Scaled Response,Long Background Response,Long Response [w/ABS],Long Detrended Resp. [w/ABS],Long Fit [w/ABS],Long Detrended Fit [w/ABS],Trans Voltage,Trans Average Voltage,Trans Detrended Voltage,Trans Demeaned Voltage,Trans Regression Fit,Trans Detrended Fit,Trans Demeaned Fit,Trans Scaled Response,Trans Avg Scaled Response,Trans Background Response,Trans Response [w/ABS],Trans Detrended Resp. [w/ABS],Trans Fit [w/ABS],Trans Detrended Fit [w/ABS],
1494378536.833,,1.000000e+001,5.000082e+000,4.994047e+000,1,0,0.000000e+000,0.000000e+000,-1.654078e-001,,,,,,,4.582353e-008,,,,,,,,,,,,,,,,,,,,,
1494378536.833,,1.000000e+001,5.000082e+000,4.994047e+000,1,0,4.723404e+000,0.000000e+000,-1.145953e-001,,,,,,,8.832753e-007,,,,,,,,,,,,,,,,,,,,,
1494378536.833,,1.000000e+001,4.999124e+000,4.993282e+000,2,0,3.319149e+000,0.000000e+000,-2.203403e-001,-2.255283e-001,-8.614872e-002,-6.707053e-002,-2.258436e-001,-8.646399e-002,-6.738579e-002,-2.204846e-006,-1.987627e-006,,,,,,,,,,,,,,,,,,,,
1494378678.164,,1.000000e+001,6.988466e+000,6.972009e+000,1,0,1.914894e+000,0.000000e+000,9.048600e-002,,,,,,,7.794274e-007,,,,,,,,,,,,,,,,,,,,,
1494378678.164,,1.000000e+001,6.979336e+000,6.969792e+000,2,0,5.106383e-001,0.000000e+000,6.683452e-002,6.584268e-002,7.703108e-003,1.115370e-002,7.859097e-002,2.045139e-002,2.390198e-002,-2.378304e-007,2.998286e-008,,,,,,,,,,,,,,,,,,,,
1494378678.164,,1.000000e+001,6.979336e+000,6.969792e+000,2,0,5.234043e+000,0.000000e+000,1.095598e-001,9.895475e-002,8.897224e-003,4.426577e-002,1.177770e-001,2.771948e-002,6.308803e-002,4.404903e-007,4.325171e-007,,,,,,,,,,,,,,,,,,,,
1494378833.974,,1.000000e+001,8.956560e+000,8.956163e+000,1,0,3.829787e+000,0.000000e+000,-6.985580e-001,,,,,,,4.621452e-007,,,,,,,,,,,,,,,,,,,,,
1494378833.974,,1.000000e+001,8.970488e+000,8.952988e+000,2,0,2.425532e+000,0.000000e+000,-7.708858e-001,-7.770657e-001,-6.398697e-002,-4.797941e-002,-7.742562e-001,-6.117745e-002,-4.516989e-002,-1.602635e-006,-1.525551e-006,,,,,,,,,,,,,,,,,,,,
1494378975.944,,1.000000e+001,1.092866e+001,1.092633e+001,1,0,1.021277e+000,0.000000e+000,8.763256e-001,,,,,,,2.973684e-007,,,,,,,,,,,,,,,,,,,,,
1494378975.944,,1.000000e+001,1.092866e+001,1.092633e+001,1,0,5.744681e+000,0.000000e+000,8.937209e-001,,,,,,,4.281428e-007,,,,,,,,,,,,,,,,,,,,,
1494378975.944,,1.000000e+001,1.092748e+001,1.092761e+001,2,0,4.340425e+000,0.000000e+000,9.542992e-001,9.365988e-001,4.706666e-002,7.092220e-002,9.257282e-001,3.619608e-002,6.005162e-002,1.381213e-006,1.246475e-006,,,,,,,,,,,,,,,,,,,,
1494379135.704,,1.000000e+001,1.291408e+001,1.290982e+001,1,0,2.936170e+000,0.000000e+000,-4.307622e-001,,,,,,,-3.007790e-006,,,,,,,,,,,,,,,,,,,,,
1494379135.704,,1.000000e+001,1.291840e+001,1.291013e+001,2,0,1.531915e+000,0.000000e+000,-2.288853e-001,-2.458991e-001,5.105115e-002,6.132573e-002,-2.487716e-001,4.817870e-002,5.845328e-002,1.173612e-006,1.141454e-006,,,,,,,,,,,,,,,,,,,,
1494379268.864,,1.000000e+001,1.488743e+001,1.488799e+001,1,0,1.276596e-001,0.000000e+000,5.004959e-001,,,,,,,-6.860246e-007,,,,,,,,,,,,,,,,,,,,,
1494379268.864,,1.000000e+001,1.488743e+001,1.488799e+001,1,0,4.851064e+000,0.000000e+000,5.618372e-001,,,,,,,4.519461e-007,,,,,,,,,,,,,,,,,,,,,
1494379268.864,,1.000000e+001,1.489195e+001,1.489760e+001,2,0,3.446809e+000,0.000000e+000,4.950027e-001,4.918746e-001,-6.057139e-002,-4.430830e-002,4.807974e-001,-7.164856e-002,-5.538547e-002,-1.559276e-006,-1.375739e-006,,,,,,,,,,,,,,,,,,,,
1494379414.255,,1.000000e+001,1.687053e+001,1.687344e+001,1,0,2.042553e+000,0.000000e+000,-2.862593e-001,,,,,,,4.959575e-007,,,,,,,,,,,,,,,,,,,,,
1494379414.255,,1.000000e+001,1.687781e+001,1.687708e+001,2,0,6.382979e-001,0.000000e+000,-2.935836e-001,-2.909895e-001,1.426555e-002,1.861539e-002,-2.802477e-001,2.500739e-002,2.935722e-002,-1.639482e-007,1.939984e-007,,,,,,,,,,,,,,,,,,,,
1494379414.255,,1.000000e+001,1.687781e+001,1.687708e+001,2,0,5.361702e+000,0.000000e+000,-2.452125e-001,-2.594797e-001,1.358662e-002,5.012527e-002,-2.490632e-001,2.400309e-002,6.054175e-002,5.763868e-007,5.588363e-007,,,,,,,,,,,,,,,,,,,,
1494379557.305,,1.000000e+001,1.884890e+001,1.884980e+001,1,0,3.957447e+000,0.000000e+000,3.306630e-001,,,,,,,1.371468e-006,,,,,,,,,,,,,,,,,,,,,
1494379557.305,,1.000000e+001,1.884980e+001,1.885614e+001,2,0,2.553191e+000,0.000000e+000,2.246128e-001,2.161441e-001,-6.072135e-002,-4.337528e-002,2.024785e-001,-7.438692e-002,-5.704086e-002,-1.451148e-006,-1.441283e-006,,,,,,,,,,,,,,,,,,,,
1494379701.735,,1.000000e+001,2.082714e+001,2.082824e+001,1,0,1.148936e+000,0.000000e+000,-3.549249e-001,,,,,,,6.710052e-007,,,,,,,,,,,,,,,,,,,,,
1494379701.735,,1.000000e+001,2.082714e+001,2.082824e+001,1,0,5.872340e+000,0.000000e+000,-3.370718e-001,,,,,,,8.291881e-007,,,,,,,,,,,,,,,,,,,,,
1494379701.735,,1.000000e+001,2.082934e+001,2.083595e+001,2,0,4.468085e+000,0.000000e+000,-2.882429e-001,-3.220417e-001,3.858090e-002,6.062651e-002,-3.117263e-001,4.889629e-002,7.094190e-002,1.635351e-006,1.048534e-006,,,,,,,,,,,,,,,,,,,,
1494379849.585,,1.000000e+001,2.279240e+001,2.280423e+001,1,0,3.063830e+000,0.000000e+000,-2.697795e-001,,,,,,,-3.318645e-006,,,,,,,,,,,,,,,,,,,,,
1494379849.585,,1.000000e+001,2.280686e+001,2.281541e+001,2,0,1.659575e+000,0.000000e+000,-5.539025e-002,-5.218586e-002,6.974249e-002,7.910564e-002,-8.464350e-002,3.728484e-002,4.664800e-002,1.217181e-006,1.615474e-006,,,,,,,,,,,,,,,,,,,,
1494379999.856,,1.000000e+001,2.477795e+001,2.477871e+001,1,0,2.553191e-001,0.000000e+000,-3.837644e-001,,,,,,,-4.802259e-007,,,,,,,,,,,,,,,,,,,,,
1494379999.856,,1.000000e+001,2.477795e+001,2.477871e+001,1,0,4.978724e+000,0.000000e+000,-3.517205e-001,,,,,,,-8.326788e-008,,,,,,,,,,,,,,,,,,,,,
1494379999.856,,1.000000e+001,2.478026e+001,2.478642e+001,2,0,3.574468e+000,0.000000e+000,-4.026856e-001,-4.023804e-001,-6.315554e-002,-3.948802e-002,-3.948918e-001,-5.566696e-002,-3.199944e-002,-1.658007e-006,-1.415613e-006,,,,,,,,,,,,,,,,,,,,
1494380149.466,,1.000000e+001,2.677217e+001,2.677039e+001,1,0,2.170213e+000,0.000000e+000,2.355993e-001,,,,,,,-5.937072e-007,,,,,,,,,,,,,,,,,,,,,
1494380149.466,,1.000000e+001,2.677484e+001,2.676860e+001,2,0,7.659575e-001,0.000000e+000,2.989242e-001,2.674144e-001,5.977772e-003,1.150763e-002,2.933761e-001,3.193953e-002,3.746939e-002,4.519752e-007,-1.679837e-009,,,,,,,,,,,,,,,,,,,,
1494380149.466,,1.000000e+001,2.677484e+001,2.676860e+001,2,0,5.489362e+000,0.000000e+000,3.192188e-001,3.160906e-001,2.055326e-002,6.018391e-002,3.148424e-001,1.930505e-002,5.893570e-002,5.550182e-007,7.465483e-007,,,,,,,,,,,,,,,,,,,,
1494380296.506,,1.000000e+001,2.875202e+001,2.874386e+001,1,0,4.085106e+000,0.000000e+000,6.535439e-001,,,,,,,1.952769e-006,,,,,,,,,,,,,,,,,,,,,
1494380296.506,,1.000000e+001,2.875610e+001,2.875304e+001,2,0,2.680851e+000,0.000000e+000,4.776074e-001,4.635691e-001,-1.150709e-001,-1.031696e-001,4.739445e-001,-1.046954e-001,-9.279415e-002,-2.583358e-006,-2.711447e-006,,,,,,,,,,,,,,,,,,,,
1494380455.546,,1.000000e+001,3.073207e+001,3.073092e+001,1,0,1.276596e+000,0.000000e+000,-3.778134e-001,,,,,,,5.672891e-007,,,,,,,,,,,,,,,,,,,,,
1494380455.546,,1.000000e+001,3.073207e+001,3.073092e+001,1,0,6.000000e+000,0.000000e+000,-3.270008e-001,,,,,,,1.291733e-006,,,,,,,,,,,,,,,,,,,,,
1494380455.546,,1.000000e+001,3.073439e+001,3.072744e+001,2,0,4.595745e+000,0.000000e+000,-3.056382e-001,-3.228046e-001,4.238793e-002,7.850024e-002,-3.114313e-001,5.376127e-002,8.987358e-002,1.278553e-006,1.202883e-006,,,,,,,,,,,,,,,,,,,,
1494380615.156,,1.000000e+001,3.271481e+001,3.271481e+001,1,0,3.191489e+000,0.000000e+000,-7.038987e-001,,,,,,,-2.852672e-006,,,,,,,,,,,,,,,,,,,,,
1494380615.156,,1.000000e+001,3.271350e+001,3.270178e+001,2,0,1.787234e+000,0.000000e+000,-5.223163e-001,-5.265889e-001,5.799539e-002,7.085329e-002,-5.577704e-001,2.681387e-002,3.967178e-002,1.261216e-006,1.324490e-006,,,,,,,,,,,,,,,,,,,,
1494380773.327,,1.000000e+001,3.469387e+001,3.469242e+001,1,0,3.829787e-001,0.000000e+000,-8.128482e-001,,,,,,,1.945809e-007,,,,,,,,,,,,,,,,,,,,,
1494380773.327,,1.000000e+001,3.469387e+001,3.469242e+001,1,0,5.106383e+000,0.000000e+000,-8.004883e-001,,,,,,,9.596079e-008,,,,,,,,,,,,,,,,,,,,,
1494380773.327,,1.000000e+001,3.469533e+001,3.468659e+001,2,0,3.702128e+000,0.000000e+000,-7.954528e-001,-8.081178e-001,-1.372498e-002,1.279461e-002,-8.266629e-001,-3.227007e-002,-5.750477e-003,-1.754943e-007,-2.229308e-007,,,,,,,,,,,,,,,,,,,,
1494380935.307,,1.000000e+001,3.667407e+001,3.667407e+001,1,0,2.297872e+000,0.000000e+000,5.267414e-001,,,,,,,-1.220817e-006,,,,,,,,,,,,,,,,,,,,,
1494380935.307,,1.000000e+001,3.666759e+001,3.666759e+001,2,0,8.936170e-001,0.000000e+000,5.918975e-001,5.899901e-001,8.108178e-003,1.328909e-002,6.209854e-001,3.910343e-002,4.428434e-002,-1.716235e-007,9.680025e-008,,,,,,,,,,,,,,,,,,,,
1494380935.307,,1.000000e+001,3.666759e+001,3.666759e+001,2,0,5.617021e+000,0.000000e+000,6.286717e-001,6.248569e-001,1.559015e-002,4.815590e-002,6.237361e-001,1.446934e-002,4.703510e-002,4.558497e-007,5.913089e-007,,,,,,,,,,,,,,,,,,,,
1494381098.487,,1.000000e+001,3.865672e+001,3.865136e+001,1,0,4.212766e+000,0.000000e+000,7.074082e-001,,,,,,,1.394355e-006,,,,,,,,,,,,,,,,,,,,,
1494381098.487,,1.000000e+001,3.865494e+001,3.864064e+001,2,0,2.808511e+000,0.000000e+000,5.076677e-001,5.008011e-001,-1.562113e-001,-1.374403e-001,5.393342e-001,-1.176782e-001,-9.890723e-002,-3.792698e-006,-3.688799e-006,,,,,,,,,,,,,,,,,,,,
1494381266.787,,1.000000e+001,4.063807e+001,4.064002e+001,1,0,1.404255e+000,0.000000e+000,-3.274586e-001,,,,,,,-3.811620e-007,,,,,,,,,,,,,,,,,,,,,
1494381266.787,,1.000000e+001,4.063022e+001,4.063022e+001,2,0,0.000000e+000,0.000000e+000,-2.758831e-001,-2.883955e-001,2.550745e-002,2.550745e-002,-3.053355e-001,8.567482e-003,8.567482e-003,4.416279e-007,3.981813e-007,,,,,,,,,,,,,,,,,,,,
1494381266.787,,1.000000e+001,4.063022e+001,4.063022e+001,2,0,4.723404e+000,0.000000e+000,-2.349889e-001,-2.557412e-001,2.428777e-002,5.816177e-002,-2.313126e-001,4.871638e-002,8.259037e-002,9.430969e-007,7.648705e-007,,,,,,,,,,,,,,,,,,,,
1494381430.388,,1.000000e+001,4.262430e+001,4.262002e+001,1,0,3.319149e+000,0.000000e+000,-1.426261e+000,,,,,,,-2.783414e-006,,,,,,,,,,,,,,,,,,,,,
1494381430.388,,1.000000e+001,4.262002e+001,4.259647e+001,2,0,1.914894e+000,0.000000e+000,-1.259937e+000,-1.258946e+000,4.569883e-002,5.740261e-002,-1.295545e+000,9.099307e-003,2.080309e-002,7.640556e-007,1.055962e-006,,,,,,,,,,,,,,,,,,,,
1494381609.438,,1.000000e+001,4.460213e+001,4.459512e+001,1,0,5.106383e-001,0.000000e+000,-1.359426e+000,,,,,,,5.436959e-007,,,,,,,,,,,,,,,,,,,,,
1494381609.438,,1.000000e+001,4.460213e+001,4.459512e+001,1,0,5.234043e+000,0.000000e+000,-1.368429e+000,,,,,,,-8.208372e-008,,,,,,,,,,,,,,,,,,,,,
1494381609.438,,1.000000e+001,4.459512e+001,4.459045e+001,2,0,3.829787e+000,0.000000e+000,-1.319295e+000,-1.334783e+000,1.972601e-002,3.943658e-002,-1.367368e+000,-1.285901e-002,6.851554e-003,6.535847e-007,5.630445e-007,,,,,,,,,,,,,,,,,,,,
1494381774.448,,1.000000e+001,4.658948e+001,4.657121e+001,1,0,2.425532e+000,0.000000e+000,-7.879759e-001,,,,,,,-1.453725e-006,,,,,,,,,,,,,,,,,,,,,
1494381774.448,,1.000000e+001,4.657222e+001,4.658643e+001,2,0,1.021277e+000,0.000000e+000,-6.822309e-001,-6.918441e-001,3.774063e-002,4.466075e-002,-6.867843e-001,4.280041e-002,4.972053e-002,8.476254e-007,7.845083e-007,,,,,,,,,,,,,,,,,,,,
1494381774.448,,1.000000e+001,4.657222e+001,4.658643e+001,2,0,5.744681e+000,0.000000e+000,-6.825361e-001,-6.897841e-001,7.795085e-003,4.672074e-002,-6.861995e-001,1.137971e-002,5.030537e-002,4.529356e-007,4.455997e-007,,,,,,,,,,,,,,,,,,,,
1494381935.238,,1.000000e+001,4.858370e+001,4.856721e+001,1,0,4.340425e+000,0.000000e+000,5.358968e-001,,,,,,,1.354911e-006,,,,,,,,,,,,,,,,,,,,,
1494381935.238,,1.000000e+001,4.857271e+001,4.856721e+001,2,0,2.936170e+000,0.000000e+000,3.880369e-001,3.508049e-001,-1.352508e-001,-1.173389e-001,3.629083e-001,-1.231474e-001,-1.052355e-001,-2.530971e-006,-3.179356e-006,,,,,,,,,,,,,,,,,,,,
1494382090.568,,1.000000e+001,5.057611e+001,5.055244e+001,1,0,1.531915e+000,0.000000e+000,8.754101e-001,,,,,,,1.089238e-006,,,,,,,,,,,,,,,,,,,,,
1494382090.568,,1.000000e+001,5.055244e+001,5.056309e+001,2,0,1.276596e-001,0.000000e+000,8.192569e-001,8.194095e-001,3.142416e-004,1.417518e-003,8.298763e-001,1.078106e-002,1.188433e-002,-3.867353e-007,-2.393972e-007,,,,,,,,,,,,,,,,,,,,
1494382090.568,,1.000000e+001,5.055244e+001,5.056309e+001,2,0,4.851064e+000,0.000000e+000,8.928054e-001,8.841840e-001,2.426754e-002,6.619203e-002,9.007401e-001,4.082363e-002,8.274812e-002,8.653878e-007,8.039851e-007,,,,,,,,,,,,,,,,,,,,
1494382278.179,,1.000000e+001,5.252026e+001,5.250883e+001,1,0,3.446809e+000,0.000000e+000,-1.001602e+000,,,,,,,-1.379234e-006,,,,,,,,,,,,,,,,,,,,,
1494382278.179,,1.000000e+001,5.252535e+001,5.250630e+001,2,0,2.042553e+000,0.000000e+000,-9.091326e-001,-9.261464e-001,1.222448e-002,2.206486e-002,-9.499249e-001,-1.155408e-002,-1.713693e-003,4.949216e-007,2.838351e-007,,,,,,,,,,,,,,,,,,,,
1494382437.909,,1.000000e+001,5.454733e+001,5.451735e+001,1,0,6.382979e-001,0.000000e+000,-8.099489e-001,,,,,,,2.734669e-007,,,,,,,,,,,,,,,,,,,,,
1494382437.909,,1.000000e+001,5.454733e+001,5.451735e+001,1,0,5.361702e+000,0.000000e+000,-8.036927e-001,,,,,,,4.468347e-008,,,,,,,,,,,,,,,,,,,,,
1494382437.909,,1.000000e+001,5.451871e+001,5.451463e+001,2,0,3.957447e+000,0.000000e+000,-7.110704e-001,-7.331197e-001,5.878707e-002,9.014678e-002,-7.833593e-001,8.547452e-003,3.990716e-002,1.746246e-006,1.529178e-006,,,,,,,,,,,,,,,,,,,,
1494382602.919,,1.000000e+001,5.653432e+001,5.651534e+001,1,0,2.553191e+000,0.000000e+000,-1.195087e+000,,,,,,,-1.999178e-006,,,,,,,,,,,,,,,,,,,,,
1494382602.919,,1.000000e+001,5.651388e+001,5.649345e+001,2,0,1.148936e+000,0.000000e+000,-1.067216e+000,-1.079652e+000,3.256753e-002,4.018557e-002,-1.062096e+000,5.012360e-002,5.774164e-002,7.970957e-007,6.777027e-007,,,,,,,,,,,,,,,,,,,,
1494382602.919,,1.000000e+001,5.651388e+001,5.649345e+001,2,0,5.872340e+000,0.000000e+000,-1.042801e+000,-1.070573e+000,1.032800e-002,4.926467e-002,-1.071861e+000,9.040304e-003,4.797697e-002,9.644937e-007,5.094098e-007,,,,,,,,,,,,,,,,,,,,
1494382758.079,,1.000000e+001,5.851542e+001,5.851229e+001,1,0,4.468085e+000,0.000000e+000,-1.024643e+000,,,,,,,1.299464e-006,,,,,,,,,,,,,,,,,,,,,
1494382758.079,,1.000000e+001,5.851229e+001,5.849981e+001,2,0,3.063830e+000,0.000000e+000,-1.169451e+000,-1.186007e+000,-1.133065e-001,-8.966124e-002,-1.181849e+000,-1.091484e-001,-8.550310e-002,-2.498982e-006,-2.650517e-006,,,,,,,,,,,,,,,,,,,,
1494382916.470,,1.000000e+001,6.049137e+001,6.047141e+001,1,0,1.659575e+000,0.000000e+000,-8.885328e-001,,,,,,,1.508404e-006,,,,,,,,,,,,,,,,,,,,,
1494382916.470,,1.000000e+001,6.047141e+001,6.043484e+001,2,0,2.553191e-001,0.000000e+000,-9.500268e-001,-9.594873e-001,-4.259756e-003,-2.541661e-003,-9.430296e-001,1.219792e-002,1.391602e-002,-2.601737e-007,-2.779016e-007,,,,,,,,,,,,,,,,,,,,
1494382916.470,,1.000000e+001,6.047141e+001,6.043484e+001,2,0,4.978724e+000,0.000000e+000,-9.059281e-001,-9.132525e-001,1.019034e-002,4.369318e-002,-8.871685e-001,3.627429e-002,6.977713e-002,3.920031e-007,4.384456e-007,,,,,,,,,,,,,,,,,,,,
1494383073.430,,1.000000e+001,6.248341e+001,6.245157e+001,1,0,3.574468e+000,0.000000e+000,-4.344243e-001,,,,,,,-7.832505e-007,,,,,,,,,,,,,,,,,,,,,
1494383073.430,,1.000000e+001,6.245863e+001,6.244450e+001,2,0,2.170213e+000,0.000000e+000,-3.988708e-001,-4.122988e-001,-1.521659e-002,-2.264351e-003,-4.280926e-001,-3.101042e-002,-1.805818e-002,-2.850666e-007,-3.776431e-007,,,,,,,,,,,,,,,,,,,,
1494383236.790,,1.000000e+001,6.447717e+001,6.443964e+001,1,0,7.659575e-001,0.000000e+000,-8.735790e-001,,,,,,,-1.562985e-007,,,,,,,,,,,,,,,,,,,,,
1494383236.790,,1.000000e+001,6.447717e+001,6.443964e+001,1,0,5.489362e+000,0.000000e+000,-8.253605e-001,,,,,,,5.660040e-007,,,,,,,,,,,,,,,,,,,,,
1494383236.790,,1.000000e+001,6.444340e+001,6.442652e+001,2,0,4.085106e+000,0.000000e+000,-7.521173e-001,-7.626460e-001,7.467249e-002,1.068947e-001,-8.140033e-001,2.331511e-002,5.553728e-002,1.898195e-006,1.916516e-006,,,,,,,,,,,,,,,,,,,,
1494383417.340,,1.000000e+001,6.642474e+001,6.638902e+001,1,0,2.680851e+000,0.000000e+000,-1.226825e+000,,,,,,,-2.296852e-006,,,,,,,,,,,,,,,,,,,,,
1494383417.340,,1.000000e+001,6.639101e+001,6.639299e+001,2,0,1.276596e+000,0.000000e+000,-1.070573e+000,-1.077974e+000,5.487408e-002,6.427372e-002,-1.091113e+000,4.173459e-002,5.113423e-002,1.203938e-006,1.195511e-006,,,,,,,,,,,,,,,,,,,,
1494383417.340,,1.000000e+001,6.639101e+001,6.639299e+001,2,0,6.000000e+000,0.000000e+000,-1.075761e+000,-1.087053e+000,1.101622e-002,5.519450e-002,-1.092563e+000,5.506245e-003,4.968452e-002,6.164883e-007,5.512811e-007,,,,,,,,,,,,,,,,,,,,
1494383579.441,,1.000000e+001,6.842715e+001,6.837681e+001,1,0,4.595745e+000,0.000000e+000,-8.447394e-001,,,,,,,1.421649e-006,,,,,,,,,,,,,,,,,,,,,
1494383579.441,,1.000000e+001,6.840407e+001,6.838100e+001,2,0,3.191489e+000,0.000000e+000,-9.993134e-001,-9.975586e-001,-1.066064e-001,-8.467209e-002,-9.761574e-001,-8.520516e-002,-6.327087e-002,-2.892202e-006,-2.483009e-006,,,,,,,,,,,,,,,,,,,,
1494383749.181,,1.000000e+001,7.042250e+001,7.038489e+001,1,0,1.787234e+000,0.000000e+000,2.908370e-001,,,,,,,1.350826e-006,,,,,,,,,,,,,,,,,,,,,
1494383749.181,,1.000000e+001,7.037605e+001,7.036279e+001,2,0,3.829787e-001,0.000000e+000,2.139315e-001,2.174411e-001,-1.704500e-002,-1.421507e-002,2.486947e-001,1.420868e-002,1.703861e-002,-1.000736e-006,-5.947618e-007,,,,,,,,,,,,,,,,,,,,
1494383749.181,,1.000000e+001,7.037605e+001,7.036279e+001,2,0,5.106383e+000,0.000000e+000,2.592508e-001,2.568094e-001,-1.257922e-002,2.515323e-002,2.934694e-001,2.408079e-002,6.181325e-002,-3.598152e-007,-8.520510e-008,,,,,,,,,,,,,,,,,,,,
1494383914.841,,1.000000e+001,7.241606e+001,7.239278e+001,1,0,3.702128e+000,0.000000e+000,-4.979019e-001,,,,,,,-3.403966e-007,,,,,,,,,,,,,,,,,,,,,
1494383914.841,,1.000000e+001,7.236951e+001,7.234392e+001,2,0,2.297872e+000,0.000000e+000,-4.686046e-001,-4.907301e-001,-1.172849e-002,5.810797e-003,-5.167821e-001,-3.778046e-002,-2.024117e-002,-5.713810e-008,-3.104669e-007,,,,,,,,,,,,,,,,,,,,
1494384077.611,,1.000000e+001,7.439044e+001,7.437820e+001,1,0,8.936170e-001,0.000000e+000,-1.145953e-001,,,,,,,1.084791e-007,,,,,,,,,,,,,,,,,,,,,
1494384077.611,,1.000000e+001,7.439044e+001,7.437820e+001,1,0,5.617021e+000,0.000000e+000,-9.628443e-002,,,,,,,2.347688e-007,,,,,,,,,,,,,,,,,,,,,
1494384077.611,,1.000000e+001,7.434886e+001,7.432442e+001,2,0,4.212766e+000,0.000000e+000,-5.310140e-002,-4.913405e-002,4.733756e-002,7.185589e-002,-7.329100e-002,2.318062e-002,4.769894e-002,9.243583e-007,1.234029e-006,,,,,,,,,,,,,,,,,,,,
1494384250.501,,1.000000e+001,7.635533e+001,7.632454e+001,1,0,2.808511e+000,0.000000e+000,-5.197223e-001,,,,,,,-1.592619e-006,,,,,,,,,,,,,,,,,,,,,
1494384250.501,,1.000000e+001,7.632454e+001,7.630659e+001,2,0,1.404255e+000,0.000000e+000,-4.271000e-001,-4.270237e-001,2.332583e-002,3.061944e-002,-4.263164e-001,2.403319e-002,3.132680e-002,2.578472e-007,4.801905e-007,,,,,,,,,,,,,,,,,,,,
1494384418.972,,1.000000e+001,7.835838e+001,7.832610e+001,1,0,0.000000e+000,0.000000e+000,-7.275501e-001,,,,,,,-1.027493e-007,,,,,,,,,,,,,,,,,,,,,
1494384418.972,,1.000000e+001,7.835838e+001,7.832610e+001,1,0,4.723404e+000,0.000000e+000,-7.052720e-001,,,,,,,1.004919e-007,,,,,,,,,,,,,,,,,,,,,
1494384418.972,,1.000000e+001,7.830996e+001,7.828309e+001,2,0,3.319149e+000,0.000000e+000,-6.892500e-001,-6.991684e-001,2.178694e-003,1.722699e-002,-7.009119e-001,4.351984e-004,1.548350e-002,3.544665e-008,7.118615e-008,,,,,,,,,,,,,,,,,,,,
1494384586.652,,1.000000e+001,8.034061e+001,8.031808e+001,1,0,1.914894e+000,0.000000e+000,-5.870146e-001,,,,,,,-3.545229e-007,,,,,,,,,,,,,,,,,,,,,
1494384586.652,,1.000000e+001,8.030119e+001,8.029559e+001,2,0,5.106383e-001,0.000000e+000,-5.868620e-001,-5.784695e-001,-6.142245e-004,2.700388e-003,-5.787488e-001,-8.935318e-004,2.421081e-003,-5.614784e-007,-2.089819e-007,,,,,,,,,,,,,,,,,,,,
1494384586.652,,1.000000e+001,8.030119e+001,8.029559e+001,2,0,5.234043e+000,0.000000e+000,-5.526817e-001,-5.500877e-001,-2.892569e-003,3.108221e-002,-5.485516e-001,-1.356438e-003,3.261834e-002,-1.587068e-007,1.017188e-007,,,,,,,,,,,,,,,,,,,,
1494384755.212,,1.000000e+001,8.232408e+001,8.230054e+001,1,0,3.829787e+000,0.000000e+000,8.650339e-001,,,,,,,6.397750e-007,,,,,,,,,,,,,,,,,,,,,
1494384755.212,,1.000000e+001,8.228878e+001,8.225645e+001,2,0,2.425532e+000,0.000000e+000,8.253605e-001,8.258946e-001,-1.421042e-002,3.989935e-003,8.387206e-001,-1.384451e-003,1.681590e-002,-6.252958e-007,-3.990572e-007,,,,,,,,,,,,,,,,,,,,
1494384934.702,,1.000000e+001,8.429356e+001,8.424444e+001,1,0,1.021277e+000,0.000000e+000,-7.716488e-001,,,,,,,1.079734e-007,,,,,,,,,,,,,,,,,,,,,
1494384934.702,,1.000000e+001,8.429356e+001,8.424444e+001,1,0,5.744681e+000,0.000000e+000,-7.411307e-001,,,,,,,4.197500e-007,,,,,,,,,,,,,,,,,,,,,
1494384934.702,,1.000000e+001,8.425365e+001,8.422603e+001,2,0,4.340425e+000,0.000000e+000,-7.246510e-001,-7.421988e-001,2.663440e-003,3.587633e-002,-7.444036e-001,4.586643e-004,3.367156e-002,3.267887e-007,2.133356e-007,,,,,,,,,,,,,,,,,,,,
1494385106.953,,1.000000e+001,8.627337e+001,8.625414e+001,1,0,2.936170e+000,0.000000e+000,-5.484092e-001,,,,,,,2.708748e-007,,,,,,,,,,,,,,,,,,,,,
1494385106.953,,1.000000e+001,8.623492e+001,8.625734e+001,2,0,1.531915e+000,0.000000e+000,-5.453575e-001,-5.578699e-001,1.328117e-003,1.150119e-002,-5.603471e-001,-1.149112e-003,9.023964e-003,-3.251080e-008,-8.544794e-008,,,,,,,,,,,,,,,,,,,,
1494385280.513,,1.000000e+001,8.827477e+001,8.821249e+001,1,0,1.276596e-001,0.000000e+000,-2.929732e-002,,,,,,,3.512127e-009,,,,,,,,,,,,,,,,,,,,,
1494385280.513,,1.000000e+001,8.827477e+001,8.821249e+001,1,0,4.851064e+000,0.000000e+000,1.388571e-002,,,,,,,7.132473e-007,,,,,,,,,,,,,,,,,,,,,
1494385280.513,,1.000000e+001,8.822584e+001,8.818913e+001,2,0,3.446809e+000,0.000000e+000,1.709010e-002,1.754788e-003,1.115434e-002,3.072241e-002,-9.034072e-003,3.654772e-004,1.993355e-002,4.367754e-007,2.953959e-007,,,,,,,,,,,,,,,,,,,,
1494385459.343,,1.000000e+001,9.023341e+001,9.019857e+001,1,0,2.042553e+000,0.000000e+000,-3.952087e-002,,,,,,,6.478786e-008,,,,,,,,,,,,,,,,,,,,,
1494385459.343,,1.000000e+001,9.020206e+001,9.018813e+001,2,0,6.382979e-001,0.000000e+000,-2.716106e-002,-3.868162e-002,1.071154e-003,4.224539e-003,-4.073251e-002,-9.797339e-004,2.173651e-003,-1.190085e-007,-1.151718e-007,,,,,,,,,,,,,,,,,,,,
1494385459.343,,1.000000e+001,9.020206e+001,9.018813e+001,2,0,5.361702e+000,0.000000e+000,2.029450e-002,-1.167315e-002,4.744572e-003,3.123301e-002,-1.739746e-002,-9.797313e-004,2.550870e-002,7.180673e-007,2.500279e-007,,,,,,,,,,,,,,,,,,,,
1494385640.243,,1.000000e+001,9.222882e+001,9.217075e+001,1,0,3.957447e+000,0.000000e+000,7.466239e-001,,,,,,,-7.585459e-007,,,,,,,,,,,,,,,,,,,,,
1494385640.243,,1.000000e+001,9.217437e+001,9.214537e+001,2,0,2.553191e+000,0.000000e+000,7.939270e-001,7.592126e-001,-2.440652e-002,-1.059461e-002,7.858254e-001,2.206295e-003,1.601821e-002,-3.704372e-008,-6.107921e-007,,,,,,,,,,,,,,,,,,,,
1494385819.404,,1.000000e+001,9.418477e+001,9.416587e+001,1,0,1.148936e+000,0.000000e+000,1.022354e-001,,,,,,,-5.891525e-007,,,,,,,,,,,,,,,,,,,,,
1494385819.404,,1.000000e+001,9.418477e+001,9.416587e+001,1,0,5.872340e+000,0.000000e+000,1.499962e-001,,,,,,,1.415397e-007,,,,,,,,,,,,,,,,,,,,,
1494385819.404,,1.000000e+001,9.413945e+001,9.416587e+001,2,0,4.468085e+000,0.000000e+000,1.704433e-001,1.552605e-001,1.215015e-003,2.828814e-002,1.555065e-001,1.460944e-003,2.853407e-002,2.453367e-007,1.357746e-007,,,,,,,,,,,,,,,,,,,,
1494385982.314,,1.000000e+001,9.621706e+001,9.615805e+001,1,0,3.063830e+000,0.000000e+000,-8.346685e-001,,,,,,,5.738329e-007,,,,,,,,,,,,,,,,,,,,,
1494385982.314,,1.000000e+001,9.617770e+001,9.614233e+001,2,0,1.659575e+000,0.000000e+000,-8.467231e-001,-8.567941e-001,-3.445758e-003,7.072031e-003,-8.570225e-001,-3.674103e-003,6.843686e-003,-2.720990e-007,-1.763001e-007,,,,,,,,,,,,,,,,,,,,
1494386174.544,,1.000000e+001,9.815004e+001,9.814595e+001,1,0,2.553191e-001,0.000000e+000,-8.841077e-001,,,,,,,-8.171464e-007,,,,,,,,,,,,,,,,,,,,,
1494386174.544,,1.000000e+001,9.815004e+001,9.814595e+001,1,0,4.978724e+000,0.000000e+000,-8.317693e-001,,,,,,,-9.345968e-009,,,,,,,,,,,,,,,,,,,,,
1494386174.544,,1.000000e+001,9.809695e+001,9.809286e+001,2,0,3.574468e+000,0.000000e+000,-8.120852e-001,-8.157474e-001,6.808044e-003,2.905434e-002,-8.103551e-001,1.220030e-002,3.444660e-002,-2.118577e-008,1.969811e-007,,,,,,,,,,,,,,,,,,,,
1494386361.104,,1.000000e+001,1.001383e+002,1.000874e+002,1,0,2.170213e+000,0.000000e+000,-6.849775e-001,,,,,,,4.398680e-008,,,,,,,,,,,,,,,,,,,,,
1494386361.104,,1.000000e+001,1.000874e+002,1.000662e+002,2,0,7.659575e-001,0.000000e+000,-7.025254e-001,-7.141222e-001,-2.649546e-002,-2.187353e-002,-6.881235e-001,-4.966931e-004,4.125237e-003,-7.571343e-007,-7.919389e-007,,,,,,,,,,,,,,,,,,,,
1494386361.104,,1.000000e+001,1.000874e+002,1.000662e+002,2,0,5.489362e+000,0.000000e+000,-6.471351e-001,-6.607157e-001,-1.590833e-003,3.153300e-002,-6.594521e-001,-3.272142e-004,3.279662e-002,2.164543e-007,1.401822e-007,,,,,,,,,,,,,,,,,,,,
1494386590.565,,1.000000e+001,1.000069e+002,9.997305e+001,1,0,4.085106e+000,0.000000e+000,-4.368658e-001,,,,,,,-2.392098e-007,,,,,,,,,,,,,,,,,,,,,
1494386590.565,,1.000000e+001,9.996880e+001,9.997726e+001,2,0,2.680851e+000,0.000000e+000,-4.097047e-001,-4.126803e-001,4.709592e-003,2.075365e-002,-4.162681e-001,1.121750e-003,1.716581e-002,-1.866674e-007,8.887446e-008,,,,,,,,,,,,,,,,,,,,
1494386822.285,,1.000000e+001,9.784037e+001,9.781602e+001,1,0,1.276596e+000,0.000000e+000,-1.819028e+000,,,,,,,1.613225e-007,,,,,,,,,,,,,,,,,,,,,
1494386822.285,,1.000000e+001,9.784037e+001,9.781602e+001,1,0,6.000000e+000,0.000000e+000,-1.795224e+000,,,,,,,4.171525e-007,,,,,,,,,,,,,,,,,,,,,
1494386822.285,,1.000000e+001,9.783631e+001,9.792169e+001,2,0,4.595745e+000,0.000000e+000,-1.788205e+000,-1.796368e+000,3.655241e-003,2.649927e-002,-1.799065e+000,9.584883e-004,2.380252e-002,7.647759e-008,1.822300e-007,,,,,,,,,,,,,,,,,,,,
1494387034.645,,1.000000e+001,9.590711e+001,9.591103e+001,1,0,3.191489e+000,0.000000e+000,-2.024872e-001,,,,,,,1.587478e-007,,,,,,,,,,,,,,,,,,,,,
1494387034.645,,1.000000e+001,9.584847e+001,9.593059e+001,2,0,1.787234e+000,0.000000e+000,-1.797513e-001,-1.960784e-001,6.417142e-003,1.811279e-002,-2.033646e-001,-8.689894e-004,1.082666e-002,7.008566e-008,5.609945e-008,,,,,,,,,,,,,,,,,,,,
1494387229.246,,1.000000e+001,9.386085e+001,9.380832e+001,1,0,3.829787e-001,0.000000e+000,3.422599e-001,,,,,,,-7.208928e-008,,,,,,,,,,,,,,,,,,,,,
1494387229.246,,1.000000e+001,9.386085e+001,9.380832e+001,1,0,5.106383e+000,0.000000e+000,3.556878e-001,,,,,,,8.224652e-008,,,,,,,,,,,,,,,,,,,,,
1494387229.246,,1.000000e+001,9.381580e+001,9.389840e+001,2,0,3.702128e+000,0.000000e+000,3.607233e-001,3.559930e-001,-3.343803e-003,6.820351e-003,3.616529e-001,2.316165e-003,1.248032e-002,-1.445133e-007,-5.922948e-008,,,,,,,,,,,,,,,,,,,,
1494387421.136,,1.000000e+001,9.188866e+001,9.183101e+001,1,0,2.297872e+000,0.000000e+000,-2.021820e-001,,,,,,,-2.770421e-007,,,,,,,,,,,,,,,,,,,,,
1494387421.136,,1.000000e+001,9.192473e+001,9.192834e+001,2,0,8.936170e-001,0.000000e+000,-1.817349e-001,-2.240024e-001,-3.879558e-002,-3.539754e-002,-1.867744e-001,-1.567498e-003,1.830533e-003,-3.095088e-007,-1.020822e-006,,,,,,,,,,,,,,,,,,,,
1494387421.136,,1.000000e+001,9.192473e+001,9.192834e+001,2,0,5.617021e+000,0.000000e+000,-1.664759e-001,-1.750210e-001,-7.775153e-003,1.358390e-002,-1.679342e-001,-6.883253e-004,2.067073e-002,-1.365161e-007,-6.857795e-008,,,,,,,,,,,,,,,,,,,,
1494387622.106,,1.000000e+001,8.993472e+001,8.987936e+001,1,0,4.212766e+000,0.000000e+000,-8.180361e-001,,,,,,,4.888170e-007,,,,,,,,,,,,,,,,,,,,,
1494387622.106,,1.000000e+001,8.992434e+001,8.997630e+001,2,0,2.808511e+000,0.000000e+000,-8.456550e-001,-8.329137e-001,-2.301952e-003,1.108253e-002,-8.307475e-001,-1.357403e-004,1.324874e-002,-6.553801e-007,-6.561004e-008,,,,,,,,,,,,,,,,,,,,
1494387822.176,,1.000000e+001,8.797947e+001,8.791641e+001,1,0,1.404255e+000,0.000000e+000,-2.497902e-001,,,,,,,2.473944e-007,,,,,,,,,,,,,,,,,,,,,
1494387822.176,,1.000000e+001,8.803262e+001,8.808252e+001,2,0,0.000000e+000,0.000000e+000,-2.449073e-001,-2.473488e-001,1.664421e-002,1.664421e-002,-2.642213e-001,-2.282858e-004,-2.282858e-004,-4.269714e-008,1.633198e-007,,,,,,,,,,,,,,,,,,,,
1494387822.176,,1.000000e+001,8.803262e+001,8.808252e+001,2,0,4.723404e+000,0.000000e+000,-2.275120e-001,-2.236973e-001,9.647930e-003,4.029569e-002,-2.347772e-001,-1.432022e-003,2.921574e-002,5.198763e-008,3.615623e-007,,,,,,,,,,,,,,,,,,,,
1494388077.427,,1.000000e+001,8.621892e+001,8.622532e+001,1,0,3.319149e+000,0.000000e+000,-1.471580e+000,,,,,,,-1.126282e-007,,,,,,,,,,,,,,,,,,,,,
1494388077.427,,1.000000e+001,8.615495e+001,8.620612e+001,2,0,1.914894e+000,0.000000e+000,-1.452811e+000,-1.466163e+000,-7.207601e-003,1.868010e-003,-1.459702e+000,-7.459805e-004,8.329630e-003,-2.529378e-007,-2.308825e-007,,,,,,,,,,,,,,,,,,,,
1494388298.927,,1.000000e+001,8.410655e+001,8.410350e+001,1,0,5.106383e-001,0.000000e+000,7.051194e-001,,,,,,,-3.070418e-007,,,,,,,,,,,,,,,,,,,,,
1494388298.927,,1.000000e+001,8.410655e+001,8.410350e+001,1,0,5.234043e+000,0.000000e+000,7.498283e-001,,,,,,,3.482219e-007,,,,,,,,,,,,,,,,,,,,,
1494388298.927,,1.000000e+001,8.410350e+001,8.410043e+001,2,0,3.829787e+000,0.000000e+000,7.531854e-001,7.309835e-001,-1.161180e-002,1.204574e-002,7.434148e-001,8.195218e-004,2.447706e-002,7.520794e-008,-2.160505e-007,,,,,,,,,,,,,,,,,,,,
1494388502.357,,1.000000e+001,8.207169e+001,8.204243e+001,1,0,2.425532e+000,0.000000e+000,-2.366674e-001,,,,,,,5.533366e-009,,,,,,,,,,,,,,,,,,,,,
1494388502.357,,1.000000e+001,8.207462e+001,8.211561e+001,2,0,1.021277e+000,0.000000e+000,-2.169833e-001,-2.285801e-001,8.663852e-003,1.542875e-002,-2.371907e-001,5.327538e-005,6.818175e-003,9.967425e-008,4.635967e-008,,,,,,,,,,,,,,,,,,,,
1494388502.357,,1.000000e+001,8.207462e+001,8.211561e+001,2,0,5.744681e+000,0.000000e+000,-1.919585e-001,-2.143893e-001,-8.432928e-003,2.961963e-002,-2.094261e-001,-3.469813e-003,3.458275e-002,2.560482e-007,4.499543e-008,,,,,,,,,,,,,,,,,,,,
1494388696.708,,1.000000e+001,8.010470e+001,8.007111e+001,1,0,4.340425e+000,0.000000e+000,6.152438e-001,,,,,,,-7.724029e-007,,,,,,,,,,,,,,,,,,,,,
1494388696.708,,1.000000e+001,8.014114e+001,8.015234e+001,2,0,2.936170e+000,0.000000e+000,6.633097e-001,6.567483e-001,5.160249e-004,1.439935e-002,6.662200e-001,9.987740e-003,2.387106e-002,-1.382923e-007,3.883542e-009,,,,,,,,,,,,,,,,,,,,
1494388911.828,,1.000000e+001,7.821873e+001,7.817046e+001,1,0,1.531915e+000,0.000000e+000,1.976043e-001,,,,,,,4.212793e-007,,,,,,,,,,,,,,,,,,,,,
1494388911.828,,1.000000e+001,7.817046e+001,7.825352e+001,2,0,1.276596e-001,0.000000e+000,1.989776e-001,1.865416e-001,4.136169e-003,4.562616e-003,1.842164e-001,1.810962e-003,2.237409e-003,6.653227e-008,-7.934432e-009,,,,,,,,,,,,,,,,,,,,
1494388911.828,,1.000000e+001,7.817046e+001,7.825352e+001,2,0,4.851064e+000,0.000000e+000,2.133211e-001,2.086671e-001,1.048318e-002,2.668819e-002,2.066892e-001,8.505245e-003,2.471025e-002,2.198021e-007,3.309681e-007,,,,,,,,,,,,,,,,,,,,
1494389119.128,,1.000000e+001,7.621439e+001,7.617348e+001,1,0,3.446809e+000,0.000000e+000,9.597925e-002,,,,,,,-2.791039e-007,,,,,,,,,,,,,,,,,,,,,
1494389119.128,,1.000000e+001,7.618881e+001,7.631171e+001,2,0,2.042553e+000,0.000000e+000,1.522850e-001,1.358053e-001,1.804222e-002,2.823345e-002,1.090722e-001,-8.690856e-003,1.500368e-003,4.275389e-007,3.993277e-007,,,,,,,,,,,,,,,,,,,,
1494389330.279,,1.000000e+001,7.426826e+001,7.421220e+001,1,0,6.382979e-001,0.000000e+000,-8.305486e-001,,,,,,,-9.822361e-008,,,,,,,,,,,,,,,,,,,,,
1494389330.279,,1.000000e+001,7.426826e+001,7.421220e+001,1,0,5.361702e+000,0.000000e+000,-8.104066e-001,,,,,,,-4.646608e-008,,,,,,,,,,,,,,,,,,,,,
1494389330.279,,1.000000e+001,7.421707e+001,7.427071e+001,2,0,3.957447e+000,0.000000e+000,-7.241932e-001,-7.492180e-001,4.500882e-002,7.189363e-002,-7.868846e-001,7.342196e-003,3.422701e-002,1.403370e-006,1.172484e-006,,,,,,,,,,,,,,,,,,,,
1494389531.339,,1.000000e+001,7.226495e+001,7.226263e+001,1,0,2.553191e+000,0.000000e+000,-1.032120e+000,,,,,,,-8.785937e-007,,,,,,,,,,,,,,,,,,,,,
1494389531.339,,1.000000e+001,7.225800e+001,7.228816e+001,2,0,1.148936e+000,0.000000e+000,-9.422446e-001,-9.763485e-001,1.284852e-002,1.999241e-002,-9.634173e-001,2.577975e-002,3.292364e-002,6.301998e-007,1.946300e-007,,,,,,,,,,,,,,,,,,,,
1494389531.339,,1.000000e+001,7.225800e+001,7.228816e+001,2,0,5.872340e+000,0.000000e+000,-9.306478e-001,-9.433128e-001,1.651494e-002,5.302817e-002,-9.555152e-001,4.312502e-003,4.082572e-002,5.993315e-007,6.226819e-007,,,,,,,,,,,,,,,,,,,,
1494389720.089,,1.000000e+001,7.027228e+001,7.024583e+001,1,0,4.468085e+000,0.000000e+000,-4.332036e-001,,,,,,,1.470817e-007,,,,,,,,,,,,,,,,,,,,,
1494389720.089,,1.000000e+001,7.023482e+001,7.034291e+001,2,0,3.063830e+000,0.000000e+000,-4.809644e-001,-5.056077e-001,-7.737937e-002,-6.285465e-002,-4.933040e-001,-6.507569e-002,-5.055097e-002,-1.541716e-006,-1.813669e-006,,,,,,,,,,,,,,,,,,,,
1494389918.829,,1.000000e+001,6.832863e+001,6.829724e+001,1,0,1.659575e+000,0.000000e+000,-7.110704e-001,,,,,,,9.121468e-007,,,,,,,,,,,,,,,,,,,,,
1494389918.829,,1.000000e+001,6.833700e+001,6.836004e+001,2,0,2.553191e-001,0.000000e+000,-7.254139e-001,-7.474632e-001,1.388218e-003,2.779961e-003,-7.388561e-001,9.995308e-003,1.138705e-002,1.596709e-007,-1.085327e-007,,,,,,,,,,,,,,,,,,,,
1494389918.829,,1.000000e+001,6.833700e+001,6.836004e+001,2,0,4.978724e+000,0.000000e+000,-7.003891e-001,-7.277790e-001,-4.674818e-003,2.246416e-002,-6.997063e-001,2.339790e-002,5.053687e-002,4.608228e-007,4.061621e-008,,,,,,,,,,,,,,,,,,,,
1494390109.170,,1.000000e+001,6.632365e+001,6.631573e+001,1,0,3.574468e+000,0.000000e+000,-8.090333e-001,,,,,,,-6.246628e-007,,,,,,,,,,,,,,,,,,,,,
1494390109.170,,1.000000e+001,6.636128e+001,6.637118e+001,2,0,2.170213e+000,0.000000e+000,-7.739376e-001,-7.972076e-001,-2.066975e-002,-6.840229e-003,-7.991662e-001,-2.262836e-002,-8.798838e-003,-2.658380e-007,-5.240900e-007,,,,,,,,,,,,,,,,,,,,
1494390325.660,,1.000000e+001,6.442090e+001,6.443964e+001,1,0,7.659575e-001,0.000000e+000,-1.518883e+000,,,,,,,2.140005e-007,,,,,,,,,,,,,,,,,,,,,
1494390325.660,,1.000000e+001,6.442090e+001,6.443964e+001,1,0,5.489362e+000,0.000000e+000,-1.518120e+000,,,,,,,-4.449248e-009,,,,,,,,,,,,,,,,,,,,,
1494390325.660,,1.000000e+001,6.443403e+001,6.438718e+001,2,0,4.085106e+000,0.000000e+000,-1.477073e+000,-1.468681e+000,4.057540e-002,6.196260e-002,-1.491439e+000,1.781692e-002,3.920412e-002,6.714581e-007,1.057031e-006,,,,,,,,,,,,,,,,,,,,
1494390522.850,,1.000000e+001,6.242683e+001,6.239857e+001,1,0,2.680851e+000,0.000000e+000,1.977569e-001,,,,,,,-2.635734e-006,,,,,,,,,,,,,,,,,,,,,
1494390522.850,,1.000000e+001,6.239857e+001,6.241269e+001,2,0,1.276596e+000,0.000000e+000,3.497368e-001,3.376822e-001,2.430241e-002,3.104219e-002,3.476042e-001,3.422450e-002,4.096428e-002,5.138008e-007,5.035445e-007,,,,,,,,,,,,,,,,,,,,
1494390522.850,,1.000000e+001,6.239857e+001,6.241269e+001,2,0,6.000000e+000,0.000000e+000,3.852903e-001,3.631647e-001,2.484778e-002,5.652475e-002,3.427896e-001,4.472649e-003,3.614962e-002,1.027821e-006,8.010556e-007,,,,,,,,,,,,,,,,,,,,
1494390723.761,,1.000000e+001,6.045977e+001,6.041159e+001,1,0,4.595745e+000,0.000000e+000,5.304036e-001,,,,,,,5.604907e-007,,,,,,,,,,,,,,,,,,,,,
1494390723.761,,1.000000e+001,6.041159e+001,6.045145e+001,2,0,3.191489e+000,0.000000e+000,4.481575e-001,4.417487e-001,-7.451880e-002,-5.721182e-002,4.500793e-001,-6.618822e-002,-4.888123e-002,-1.871014e-006,-1.732687e-006,,,,,,,,,,,,,,,,,,,,
1494390934.301,,1.000000e+001,5.850449e+001,5.844214e+001,1,0,1.787234e+000,0.000000e+000,1.512169e-001,,,,,,,1.290483e-006,,,,,,,,,,,,,,,,,,,,,
1494390934.301,,1.000000e+001,5.847174e+001,5.846862e+001,2,0,3.829787e-001,0.000000e+000,1.103227e-001,9.208819e-002,-6.193920e-003,-4.423194e-003,1.108686e-001,1.258651e-002,1.435723e-002,-3.539844e-008,-2.548048e-007,,,,,,,,,,,,,,,,,,,,
1494390934.301,,1.000000e+001,5.847174e+001,5.846862e+001,2,0,5.106383e+000,0.000000e+000,8.865492e-002,8.232243e-002,-3.779864e-002,-1.418896e-002,1.399392e-001,1.981813e-002,4.342782e-002,-8.380794e-007,-7.601851e-007,,,,,,,,,,,,,,,,,,,,
1494391137.081,,1.000000e+001,5.651534e+001,5.648178e+001,1,0,3.702128e+000,0.000000e+000,-7.600519e-001,,,,,,,-5.595030e-008,,,,,,,,,,,,,,,,,,,,,
1494391137.081,,1.000000e+001,5.649636e+001,5.649345e+001,2,0,2.297872e+000,0.000000e+000,-7.859922e-001,-8.004883e-001,-5.019077e-002,-3.627414e-002,-7.971588e-001,-4.686131e-002,-3.294468e-002,-1.135060e-006,-1.210202e-006,,,,,,,,,,,,,,,,,,,,
1494391323.601,,1.000000e+001,5.452280e+001,5.450509e+001,1,0,8.936170e-001,0.000000e+000,-4.275578e-001,,,,,,,3.137939e-008,,,,,,,,,,,,,,,,,,,,,
1494391323.601,,1.000000e+001,5.452280e+001,5.450509e+001,1,0,5.617021e+000,0.000000e+000,-3.685054e-001,,,,,,,1.000068e-006,,,,,,,,,,,,,,,,,,,,,
1494391323.601,,1.000000e+001,5.450509e+001,5.453643e+001,2,0,4.212766e+000,0.000000e+000,-3.411917e-001,-3.480583e-001,5.272613e-002,8.144674e-002,-3.721718e-001,2.861257e-002,5.733317e-002,1.309220e-006,1.381262e-006,,,,,,,,,,,,,,,,,,,,
1494391521.922,,1.000000e+001,5.254442e+001,5.254442e+001,1,0,2.808511e+000,0.000000e+000,-7.383841e-001,,,,,,,-1.553739e-006,,,,,,,,,,,,,,,,,,,,,
1494391521.922,,1.000000e+001,5.254696e+001,5.252662e+001,2,0,1.404255e+000,0.000000e+000,-6.604105e-001,-6.366827e-001,3.503020e-002,4.366088e-002,-6.402600e-001,3.145285e-002,4.008353e-002,-2.741945e-008,7.494700e-007,,,,,,,,,,,,,,,,,,,,
1494391700.312,,1.000000e+001,5.057019e+001,5.055007e+001,1,0,0.000000e+000,0.000000e+000,1.510643e-001,,,,,,,1.469602e-007,,,,,,,,,,,,,,,,,,,,,
1494391700.312,,1.000000e+001,5.057019e+001,5.055007e+001,1,0,4.723404e+000,0.000000e+000,1.817349e-001,,,,,,,5.532465e-007,,,,,,,,,,,,,,,,,,,,,
1494391700.312,,1.000000e+001,5.055007e+001,5.055480e+001,2,0,3.319149e+000,0.000000e+000,1.191730e-001,1.205463e-001,-4.739162e-002,-3.047868e-002,1.188803e-001,-4.905757e-002,-3.214463e-002,-1.388663e-006,-1.081538e-006,,,,,,,,,,,,,,,,,,,,
1494391881.792,,1.000000e+001,4.862331e+001,4.860350e+001,1,0,1.914894e+000,0.000000e+000,-5.780118e-001,,,,,,,7.436029e-008,,,,,,,,,,,,,,,,,,,,,
1494391881.792,,1.000000e+001,4.860680e+001,4.858260e+001,2,0,5.106383e-001,0.000000e+000,-5.728237e-001,-5.770962e-001,1.586212e-003,4.805744e-003,-5.638306e-001,1.485188e-002,1.807141e-002,-3.586556e-007,-1.143553e-007,,,,,,,,,,,,,,,,,,,,
1494391881.792,,1.000000e+001,4.860680e+001,4.858260e+001,2,0,5.234043e+000,0.000000e+000,-5.517662e-001,-5.555047e-001,-6.602911e-003,2.639729e-002,-5.340512e-001,1.485059e-002,4.785079e-002,-1.371864e-007,3.184959e-008,,,,,,,,,,,,,,,,,,,,
1494392060.222,,1.000000e+001,4.659557e+001,4.659050e+001,1,0,3.829787e+000,0.000000e+000,-6.118868e-001,,,,,,,1.097840e-006,,,,,,,,,,,,,,,,,,,,,
1494392060.222,,1.000000e+001,4.659050e+001,4.660065e+001,2,0,2.425532e+000,0.000000e+000,-7.104601e-001,-7.095445e-001,-5.250034e-002,-3.579384e-002,-7.103040e-001,-5.325977e-002,-3.655326e-002,-1.452134e-006,-1.265054e-006,,,,,,,,,,,,,,,,,,,,
1494392249.703,,1.000000e+001,4.460540e+001,4.457832e+001,1,0,1.021277e+000,0.000000e+000,-9.384298e-001,,,,,,,8.447751e-008,,,,,,,,,,,,,,,,,,,,,
1494392249.703,,1.000000e+001,4.460540e+001,4.457832e+001,1,0,5.744681e+000,0.000000e+000,-8.932632e-001,,,,,,,8.955467e-007,,,,,,,,,,,,,,,,,,,,,
1494392249.703,,1.000000e+001,4.459605e+001,4.458018e+001,2,0,4.340425e+000,0.000000e+000,-8.796826e-001,-9.033341e-001,1.824277e-002,3.414202e-002,-8.884345e-001,3.314232e-002,4.904157e-002,8.648749e-007,5.180846e-007,,,,,,,,,,,,,,,,,,,,
1494392423.623,,1.000000e+001,4.262730e+001,4.262045e+001,1,0,2.936170e+000,0.000000e+000,-4.983597e-001,,,,,,,-2.241512e-006,,,,,,,,,,,,,,,,,,,,,
1494392423.623,,1.000000e+001,4.262473e+001,4.261016e+001,2,0,1.531915e+000,0.000000e+000,-3.225757e-001,-3.450065e-001,6.044297e-002,7.117325e-002,-3.794368e-001,2.601264e-002,3.674293e-002,1.685159e-006,1.346359e-006,,,,,,,,,,,,,,,,,,,,
1494392615.903,,1.000000e+001,4.063884e+001,4.062630e+001,1,0,1.276596e-001,0.000000e+000,9.871062e-001,,,,,,,-8.182687e-007,,,,,,,,,,,,,,,,,,,,,
1494392615.903,,1.000000e+001,4.063884e+001,4.062630e+001,1,0,4.851064e+000,0.000000e+000,1.037003e+000,,,,,,,-2.734305e-008,,,,,,,,,,,,,,,,,,,,,
1494392615.903,,1.000000e+001,4.063493e+001,4.063570e+001,2,0,3.446809e+000,0.000000e+000,1.046464e+000,1.015488e+000,-3.042765e-002,-1.146102e-002,1.007476e+000,-3.843911e-002,-1.947248e-002,-1.781336e-007,-6.685295e-007,,,,,,,,,,,,,,,,,,,,
1494392795.883,,1.000000e+001,3.865386e+001,3.864170e+001,1,0,2.042553e+000,0.000000e+000,4.022278e-001,,,,,,,2.415618e-009,,,,,,,,,,,,,,,,,,,,,
1494392795.883,,1.000000e+001,3.864743e+001,3.864170e+001,2,0,6.382979e-001,0.000000e+000,3.976501e-001,4.009308e-001,-2.377438e-003,9.014308e-004,4.215663e-001,1.825805e-002,2.153692e-002,-4.663416e-007,-1.666763e-007,,,,,,,,,,,,,,,,,,,,
1494392795.883,,1.000000e+001,3.864743e+001,3.864170e+001,2,0,5.361702e+000,0.000000e+000,4.170291e-001,4.049745e-001,-2.259743e-002,4.945070e-003,4.400321e-001,1.246020e-002,4.000270e-002,-3.270579e-007,-3.716168e-007,,,,,,,,,,,,,,,,,,,,
1494393030.764,,1.000000e+001,3.666435e+001,3.665788e+001,1,0,3.957447e+000,0.000000e+000,-6.320287e-001,,,,,,,9.001615e-007,,,,,,,,,,,,,,,,,,,,,
1494393030.764,,1.000000e+001,3.666273e+001,3.666435e+001,2,0,2.553191e+000,0.000000e+000,-7.423514e-001,-7.467002e-001,-7.969514e-002,-7.012653e-002,-7.313392e-001,-6.433406e-002,-5.476546e-002,-1.941560e-006,-1.886135e-006,,,,,,,,,,,,,,,,,,,,
1494393202.064,,1.000000e+001,3.472888e+001,3.471574e+001,1,0,1.148936e+000,0.000000e+000,-5.616846e-001,,,,,,,4.180110e-007,,,,,,,,,,,,,,,,,,,,,
1494393202.064,,1.000000e+001,3.472888e+001,3.471574e+001,1,0,5.872340e+000,0.000000e+000,-5.349813e-001,,,,,,,6.322152e-007,,,,,,,,,,,,,,,,,,,,,
1494393202.064,,1.000000e+001,3.471283e+001,3.470261e+001,2,0,4.468085e+000,0.000000e+000,-5.194171e-001,-5.214008e-001,3.399970e-002,6.213593e-002,-5.211839e-001,3.421661e-002,6.235284e-002,8.542393e-007,9.439145e-007,,,,,,,,,,,,,,,,,,,,
1494393385.444,,1.000000e+001,3.270569e+001,3.270569e+001,1,0,3.063830e+000,0.000000e+000,8.606088e-002,,,,,,,-2.128244e-006,,,,,,,,,,,,,,,,,,,,,
1494393385.444,,1.000000e+001,3.270569e+001,3.269657e+001,2,0,1.659575e+000,0.000000e+000,2.352941e-001,2.261387e-001,5.042390e-002,5.933370e-002,1.953924e-001,1.967756e-002,2.858736e-002,1.201193e-006,1.147051e-006,,,,,,,,,,,,,,,,,,,,
1494393566.555,,1.000000e+001,3.072281e+001,3.071703e+001,1,0,2.553191e-001,0.000000e+000,5.004959e-002,,,,,,,6.893647e-007,,,,,,,,,,,,,,,,,,,,,
1494393566.555,,1.000000e+001,3.072281e+001,3.071703e+001,1,0,4.978724e+000,0.000000e+000,4.074159e-002,,,,,,,7.339156e-008,,,,,,,,,,,,,,,,,,,,,
1494393566.555,,1.000000e+001,3.072397e+001,3.071703e+001,2,0,3.574468e+000,0.000000e+000,6.713970e-002,3.288319e-002,-1.553758e-002,6.647034e-003,1.921023e-002,-2.921054e-002,-7.025927e-003,2.113625e-007,-3.002815e-007,,,,,,,,,,,,,,,,,,,,
1494393745.585,,1.000000e+001,2.874182e+001,2.873774e+001,1,0,2.170213e+000,0.000000e+000,-1.141222e+000,,,,,,,-8.771531e-008,,,,,,,,,,,,,,,,,,,,,
1494393745.585,,1.000000e+001,2.874386e+001,2.873672e+001,2,0,7.659575e-001,0.000000e+000,-1.101549e+000,-1.109941e+000,3.336521e-002,3.822505e-002,-1.120991e+000,2.231594e-002,2.717578e-002,7.381568e-007,6.595765e-007,,,,,,,,,,,,,,,,,,,,
1494393745.585,,1.000000e+001,2.874386e+001,2.873672e+001,2,0,5.489362e+000,0.000000e+000,-1.097581e+000,-1.108568e+000,4.769447e-003,3.959835e-002,-1.102163e+000,1.117409e-002,4.600298e-002,5.165930e-007,3.259938e-007,,,,,,,,,,,,,,,,,,,,
1494393934.355,,1.000000e+001,2.676059e+001,2.675613e+001,1,0,4.085106e+000,0.000000e+000,-5.081255e-002,,,,,,,1.464412e-006,,,,,,,,,,,,,,,,,,,,,
1494393934.355,,1.000000e+001,2.676147e+001,2.675792e+001,2,0,2.680851e+000,0.000000e+000,-1.429770e-001,-1.503014e-001,-4.078295e-002,-2.331509e-002,-1.547292e-001,-4.521081e-002,-2.774295e-002,-9.947667e-007,-9.767036e-007,,,,,,,,,,,,,,,,,,,,
1494394165.585,,1.000000e+001,2.475870e+001,2.476947e+001,1,0,1.276596e+000,0.000000e+000,-4.322881e-001,,,,,,,2.098295e-007,,,,,,,,,,,,,,,,,,,,,
1494394165.585,,1.000000e+001,2.475870e+001,2.476947e+001,1,0,6.000000e+000,0.000000e+000,-3.854429e-001,,,,,,,9.641772e-007,,,,,,,,,,,,,,,,,,,,,
1494394165.585,,1.000000e+001,2.477332e+001,2.478565e+001,2,0,4.595745e+000,0.000000e+000,-3.939880e-001,-4.109254e-001,5.354814e-003,2.473024e-002,-3.898892e-001,2.639108e-002,4.576650e-002,3.948935e-007,2.282550e-007,,,,,,,,,,,,,,,,,,,,
1494394382.406,,1.000000e+001,2.280357e+001,2.280225e+001,1,0,3.191489e+000,0.000000e+000,-5.197223e-001,,,,,,,-1.655849e-006,,,,,,,,,,,,,,,,,,,,,
1494394382.406,,1.000000e+001,2.281146e+001,2.281146e+001,2,0,1.787234e+000,0.000000e+000,-4.019226e-001,-4.002441e-001,4.516813e-002,5.527228e-002,-4.340433e-001,1.136893e-002,2.147308e-002,7.214076e-007,1.018586e-006,,,,,,,,,,,,,,,,,,,,
1494394547.226,,1.000000e+001,2.085910e+001,2.083650e+001,1,0,3.829787e-001,0.000000e+000,3.389029e-001,,,,,,,-1.217031e-007,,,,,,,,,,,,,,,,,,,,,
1494394547.226,,1.000000e+001,2.085910e+001,2.083650e+001,1,0,5.106383e+000,0.000000e+000,3.649958e-001,,,,,,,2.562165e-007,,,,,,,,,,,,,,,,,,,,,
1494394547.226,,1.000000e+001,2.083595e+001,2.082824e+001,2,0,3.702128e+000,0.000000e+000,3.770505e-001,3.606470e-001,-5.688115e-003,1.139355e-002,3.568749e-001,-9.460225e-003,7.621437e-003,1.523131e-008,-7.512926e-008,,,,,,,,,,,,,,,,,,,,
1494394709.186,,1.000000e+001,1.886792e+001,1.886067e+001,1,0,2.297872e+000,0.000000e+000,-6.070039e-001,,,,,,,-3.728692e-007,,,,,,,,,,,,,,,,,,,,,
1494394709.186,,1.000000e+001,1.885569e+001,1.885342e+001,2,0,8.936170e-001,0.000000e+000,-5.799954e-001,-5.876249e-001,3.688984e-003,8.458078e-003,-5.669191e-001,2.439480e-002,2.916390e-002,-2.999877e-008,-1.482658e-008,,,,,,,,,,,,,,,,,,,,
1494394709.186,,1.000000e+001,1.885569e+001,1.885342e+001,2,0,5.617021e+000,0.000000e+000,-5.123979e-001,-5.490196e-001,1.708625e-002,4.706341e-002,-5.581815e-001,7.924359e-003,3.790152e-002,1.273465e-006,5.940574e-007,,,,,,,,,,,,,,,,,,,,
1494394862.346,,1.000000e+001,1.688218e+001,1.687489e+001,1,0,4.212766e+000,0.000000e+000,-1.630884e+000,,,,,,,9.048963e-007,,,,,,,,,,,,,,,,,,,,,
1494394862.346,,1.000000e+001,1.687562e+001,1.687380e+001,2,0,2.808511e+000,0.000000e+000,-1.736171e+000,-1.760967e+000,-9.867803e-002,-8.297741e-002,-1.739795e+000,-7.750551e-002,-6.180489e-002,-1.998913e-006,-2.332416e-006,,,,,,,,,,,,,,,,,,,,
1494395002.837,,1.000000e+001,1.490325e+001,1.489816e+001,1,0,1.404255e+000,0.000000e+000,2.830549e-001,,,,,,,6.173186e-007,,,,,,,,,,,,,,,,,,,,,
1494395002.837,,1.000000e+001,1.489703e+001,1.489703e+001,2,0,0.000000e+000,0.000000e+000,2.613871e-001,2.562753e-001,-8.806586e-004,-8.806586e-004,2.628512e-001,5.695254e-003,5.695254e-003,-1.120870e-007,-9.666928e-008,,,,,,,,,,,,,,,,,,,,
1494395002.837,,1.000000e+001,1.489703e+001,1.489703e+001,2,0,4.723404e+000,0.000000e+000,2.952621e-001,2.835126e-001,1.213740e-002,2.635667e-002,3.018017e-001,3.042643e-002,4.464570e-002,5.445700e-007,3.748987e-007,,,,,,,,,,,,,,,,,,,,
1494395150.597,,1.000000e+001,1.292254e+001,1.292041e+001,1,0,3.319149e+000,0.000000e+000,-4.682994e-001,,,,,,,-1.309259e-006,,,,,,,,,,,,,,,,,,,,,
1494395150.597,,1.000000e+001,1.291767e+001,1.291733e+001,2,0,1.914894e+000,0.000000e+000,-3.703365e-001,-3.813230e-001,2.907083e-002,3.977561e-002,-4.087388e-001,1.654988e-003,1.235977e-002,6.982627e-007,6.517121e-007,,,,,,,,,,,,,,,,,,,,
1494395307.357,,1.000000e+001,1.093252e+001,1.092771e+001,1,0,5.106383e-001,0.000000e+000,-7.142749e-001,,,,,,,4.423400e-007,,,,,,,,,,,,,,,,,,,,,
1494395307.357,,1.000000e+001,1.093252e+001,1.092771e+001,1,0,5.234043e+000,0.000000e+000,-7.061875e-001,,,,,,,3.014229e-007,,,,,,,,,,,,,,,,,,,,,
1494395307.357,,1.000000e+001,1.093281e+001,1.093609e+001,2,0,3.829787e+000,0.000000e+000,-6.947433e-001,-7.032120e-001,3.478689e-003,2.370715e-002,-7.106901e-001,-3.999369e-003,1.622909e-002,5.326729e-008,1.615263e-007,,,,,,,,,,,,,,,,,,,,
1494395454.817,,1.000000e+001,8.964911e+000,8.957157e+000,1,0,2.425532e+000,0.000000e+000,-9.806973e-001,,,,,,,-1.111777e-006,,,,,,,,,,,,,,,,,,,,,
1494395454.817,,1.000000e+001,8.957157e+000,8.962126e+000,2,0,1.021277e+000,0.000000e+000,-9.102007e-001,-9.095141e-001,2.233755e-002,2.763373e-002,-9.002279e-001,3.162371e-002,3.691989e-002,2.152156e-007,4.453650e-007,,,,,,,,,,,,,,,,,,,,
1494395454.817,,1.000000e+001,8.957157e+000,8.962126e+000,2,0,5.744681e+000,0.000000e+000,-8.520638e-001,-8.720531e-001,3.530364e-002,6.509465e-002,-9.007847e-001,6.572120e-003,3.636312e-002,1.242610e-006,1.030385e-006,,,,,,,,,,,,,,,,,,,,
1494395600.897,,1.000000e+001,7.002298e+000,6.993238e+000,1,0,4.340425e+000,0.000000e+000,-3.614862e-001,,,,,,,9.145670e-007,,,,,,,,,,,,,,,,,,,,,
1494395600.897,,1.000000e+001,6.993238e+000,6.986435e+000,2,0,2.936170e+000,0.000000e+000,-4.774548e-001,-4.827192e-001,-9.040816e-002,-7.351413e-002,-4.801337e-001,-8.782275e-002,-7.092872e-002,-2.264628e-006,-2.124021e-006,,,,,,,,,,,,,,,,,,,,
1494395764.208,,1.000000e+001,5.002675e+000,4.997302e+000,1,0,1.531915e+000,0.000000e+000,-6.005951e-001,,,,,,,8.937513e-007,,,,,,,,,,,,,,,,,,,,,
1494395764.208,,1.000000e+001,5.008930e+000,4.997877e+000,2,0,1.276596e-001,0.000000e+000,-6.228732e-001,-6.417181e-001,-3.745004e-003,-2.974510e-003,-6.285217e-001,9.451404e-003,1.022190e-002,-8.981078e-008,-2.519846e-007,,,,,,,,,,,,,,,,,,,,
1494395764.208,,1.000000e+001,5.008930e+000,4.997877e+000,2,0,4.851064e+000,0.000000e+000,-5.818265e-001,-6.039521e-001,5.512810e-003,3.479159e-002,-5.791175e-001,3.034732e-002,5.962610e-002,5.763050e-007,2.902989e-007,,,,,,,,,,,,,,,,,,,,
1494395764.208,,1.000000e+001,5.008930e+000,4.997877e+000,2,0,6.000000e+000,0.000000e+000,-5.754177e-001,-5.754940e-001,2.703642e-002,6.324965e-002,-5.976777e-001,4.852706e-003,4.106593e-002,6.532173e-007,8.809811e-007,,,,,,,,,,,,,,,,,,,,