File: Data/Gd (7 nm)/YBCO_Gd_7_12192017_resistivity.dat
[Header]
; AC Transport Data File (default extension .dat)
; Copyright 1998, Quantum Design, Inc. All rights reserved.
TITLE,PPMS_MANG
FILEOPENTIME,30551386.52,12/20/2017,3:57 pm
BYAPP,ACTRANSPORT,2.0,1.1
INFO,PPMS AC Transport Option Release 2.2.4. Build 2,APPNAME
INFO,,SAMPLE1_MATERIAL
INFO,,SAMPLE1_COMMENT
INFO,1.0,SAMPLE1_LEAD_SEPARATION
INFO,1.0,SAMPLE1_CROSS_SECTION
INFO,,SAMPLE2_MATERIAL
INFO,,SAMPLE2_COMMENT
INFO,1.0,SAMPLE2_LEAD_SEPARATION
INFO,1.0,SAMPLE2_CROSS_SECTION
DATATYPE,COMMENT,1
DATATYPE,TIME,2
FIELDGROUP,ACResist,2,4,5,6,7,8,9,10,13,14,15,16,53
FIELDGROUP,ACHall,2,4,5,6,7,8,9,10,17,18,19,20,53
FIELDGROUP,ACIVcurve,2,4,5,6,7,8,9,10,53
FIELDGROUP,ACCritCurrent,2,4,5,6,7,8,9,21,22,23,24,53
STARTUPGROUP,All
STARTUPAXIS,X,2
STARTUPAXIS,Y1,3
[Data]
Comment,Time Stamp (sec),Status (code),Temperature (K),Magnetic Field (Oe),Sample Position (deg),Excitation (mA),Frequency (Hz),Volts ch1,Volts ch2,V Std.Dev. ch1,V Std.Dev. ch2,Res. ch1 (ohm-cm),Res. ch2 (ohm-cm),Res. Std.Dev. ch1,Res. Std.Dev. ch2,Hall ch1 (cm^3/coul),Hall ch2 (cm^3/coul),Hall Std.Dev. ch1,Hall Std.Dev. ch2,Crit.Cur. ch1 (mA),Crit.Cur. ch2 (mA),C.Cur. Std.Dev. ch1,C.Cur. Std.Dev. ch2,ACT Status (code),ACT Gain,2nd Harm. ch1 (dB),2nd Harm. ch2 (dB),3rd Harm. ch1 (dB),3rd Harm. ch2 (dB),Quad.Error ch1 (ohm-cm-rad),Quad.Error ch2 (ohm-cm-rad),Drive Signal ch1 (V),Drive Signal ch2 (V),Bridge 1 Resistance (ohms),Bridge 1 Excitation (uA),Bridge 2 Resistance (ohms),Bridge 2 Excitation (uA),Bridge 3 Resistance (ohms),Bridge 3 Excitation (uA),Bridge 4 Resistance (ohms),Bridge 4 Excitation (uA),Signal 1 Vin (V),Signal 2 Vin (V),Digital Inputs (code),Drive 1 Iout (mA),Drive 1 Ipower (watts),Drive 2 Iout (mA),Drive 2 Ipower (watts),Pressure (),Map 20 (),Map 21 (),Map 22 (),Map 23 (),Map 24 (),Map 25 (),Map 26 (),Map 27 (),Map 28 (),Map 29 ()
,30551420.78,4370,300.0162,312.857,90.014,0.102153342753992,173,0.00108839840608654,,1.60251393637912E-7,,10.6546721994364,,0.00156875093186033,,,,,,,,,,0,2500,-91.6806589534157,,-82.6427471905906,,-4.71700634033239E-6,,0.00108839844110245,,,,,,,,,,,,,,,,,,,,,,,,,,,
,30551472.98,4374,298.3999,312.857,90.014,0.102153342753992,173,0.00108755941176715,,1.60141627231291E-7,,10.6464589315029,,0.00156767638915125,,,,,,,,,,0,2500,-93.764183691868,,-84.1399321596125,,-4.31238325482745E-6,,0.00108755944105599,,,,,,,,,,,,,,,,,,,,,,,,,,,
,30551526.575,4374,296.0267,312.857,90.014,0.102153342753992,173,0.0010858468286981,,1.66465155309495E-7,,10.6296937366542,,0.00162957932150911,,,,,,,,,,0,2500,-90.1553814026912,,-86.0277220260534,,-5.59232351663138E-6,,0.00108584687803098,,,,,,,,,,,,,,,,,,,,,,,,,,,
,30551579.6,4370,292.16965,312.857,90.014,0.102153342753992,173,0.00108221311266365,,1.62823394202844E-7,,10.5941217663647,,0.00159392894339206,,,,,,,,,,0,2500,-88.4831425584581,,-82.0987301974275,,-4.9335846180873E-6,,0.00108221315118777,,,,,,,,,,,,,,,,,,,,,,,,,,,
,30551633.1,4370,289.904,312.857,90.014,0.102153342753992,173,0.00108010294724904,,1.71655575272431E-7,,10.5734644732894,,0.00168038988245886,,,,,,,,,,0,2500,-88.8869278705854,,-81.0685780418237,,-4.83182070518213E-6,,0.00108010298427249,,,,,,,,,,,,,,,,,,,,,,,,,,,
,30551686.97,4370,287.073,312.857,90.014,0.102153342753992,173,0.0010776449935196,,1.56058943698754E-7,,10.5494025358422,,0.00152770956293509,,,,,,,,,,0,2500,-90.7888355591145,,-82.6081733915244,,-4.73093399686194E-6,,0.00107764502909408,,,,,,,,,,,,,,,,,,,,,,,,,,,
,30551742.11,4370,284.31665,312.857,90.014,0.102153342753992,173,0.00107521012274147,,1.62968933224683E-7,,10.5255665682419,,0.00159535356175529,,,,,,,,,,0,2500,-91.2389587005804,,-81.4053527637997,,-4.70501539670322E-6,,0.00107521015800689,,,,,,,,,,,,,,,,,,,,,,,,,,,
,30551791.82,4370,281.82695,312.857,90.014,0.102153342753992,173,0.00107294649711789,,1.74018594747655E-7,,10.503406992077,,0.00170352209187172,,,,,,,,,,0,2500,-86.5573652183414,,-81.2221419907204,,-4.83548313814709E-6,,0.00107294653444481,,,,,,,,,,,,,,,,,,,,,,,,,,,
,30551846.19,4370,279.09825,312.857,90.014,0.102153342753992,173,0.00107046262213305,,1.6670429748373E-7,,10.4790913041398,,0.0016319201192931,,,,,,,,,,0,2500,-89.8236133000874,,-81.1818912859692,,-4.95511359337726E-6,,0.00107046266142071,,,,,,,,,,,,,,,,,,,,,,,,,,,
,30551902.235,4370,276.29265,312.857,90.014,0.102153342753992,173,0.00106789809498267,,1.63027285340585E-7,,10.4539860798055,,0.00159592466381536,,,,,,,,,,0,2500,-90.6798099390727,,-80.947194446442,,-4.97494018566628E-6,,0.00106789813468046,,,,,,,,,,,,,,,,,,,,,,,,,,,
,30551954.82,4370,273.6601,312.857,90.014,0.102153342753992,173,0.00106541258160514,,1.64524683710196E-7,,10.4296543554431,,0.00161058311632992,,,,,,,,,,0,2500,-88.6195076887558,,-80.7024205154257,,-5.13129285053976E-6,,0.00106541262393591,,,,,,,,,,,,,,,,,,,,,,,,,,,
,30552009.375,4370,270.93685,312.857,90.014,0.102153342753992,173,0.00106288631986006,,1.709845358364E-7,,10.4049237296133,,0.0016738205945288,,,,,,,,,,0,2500,-97.3416470803343,,-80.7465299193543,,-3.96921615616395E-6,,0.00106288634524891,,,,,,,,,,,,,,,,,,,,,,,,,,,
,30552063.165,4370,268.2361,312.857,90.014,0.102153342753992,173,0.0010604147543553,,1.6987905481434E-7,,10.3807285492276,,0.00166299862136033,,,,,,,,,,0,2500,-85.9798677334507,,-82.0483340212786,,-5.44581383254497E-6,,0.00106041480225913,,,,,,,,,,,,,,,,,,,,,,,,,,,
,30552116.555,4370,265.55235,312.857,90.014,0.102153342753992,173,0.00105782674543928,,1.52479192124341E-7,,10.3553934572626,,0.0014926659505016,,,,,,,,,,0,2500,-91.8162511718625,,-82.700485365816,,-5.14768103704728E-6,,0.00105782678834637,,,,,,,,,,,,,,,,,,,,,,,,,,,
,30552170.945,4370,262.8405,312.857,90.014,0.102153342753992,173,0.00105516220778655,,1.64100980228455E-7,,10.3293091951592,,0.00160643517697556,,,,,,,,,,0,2500,-85.7777604022638,,-81.2577374116019,,-5.39869295638848E-6,,0.00105516225509932,,,,,,,,,,,,,,,,,,,,,,,,,,,
,30552227.43,4370,260.01915,312.857,90.014,0.102153342753992,173,0.00105252033896692,,1.70166673136862E-7,,10.3034468490343,,0.00166581407058696,,,,,,,,,,0,2500,-85.3712586119938,,-80.2854164768637,,-5.49689120854707E-6,,0.00105252038813963,,,,,,,,,,,,,,,,,,,,,,,,,,,
,30552285.72,4370,257.1012,312.857,90.014,0.102153342753992,173,0.00104975060369331,,1.62990363403533E-7,,10.2763327668099,,0.00159556295096199,,,,,,,,,,0,2500,-86.2583132074613,,-82.2235404738774,,-3.97398040558511E-6,,0.00104975062946161,,,,,,,,,,,,,,,,,,,,,,,,,,,
,30552343.245,4370,254.2254,312.857,90.014,0.102153342753992,173,0.00104684842686591,,1.65493941658373E-7,,10.2479221611588,,0.00162007117269527,,,,,,,,,,0,2500,-89.9062118946629,,-81.9759669807424,,-5.27329778328914E-6,,0.00104684847236485,,,,,,,,,,,,,,,,,,,,,,,,,,,
,30552398.05,4370,251.48075,312.857,90.014,0.102153342753992,173,0.00104403142763124,,1.62372967087085E-7,,10.2203453956796,,0.00158951889549746,,,,,,,,,,0,2500,-94.308294124343,,-80.9132434828055,,-6.91890890993658E-6,,0.00104403150616965,,,,,,,,,,,,,,,,,,,,,,,,,,,
,30552454.265,4370,248.68905,312.857,90.014,0.102153342753992,173,0.00104106960074209,,1.60721559524182E-7,,10.191350854348,,0.00157335274373075,,,,,,,,,,0,2500,-87.1767028433272,,-82.364428918743,,-5.9038331403314E-6,,0.00104106965808884,,,,,,,,,,,,,,,,,,,,,,,,,,,
,30552508.375,4370,245.9658,312.857,90.014,0.102153342753992,173,0.00103863421866904,,1.60121048913207E-7,,10.1675098990979,,0.00156747414059937,,,,,,,,,,0,2500,-86.2381095618217,,-82.4671559647437,,-5.22506962728443E-6,,0.00103863426369282,,,,,,,,,,,,,,,,,,,,,,,,,,,
,30552564.445,4370,243.169,312.857,90.014,0.102153342753992,173,0.00103568609128499,,1.70841082692885E-7,,10.1386494710002,,0.00167241578774307,,,,,,,,,,0,2500,-94.7470125687178,,-78.2269224976443,,-5.46008180536918E-6,,0.00103568614058995,,,,,,,,,,,,,,,,,,,,,,,,,,,
,30552617.785,4370,240.5042,312.857,90.014,0.102153342753992,173,0.00103268865105368,,1.55486360597383E-7,,10.1093063009793,,0.00152210366884302,,,,,,,,,,0,2500,-96.1680944807364,,-81.1869473876016,,-4.88972613252728E-6,,0.0010326886907107,,,,,,,,,,,,,,,,,,,,,,,,,,,
,30552674,4370,237.6905,312.857,90.014,0.102153342753992,173,0.00102985670544663,,1.59999839156944E-7,,10.0815832272469,,0.00156628739964949,,,,,,,,,,0,2500,-92.7915668894558,,-81.7042102507943,,-6.60423109515255E-6,,0.0010298567779884,,,,,,,,,,,,,,,,,,,,,,,,,,,
,30552731.105,4370,234.83775,312.857,90.014,0.102153342753992,173,0.00102697771773023,,1.71453287282521E-7,,10.0533996406943,,0.00167840868045206,,,,,,,,,,0,2500,-91.0374241625725,,-80.2673322343373,,-5.99750237341922E-6,,0.00102697777772319,,,,,,,,,,,,,,,,,,,,,,,,,,,
,30552789.825,4370,231.89355,312.857,90.014,0.102153342753992,173,0.00102393894977581,,1.67142216510026E-7,,10.023651901916,,0.00163620625168811,,,,,,,,,,0,2500,-88.5179545486263,,-80.3467040305829,,-5.58715986539641E-6,,0.00102393900199481,,,,,,,,,,,,,,,,,,,,,,,,,,,
,30552848.125,4370,228.99615,312.857,90.014,0.102153342753992,173,0.0010208498724143,,1.63388590550165E-7,,9.99341166570785,,0.00159946080152849,,,,,,,,,,0,2500,-90.9592955783014,,-81.4101227066841,,-5.84467901812323E-6,,0.00102084992973083,,,,,,,,,,,,,,,,,,,,,,,,,,,
,30552904.82,4370,226.1446,312.857,90.014,0.102153342753992,173,0.00101782561977741,,1.64687961782984E-7,,9.96380602695608,,0.00161218066670071,,,,,,,,,,0,2500,-85.7652278663034,,-82.326902708544,,-6.6478913773773E-6,,0.00101782569415034,,,,,,,,,,,,,,,,,,,,,,,,,,,
,30552960.035,4370,223.38995,312.857,90.014,0.102153342753992,173,0.00101501297603592,,1.56222898192068E-7,,9.93627191534806,,0.00152931357829222,,,,,,,,,,0,2500,-85.2996117150645,,-81.3540870751789,,-5.18739956088341E-6,,0.00101501302144557,,,,,,,,,,,,,,,,,,,,,,,,,,,
,30553016.665,4370,220.5682,312.857,90.014,0.102153342753992,173,0.00101191588725434,,1.51073535907909E-7,,9.90595325756027,,0.00147890484457981,,,,,,,,,,0,2500,-92.3970402478274,,-82.2117103199802,,-5.55294644488495E-6,,0.00101191593944863,,,,,,,,,,,,,,,,,,,,,,,,,,,
,30553075.5,4370,217.6182,312.857,90.014,0.102153342753992,173,0.00100881552330077,,1.58261438520536E-7,,9.87560253968737,,0.0015492693578994,,,,,,,,,,0,2500,-84.9836796359712,,-82.542208836887,,-5.72331019923341E-6,,0.00100881557891722,,,,,,,,,,,,,,,,,,,,,,,,,,,
,30553131.05,4370,214.8464,312.857,90.014,0.102153342753992,173,0.00100580140134636,,1.57017552864821E-7,,9.8460960814817,,0.00153709253564994,,,,,,,,,,0,2500,-87.1896599695997,,-83.6032241531306,,-5.71952453166778E-6,,0.00100580145705571,,,,,,,,,,,,,,,,,,,,,,,,,,,
,30553190.89,4370,211.84905,312.857,90.014,0.102153342753992,173,0.00100254322060143,,1.57655941439717E-7,,9.81420043514248,,0.00154334186783936,,,,,,,,,,0,2500,-86.3794823614639,,-83.3292917281355,,-5.59041854508237E-6,,0.00100254327399709,,,,,,,,,,,,,,,,,,,,,,,,,,,
,30553250.305,4370,208.88775,312.857,90.014,0.102153342753992,173,0.000999379332317973,,1.55014084352005E-7,,9.78322785777647,,0.00151747988153802,,,,,,,,,,0,2500,-84.324810250929,,-81.1716389434651,,-5.46097633493958E-6,,0.000999379383430888,,,,,,,,,,,,,,,,,,,,,,,,,,,
,30553309.125,4370,205.9409,312.857,90.014,0.102153342753992,173,0.000996146624304244,,1.56428182241185E-7,,9.75158157838474,,0.00153132286811696,,,,,,,,,,0,2500,-86.8815021189976,,-80.1404306519994,,-5.31879663474569E-6,,0.000996146672947645,,,,,,,,,,,,,,,,,,,,,,,,,,,
,30553365.105,4370,203.1359,312.857,90.014,0.102153342753992,173,0.000993129760044482,,1.55660826323293E-7,,9.72204828220879,,0.00152381094008945,,,,,,,,,,0,2500,-90.9118898119821,,-81.0524726044851,,-5.37327572665284E-6,,0.000993129809840278,,,,,,,,,,,,,,,,,,,,,,,,,,,
,30553423.11,4370,200.23675,312.857,90.014,0.102153342753992,173,0.000989967872167174,,1.56458048400142E-7,,9.69109529351501,,0.00153161515026769,,,,,,,,,,0,2500,-89.3633007325718,,-80.0934521274203,,-4.95995966563289E-6,,0.000989967914732466,,,,,,,,,,,,,,,,,,,,,,,,,,,
,30553482.5,4370,197.27035,312.857,90.014,0.102153342753992,173,0.000986687767585559,,1.54112891136803E-7,,9.65898503617598,,0.00150865762703003,,,,,,,,,,0,2500,-87.5070717548042,,-80.5297418527295,,-5.63994811781766E-6,,0.000986687822804859,,,,,,,,,,,,,,,,,,,,,,,,,,,
,30553541.885,4370,194.2965,312.857,90.014,0.102153342753992,173,0.000983400784322599,,1.6274179795476E-7,,9.62680744280668,,0.00159312854089705,,,,,,,,,,0,2500,-90.6920752135492,,-79.7518428770771,,-5.85613194279598E-6,,0.000983400844055221,,,,,,,,,,,,,,,,,,,,,,,,,,,
,30553596.79,4370,191.563,312.857,90.014,0.102153342753992,173,0.000980348681028427,,1.54016101719E-7,,9.59692918527664,,0.00150771003365863,,,,,,,,,,0,2500,-88.0319651516945,,-80.6959558548501,,-5.46652170749512E-6,,0.000980348733239427,,,,,,,,,,,,,,,,,,,,,,,,,,,
,30553653.22,4370,188.7405,312.857,90.014,0.102153342753992,173,0.000977186787754419,,1.51991680119072E-7,,9.56597615175075,,0.00148789231847608,,,,,,,,,,0,2500,-85.3062585826567,,-82.7231899560032,,-5.25669048659432E-6,,0.00097718683619035,,,,,,,,,,,,,,,,,,,,,,,,,,,
,30553711.775,4370,185.79635,312.857,90.014,0.102153342753992,173,0.000973879502216485,,1.50079777136098E-7,,9.53359981752016,,0.00146917606528375,,,,,,,,,,0,2500,-91.0312731504644,,-82.3759720664881,,-5.59162017969785E-6,,0.000973879557207346,,,,,,,,,,,,,,,,,,,,,,,,,,,
,30553770.085,4370,182.89935,312.857,90.014,0.102153342753992,173,0.000970622560242942,,1.5800335348325E-7,,9.50171631859077,,0.00154674229120824,,,,,,,,,,0,2500,-85.6711656203029,,-81.6717881892227,,-5.39532234316876E-6,,0.000970622611612382,,,,,,,,,,,,,,,,,,,,,,,,,,,
,30553827.425,4370,180.01645,312.857,90.014,0.102153342753992,173,0.000967372246017494,,1.44680678927371E-7,,9.46989770341368,,0.00141632258293908,,,,,,,,,,0,2500,-89.1507796597827,,-82.2530727038374,,-5.31937939513082E-6,,0.000967372296118764,,,,,,,,,,,,,,,,,,,,,,,,,,,
,30553884.125,4370,177.1924,312.857,90.014,0.102153342753992,173,0.000964149746533048,,1.47709632023791E-7,,9.438351379833,,0.00144597385515118,,,,,,,,,,0,2500,-85.6628096468039,,-82.3346891970552,,-5.69410516706635E-6,,0.000964149804133633,,,,,,,,,,,,,,,,,,,,,,,,,,,
,30553940.81,4370,174.35745,312.857,90.014,0.102153342753992,173,0.000960958495551925,,1.45347865560681E-7,,9.40711096225144,,0.00142285377508612,,,,,,,,,,0,2500,-89.7759112364757,,-81.5179535003378,,-5.48707541314539E-6,,0.000960958549217731,,,,,,,,,,,,,,,,,,,,,,,,,,,
,30554000.47,4370,171.37415,312.857,90.014,0.102153342753992,173,0.000957536118357907,,1.53813683821964E-7,,9.37360796103116,,0.0015057281574733,,,,,,,,,,0,2500,-84.4043727036137,,-82.1744902338924,,-5.31120986447037E-6,,0.000957536168818481,,,,,,,,,,,,,,,,,,,,,,,,,,,
,30554056.25,4370,168.5751,312.857,90.014,0.102153342753992,173,0.000954360247597591,,1.58804815095111E-7,,9.3425181106642,,0.00155458778896332,,,,,,,,,,0,2500,-86.5179944000415,,-79.9647507591708,,-5.14646674484511E-6,,0.000954360295134006,,,,,,,,,,,,,,,,,,,,,,,,,,,
,30554114.58,4370,165.66755,312.857,90.014,0.102153342753992,173,0.000951016648048925,,1.45733800507898E-7,,9.30978629924948,,0.00142663167210923,,,,,,,,,,0,2500,-91.0296510187327,,-80.9657456407865,,-5.16310875601104E-6,,0.000951016696061484,,,,,,,,,,,,,,,,,,,,,,,,,,,
,30554172.765,4370,162.7572,312.857,90.014,0.102153342753992,173,0.00094765344835056,,1.49165696482506E-7,,9.27686261649046,,0.00146022746106758,,,,,,,,,,0,2500,-87.162668058136,,-81.0505219971658,,-5.65840579174897E-6,,0.000947653506221302,,,,,,,,,,,,,,,,,,,,,,,,,,,
,30554228.365,4370,159.98565,312.857,90.014,0.102153342753992,173,0.000944468478448009,,1.51867902233754E-7,,9.24568369726707,,0.00148668011487837,,,,,,,,,,0,2500,-88.9813562369329,,-80.2492439140853,,-5.50751177540191E-6,,0.000944468533458284,,,,,,,,,,,,,,,,,,,,,,,,,,,
,30554283.915,4370,157.2063,312.857,90.014,0.102153342753992,173,0.000941235965590205,,1.53694749215649E-7,,9.21403936346568,,0.00150456361557729,,,,,,,,,,0,2500,-95.0019213472828,,-79.4210615185699,,-5.46358486447137E-6,,0.000941236019912398,,,,,,,,,,,,,,,,,,,,,,,,,,,
,30554343.2,4370,154.23635,312.857,90.014,0.102153342753992,173,0.000937822964865134,,1.4900141705289E-7,,9.18062816552028,,0.00145861914675114,,,,,,,,,,0,2500,-91.087375470778,,-80.1147838979929,,-5.24482317058796E-6,,0.000937823015106479,,,,,,,,,,,,,,,,,,,,,,,,,,,
,30554399.1,4370,151.4456,312.857,90.014,0.102153342753992,173,0.000934594946288988,,1.45596810742499E-7,,9.14902783224571,,0.00142529043540181,,,,,,,,,,0,2500,-91.0848905050047,,-81.8341711352471,,-3.70456251831688E-6,,0.000934594971440892,,,,,,,,,,,,,,,,,,,,,,,,,,,
,30554458.13,4370,148.49045,312.857,90.014,0.102153342753992,173,0.000931117440019941,,1.45558022633606E-7,,9.11498516891364,,0.00142491064121049,,,,,,,,,,0,2500,-86.5381340189029,,-80.3084556704196,,-5.13142114940198E-6,,0.000931117488458508,,,,,,,,,,,,,,,,,,,,,,,,,,,
,30554517.465,4370,145.52325,312.857,90.014,0.102153342753992,173,0.000927673886745939,,1.51404678611428E-7,,9.081274887033,,0.00148214524462729,,,,,,,,,,0,2500,-87.3987748454362,,-79.8794793473899,,-4.90526959592947E-6,,0.000927673931173334,,,,,,,,,,,,,,,,,,,,,,,,,,,
,30554576.85,4370,142.55025,312.857,90.014,0.102153342753992,173,0.000924209854470168,,1.34423354624748E-7,,9.04736413060956,,0.00131590997868982,,,,,,,,,,0,2500,-91.5898113970784,,-80.6387399779546,,-5.24327874337543E-6,,0.000924209905421521,,,,,,,,,,,,,,,,,,,,,,,,,,,
,30554636.35,4370,139.5807,312.857,90.014,0.102153342753992,173,0.000920729974789801,,1.4356028877493E-7,,9.01329824018301,,0.00140535407996709,,,,,,,,,,0,2500,-87.2443905238125,,-81.2318776821826,,-5.2316330375061E-6,,0.000920730025706787,,,,,,,,,,,,,,,,,,,,,,,,,,,
,30554694.1,4370,136.6953,312.857,90.014,0.102153342753992,173,0.000917344701751764,,1.48739111859516E-7,,8.98015849313222,,0.00145605106239955,,,,,,,,,,0,2500,-99.3435001095978,,-80.7142942410924,,-5.1122465690471E-6,,0.000917344750550823,,,,,,,,,,,,,,,,,,,,,,,,,,,
,30554752.515,4370,133.7746,312.857,90.014,0.102153342753992,173,0.000913866308374155,,1.40465058374075E-7,,8.94610715742494,,0.00137505386174539,,,,,,,,,,0,2500,-90.4650911956735,,-81.2999795648464,,-5.1229670121851E-6,,0.000913866357564614,,,,,,,,,,,,,,,,,,,,,,,,,,,
,30554811.365,4370,130.8336,312.857,90.014,0.102153342753992,173,0.000910364331241317,,1.42995196346404E-7,,8.91182495365158,,0.00139982208409429,,,,,,,,,,0,2500,-91.3784117771089,,-81.6104626214901,,-4.91439230145174E-6,,0.000910364376681998,,,,,,,,,,,,,,,,,,,,,,,,,,,
,30554870.44,4370,127.8856,312.857,90.014,0.102153342753992,173,0.000906879902419123,,1.3780388281072E-7,,8.87771453946306,,0.00134900273573278,,,,,,,,,,0,2500,-89.6120131651531,,-81.8387190259355,,-5.03835721176276E-6,,0.0009068799503647,,,,,,,,,,,,,,,,,,,,,,,,,,,
,30554930.09,4370,124.89905,312.857,90.014,0.102153342753992,173,0.000903328688702657,,1.40960433318416E-7,,8.84295034472508,,0.00137990309422222,,,,,,,,,,0,2500,-96.1467527220253,,-80.341231621148,,-4.77928092695527E-6,,0.00090332873201381,,,,,,,,,,,,,,,,,,,,,,,,,,,
,30554989.28,4370,121.931,312.857,90.014,0.102153342753992,173,0.000899804930398453,,1.4455953535924E-7,,8.80845492402772,,0.00141513569993856,,,,,,,,,,0,2500,-87.3659771046484,,-80.7969470315961,,-5.13612649784073E-6,,0.000899804980614611,,,,,,,,,,,,,,,,,,,,,,,,,,,
,30555048.35,4370,118.9844,312.857,90.014,0.102153342753992,173,0.000896255584791202,,1.39650533880369E-7,,8.77370902189758,,0.00136707998734243,,,,,,,,,,0,2500,-89.9017270492367,,-80.1294267180144,,-5.37591714114878E-6,,0.000896255640023572,,,,,,,,,,,,,,,,,,,,,,,,,,,
,30555109.805,4370,115.9155,312.857,90.014,0.102153342753992,173,0.000892569617697979,,1.45167779188107E-7,,8.73762568240897,,0.00142108988663765,,,,,,,,,,0,2500,-89.0395036242724,,-80.1505532773743,,-4.6458615376753E-6,,0.000892569659118051,,,,,,,,,,,,,,,,,,,,,,,,,,,
,30555168.35,4370,112.99165,312.857,90.014,0.102153342753992,173,0.000889039448396506,,1.41931790232027E-7,,8.70306750952144,,0.00138941178986824,,,,,,,,,,0,2500,-85.1845756325881,,-79.8910225038412,,-4.76880623565911E-6,,0.000889039492211096,,,,,,,,,,,,,,,,,,,,,,,,,,,
,30555227.315,4370,110.0337,312.857,90.014,0.102153342753992,173,0.000885512588357461,,1.37724979372211E-7,,8.66854173472821,,0.00134823003960293,,,,,,,,,,0,2500,-89.6389420645038,,-81.4642959112815,,-4.77784763942661E-6,,0.000885512632513517,,,,,,,,,,,,,,,,,,,,,,,,,,,
,30555286.75,4370,107.06065,312.857,90.014,0.102153342753992,173,0.000881892407368443,,1.47311177410137E-7,,8.63310240821013,,0.00144207207845272,,,,,,,,,,0,2500,-87.6554025266637,,-80.8396293523416,,-4.76485132412003E-6,,0.000881892451464882,,,,,,,,,,,,,,,,,,,,,,,,,,,
,30555343.405,4370,104.2332,312.857,90.014,0.102153342753992,173,0.00087887290477383,,1.73977462702423E-7,,8.61476921863717,,0.00170533836517328,,,,,,,,,,0,5000,-73.8244990207013,,-81.9480798055464,,1.53227811082178E-6,,0.000878872909349656,,,,,,,,,,,,,,,,,,,,,,,,,,,
,30555401.265,4370,101.3362,312.857,90.014,0.102153342753992,173,0.000875455196545533,,1.71253676347311E-7,,8.58122478281272,,0.00167863106064416,,,,,,,,,,0,5000,-73.746622007403,,-82.6263374071182,,1.40634141978351E-6,,0.000875455200415151,,,,,,,,,,,,,,,,,,,,,,,,,,,
,30555453.705,4370,98.70615,312.857,90.014,0.102153342753992,173,0.000871985152307555,,1.72556378463144E-7,,8.54716702536537,,0.00169139139075952,,,,,,,,,,0,5000,-73.7495146115044,,-82.061231943307,,1.60264141880455E-6,,0.000871985157352821,,,,,,,,,,,,,,,,,,,,,,,,,,,
,30555513.255,4370,95.72885,312.857,90.014,0.102153342753992,173,0.000868519050168214,,1.72223491664049E-7,,8.51314831148713,,0.00168811970127467,,,,,,,,,,0,5000,-73.7879474711191,,-81.8919886472865,,1.52444276397493E-6,,0.000868519054751356,,,,,,,,,,,,,,,,,,,,,,,,,,,
,30555570.575,4370,92.85875,312.857,90.014,0.102153342753992,173,0.000864864160281186,,1.69979548496189E-7,,8.4772770864264,,0.00166611566194901,,,,,,,,,,0,5000,-73.9047718597972,,-82.328957006558,,1.62608575215527E-6,,0.000864864165517907,,,,,,,,,,,,,,,,,,,,,,,,,,,
,30555629.9,4370,89.9078,312.857,90.014,0.102153342753992,173,0.000861221456573225,,1.69019043781517E-7,,8.44152585361804,,0.00165669190953143,,,,,,,,,,0,5000,-73.8612226579487,,-82.3377106792914,,1.5981680381288E-6,,0.000861221461653071,,,,,,,,,,,,,,,,,,,,,,,,,,,
,30555694.74,4370,86.6567,312.857,90.014,0.102153342753992,173,0.000857578137763397,,1.68244522715685E-7,,8.40576897331753,,0.00164909122774507,,,,,,,,,,0,5000,-73.9135009693535,,-82.0969720992627,,1.21752394392714E-6,,0.000857578140724147,,,,,,,,,,,,,,,,,,,,,,,,,,,
,30555754.68,4370,83.6646,312.857,90.014,0.102153342753992,173,0.000853539147950871,,1.6557628701556E-7,,8.36612928641276,,0.00162292804182443,,,,,,,,,,0,5000,-74.0189635178264,,-82.3415307800376,,1.3495870207548E-6,,0.000853539151605967,,,,,,,,,,,,,,,,,,,,,,,,,,,
,30555811.27,4370,80.8229,312.857,90.014,0.102153342753992,173,0.000849605804958743,,1.66225639543274E-7,,8.32752690462444,,0.00162928321446437,,,,,,,,,,0,5000,-73.9804046350347,,-82.0182920434017,,1.61847765784715E-6,,0.000849605810239745,,,,,,,,,,,,,,,,,,,,,,,,,,,
,30555868.055,4370,77.9545,312.857,90.014,0.102153342753992,173,0.000845747063090847,,1.66087194597647E-7,,8.28965710983018,,0.00162791684023614,,,,,,,,,,0,5000,-74.0091155079523,,-82.0837759259633,,1.45318091595587E-6,,0.000845747067367651,,,,,,,,,,,,,,,,,,,,,,,,,,,
,30555923.435,4370,75.18265,312.857,90.014,0.102153342753992,173,0.000841738934584581,,1.63230042184301E-7,,8.25032169313799,,0.00159990265045275,,,,,,,,,,0,5000,-74.032046491187,,-82.1259725308637,,1.30845387647908E-6,,0.000841738938068434,,,,,,,,,,,,,,,,,,,,,,,,,,,
,30555977.995,4370,72.45235,312.857,90.014,0.102153342753992,173,0.000836977813254488,,1.63549558824837E-7,,8.20359708426767,,0.0016030229925034,,,,,,,,,,0,5000,-74.1147647753536,,-82.2287962054133,,1.24029148666136E-6,,0.000836977816402628,,,,,,,,,,,,,,,,,,,,,,,,,,,
,30556034.04,4370,69.6383,312.857,90.014,0.102153342753992,173,0.00083146104010976,,1.60956231484034E-7,,8.14945750458501,,0.00157759161523009,,,,,,,,,,0,5000,-74.1858807541197,,-82.1720920940669,,1.00914504004518E-6,,0.000831461042207665,,,,,,,,,,,,,,,,,,,,,,,,,,,
,30556089.695,4370,66.87855,312.857,90.014,0.102153342753992,173,0.000826213547706988,,1.57974118540126E-7,,8.09796137543401,,0.00154835068098329,,,,,,,,,,0,5000,-74.3074525650976,,-82.4264675529194,,5.65481643779116E-7,,0.000826213548369914,,,,,,,,,,,,,,,,,,,,,,,,,,,
,30556145.29,4370,64.1029,312.857,90.014,0.102153342753992,173,0.000821569156509416,,1.56240020309245E-7,,8.05238443799826,,0.00153134364633798,,,,,,,,,,0,5000,-74.3519032292286,,-82.5499440609566,,2.97596327795886E-7,,0.000821569156694058,,,,,,,,,,,,,,,,,,,,,,,,,,,
,30556198.995,4370,61.40025,312.857,90.014,0.102153342753992,173,0.000817701957807637,,1.56287308175566E-7,,8.01443482876945,,0.00153179827143566,,,,,,,,,,0,5000,-74.4244740215461,,-82.2076212269105,,3.60752947131295E-7,,0.000817701958080249,,,,,,,,,,,,,,,,,,,,,,,,,,,
,30556254.825,4370,58.60575,312.857,90.014,0.102153342753992,173,0.000813905557162953,,1.53845818761254E-7,,7.97718040202568,,0.00150786026592855,,,,,,,,,,0,5000,-74.462679571216,,-82.2949073644267,,3.93525852826091E-7,,0.000813905557488859,,,,,,,,,,,,,,,,,,,,,,,,,,,
,30556309.625,4370,55.86645,312.857,90.014,0.102153342753992,173,0.00081068363322534,,1.5557943380808E-7,,7.94556369939807,,0.00152484428052093,,,,,,,,,,0,5000,-74.3439085045513,,-82.1061039517375,,2.50889099662997E-7,,0.000810683633358334,,,,,,,,,,,,,,,,,,,,,,,,,,,
,30556364.625,4370,53.1498,312.857,90.014,0.102153342753992,173,0.000807600474465161,,1.54037277837935E-7,,7.91530898297203,,0.00150972255158699,,,,,,,,,,0,5000,-74.3572899667258,,-81.9026642250205,,5.79759922532193E-8,,0.00080760047447229,,,,,,,,,,,,,,,,,,,,,,,,,,,
,30556419.585,4370,50.39365,312.857,90.014,0.102153342753992,173,0.00080359370741389,,1.50434093657856E-7,,7.87599141102345,,0.00147439883858803,,,,,,,,,,0,5000,-74.7364054439414,,-82.0295117949849,,4.60583813381399E-7,,0.00080359370786606,,,,,,,,,,,,,,,,,,,,,,,,,,,
,30556474.495,4370,47.65295,312.857,90.014,0.102153342753992,173,0.000799830748122488,,1.49474922419424E-7,,7.83906670271685,,0.00146498979841868,,,,,,,,,,0,5000,-74.674219571636,,-82.2117503321849,,4.94855436094594E-7,,0.000799830748646907,,,,,,,,,,,,,,,,,,,,,,,,,,,
,30556528.805,4370,44.9259,312.857,90.014,0.102153342753992,173,0.000796031690974703,,1.47958660313665E-7,,7.80178819908717,,0.00145012082048979,,,,,,,,,,0,5000,-74.7856245881402,,-82.2412600463494,,6.03325039016623E-7,,0.000796031691757939,,,,,,,,,,,,,,,,,,,,,,,,,,,
,30556584.855,4370,42.1208,312.857,90.014,0.102153342753992,173,0.000791917692202217,,1.47734387361074E-7,,7.76141978701665,,0.00144791385174162,,,,,,,,,,0,5000,-74.7008676085966,,-82.9229174779937,,6.46310221281077E-7,,0.000791917693105705,,,,,,,,,,,,,,,,,,,,,,,,,,,
,30556639.53,4370,39.39805,312.857,90.014,0.102153342753992,173,0.000787765734190904,,1.44622928124737E-7,,7.72067940507433,,0.00141741029425797,,,,,,,,,,0,5000,-74.7587516312346,,-83.8906886815709,,7.13360213097653E-7,,0.000787765735297378,,,,,,,,,,,,,,,,,,,,,,,,,,,
,30556694.405,4370,36.6626,312.857,90.014,0.102153342753992,173,0.000784124064125919,,1.44502501585014E-7,,7.68494655304599,,0.00141622231834896,,,,,,,,,,0,5000,-74.8430405086648,,-83.2065101814514,,6.94620313916845E-7,,0.000784124065179894,,,,,,,,,,,,,,,,,,,,,,,,,,,
,30556750.265,4370,33.8741,312.857,90.014,0.102153342753992,173,0.000780670078397884,,1.45126949987638E-7,,7.65105565961192,,0.00142233499246006,,,,,,,,,,0,5000,-74.7831961854869,,-82.511210597995,,7.99203139728845E-7,,0.0007806700797993,,,,,,,,,,,,,,,,,,,,,,,,,,,
,30556805.275,4370,31.1378,312.857,90.014,0.102153342753992,173,0.00077777772358336,,1.44903159572496E-7,,7.62267582055793,,0.00142013556780595,,,,,,,,,,0,5000,-74.8114426523375,,-82.288198076735,,7.3462798921714E-7,,0.000777777724771862,,,,,,,,,,,,,,,,,,,,,,,,,,,
,30556860.05,4370,28.3893,312.857,90.014,0.102153342753992,173,0.000774785651590783,,1.4395567633151E-7,,7.59331781289145,,0.00141084336911942,,,,,,,,,,0,5000,-74.8736690427619,,-82.5043919935671,,8.62297478094323E-7,,0.000774785653234599,,,,,,,,,,,,,,,,,,,,,,,,,,,
,30556914.735,4370,25.6778,312.857,90.014,0.102153342753992,173,0.000772154197551444,,1.42531700175363E-7,,7.56749838114756,,0.00139688213941804,,,,,,,,,,0,5000,-74.9428321657309,,-82.247662428591,,9.67908895233037E-7,,0.000772154199629635,,,,,,,,,,,,,,,,,,,,,,,,,,,
,30556969.37,4370,22.9515,312.857,90.014,0.102153342753992,173,0.000769939715028772,,1.42831572313307E-7,,7.54577036864998,,0.00139981640393584,,,,,,,,,,0,5000,-74.9079660350197,,-82.3980343496379,,9.70067826446712E-7,,0.000769939717122248,,,,,,,,,,,,,,,,,,,,,,,,,,,
,30557024.065,4370,20.20895,312.857,90.014,0.102153342753992,173,0.000768082564026423,,1.41055657233239E-7,,7.52754852484194,,0.00138240776562504,,,,,,,,,,0,5000,-74.9436638570372,,-82.6739577883927,,1.04637005600702E-6,,0.000768082566468072,,,,,,,,,,,,,,,,,,,,,,,,,,,
,30557081.11,4370,17.3789,312.857,90.014,0.102153342753992,173,0.000766781904240041,,1.39418907084399E-7,,7.5147868767074,,0.00136636423479638,,,,,,,,,,0,5000,-75.0026605039832,,-82.571236428769,,1.06779202636818E-6,,0.000766781906787,,,,,,,,,,,,,,,,,,,,,,,,,,,
,30557135.9,4370,14.6702,312.857,90.014,0.102153342753992,173,0.000765735837747005,,1.40738079043253E-7,,7.50452325063839,,0.00137929052034265,,,,,,,,,,0,5000,-74.9863343075396,,-82.4320140629663,,1.18592126744783E-6,,0.000765735840892965,,,,,,,,,,,,,,,,,,,,,,,,,,,
,30557191.11,4370,11.9197,312.857,90.014,0.102153342753992,173,0.000765411746716313,,1.42342416754942E-7,,7.50134339317985,,0.00139501300823806,,,,,,,,,,0,5000,-74.9106716083198,,-82.0871175948982,,1.15526583727158E-6,,0.000765411749702996,,,,,,,,,,,,,,,,,,,,,,,,,,,
,30557245.71,4375,9.5823,312.857,90.014,0.102153342753992,173,0.00076535463842606,,1.41873881019219E-7,,7.50078306875846,,0.00139042105094003,,,,,,,,,,0,5000,-74.9659127172701,,-82.0890985702866,,1.12607301961542E-6,,0.000765354641263919,,,,,,,,,,,,,,,,,,,,,,,,,,,
,30557322.115,4375,9.477,312.857,90.014,0.102153342753992,173,0.000765761802599979,,1.43884413085122E-7,,7.50477800799594,,0.00141012593356677,,,,,,,,,,0,5000,-74.6410912957903,,-81.8797583706912,,8.41504697841179E-7,,0.000765761804183923,,,,,,,,,,,,,,,,,,,,,,,,,,,
,30557376.75,4375,9.3116,312.857,90.014,0.102153342753992,173,0.000765091520242952,,1.39588160425478E-7,,7.49820145630785,,0.00136801953058093,,,,,,,,,,0,5000,-75.2360786989539,,-82.2375490319037,,1.32924997107316E-6,,0.000765091524198625,,,,,,,,,,,,,,,,,,,,,,,,,,,
,30557426.685,4375,9.07575,312.857,90.014,0.102153342753992,173,0.000765049601937176,,1.40844412596504E-7,,7.4977901705142,,0.00138033121480326,,,,,,,,,,0,5000,-74.9234739313412,,-81.9160618733221,,1.38302980058459E-6,,0.000765049606219642,,,,,,,,,,,,,,,,,,,,,,,,,,,
,30557495.23,4375,8.8071,312.857,90.014,0.102153342753992,173,0.000765030258250972,,1.40723130388513E-7,,7.49760037795323,,0.00137914256046338,,,,,,,,,,0,5000,-74.9512189977291,,-81.9012751485643,,1.43871528672462E-6,,0.000765030262885351,,,,,,,,,,,,,,,,,,,,,,,,,,,
,30557552.37,4375,8.5848,312.857,90.014,0.102153342753992,173,0.000764988838374194,,1.41348947978985E-7,,7.49719398262135,,0.0013852757357845,,,,,,,,,,0,5000,-75.0335231293496,,-81.7369567310841,,1.42429255580288E-6,,0.000764988842916367,,,,,,,,,,,,,,,,,,,,,,,,,,,
,30557609.155,4375,8.36285,312.857,90.014,0.102153342753992,173,0.00076505703322654,,1.40730141762512E-7,,7.49786308337481,,0.00137921133008632,,,,,,,,,,0,5000,-75.0456733214992,,-81.7889082969544,,1.42280402382152E-6,,0.000765057037758821,,,,,,,,,,,,,,,,,,,,,,,,,,,
,30557666.245,4375,8.17455,312.857,90.014,0.102153342753992,173,0.000765021029676066,,1.40801015347995E-7,,7.49750983084798,,0.00137990584454904,,,,,,,,,,0,5000,-75.0145869287837,,-81.7086904531632,,1.47393784647153E-6,,0.000765021034540198,,,,,,,,,,,,,,,,,,,,,,,,,,,
,30557734.615,4375,7.93555,312.857,90.014,0.102153342753992,173,0.000765035480916857,,1.41221334717046E-7,,7.49765162067408,,0.00138402517141223,,,,,,,,,,0,5000,-75.0114344813887,,-81.4816638073815,,1.44861480159667E-6,,0.0007650354856152,,,,,,,,,,,,,,,,,,,,,,,,,,,
,30557788.035,4375,7.7583,312.857,90.014,0.102153342753992,173,0.000765188703887298,,1.40176007100115E-7,,7.49915498388644,,0.00137378086124223,,,,,,,,,,0,5000,-75.1618344443735,,-81.8195346281612,,1.35270892557262E-6,,0.000765188707983304,,,,,,,,,,,,,,,,,,,,,,,,,,,
,30557846.895,4375,7.58105,312.857,90.014,0.102153342753992,173,0.000765098974167053,,1.41657744166335E-7,,7.49827459126068,,0.00138830228901952,,,,,,,,,,0,5000,-74.9661319890763,,-81.5087515396198,,1.45448336183963E-6,,0.000765098978903147,,,,,,,,,,,,,,,,,,,,,,,,,,,
,30557921.145,4375,7.3714,312.857,90.014,0.102153342753992,173,0.000765157051071238,,1.41444524076942E-7,,7.49884441891213,,0.00138621276714666,,,,,,,,,,0,5000,-75.038006879385,,-81.6288701787681,,1.49038527139386E-6,,0.000765157056043648,,,,,,,,,,,,,,,,,,,,,,,,,,,
,30557983.83,4375,7.19675,312.857,90.014,0.102153342753992,173,0.000765191757361407,,1.41676572345499E-7,,7.49918494337427,,0.00138848700527217,,,,,,,,,,0,5000,-74.9114434973343,,-81.3758909512421,,1.44886981885246E-6,,0.000765191762060444,,,,,,,,,,,,,,,,,,,,,,,,,,,
,30558040.81,4375,7.056,312.857,90.014,0.102153342753992,173,0.000765048069086157,,1.42843734339182E-7,,7.49777513078882,,0.00139992535736881,,,,,,,,,,0,5000,-74.8408696390759,,-81.3638860604315,,1.53630006741383E-6,,0.000765048074370413,,,,,,,,,,,,,,,,,,,,,,,,,,,
,30558308.445,4374,5.49465,312.857,90.014,0.102153342753992,173,0.00076534683828566,,1.42060437282226E-7,,7.50070653680989,,0.00139224935617473,,,,,,,,,,0,5000,-75.0856639637851,,-80.6625774306971,,1.57112247189545E-6,,0.000765346843810023,,,,,,,,,,,,,,,,,,,,,,,,,,,
,30558360.815,4373,4.99755,312.857,90.014,0.102153342753992,173,0.000765431540005585,,1.44196935193816E-7,,7.501537597289,,0.00141318807160465,,,,,,,,,,0,5000,-74.9899381334929,,-79.7794701059222,,1.6685624476035E-6,,0.000765431546235742,,,,,,,,,,,,,,,,,,,,,,,,,,,
,30558438.48,4374,7.069,312.857,90.014,0.102153342753992,173,0.000765115469111068,,1.42094150694809E-7,,7.49843643312807,,0.00139257928147056,,,,,,,,,,0,5000,-74.9569487217389,,-81.3053720950257,,1.42016024376092E-6,,0.000765115473626176,,,,,,,,,,,,,,,,,,,,,,,,,,,
,30558490.91,4374,17.09765,312.857,90.014,0.102153342753992,173,0.000766250108665316,,1.40734169802076E-7,,7.50956908686759,,0.00137925326572003,,,,,,,,,,0,5000,-75.0505716183927,,-82.0052776570137,,1.42681612462786E-6,,0.000766250113216096,,,,,,,,,,,,,,,,,,,,,,,,,,,
,30558546.585,4370,28.18215,312.857,90.014,0.102153342753992,173,0.000773943667817152,,1.41541711615223E-7,,7.58505637249097,,0.00138718346435011,,,,,,,,,,0,5000,-75.025980691158,,-82.5534274472989,,1.04083570282768E-6,,0.000773943670214745,,,,,,,,,,,,,,,,,,,,,,,,,,,
,30558602.485,4370,39.40025,312.857,90.014,0.102153342753992,173,0.000786626204152336,,1.44507782008644E-7,,7.7094980487755,,0.00141627936537217,,,,,,,,,,0,5000,-74.8511994900951,,-83.5182925305346,,8.49696545659124E-7,,0.000786626205724435,,,,,,,,,,,,,,,,,,,,,,,,,,,
,30558659.855,4370,50.907,312.857,90.014,0.102153342753992,173,0.000802439042319926,,1.51530235933116E-7,,7.86466100995051,,0.00148513952410285,,,,,,,,,,0,5000,-74.6066631913804,,-81.8893687689438,,5.44307098444022E-7,,0.000802439042952332,,,,,,,,,,,,,,,,,,,,,,,,,,,
,30558714.71,4370,61.90785,312.857,90.014,0.102153342753992,173,0.000815660182714238,,1.54175514963451E-7,,7.99439865049372,,0.00151109561784802,,,,,,,,,,0,5000,-74.5887897888908,,-82.2182466189552,,5.6427540334156E-7,,0.000815660183382879,,,,,,,,,,,,,,,,,,,,,,,,,,,
,30558768.5,4370,72.6594,312.857,90.014,0.102153342753992,173,0.000833282371579816,,1.60715122224425E-7,,8.16733128206811,,0.00157523270180243,,,,,,,,,,0,5000,-74.1068867237657,,-81.816564328045,,1.0685241464336E-6,,0.000833282373926729,,,,,,,,,,,,,,,,,,,,,,,,,,,
,30558822.85,4370,83.5285,312.857,90.014,0.102153342753992,173,0.000849643393582668,,1.65199035506672E-7,,8.32789580252261,,0.00161922090614804,,,,,,,,,,0,5000,-74.0346620202963,,-82.4174762295648,,1.63415384385608E-6,,0.000849643398966229,,,,,,,,,,,,,,,,,,,,,,,,,,,
,30558885.15,4370,96.0073,312.857,90.014,0.102153342753992,173,0.00086524329866406,,1.7098869886994E-7,,8.48099815384318,,0.00167600816336563,,,,,,,,,,0,5000,-73.8177024461126,,-82.2450967558538,,1.51205303620568E-6,,0.000865243303190077,,,,,,,,,,,,,,,,,,,,,,,,,,,
,30558941.68,4370,107.30965,312.857,90.014,0.102153342753992,173,0.000878931581783119,,1.7420936397245E-7,,8.6153451301161,,0.00170761162706021,,,,,,,,,,0,5000,-73.8094958016528,,-82.2788556179004,,1.45834226300457E-6,,0.000878931585927734,,,,,,,,,,,,,,,,,,,,,,,,,,,
,30558999.93,4370,118.9189,312.857,90.014,0.102153342753992,173,0.000892203071373917,,1.45236338461837E-7,,8.73403742061143,,0.00142176101973035,,,,,,,,,,0,2500,-96.4794619888987,,-81.1355576261981,,-4.93203892674592E-6,,0.000892203118073145,,,,,,,,,,,,,,,,,,,,,,,,,,,
,30559055.61,4370,130.06955,312.857,90.014,0.102153342753992,173,0.000905248674951273,,1.42015429785664E-7,,8.86174582707834,,0.00139023078086929,,,,,,,,,,0,2500,-87.9369995667469,,-79.8939191658981,,-5.15950719108115E-6,,0.000905248725320927,,,,,,,,,,,,,,,,,,,,,,,,,,,
,30559115.195,4370,142.00285,312.857,90.014,0.102153342753992,173,0.000919127624452418,,1.55669638359342E-7,,8.99761221272584,,0.00152389606090129,,,,,,,,,,0,2500,-86.2975530574019,,-79.2735672364146,,-5.06601175921191E-6,,0.000919127672279842,,,,,,,,,,,,,,,,,,,,,,,,,,,
,30559174.585,4370,153.8952,312.857,90.014,0.102153342753992,173,0.000932809639902703,,1.32925893940609E-7,,9.13155077236704,,0.00130125100567704,,,,,,,,,,0,2500,-91.2661282210568,,-81.3717939021855,,-5.31317611271014E-6,,0.00093280969173922,,,,,,,,,,,,,,,,,,,,,,,,,,,
,30559233.965,4370,165.7763,312.857,90.014,0.102153342753992,173,0.000946408491819243,,1.51577042385276E-7,,9.26467524861087,,0.00148383283266913,,,,,,,,,,0,2500,-86.8055705450457,,-80.874326860817,,-5.44315924694156E-6,,0.00094640854544135,,,,,,,,,,,,,,,,,,,,,,,,,,,
,30559293.38,4370,177.64365,312.857,90.014,0.102153342753992,173,0.000959815343158474,,1.47923053613683E-7,,9.39592019199322,,0.00144806304484372,,,,,,,,,,0,2500,-88.534193360353,,-81.4847861066231,,-5.49427460501909E-6,,0.000959815397029278,,,,,,,,,,,,,,,,,,,,,,,,,,,
,30559352.46,4370,189.40045,312.857,90.014,0.102153342753992,173,0.000973028728624423,,1.54199208031372E-7,,9.52527125662108,,0.00150950240350438,,,,,,,,,,0,2500,-87.9263608184233,,-80.9789735944032,,-5.47037758056513E-6,,0.000973028781302434,,,,,,,,,,,,,,,,,,,,,,,,,,,
,30559411.76,4374,200.5652,312.857,90.014,0.102153342753992,173,0.000985538644373695,,1.60162177091168E-7,,9.64773580936721,,0.0015678758945714,,,,,,,,,,0,2500,-90.3103826859904,,-80.1613344278036,,-5.66813719000085E-6,,0.000985538700211389,,,,,,,,,,,,,,,,,,,,,,,,,,,
,30559467.705,4374,210.7014,312.857,90.014,0.102153342753992,173,0.00099671705489469,,1.46964761593261E-7,,9.75716575279095,,0.00143868257826788,,,,,,,,,,0,2500,-90.0307384541948,,-82.3070364006856,,-5.55692664338753E-6,,0.000996717107960874,,,,,,,,,,,,,,,,,,,,,,,,,,,
,30559523.485,4374,220.37165,312.857,90.014,0.102153342753992,173,0.00100715581347504,,1.51820717197173E-7,,9.85935496907881,,0.0014862191567352,,,,,,,,,,0,2500,-93.9689890474872,,-81.6726271141376,,-5.58011287136562E-6,,0.00100715586643037,,,,,,,,,,,,,,,,,,,,,,,,,,,
,30559577.095,4374,229.3338,312.857,90.014,0.102153342753992,173,0.00101661465349387,,1.56771117005698E-7,,9.95195138612381,,0.00153468027277848,,,,,,,,,,0,2500,-86.895210836989,,-80.8111611110788,,-5.61263093046836E-6,,0.00101661470656972,,,,,,,,,,,,,,,,,,,,,,,,,,,
,30559632.6,4374,238.41695,312.857,90.014,0.102153342753992,173,0.00102575919846459,,1.5459363121013E-7,,10.0414710584461,,0.00151336434673079,,,,,,,,,,0,2500,-89.0928174918398,,-81.8039624275272,,-5.42338404005378E-6,,0.00102575924757977,,,,,,,,,,,,,,,,,,,,,,,,,,,
,30559685.465,4374,246.7549,312.857,90.014,0.102153342753992,173,0.00103389082439679,,1.54783646478861E-7,,10.1210748679694,,0.00151522459793892,,,,,,,,,,0,2500,-90.9779588834219,,-83.0538738133952,,-5.1135745987449E-6,,0.00103389086771743,,,,,,,,,,,,,,,,,,,,,,,,,,,
,30559739.35,4374,255.08835,312.857,90.014,0.102153342753992,173,0.00104245668758304,,1.5619610805609E-7,,10.2049296175929,,0.00152905174532628,,,,,,,,,,0,2500,-88.0951501951144,,-82.7746174626318,,-5.34136135106957E-6,,0.00104245673446074,,,,,,,,,,,,,,,,,,,,,,,,,,,
,30559791.51,4374,262.9173,312.857,90.014,0.102153342753992,173,0.00105090623666503,,1.58528064400515E-7,,10.2876457349494,,0.00155188011721995,,,,,,,,,,0,2500,-88.2476758155496,,-81.0254940953849,,-5.32999428572277E-6,,0.00105090628296812,,,,,,,,,,,,,,,,,,,,,,,,,,,
,30559844.29,4374,270.70725,312.857,90.014,0.102153342753992,173,0.001058396302378,,1.64357415385553E-7,,10.3609690860938,,0.00160894556074829,,,,,,,,,,0,2500,-89.00043349237,,-81.5656063343507,,-5.09739225918965E-6,,0.00105839634442822,,,,,,,,,,,,,,,,,,,,,,,,,,,
,30559896.4,4374,278.2285,312.857,90.014,0.102153342753992,173,0.00106558843101534,,1.63089231263078E-7,,10.4313758184282,,0.00159653103493994,,,,,,,,,,0,2500,-93.2385528441182,,-81.7579321510516,,-4.94109199779707E-6,,0.00106558847025966,,,,,,,,,,,,,,,,,,,,,,,,,,,
,30559950.445,4374,285.9098,312.857,90.014,0.102153342753992,173,0.0010727547751282,,1.62766573433337E-7,,10.5015301455334,,0.00159337255209652,,,,,,,,,,0,2500,-91.6046519713497,,-81.9704531547339,,-5.00678139808983E-6,,0.00107275481515375,,,,,,,,,,,,,,,,,,,,,,,,,,,
,30560004.03,4374,293.38815,312.857,90.014,0.102153342753992,173,0.00107986053798135,,1.65225012238502E-7,,10.5710914274926,,0.00161743909068658,,,,,,,,,,0,2500,-91.9229940176055,,-81.4203900855003,,-4.98915784404114E-6,,0.00107986057746409,,,,,,,,,,,,,,,,,,,,,,,,,,,
,30560056.8,4370,300.6514,312.857,90.014,0.102153342753992,173,0.00108676566514667,,1.55703402541211E-7,,10.6386886124352,,0.00152422920107583,,,,,,,,,,0,2500,-88.1012374134229,,-82.9030088805136,,-4.74064042986108E-6,,0.00108676570056748,,,,,,,,,,,,,,,,,,,,,,,,,,,
,30560097.895,4373,299.663,312.857,90.014,0.102153342753992,173,,1.78093815603742E-5,,8.01819801857525E-9,,0.174344319681025,,7.84937799766998E-5,,,,,,,,,0,25000,,-74.4771392108867,,-81.7674213909509,,4.6049842374144E-7,,1.78094019555589E-5,,,,,,,,,,,,,,,,,,,,,,,,,,