File: Data/Gd (20 nm)/20171121-YBCO-Gd20nm.dc.dat
[Header]
TITLE,MPMS DC Measurement
BYAPP,MPMS Measurement,2.1,Summary
FILEOPENTIME, 1511291515.824000 11/21/2017, 11:11:55 AM

INFO, APPNAME, MPMS MultiVu Application, Revision 1.61,  Build 082

INFO, NAME, YBCO Gd20nm
INFO, WEIGHT, 21.900
INFO, AREA, 1.000
INFO, LENGTH, 1.000
INFO, SHAPE,
INFO, COMMENT, H in plane
INFO, SEQUENCE FILE: 20171121-YBCO-Gd20nm.seq


INFO, BACKGROUND DATA FILE:, None


STARTUPAXIS,X,4,LINEAR,AUTO,0.000000,0.000000
STARTUPAXIS,Y1,5,LINEAR,AUTO,0.000000,0.000000


STARTUPGROUP,Longitudinal
FIELDGROUP,Longitudinal,1,2,3,4,5,6,7,8,9,15,16,17,18,27,28
FIELDGROUP,Transverse,1,2,3,4,10,11,12,13,14,19,20,21,22,27,28

PLOT_APPEARANCE,ALL,HORZ_GRID_ON,VERT_GRID_ON,MARKERS_AND_LINES

[Data]
Time,Comment,Field (Oe),Temperature (K),Long Moment (emu),Long Scan Std Dev,Long Algorithm,Long Reg Fit,Long Percent Error (%),Trans Moment (emu),Trans Scan Std Dev,Trans Algorithm,Trans Reg Fit,Trans Percent Error (%),Long Moment [w/o ABS] (emu),Long Scan Std Dev [w/o ABS],Long Reg Fit [w/o ABS],Long Percent Error [w/o ABS] (%),Trans Moment [w/o ABS] (emu),Trans Scan Std Dev [w/o ABS],Trans Reg Fit [w/o ABS],Trans Percent Error [w/o ABS] (%),Points per Scan,Scans per Measurement,Scan Length (cm),Delta Temp (K),Rot Position (deg),Error,EC Comp. Running,Using ABS,
1511291515.821,,1.000000e+001,1.998637e+000,9.620012e-008,1.939058e-008,3,0.000000e+000,2.015650e+001,,,,,,,,,,,,,,48,2,6.000000e+000,3.160238e-004,0.000000e+000,0,,0,
1511291887.570,,1.000000e+001,4.011210e+000,-4.448931e-008,1.203491e-007,3,0.000000e+000,2.705123e+002,,,,,,,,,,,,,,48,2,6.000000e+000,9.980679e-003,0.000000e+000,0,,0,
1511292297.343,,1.000000e+001,6.000300e+000,-1.457127e-007,1.362561e-007,3,0.000000e+000,9.351009e+001,,,,,,,,,,,,,,48,2,6.000000e+000,5.984783e-003,0.000000e+000,0,,0,
1511292490.992,,1.000000e+001,8.010056e+000,-1.482801e-008,1.281182e-008,3,0.000000e+000,8.640281e+001,,,,,,,,,,,,,,48,2,6.000000e+000,3.164577e-002,0.000000e+000,0,,0,
1511292636.974,,1.000000e+001,1.000817e+001,9.185285e-008,9.373696e-008,3,0.000000e+000,1.020512e+002,,,,,,,,,,,,,,48,2,6.000000e+000,2.608395e-002,0.000000e+000,0,,0,
1511292878.124,,1.000000e+001,1.200195e+001,-1.540743e-007,2.255942e-007,3,0.000000e+000,1.464191e+002,,,,,,,,,,,,,,48,2,6.000000e+000,7.820129e-003,0.000000e+000,0,,0,
1511293018.206,,1.000000e+001,1.399741e+001,4.636595e-008,2.630043e-008,3,0.000000e+000,5.672358e+001,,,,,,,,,,,,,,48,2,6.000000e+000,4.000664e-003,0.000000e+000,0,,0,
1511293163.731,,1.000000e+001,1.599673e+001,-8.828937e-008,2.709382e-008,3,0.000000e+000,3.068752e+001,,,,,,,,,,,,,,48,2,6.000000e+000,8.501053e-003,0.000000e+000,0,,0,
1511293307.872,,1.000000e+001,1.799253e+001,-1.476437e-010,1.623834e-007,3,0.000000e+000,1.099833e+005,,,,,,,,,,,,,,48,2,6.000000e+000,6.610870e-003,0.000000e+000,0,,0,
1511293453.294,,1.000000e+001,1.999194e+001,-3.236643e-009,1.232200e-007,3,0.000000e+000,3.807032e+003,,,,,,,,,,,,,,48,2,6.000000e+000,6.099701e-003,0.000000e+000,0,,0,
1511293603.008,,1.000000e+001,2.199136e+001,-1.165576e-007,2.412017e-007,3,0.000000e+000,2.069377e+002,,,,,,,,,,,,,,48,2,6.000000e+000,4.291534e-003,0.000000e+000,0,,0,
1511293749.686,,1.000000e+001,2.398824e+001,8.702968e-008,8.700471e-008,2,0.000000e+000,9.997131e+001,,,,,,,,,,,,,,48,2,6.000000e+000,3.618240e-003,0.000000e+000,0,,0,
1511293891.018,,1.000000e+001,2.599862e+001,-6.795710e-008,2.612391e-008,3,0.000000e+000,3.844176e+001,,,,,,,,,,,,,,48,2,6.000000e+000,5.060196e-003,0.000000e+000,0,,0,
1511294045.444,,1.000000e+001,2.800149e+001,-3.852659e-008,3.887650e-007,3,0.000000e+000,1.009082e+003,,,,,,,,,,,,,,48,2,6.000000e+000,5.819321e-003,0.000000e+000,0,,0,
1511294198.814,,1.000000e+001,3.000098e+001,2.114292e-008,3.081039e-007,2,0.000000e+000,1.457244e+003,,,,,,,,,,,,,,48,2,6.000000e+000,6.639481e-003,0.000000e+000,0,,0,
1511294349.586,,1.000000e+001,3.200344e+001,3.003894e-008,7.310508e-009,3,0.000000e+000,2.433677e+001,,,,,,,,,,,,,,48,2,6.000000e+000,7.511139e-003,0.000000e+000,0,,0,
1511294506.668,,1.000000e+001,3.400681e+001,7.370429e-009,4.229115e-008,3,0.000000e+000,5.737950e+002,,,,,,,,,,,,,,48,2,6.000000e+000,1.122665e-002,0.000000e+000,0,,0,
1511294676.151,,1.000000e+001,3.600520e+001,6.341341e-008,3.074133e-008,3,0.000000e+000,4.847765e+001,,,,,,,,,,,,,,48,2,6.000000e+000,6.259918e-003,0.000000e+000,0,,0,
1511294846.618,,1.000000e+001,3.799598e+001,-7.796168e-008,1.823559e-007,3,0.000000e+000,2.339045e+002,,,,,,,,,,,,,,48,2,6.000000e+000,1.905060e-002,0.000000e+000,0,,0,
1511295017.678,,1.000000e+001,4.000961e+001,1.703215e-007,2.664833e-007,3,0.000000e+000,1.564590e+002,,,,,,,,,,,,,,48,2,6.000000e+000,7.629395e-003,0.000000e+000,0,,0,
1511295188.391,,1.000000e+001,4.201262e+001,1.211046e-007,9.865865e-008,2,0.000000e+000,8.146564e+001,,,,,,,,,,,,,,48,2,6.000000e+000,1.250839e-002,0.000000e+000,0,,0,
1511295367.179,,1.000000e+001,4.401317e+001,5.075440e-008,2.393076e-007,3,0.000000e+000,4.715012e+002,,,,,,,,,,,,,,48,2,6.000000e+000,1.365662e-002,0.000000e+000,0,,0,
1511295571.877,,1.000000e+001,4.600674e+001,1.087233e-008,2.485250e-009,3,0.000000e+000,2.285849e+001,,,,,,,,,,,,,,48,2,6.000000e+000,1.486969e-002,0.000000e+000,0,,0,
1511295740.253,,1.000000e+001,4.801577e+001,-1.034504e-007,1.331298e-009,3,0.000000e+000,1.286895e+000,,,,,,,,,,,,,,48,2,6.000000e+000,1.935959e-002,0.000000e+000,0,,0,
1511295914.515,,1.000000e+001,5.002399e+001,7.014656e-008,2.220412e-007,2,0.000000e+000,3.165390e+002,,,,,,,,,,,,,,48,2,6.000000e+000,2.553177e-002,0.000000e+000,0,,0,
1511296072.151,,1.000000e+001,5.204357e+001,-3.052862e-007,1.326790e-007,3,0.000000e+000,4.346053e+001,,,,,,,,,,,,,,48,2,6.000000e+000,3.123856e-002,0.000000e+000,0,,0,
1511296237.601,,1.000000e+001,5.404937e+001,-2.488623e-008,1.002245e-008,3,0.000000e+000,4.027308e+001,,,,,,,,,,,,,,48,2,6.000000e+000,3.216171e-002,0.000000e+000,0,,0,
1511296393.376,,1.000000e+001,5.605514e+001,1.589991e-007,6.243984e-008,3,0.000000e+000,3.927056e+001,,,,,,,,,,,,,,48,2,6.000000e+000,4.166794e-002,0.000000e+000,0,,0,
1511296547.978,,1.000000e+001,5.806489e+001,1.289135e-007,4.367169e-007,3,0.000000e+000,3.387674e+002,,,,,,,,,,,,,,48,2,6.000000e+000,2.614975e-002,0.000000e+000,0,,0,
1511296704.092,,1.000000e+001,6.007101e+001,2.201806e-008,2.564724e-007,3,0.000000e+000,1.164828e+003,,,,,,,,,,,,,,48,2,6.000000e+000,4.104996e-002,0.000000e+000,0,,0,
1511296904.969,,1.000000e+001,6.203421e+001,-2.383639e-007,2.420535e-009,3,0.000000e+000,1.015479e+000,,,,,,,,,,,,,,48,2,6.000000e+000,1.919937e-002,0.000000e+000,0,,0,
1511297072.192,,1.000000e+001,6.406561e+001,-6.577006e-008,1.523713e-007,3,0.000000e+000,2.316727e+002,,,,,,,,,,,,,,48,2,6.000000e+000,4.080963e-002,0.000000e+000,0,,0,
1511297237.914,,1.000000e+001,6.608083e+001,2.703495e-008,6.202362e-008,3,0.000000e+000,2.294201e+002,,,,,,,,,,,,,,48,2,6.000000e+000,4.521179e-002,0.000000e+000,0,,0,
1511297401.078,,1.000000e+001,6.807907e+001,1.175830e-008,5.527550e-008,2,0.000000e+000,4.700979e+002,,,,,,,,,,,,,,48,2,6.000000e+000,3.947449e-002,0.000000e+000,0,,0,
1511297555.518,,1.000000e+001,7.008996e+001,1.102188e-007,6.436573e-008,3,0.000000e+000,5.839814e+001,,,,,,,,,,,,,,48,2,6.000000e+000,4.389954e-002,0.000000e+000,0,,0,
1511297716.702,,1.000000e+001,7.206902e+001,-1.446722e-007,6.761989e-009,3,0.000000e+000,4.674006e+000,,,,,,,,,,,,,,48,2,6.000000e+000,6.927490e-002,0.000000e+000,0,,0,
1511297886.065,,1.000000e+001,7.408774e+001,9.409385e-008,4.478770e-008,3,0.000000e+000,4.759897e+001,,,,,,,,,,,,,,48,2,6.000000e+000,2.429199e-002,0.000000e+000,0,,0,
1511298045.123,,1.000000e+001,7.609450e+001,-3.411662e-008,2.084910e-007,3,0.000000e+000,6.111128e+002,,,,,,,,,,,,,,48,2,6.000000e+000,6.632233e-002,0.000000e+000,0,,0,
1511298218.548,,1.000000e+001,7.808627e+001,-8.923791e-008,3.209577e-008,3,0.000000e+000,3.596652e+001,,,,,,,,,,,,,,48,2,6.000000e+000,5.616760e-002,0.000000e+000,0,,0,
1511298406.394,,1.000000e+001,8.007613e+001,5.773081e-008,1.563902e-007,2,0.000000e+000,2.708956e+002,,,,,,,,,,,,,,48,2,6.000000e+000,7.556915e-002,0.000000e+000,0,,0,
1511298573.168,,1.000000e+001,8.210618e+001,-2.221042e-008,3.211779e-008,3,0.000000e+000,1.446068e+002,,,,,,,,,,,,,,48,2,6.000000e+000,3.806305e-002,0.000000e+000,0,,0,
1511298742.460,,1.000000e+001,8.409973e+001,1.007395e-007,2.469682e-007,3,0.000000e+000,2.451553e+002,,,,,,,,,,,,,,48,2,6.000000e+000,5.506897e-002,0.000000e+000,0,,0,
1511298919.920,,1.000000e+001,8.610864e+001,-1.318298e-007,6.268154e-008,2,0.000000e+000,4.754734e+001,,,,,,,,,,,,,,48,2,6.000000e+000,4.470825e-002,0.000000e+000,0,,0,
1511299090.120,,1.000000e+001,8.811331e+001,1.081345e-007,2.058188e-007,3,0.000000e+000,1.903360e+002,,,,,,,,,,,,,,48,2,6.000000e+000,6.993103e-002,0.000000e+000,0,,0,
1511299260.810,,1.000000e+001,9.010551e+001,5.271048e-008,1.246964e-007,3,0.000000e+000,2.365685e+002,,,,,,,,,,,,,,48,2,6.000000e+000,5.211639e-002,0.000000e+000,0,,0,
1511299433.084,,1.000000e+001,9.212356e+001,2.539564e-008,1.203691e-007,2,0.000000e+000,4.739755e+002,,,,,,,,,,,,,,48,2,6.000000e+000,5.800629e-002,0.000000e+000,0,,0,
1511299611.246,,1.000000e+001,9.409782e+001,-3.443746e-008,1.357835e-007,3,0.000000e+000,3.942903e+002,,,,,,,,,,,,,,48,2,6.000000e+000,6.790924e-002,0.000000e+000,0,,0,
1511299789.695,,1.000000e+001,9.610094e+001,-6.810579e-008,2.520536e-008,3,0.000000e+000,3.700914e+001,,,,,,,,,,,,,,48,2,6.000000e+000,4.319000e-002,0.000000e+000,0,,0,
1511299964.502,,1.000000e+001,9.811717e+001,3.954671e-009,1.404922e-007,2,0.000000e+000,3.552564e+003,,,,,,,,,,,,,,48,2,6.000000e+000,6.536102e-002,0.000000e+000,0,,0,