File: Data/Gd (20 nm)/YBCO_Gd_20_12202017_resistivity.dat
[Header]
; AC Transport Data File (default extension .dat)
; Copyright 1998, Quantum Design, Inc. All rights reserved.
TITLE,PPMS_MANG
FILEOPENTIME,30541543.30,12/20/2017,1:13 pm
BYAPP,ACTRANSPORT,2.0,1.1
INFO,PPMS AC Transport Option Release 2.2.4. Build 2,APPNAME
INFO,,SAMPLE1_MATERIAL
INFO,,SAMPLE1_COMMENT
INFO,1.0,SAMPLE1_LEAD_SEPARATION
INFO,1.0,SAMPLE1_CROSS_SECTION
INFO,,SAMPLE2_MATERIAL
INFO,,SAMPLE2_COMMENT
INFO,1.0,SAMPLE2_LEAD_SEPARATION
INFO,1.0,SAMPLE2_CROSS_SECTION
DATATYPE,COMMENT,1
DATATYPE,TIME,2
FIELDGROUP,ACResist,2,4,5,6,7,8,9,10,13,14,15,16,53
FIELDGROUP,ACHall,2,4,5,6,7,8,9,10,17,18,19,20,53
FIELDGROUP,ACIVcurve,2,4,5,6,7,8,9,10,53
FIELDGROUP,ACCritCurrent,2,4,5,6,7,8,9,21,22,23,24,53
STARTUPGROUP,All
STARTUPAXIS,X,2
STARTUPAXIS,Y1,3
[Data]
Comment,Time Stamp (sec),Status (code),Temperature (K),Magnetic Field (Oe),Sample Position (deg),Excitation (mA),Frequency (Hz),Volts ch1,Volts ch2,V Std.Dev. ch1,V Std.Dev. ch2,Res. ch1 (ohm-cm),Res. ch2 (ohm-cm),Res. Std.Dev. ch1,Res. Std.Dev. ch2,Hall ch1 (cm^3/coul),Hall ch2 (cm^3/coul),Hall Std.Dev. ch1,Hall Std.Dev. ch2,Crit.Cur. ch1 (mA),Crit.Cur. ch2 (mA),C.Cur. Std.Dev. ch1,C.Cur. Std.Dev. ch2,ACT Status (code),ACT Gain,2nd Harm. ch1 (dB),2nd Harm. ch2 (dB),3rd Harm. ch1 (dB),3rd Harm. ch2 (dB),Quad.Error ch1 (ohm-cm-rad),Quad.Error ch2 (ohm-cm-rad),Drive Signal ch1 (V),Drive Signal ch2 (V),Bridge 1 Resistance (ohms),Bridge 1 Excitation (uA),Bridge 2 Resistance (ohms),Bridge 2 Excitation (uA),Bridge 3 Resistance (ohms),Bridge 3 Excitation (uA),Bridge 4 Resistance (ohms),Bridge 4 Excitation (uA),Signal 1 Vin (V),Signal 2 Vin (V),Digital Inputs (code),Drive 1 Iout (mA),Drive 1 Ipower (watts),Drive 2 Iout (mA),Drive 2 Ipower (watts),Pressure (),Map 20 (),Map 21 (),Map 22 (),Map 23 (),Map 24 (),Map 25 (),Map 26 (),Map 27 (),Map 28 (),Map 29 ()
,30541552.725,4370,300.03485,312.857,90.014,0.102153342753992,173,0.00129894627244735,,2.21567275701673E-7,,12.715818138749,,0.00216899589384588,,,,,,,,,,0,2500,-82.9543738458701,,-79.8552208283172,,-4.26619391001785E-6,,0.00129894629644731,,,,,,,,,,,,,,,,,,,,,,,,,,,
,30541604.365,4374,298.382,312.857,90.014,0.102153342753992,173,,0.000250423869830466,,9.09541678114458E-8,,2.45236733107201,,0.000890701909140379,,,,,,,,,0,5000,,-71.5640393509236,,-78.7858542157281,,1.33226573368468E-6,,0.000250423881970682,,,,,,,,,,,,,,,,,,,,,,,,,,
,30541657.905,4374,296.03425,312.857,90.014,0.102153342753992,173,0.00129783884944735,,3.27400657581621E-7,,12.70497706355,,0.00320503394282848,,,,,,,,,,0,2500,-73.1452088909347,,-76.3843859408569,,-8.14134410383223E-6,,0.00129783893692395,,,,,,,,,,,,,,,,,,,,,,,,,,,
,30541708.375,4370,292.22865,312.857,90.014,0.102153342753992,173,,0.000249485257582093,,4.05262828664264E-8,,2.44317220283646,,0.000396867882706055,,,,,,,,,0,5000,,-86.27593057823,,-81.1267203106023,,8.21891102919053E-7,,0.000249485262219809,,,,,,,,,,,,,,,,,,,,,,,,,,
,30541764.205,4370,289.704,312.857,90.014,0.102153342753992,173,0.0012928024638697,,1.83410526732891E-7,,12.6556735621895,,0.00179546662213532,,,,,,,,,,0,2500,-88.0917718523355,,-82.0173457970207,,-5.84634972623172E-6,,0.00129280250915507,,,,,,,,,,,,,,,,,,,,,,,,,,,
,30541815.66,4370,287.1928,312.857,90.014,0.102153342753992,173,,0.000248557263600925,,4.0286122598196E-8,,2.43408112194777,,0.000394515478423272,,,,,,,,,0,5000,,-83.6112937554114,,-79.9155197346583,,1.00164727854971E-6,,0.000248557270514834,,,,,,,,,,,,,,,,,,,,,,,,,,
,30541870.385,4370,284.464,312.857,90.014,0.102153342753992,173,0.00128931872512302,,1.96674724857873E-7,,12.6215696397247,,0.00192531420190714,,,,,,,,,,0,2500,-88.4905011250711,,-81.33435572071,,-5.72741098611135E-6,,0.00128931876870197,,,,,,,,,,,,,,,,,,,,,,,,,,,
,30541922.1,4370,281.85965,312.857,90.014,0.102153342753992,173,,0.000247851706329717,,4.03478539889821E-8,,2.42716915623779,,0.000395119588769656,,,,,,,,,0,5000,,-83.192218203518,,-80.0152799609554,,9.4560042607332E-7,,0.000247851712509082,,,,,,,,,,,,,,,,,,,,,,,,,,
,30541975.65,4370,279.18835,312.857,90.014,0.102153342753992,173,0.00128559265319291,,1.87899513573127E-7,,12.5850934088184,,0.00183941067227667,,,,,,,,,,0,2500,-88.5488730507841,,-82.2453034694068,,-5.83028490778072E-6,,0.00128559269848232,,,,,,,,,,,,,,,,,,,,,,,,,,,
,30542026.78,4370,276.633,312.857,90.014,0.102153342753992,173,,0.000247186520419772,,4.03645247557926E-8,,2.42065270041425,,0.000395282450659005,,,,,,,,,0,5000,,-83.9530243916844,,-80.4214230945227,,9.14287393307938E-7,,0.000247186526212206,,,,,,,,,,,,,,,,,,,,,,,,,,
,30542078.795,4370,274.0205,312.857,90.014,0.102153342753992,173,0.00128190161737299,,1.83502220440602E-7,,12.5489601652091,,0.00179636404396408,,,,,,,,,,0,2500,-88.1603108026425,,-82.8081240375895,,-5.81589640721733E-6,,0.00128190166256889,,,,,,,,,,,,,,,,,,,,,,,,,,,
,30542130.36,4370,271.43585,312.857,90.014,0.102153342753992,173,,0.000246436118458246,,3.91425847920093E-8,,2.41330144594243,,0.000383315783089831,,,,,,,,,0,5000,,-85.0169949263076,,-80.300809871794,,1.01560565170355E-6,,0.000246436125627373,,,,,,,,,,,,,,,,,,,,,,,,,,
,30542183.745,4370,268.778,312.857,90.014,0.102153342753992,173,0.00127810914979094,,1.84720081896821E-7,,12.5118339623377,,0.00180828602969055,,,,,,,,,,0,2500,-91.3445114220981,,-81.8069452868458,,-5.53399130196333E-6,,0.00127810919083303,,,,,,,,,,,,,,,,,,,,,,,,,,,
,30542234.875,4370,266.2152,312.857,90.014,0.102153342753992,173,,0.000245756257403161,,3.91301115932743E-8,,2.40664125420122,,0.000383193247395649,,,,,,,,,0,5000,,-84.348613544974,,-79.9081863997244,,9.67457117157669E-7,,0.000245756263926641,,,,,,,,,,,,,,,,,,,,,,,,,,
,30542287.655,4370,263.5741,312.857,90.014,0.102153342753992,173,0.00127432985249335,,1.90385267477749E-7,,12.4748366922474,,0.00186374433134644,,,,,,,,,,0,2500,-88.4925017650461,,-82.7914454632714,,-5.70539236163958E-6,,0.00127432989624653,,,,,,,,,,,,,,,,,,,,,,,,,,,
,30542337.75,4370,261.0697,312.857,90.014,0.102153342753992,173,,0.000244982521281572,,3.93631913032981E-8,,2.39906144108761,,0.000385475306085722,,,,,,,,,0,5000,,-85.8509446026861,,-79.1119401679768,,8.77913178085931E-7,,0.000244982526670327,,,,,,,,,,,,,,,,,,,,,,,,,,
,30542390.39,4370,258.4309,312.857,90.014,0.102153342753992,173,0.00127052920442255,,1.80421896905986E-7,,12.4376304125221,,0.00176620953873634,,,,,,,,,,0,2500,-87.8711360853099,,-82.539768269549,,-5.49695580912445E-6,,0.00127052924515872,,,,,,,,,,,,,,,,,,,,,,,,,,,
,30542440.445,4370,255.93685,312.857,90.014,0.102153342753992,173,,0.000244289098552617,,4.05527468743503E-8,,2.39226842337541,,0.00039712395672229,,,,,,,,,0,5000,,-85.4248780704681,,-80.1054081479641,,9.33665184555842E-7,,0.000244289104664832,,,,,,,,,,,,,,,,,,,,,,,,,,
,30542494.26,4370,253.2334,312.857,90.014,0.102153342753992,173,0.00126685261323207,,1.94557921011476E-7,,12.4016385849757,,0.00190459167806344,,,,,,,,,,0,2500,-86.911419081303,,-81.9251708073508,,-5.42309099825537E-6,,0.00126685265299589,,,,,,,,,,,,,,,,,,,,,,,,,,,
,30542544.305,4370,250.73565,312.857,90.014,0.102153342753992,173,,0.000243553328873622,,3.9239712931769E-8,,2.38506057513852,,0.00038426528574522,,,,,,,,,0,5000,,-83.8722071009924,,-80.0727551922175,,1.01415436276357E-6,,0.000243553336106889,,,,,,,,,,,,,,,,,,,,,,,,,,
,30542596.81,4370,248.11155,312.857,90.014,0.102153342753992,173,0.0012632529638398,,1.83313165927304E-7,,12.3663999783664,,0.00179451299912351,,,,,,,,,,0,2500,-87.0274881782208,,-82.4243464248024,,-5.22256707910979E-6,,0.00126325300082246,,,,,,,,,,,,,,,,,,,,,,,,,,,
,30542647.005,4370,245.61235,312.857,90.014,0.102153342753992,173,,0.00024279685652957,,3.87551054863714E-8,,2.37764993311761,,0.000379519211723697,,,,,,,,,0,5000,,-83.7590109268465,,-79.87325589732,,9.40556795219076E-7,,0.000242796862770473,,,,,,,,,,,,,,,,,,,,,,,,,,
,30542699.585,4370,242.96565,312.857,90.014,0.102153342753992,173,0.00125957817118647,,1.84093689623543E-7,,12.3304257628117,,0.00180215373112463,,,,,,,,,,0,2500,-87.7055796227432,,-82.7656323683466,,-5.43751723584443E-6,,0.001259578211393,,,,,,,,,,,,,,,,,,,,,,,,,,,
,30542749.485,4370,240.4709,312.857,90.014,0.102153342753992,173,,0.000242139347244831,,3.99476375909427E-8,,2.37120877808483,,0.000391197002691033,,,,,,,,,0,5000,,-85.0261326358858,,-79.7071116107451,,8.59366419331517E-7,,0.000242139352468935,,,,,,,,,,,,,,,,,,,,,,,,,,
,30542801.64,4370,237.87995,312.857,90.014,0.102153342753992,173,0.00125594722195238,,1.84994893609124E-7,,12.2948807530407,,0.00181097584611036,,,,,,,,,,0,2500,-87.4541539650545,,-83.4754215430337,,-5.47006786040867E-6,,0.00125594726275936,,,,,,,,,,,,,,,,,,,,,,,,,,,
,30542851.755,4370,235.36795,312.857,90.014,0.102153342753992,173,,0.000241464645939487,,3.85322027402594E-8,,2.3645992180928,,0.000377335629584526,,,,,,,,,0,5000,,-84.3300857466204,,-79.7444641703197,,9.21520948814366E-7,,0.000241464651963381,,,,,,,,,,,,,,,,,,,,,,,,,,
,30542905.775,4370,232.6637,312.857,90.014,0.102153342753992,173,0.00125219698633598,,1.80771060610049E-7,,12.2581679974807,,0.00176962728765269,,,,,,,,,,0,2500,-90.034472872863,,-81.8084368422686,,-5.51050110315928E-6,,0.00125219702787248,,,,,,,,,,,,,,,,,,,,,,,,,,,
,30542955.6,4370,230.1788,312.857,90.014,0.102153342753992,173,,0.000240724834853356,,3.88538339911376E-8,,2.35735184004723,,0.000380484858440523,,,,,,,,,0,5000,,-84.5190200589739,,-80.2220060569506,,9.29613472106118E-7,,0.000240724841002354,,,,,,,,,,,,,,,,,,,,,,,,,,
,30543005.975,4370,227.66355,312.857,90.014,0.102153342753992,173,0.00124857363034222,,1.87225159760398E-7,,12.2226973266758,,0.00183280851847012,,,,,,,,,,0,2500,-88.6921157660938,,-82.701125213895,,-5.42730869109305E-6,,0.00124857367075096,,,,,,,,,,,,,,,,,,,,,,,,,,,
,30543057.62,4370,225.0703,312.857,90.014,0.102153342753992,173,,0.000239994530640319,,3.97009164307171E-8,,2.35019760946076,,0.000388779678237001,,,,,,,,,0,5000,,-85.0400003439399,,-79.6745069792147,,9.46900246563179E-7,,0.000239994537039546,,,,,,,,,,,,,,,,,,,,,,,,,,
,30543108.82,4370,222.501,312.857,90.014,0.102153342753992,173,0.00124484518348688,,1.91045970183179E-7,,12.1861978766028,,0.00187021161832604,,,,,,,,,,0,2500,-87.8985526585185,,-82.8384007574378,,-5.25288355599944E-6,,0.00124484522145339,,,,,,,,,,,,,,,,,,,,,,,,,,,
,30543157.735,4370,220.06425,312.857,90.014,0.102153342753992,173,,0.000239348852978002,,3.76726681881255E-8,,2.34387241332113,,0.000368917269878962,,,,,,,,,0,5000,,-85.2324472516108,,-80.7911830172113,,9.3601491678174E-7,,0.000239348859247815,,,,,,,,,,,,,,,,,,,,,,,,,,
,30543210.77,4370,217.42165,312.857,90.014,0.102153342753992,173,0.00124118884551597,,1.81972061179058E-7,,12.1504043356366,,0.00178138408620849,,,,,,,,,,0,2500,-89.4564324000127,,-83.0786584629661,,-5.09169734950692E-6,,0.00124118888129328,,,,,,,,,,,,,,,,,,,,,,,,,,,
,30543260.67,4370,214.92165,312.857,90.014,0.102153342753992,173,,0.000238620700783725,,4.08889438771872E-8,,2.33673929370402,,0.000400412869240566,,,,,,,,,0,5000,,-84.52039948223,,-78.7499008294876,,9.08992471985086E-7,,0.000238620706714792,,,,,,,,,,,,,,,,,,,,,,,,,,
,30543312.285,4370,212.34645,312.857,90.014,0.102153342753992,173,0.00123754370606137,,1.86563543920973E-7,,12.1147204246297,,0.00182633154555328,,,,,,,,,,0,2500,-87.050720714175,,-82.2019638883122,,-5.13487691073802E-6,,0.00123754374255524,,,,,,,,,,,,,,,,,,,,,,,,,,,
,30543362.635,4370,209.81595,312.857,90.014,0.102153342753992,173,,0.000237883298809257,,3.7287622062307E-8,,2.32951557726194,,0.0003651458282514,,,,,,,,,0,5000,,-85.5484679205368,,-80.614525737914,,9.27610067321819E-7,,0.000237883305004915,,,,,,,,,,,,,,,,,,,,,,,,,,
,30543414.765,4370,207.21515,312.857,90.014,0.102153342753992,173,0.00123385599306945,,1.84614425291278E-7,,12.0786197447771,,0.00180725092030457,,,,,,,,,,0,2500,-87.4455724836533,,-82.6981459356844,,-5.03078120656667E-6,,0.00123385602820338,,,,,,,,,,,,,,,,,,,,,,,,,,,
,30543464.975,4370,204.7115,312.857,90.014,0.102153342753992,173,,0.000237262653698353,,3.73175542641118E-8,,2.32343564344652,,0.00036543860640428,,,,,,,,,0,5000,,-83.9786721229194,,-80.6885253944688,,9.098953660454E-7,,0.000237262659675225,,,,,,,,,,,,,,,,,,,,,,,,,,
,30543517.305,4370,202.0965,312.857,90.014,0.102153342753992,173,0.00123017159681761,,1.79374967816634E-7,,12.0425515366718,,0.00175596009097943,,,,,,,,,,0,2500,-88.4938894439015,,-82.8741467179553,,-5.16611315461979E-6,,0.0012301716339782,,,,,,,,,,,,,,,,,,,,,,,,,,,
,30543567.25,4370,199.5961,312.857,90.014,0.102153342753992,173,,0.000236554048152682,,3.74824685425328E-8,,2.31649404962527,,0.000367053170322627,,,,,,,,,0,5000,,-85.2921774037235,,-80.0055147182458,,8.71140228511466E-7,,0.000236554053647663,,,,,,,,,,,,,,,,,,,,,,,,,,
,30543619.465,4370,196.9816,312.857,90.014,0.102153342753992,173,0.00122646412102392,,1.71975504991354E-7,,12.0062573952874,,0.00168352427187844,,,,,,,,,,0,2500,-87.0076812013784,,-83.0021549810408,,-5.14669055648571E-6,,0.0012264641580171,,,,,,,,,,,,,,,,,,,,,,,,,,,
,30543668.945,4370,194.5079,312.857,90.014,0.102153342753992,173,,0.000235867262605797,,3.7649532987052E-8,,2.3097662214226,,0.000368688798490679,,,,,,,,,0,5000,,-85.3348560633697,,-80.8822821198005,,8.40720134726131E-7,,0.000235867267738613,,,,,,,,,,,,,,,,,,,,,,,,,,
,30543721.215,4370,191.8942,312.857,90.014,0.102153342753992,173,0.00122278678753459,,1.83610060490817E-7,,11.9702583331108,,0.00179741866129955,,,,,,,,,,0,2500,-91.8505530297761,,-83.4020493035289,,-5.11711735215324E-6,,0.00122278682421384,,,,,,,,,,,,,,,,,,,,,,,,,,,
,30543770.59,4370,189.4279,312.857,90.014,0.102153342753992,173,,0.000235183371762053,,3.75564787439581E-8,,2.30306676376915,,0.000367777174492224,,,,,,,,,0,5000,,-83.6703582448602,,-80.3815827903629,,8.65228184554896E-7,,0.000235183377214296,,,,,,,,,,,,,,,,,,,,,,,,,,
,30543825.465,4370,186.6871,312.857,90.014,0.102153342753992,173,0.00121902108518267,,1.82100509049142E-7,,11.9333941913898,,0.00178264109705645,,,,,,,,,,0,2500,-85.4852768282473,,-81.974191944589,,-5.37299177856802E-6,,0.00121902112574674,,,,,,,,,,,,,,,,,,,,,,,,,,,
,30543875.485,4370,184.19355,312.857,90.014,0.102153342753992,173,,0.000234504122108456,,3.82918766301628E-8,,2.29641278518635,,0.000374978283040283,,,,,,,,,0,5000,,-84.3649145949364,,-80.6810337660956,,8.52001842817662E-7,,0.000234504127410594,,,,,,,,,,,,,,,,,,,,,,,,,,
,30543927.785,4370,181.56955,312.857,90.014,0.102153342753992,173,0.00121533022448955,,1.75271758399284E-7,,11.8972627108074,,0.00171579217687618,,,,,,,,,,0,2500,-89.4280105250436,,-83.923081521901,,-5.14295292787421E-6,,0.00121533026176743,,,,,,,,,,,,,,,,,,,,,,,,,,,
,30543977.69,4370,179.06615,312.857,90.014,0.102153342753992,173,,0.000233711303002373,,3.81794012794614E-8,,2.288646289131,,0.000373876408643953,,,,,,,,,0,5000,,-84.8031509835748,,-80.1995934665948,,9.42382988683043E-7,,0.000233711309511093,,,,,,,,,,,,,,,,,,,,,,,,,,
,30544030.5,4370,176.43055,312.857,90.014,0.102153342753992,173,0.00121160670509315,,1.82481898969944E-7,,11.8608115223525,,0.00178637452179905,,,,,,,,,,0,2500,-88.9155798300075,,-82.0044247033976,,-4.93499429460839E-6,,0.00121160673952276,,,,,,,,,,,,,,,,,,,,,,,,,,,
,30544081.115,4370,173.901,312.857,90.014,0.102153342753992,173,,0.000233016138350083,,3.68789707644025E-8,,2.28183643617491,,0.000361141411248416,,,,,,,,,0,5000,,-85.2611943336504,,-79.7417980007695,,9.04415214249226E-7,,0.000233016144362791,,,,,,,,,,,,,,,,,,,,,,,,,,
,30544133.375,4370,171.2895,312.857,90.014,0.102153342753992,173,0.00120787025281995,,1.73883509900131E-7,,11.8242337309694,,0.0017022020341895,,,,,,,,,,0,2500,-88.7977669910147,,-81.8779455689275,,-5.05303575542945E-6,,0.00120787028902798,,,,,,,,,,,,,,,,,,,,,,,,,,,
,30544183.335,4370,168.79945,312.857,90.014,0.102153342753992,173,,0.000232319490032341,,3.80865300830008E-8,,2.27501206337313,,0.000372966183796334,,,,,,,,,0,5000,,-83.2741927154469,,-80.251283267022,,8.02743846994713E-7,,0.000232319494783382,,,,,,,,,,,,,,,,,,,,,,,,,,
,30544235.705,4370,166.178,312.857,90.014,0.102153342753992,173,0.00120418491906934,,1.75883165148465E-7,,11.7881563642223,,0.00172177724804011,,,,,,,,,,0,2500,-89.8732169785254,,-83.3432772699541,,-4.80386345506142E-6,,0.00120418495189463,,,,,,,,,,,,,,,,,,,,,,,,,,,
,30544285.195,4370,163.70905,312.857,90.014,0.102153342753992,173,,0.000231637342133091,,3.78324890859252E-8,,2.26832975055192,,0.00037047808400565,,,,,,,,,0,5000,,-84.3178971413477,,-79.9672391340913,,8.18073245267148E-7,,0.000231637347081849,,,,,,,,,,,,,,,,,,,,,,,,,,
,30544337.57,4370,161.08175,312.857,90.014,0.102153342753992,173,0.00120047738392785,,1.77515834371735E-7,,11.7518616609248,,0.00173775990744003,,,,,,,,,,0,2500,-88.9412483543336,,-83.2647982475613,,-4.94303308311327E-6,,0.00120047741878995,,,,,,,,,,,,,,,,,,,,,,,,,,,
,30544387.38,4370,158.5861,312.857,90.014,0.102153342753992,173,,0.000230894953678461,,3.79711765553985E-8,,2.26105733742704,,0.000371835780322538,,,,,,,,,0,5000,,-84.1994820061234,,-79.9497808619013,,8.69983698897125E-7,,0.000230894959293183,,,,,,,,,,,,,,,,,,,,,,,,,,
,30544440.075,4370,155.9581,312.857,90.014,0.102153342753992,173,0.0011967537145923,,1.78454457974113E-7,,11.7154090155951,,0.00174694833285891,,,,,,,,,,0,2500,-86.451965517157,,-83.0901070377047,,-4.86891134294019E-6,,0.00119675374852195,,,,,,,,,,,,,,,,,,,,,,,,,,,
,30544490.36,4370,153.448,312.857,90.014,0.102153342753992,173,,0.000230187169471017,,3.63029558973057E-8,,2.25412392139527,,0.000355499221019976,,,,,,,,,0,5000,,-84.2809207949303,,-79.8872275625714,,8.40719287212935E-7,,0.000230187174730479,,,,,,,,,,,,,,,,,,,,,,,,,,
,30544541.46,4370,150.88735,312.857,90.014,0.102153342753992,173,0.0011930468508148,,1.81796463802469E-7,,11.6791208900287,,0.00177966424243547,,,,,,,,,,0,2500,-87.1526141196223,,-82.8650929836644,,-4.77198541340427E-6,,0.00119304688350828,,,,,,,,,,,,,,,,,,,,,,,,,,,
,30544590.525,4370,148.4331,312.857,90.014,0.102153342753992,173,,0.000229420845635318,,3.47899794324223E-8,,2.24661707083808,,0.000340682902816131,,,,,,,,,0,5000,,-85.4487366901713,,-79.4017813108014,,8.93236329041395E-7,,0.000229420851592218,,,,,,,,,,,,,,,,,,,,,,,,,,
,30544643.245,4370,145.8071,312.857,90.014,0.102153342753992,173,0.00118931754240634,,1.71769336513518E-7,,11.642613046808,,0.0016815053910757,,,,,,,,,,0,2500,-87.8237358723837,,-81.7618629195623,,-4.9390974493449E-6,,0.00118931757753955,,,,,,,,,,,,,,,,,,,,,,,,,,,
,30544693.165,4370,143.30725,312.857,90.014,0.102153342753992,173,,0.000228743192310315,,3.60695379809289E-8,,2.23997884423687,,0.000353212697877035,,,,,,,,,0,5000,,-86.9538125139054,,-79.3358794348933,,8.52400801780436E-7,,0.00022874319775108,,,,,,,,,,,,,,,,,,,,,,,,,,
,30544747.105,4370,140.60835,312.857,90.014,0.102153342753992,173,0.00118551996543917,,1.75724306322044E-7,,11.6054368954142,,0.00172022179908774,,,,,,,,,,0,2500,-89.8318886922069,,-82.3960241684878,,-4.92188759535361E-6,,0.00118552000043972,,,,,,,,,,,,,,,,,,,,,,,,,,,
,30544797.575,4370,138.0798,312.857,90.014,0.102153342753992,173,,0.000227991412201687,,3.67335482080558E-8,,2.23261449453369,,0.000359714646357485,,,,,,,,,0,5000,,-85.2539771336666,,-79.9645855046961,,8.49946259808352E-7,,0.000227991417629,,,,,,,,,,,,,,,,,,,,,,,,,,
,30544848.345,4370,135.5519,312.857,90.014,0.102153342753992,173,0.00118178657729253,,1.84537461915387E-7,,11.5688891194021,,0.00180649655035851,,,,,,,,,,0,2500,-86.3033734264529,,-82.9938662292355,,-4.792456765946E-6,,0.0011817866105813,,,,,,,,,,,,,,,,,,,,,,,,,,,
,30544897.5,4370,133.09485,312.857,90.014,0.102153342753992,173,,0.000227284020289281,,3.44011414858786E-8,,2.22568498148981,,0.000336874109746217,,,,,,,,,0,5000,,-85.8950135102486,,-79.0209521212355,,8.779227075817E-7,,0.000227284026097782,,,,,,,,,,,,,,,,,,,,,,,,,,
,30544950.195,4370,130.44285,312.857,90.014,0.102153342753992,173,0.00117801149423302,,1.75575016827837E-7,,11.5319331763834,,0.00171876022609664,,,,,,,,,,0,2500,-89.2075798717385,,-83.1096231976779,,-4.87235623044416E-6,,0.00117801152875128,,,,,,,,,,,,,,,,,,,,,,,,,,,
,30545000.68,4370,127.93065,312.857,90.014,0.102153342753992,173,,0.000226567412279039,,3.55144573647494E-8,,2.21866520375721,,0.000347775913378066,,,,,,,,,0,5000,,-85.2596976715078,,-79.7081121609698,,8.80517103586318E-7,,0.000226567418140402,,,,,,,,,,,,,,,,,,,,,,,,,,
,30545053.17,4370,125.31475,312.857,90.014,0.102153342753992,173,0.00117419281411884,,1.85743193522403E-7,,11.4945504455538,,0.00181829970594036,,,,,,,,,,0,2500,-88.7553786024981,,-81.3473270344558,,-4.72557628645929E-6,,0.0011741928466943,,,,,,,,,,,,,,,,,,,,,,,,,,,
,30545103.345,4370,122.7914,312.857,90.014,0.102153342753992,173,,0.00022581930520064,,3.6059582254314E-8,,2.2113368822075,,0.000353113663048423,,,,,,,,,0,5000,,-84.904499022407,,-79.0341784085372,,8.9584513807198E-7,,0.000225819311287948,,,,,,,,,,,,,,,,,,,,,,,,,,
,30545155.855,4370,120.16735,312.857,90.014,0.102153342753992,173,0.00117033030008835,,1.70603726288582E-7,,11.4567386082701,,0.00167009453834284,,,,,,,,,,0,2500,-93.4385366391764,,-82.628122245158,,-4.76295038857221E-6,,0.00117033033329033,,,,,,,,,,,,,,,,,,,,,,,,,,,
,30545206.075,4370,117.6616,312.857,90.014,0.102153342753992,173,,0.000225112287727723,,3.36383025474382E-8,,2.20441108204603,,0.000329402920980804,,,,,,,,,0,5000,,-85.4902798089496,,-80.1339768606953,,8.45231753155916E-7,,0.00022511229316364,,,,,,,,,,,,,,,,,,,,,,,,,,
,30545258.65,4370,115.03,312.857,90.014,0.102153342753992,173,0.00116648470081853,,1.82188752606954E-7,,11.4190923599018,,0.00178350400509221,,,,,,,,,,0,2500,-86.6360053248872,,-81.044529528238,,-4.67206760528115E-6,,0.00116648473287087,,,,,,,,,,,,,,,,,,,,,,,,,,,
,30545308.82,4370,112.52895,312.857,90.014,0.102153342753992,173,,0.000224368152130961,,3.6872744610886E-8,,2.19712169604702,,0.000361075778024524,,,,,,,,,0,5000,,-84.8802033199769,,-78.5359187011488,,8.69243686968859E-7,,0.000224368157899188,,,,,,,,,,,,,,,,,,,,,,,,,,
,30545361.34,4370,109.8995,312.857,90.014,0.102153342753992,173,0.00116259784053318,,1.71826376241571E-7,,11.3810421924321,,0.00168206331949685,,,,,,,,,,0,2500,-89.3250551739664,,-82.3526861219266,,-4.70634369082033E-6,,0.00116259787316627,,,,,,,,,,,,,,,,,,,,,,,,,,,
,30545411.29,4370,107.3903,312.857,90.014,0.102153342753992,173,,0.000223672132283568,,3.65263958892143E-8,,2.19030365583808,,0.000357683791724337,,,,,,,,,0,5000,,-84.408110073061,,-79.3299342684668,,8.69843945654394E-7,,0.000223672138077738,,,,,,,,,,,,,,,,,,,,,,,,,,
,30545463.79,4370,104.7662,312.857,90.014,0.102153342753992,173,0.00115867498370071,,1.81427622556503E-7,,11.3426396421234,,0.00177605292446575,,,,,,,,,,0,2500,-86.2140447020469,,-80.3356625473905,,-4.38476699438286E-6,,0.00115867501212253,,,,,,,,,,,,,,,,,,,,,,,,,,,
,30545512.25,4370,102.3495,312.857,90.014,0.102153342753992,173,,0.000222937680922472,,3.62766135569125E-8,,2.18310916528773,,0.000355237416422853,,,,,,,,,0,5000,,-84.4684088192196,,-79.677205480212,,8.00166167907198E-7,,0.000222937685841705,,,,,,,,,,,,,,,,,,,,,,,,,,
,30545564.54,4370,99.7333,312.857,90.014,0.102153342753992,173,0.00115480986398271,,1.70353169521773E-7,,11.3048023084983,,0.00166764149821257,,,,,,,,,,0,2500,-90.3526965093436,,-82.8150459107268,,-4.60033410062802E-6,,0.00115480989537252,,,,,,,,,,,,,,,,,,,,,,,,,,,
,30545617.355,4370,97.086,312.857,90.014,0.102153342753992,173,,0.000222133454973588,,3.55229978779657E-8,,2.17523119950029,,0.000347857245353892,,,,,,,,,0,5000,,-83.6974934240171,,-79.1535651570905,,7.56701663547412E-7,,0.000222133459388843,,,,,,,,,,,,,,,,,,,,,,,,,,
,30545673.29,4370,94.30205,312.857,90.014,0.102153342753992,173,0.00115061726200869,,1.63490582629075E-7,,11.2637591123488,,0.00160046138142566,,,,,,,,,,0,2500,-93.2422057538226,,-82.6312107991298,,-4.45212958570913E-6,,0.00115061729151569,,,,,,,,,,,,,,,,,,,,,,,,,,,
,30545726.27,4370,91.6455,312.857,90.014,0.102153342753992,173,,0.000221368914924022,,3.46447654055403E-8,,2.16774200289777,,0.00033925680699483,,,,,,,,,0,5000,,-86.2725983671469,,-79.8168005333206,,8.51906961330695E-7,,0.000221368920539518,,,,,,,,,,,,,,,,,,,,,,,,,,
,30545782.955,4370,88.817,312.857,90.014,0.102153342753992,173,0.00114642422790781,,1.7539229953829E-7,,11.2227116894019,,0.00171697100485439,,,,,,,,,,0,2500,-88.3172210773728,,-82.0669864826941,,-4.48837059815879E-6,,0.00114642425800684,,,,,,,,,,,,,,,,,,,,,,,,,,,
,30545836.68,4370,86.12585,312.857,90.014,0.102153342753992,173,,0.000220528724263111,,3.56255785340943E-8,,2.15951177615119,,0.000348860923998774,,,,,,,,,0,5000,,-84.1177030795094,,-79.8286138220327,,8.289370633889E-7,,0.000220528729600126,,,,,,,,,,,,,,,,,,,,,,,,,,
,30545893.405,4370,83.2846,312.857,90.014,0.102153342753992,173,0.00114218210130902,,1.67881049838877E-7,,11.1811836823175,,0.00164344092007914,,,,,,,,,,0,2500,-92.1414594369549,,-83.5440487349691,,-4.57370551649185E-6,,0.00114218213267952,,,,,,,,,,,,,,,,,,,,,,,,,,,
,30545949.5,4370,80.49325,312.857,90.014,0.102153342753992,173,,0.000219545592389453,,3.43980995990933E-8,,2.1498813713064,,0.000336840430404832,,,,,,,,,0,5000,,-86.3442359543196,,-78.7149779541499,,8.04881211053857E-7,,0.000219545597443733,,,,,,,,,,,,,,,,,,,,,,,,,,
,30546003.055,4370,77.7669,312.857,90.014,0.102153342753992,173,0.00113783529260163,,1.67647472428457E-7,,11.1386309006127,,0.00164115428926679,,,,,,,,,,0,2500,-91.5083872722405,,-83.102060428072,,-4.30887720641481E-6,,0.00113783532055082,,,,,,,,,,,,,,,,,,,,,,,,,,,
,30546053.895,4370,75.22255,312.857,90.014,0.102153342753992,173,,0.000218839140737557,,3.52005300033423E-8,,2.14296124346981,,0.000344697798056773,,,,,,,,,0,5000,,-87.2911336411997,,-78.9904186064078,,7.71508068116434E-7,,0.000218839145396382,,,,,,,,,,,,,,,,,,,,,,,,,,
,30546107.765,4370,72.5189,312.857,90.014,0.102153342753992,173,0.00113373220399692,,1.70414006708743E-7,,11.0984640033438,,0.00166823670487094,,,,,,,,,,0,2500,-85.493824630595,,-82.67166372009,,-4.1266677435185E-6,,0.00113373222972509,,,,,,,,,,,,,,,,,,,,,,,,,,,
,30546157.88,4370,70.0148,312.857,90.014,0.102153342753992,173,,0.000217980915609796,,3.5317161406669E-8,,2.13455442085953,,0.000345839456728354,,,,,,,,,0,5000,,-84.9712738376287,,-78.7508357645371,,7.6278394544009E-7,,0.000217980920181784,,,,,,,,,,,,,,,,,,,,,,,,,,
,30546210.32,4370,67.4074,312.857,90.014,0.102153342753992,173,0.0011297024281285,,1.76643372672515E-7,,11.0590147991929,,0.0017292178660066,,,,,,,,,,0,2500,-84.2708200399639,,-81.4517229115227,,-4.39197615510625E-6,,0.00112970245737516,,,,,,,,,,,,,,,,,,,,,,,,,,,
,30546260.715,4370,64.892,312.857,90.014,0.102153342753992,173,,0.000217225664237274,,3.51194764604838E-8,,2.12715630489676,,0.000343903260854467,,,,,,,,,0,5000,,-85.2668444865846,,-79.5833287416444,,7.45009975895602E-7,,0.00021722566861384,,,,,,,,,,,,,,,,,,,,,,,,,,
,30546313.11,4370,62.2712,312.857,90.014,0.102153342753992,173,0.00112562759653954,,1.74531831201521E-7,,11.0191245285396,,0.00170854724987367,,,,,,,,,,0,2500,-84.7441096197899,,-81.3485347002187,,-4.2857701608577E-6,,0.00112562762448965,,,,,,,,,,,,,,,,,,,,,,,,,,,
,30546361.455,4370,59.8184,312.857,90.014,0.102153342753992,173,,0.000216409925150557,,3.37661306578835E-8,,2.11916569617884,,0.000330650381968046,,,,,,,,,0,5000,,-84.968117248332,,-80.7161110710232,,7.23571240299414E-7,,0.000216409929294424,,,,,,,,,,,,,,,,,,,,,,,,,,
,30546413.535,4370,57.2368,312.857,90.014,0.102153342753992,173,0.00112153691088079,,1.77594958937409E-7,,10.9790790589163,,0.00173853310650528,,,,,,,,,,0,2500,-85.9614303199223,,-81.6211477846888,,-4.11246202794244E-6,,0.00112153693670998,,,,,,,,,,,,,,,,,,,,,,,,,,,
,30546462.455,4370,54.80655,312.857,90.014,0.102153342753992,173,,0.000215644381719329,,3.52252182262672E-8,,2.11166679895688,,0.000344937910968426,,,,,,,,,0,5000,,-84.6313264216668,,-81.0053860742293,,6.81388718612122E-7,,0.00021564438540717,,,,,,,,,,,,,,,,,,,,,,,,,,
,30546514.8,4370,52.19285,312.857,90.014,0.102153342753992,173,0.00111741149051408,,1.80583625792025E-7,,10.9386935597509,,0.00176779003479672,,,,,,,,,,0,2500,-84.7180036665158,,-81.8255655496675,,-4.15355267861285E-6,,0.00111741151695927,,,,,,,,,,,,,,,,,,,,,,,,,,,
,30546563.58,4370,49.7497,312.857,90.014,0.102153342753992,173,,0.000214847427719539,,3.40293720707643E-8,,2.10386023704635,,0.000333227358426671,,,,,,,,,0,5000,,-85.015343272619,,-79.6628754565169,,8.64963695289183E-7,,0.000214847433684204,,,,,,,,,,,,,,,,,,,,,,,,,,
,30546614.89,4370,47.18835,312.857,90.014,0.102153342753992,173,0.00111333673157954,,1.65633774722569E-7,,10.8988040102551,,0.00162144115820503,,,,,,,,,,0,2500,-87.3858375199765,,-82.446042878168,,-4.41639958958964E-6,,0.0011133367615871,,,,,,,,,,,,,,,,,,,,,,,,,,,
,30546664.79,4370,44.69215,312.857,90.014,0.102153342753992,173,,0.000214072517535174,,3.27960613202689E-8,,2.09626962311907,,0.000321149983850239,,,,,,,,,0,5000,,-87.2175202258331,,-80.6143985023668,,7.7777093705666E-7,,0.00021407252237537,,,,,,,,,,,,,,,,,,,,,,,,,,
,30546716.735,4370,42.0856,312.857,90.014,0.102153342753992,173,0.00110920277871654,,1.87108410763839E-7,,10.8583349895577,,0.00183166305550204,,,,,,,,,,0,2500,-85.7174091345164,,-80.8712664786175,,-4.31245559725853E-6,,0.00110920280743484,,,,,,,,,,,,,,,,,,,,,,,,,,,
,30546767.235,4370,39.5676,312.857,90.014,0.102153342753992,173,,0.00021331587940084,,3.33186877377172E-8,,2.08885800956536,,0.00032626734861639,,,,,,,,,0,5000,,-84.3255475119737,,-80.4645447751741,,7.20301929084391E-7,,0.000213315883566909,,,,,,,,,,,,,,,,,,,,,,,,,,
,30546819.155,4370,36.98415,312.857,90.014,0.102153342753992,173,0.00110519160193305,,1.6463996109125E-7,,10.8190678792918,,0.00161171227464667,,,,,,,,,,0,2500,-92.6115117100426,,-81.841300935662,,-4.19789292132962E-6,,0.00110519162924455,,,,,,,,,,,,,,,,,,,,,,,,,,,
,30546869.475,4370,34.47785,312.857,90.014,0.102153342753992,173,,0.000212612423705339,,3.39075013838191E-8,,2.08196735713442,,0.000332032854116628,,,,,,,,,0,5000,,-85.904819984189,,-80.4110335948699,,6.64055373595964E-7,,0.000212612427257891,,,,,,,,,,,,,,,,,,,,,,,,,,
,30546923.36,4370,31.7898,312.857,90.014,0.102153342753992,173,0.00110142653319135,,1.72679139085511E-7,,10.7822100278936,,0.00169041024602067,,,,,,,,,,0,2500,-88.5734073848543,,-82.0072427819891,,-4.27799094241906E-6,,0.00110142656165198,,,,,,,,,,,,,,,,,,,,,,,,,,,
,30546973.175,4370,29.2948,312.857,90.014,0.102153342753992,173,,0.000211905368992746,,3.52407900816307E-8,,2.07504146536399,,0.000345088469035219,,,,,,,,,0,5000,,-84.4887396218126,,-79.8811382328734,,6.89348731064889E-7,,0.000211905372833853,,,,,,,,,,,,,,,,,,,,,,,,,,
,30547025.44,4370,26.69235,312.857,90.014,0.102153342753992,173,0.00109812168354766,,1.7042639107471E-7,,10.7498574583361,,0.00166835733363751,,,,,,,,,,0,2500,-86.5079701006779,,-82.5120148917255,,-4.259683606814E-6,,0.00109812171185015,,,,,,,,,,,,,,,,,,,,,,,,,,,
,30547077.195,4370,24.1156,312.857,90.014,0.102153342753992,173,,0.000211310582242873,,3.26229733205593E-8,,2.06921529579799,,0.000319453731164405,,,,,,,,,0,5000,,-85.8088868250962,,-80.2103403394317,,7.50190060256947E-7,,0.000211310586804731,,,,,,,,,,,,,,,,,,,,,,,,,,
,30547129.585,4370,21.5078,312.857,90.014,0.102153342753992,173,0.00109536778833259,,1.64758173430477E-7,,10.7228984161258,,0.00161286933246491,,,,,,,,,,0,2500,-90.6909884086215,,-81.6672116113217,,-4.14585613550949E-6,,0.00109536781521009,,,,,,,,,,,,,,,,,,,,,,,,,,,
,30547179.99,4370,19.00415,312.857,90.014,0.102153342753992,173,,0.000210890271933195,,3.35122725406743E-8,,2.06509819765625,,0.00032816180493187,,,,,,,,,0,5000,,-85.5910903233311,,-80.4563576242522,,7.09827122201476E-7,,0.00021089027602551,,,,,,,,,,,,,,,,,,,,,,,,,,
,30547235.31,4370,16.26365,312.857,90.014,0.102153342753992,173,0.00109349131917461,,1.73859276905753E-7,,10.7045288686603,,0.00170196285008093,,,,,,,,,,0,2500,-85.0348937073512,,-82.0884997343124,,-4.18089607713664E-6,,0.00109349134655527,,,,,,,,,,,,,,,,,,,,,,,,,,,
,30547284.805,4370,13.75355,312.857,90.014,0.102153342753992,173,,0.000210587224808993,,3.4513899786163E-8,,2.06212973988707,,0.00033796987357951,,,,,,,,,0,5000,,-86.5413340728782,,-79.4675492814835,,7.24362110462885E-7,,0.000210587229076751,,,,,,,,,,,,,,,,,,,,,,,,,,
,30547336.525,4370,11.27,312.857,90.014,0.102153342753992,173,0.00109268336517422,,1.70869442216526E-7,,10.6966194666356,,0.00167269440906491,,,,,,,,,,0,2500,-86.7665622444306,,-80.7468125080296,,-4.19128089330355E-6,,0.00109268339271141,,,,,,,,,,,,,,,,,,,,,,,,,,,
,30547385.225,4375,9.4984,312.857,90.014,0.102153342753992,173,,0.000210536032972216,,3.27424729255263E-8,,2.06162829732887,,0.000320623536058084,,,,,,,,,0,5000,,-85.9043206928502,,-80.2118388723426,,7.1902877835577E-7,,0.000210536037178383,,,,,,,,,,,,,,,,,,,,,,,,,,
,30547488.03,4375,9.37785,312.857,90.014,0.102153342753992,173,0.00109259873537163,,1.67120060066269E-7,,10.695790989859,,0.00163599053291954,,,,,,,,,,0,2500,-88.9193290875735,,-83.0476337257322,,-4.20426442067255E-6,,0.00109259876308184,,,,,,,,,,,,,,,,,,,,,,,,,,,
,30547548.335,4375,9.11685,312.857,90.014,0.102153342753992,173,,0.000210453750463144,,3.31345518136102E-8,,2.06082231055015,,0.000324462842139472,,,,,,,,,0,5000,,-86.4177997264567,,-78.6734680047556,,7.81636071315224E-7,,0.000210453755435623,,,,,,,,,,,,,,,,,,,,,,,,,,
,30547621.32,4375,8.8114,312.857,90.014,0.102153342753992,173,0.00109256811330235,,1.67812514135748E-7,,10.6954912175276,,0.00164276918290465,,,,,,,,,,0,2500,-85.6675118914759,,-82.2834642034565,,-4.1508199535803E-6,,0.00109256814031329,,,,,,,,,,,,,,,,,,,,,,,,,,,
,30547678.53,4375,8.5874,312.857,90.014,0.102153342753992,173,,0.00021043996011935,,3.27461577205299E-8,,2.06068722919078,,0.000320659571444914,,,,,,,,,0,5000,,-85.3474338647998,,-79.2496815964819,,7.81251219585656E-7,,0.000210439965087259,,,,,,,,,,,,,,,,,,,,,,,,,,
,30547738.68,4375,8.3737,312.857,90.014,0.102153342753992,173,0.00109258199811695,,1.66220791497737E-7,,10.6956271418247,,0.00162718731165289,,,,,,,,,,0,2500,-89.456456163277,,-81.9036096739849,,-4.19082197744823E-6,,0.00109258202565067,,,,,,,,,,,,,,,,,,,,,,,,,,,
,30547798.31,4375,8.164,312.857,90.014,0.102153342753992,173,,0.000210456930495217,,3.43164222823342E-8,,2.06085346010469,,0.000336036051855293,,,,,,,,,0,5000,,-84.9993429409634,,-78.5915723919873,,7.62421278711587E-7,,0.000210456935226155,,,,,,,,,,,,,,,,,,,,,,,,,,
,30547868.445,4375,7.92445,312.857,90.014,0.102153342753992,173,0.00109258188186152,,1.65300134062206E-7,,10.6956260037513,,0.00161817471028392,,,,,,,,,,0,2500,-89.5007600617341,,-82.1972890506915,,-4.07649395171074E-6,,0.00109258190791346,,,,,,,,,,,,,,,,,,,,,,,,,,,
,30547931.37,4375,7.72325,312.857,90.014,0.102153342753992,173,,0.000210505142609269,,3.35966942926103E-8,,2.06132571508732,,0.000328988297726364,,,,,,,,,0,5000,,-86.3380031243698,,-79.688110039899,,7.12146544774579E-7,,0.000210505146735908,,,,,,,,,,,,,,,,,,,,,,,,,,
,30548023.76,4375,7.45795,312.857,90.014,0.102153342753992,173,0.00109260122465405,,1.75476128652614E-7,,10.6958153584928,,0.00171779070024632,,,,,,,,,,0,2500,-86.3220006133002,,-81.6564237319254,,-4.27011544061099E-6,,0.00109260125323904,,,,,,,,,,,,,,,,,,,,,,,,,,,
,30548083.13,4375,7.2882,312.857,90.014,0.102153342753992,173,,0.000210510666503634,,3.18848638076942E-8,,2.06137982362203,,0.000312225574365628,,,,,,,,,0,5000,,-85.6661551042593,,-80.9320043590854,,6.79482706146844E-7,,0.000210510670260305,,,,,,,,,,,,,,,,,,,,,,,,,,
,30548139.3,4375,7.1406,312.857,90.014,0.102153342753992,173,0.00109262945557104,,1.66180486688751E-7,,10.6960917228276,,0.00162679275788845,,,,,,,,,,0,2500,-85.8265649600526,,-82.3420530761718,,-4.09612680728042E-6,,0.00109262948187338,,,,,,,,,,,,,,,,,,,,,,,,,,,
,30548195.135,4375,7.0613,312.857,90.014,0.102153342753992,173,,0.000210458730018733,,3.43466247925775E-8,,2.06087108708298,,0.000336331804366129,,,,,,,,,0,5000,,-84.8913293755766,,-79.0956963610755,,7.55430529929813E-7,,0.000210458734663272,,,,,,,,,,,,,,,,,,,,,,,,,,
,30548435.65,4374,5.75595,312.857,90.014,0.102153342753992,173,0.0010926532495856,,1.75219936967903E-7,,10.6963246524562,,0.00171528276005136,,,,,,,,,,0,2500,-90.9127471963908,,-81.1732683535815,,-4.29764985133105E-6,,0.00109265327853904,,,,,,,,,,,,,,,,,,,,,,,,,,,
,30548484.15,4373,4.99345,312.857,90.014,0.102153342753992,173,,0.000210555858908654,,3.1452952210499E-8,,2.06182249953857,,0.000307996194149934,,,,,,,,,0,5000,,-85.7986209186323,,-80.5401301965346,,7.32589375150751E-7,,0.000210555863274559,,,,,,,,,,,,,,,,,,,,,,,,,,
,30548583.545,4374,9.2959,312.857,90.014,0.102153342753992,173,0.00109258907573569,,1.74862543432945E-7,,10.6956964276149,,0.0017117841221618,,,,,,,,,,0,2500,-88.9359526611518,,-82.1134363847991,,-4.28300083961074E-6,,0.00109258910449377,,,,,,,,,,,,,,,,,,,,,,,,,,,
,30548634.42,4370,19.3667,312.857,90.014,0.102153342753992,173,,0.000210875343793443,,3.27198893178019E-8,,2.06495197098736,,0.00032040255278282,,,,,,,,,0,5000,,-85.4374174489405,,-79.8061652392005,,7.50769009043686E-7,,0.000210875348371775,,,,,,,,,,,,,,,,,,,,,,,,,,
,30548686.61,4370,29.8745,312.857,90.014,0.102153342753992,173,0.00109984544206104,,1.59326570362253E-7,,10.7667320584922,,0.00155969774031591,,,,,,,,,,0,2500,-88.0563416759863,,-82.7740326113558,,-4.16860317517368E-6,,0.00109984546912366,,,,,,,,,,,,,,,,,,,,,,,,,,,
,30548737.25,4370,40.0825,312.857,90.014,0.102153342753992,173,,0.000213318878178641,,3.32918604314407E-8,,2.08888738392038,,0.000326004648236164,,,,,,,,,0,5000,,-87.6788736284874,,-80.6641409149417,,7.31243763891011E-7,,0.00021331888247218,,,,,,,,,,,,,,,,,,,,,,,,,,
,30548790.915,4370,50.80415,312.857,90.014,0.102153342753992,173,0.00111530570766578,,1.73122194597688E-7,,10.9180791547821,,0.00169474769445918,,,,,,,,,,0,2500,-87.9874107088292,,-81.1532741271055,,-4.26675179698931E-6,,0.00111530573562476,,,,,,,,,,,,,,,,,,,,,,,,,,,
,30548841.36,4370,60.96105,312.857,90.014,0.102153342753992,173,,0.000216343937555935,,3.50148404334818E-8,,2.11851931259467,,0.000342878172881912,,,,,,,,,0,5000,,-85.4747084324436,,-78.8279150967332,,7.82568529158361E-7,,0.00021634394240458,,,,,,,,,,,,,,,,,,,,,,,,,,
,30548893.685,4370,71.42525,312.857,90.014,0.102153342753992,173,0.00113129109499091,,1.71943171172914E-7,,11.0745669400272,,0.00168320613186227,,,,,,,,,,0,2500,-89.097416001359,,-81.3327916315658,,-4.47456004770464E-6,,0.00113129112530516,,,,,,,,,,,,,,,,,,,,,,,,,,,
,30548944.75,4370,81.6565,312.857,90.014,0.102153342753992,173,,0.000219486381538416,,3.56022054089547E-8,,2.1493013640923,,0.000348631502743005,,,,,,,,,0,5000,,-85.6806193228496,,-79.769775114656,,7.72311524990206E-7,,0.000219486386193182,,,,,,,,,,,,,,,,,,,,,,,,,,
,30549004.875,4370,93.6801,312.857,90.014,0.102153342753992,173,0.00114804936014751,,1.81676426982535E-7,,11.2386208108283,,0.00177848835922027,,,,,,,,,,0,2500,-86.0600962078837,,-80.4545219249469,,-4.3534777980981E-6,,0.00114804938842446,,,,,,,,,,,,,,,,,,,,,,,,,,,
,30549058.6,4370,104.37625,312.857,90.014,0.102153342753992,173,,0.000222899966853899,,3.34017230567871E-8,,2.18273972871034,,0.000327085137397904,,,,,,,,,0,5000,,-86.7101961233508,,-81.2793934580736,,8.07529347340399E-7,,0.000222899971864929,,,,,,,,,,,,,,,,,,,,,,,,,,
,30549110.665,4370,114.80815,312.857,90.014,0.102153342753992,173,0.00116387340734733,,1.78536125610794E-7,,11.3935292709614,,0.00174774722561889,,,,,,,,,,0,2500,-87.5763356557293,,-82.3235812872733,,-4.59921483862244E-6,,0.00116387343847754,,,,,,,,,,,,,,,,,,,,,,,,,,,
,30549160.035,4370,124.6924,312.857,90.014,0.102153342753992,173,,0.000225744556928337,,3.47194013657307E-8,,2.21060466255947,,0.000339989897656211,,,,,,,,,0,5000,,-84.9064594563567,,-80.3754557722997,,8.19824014281216E-7,,0.000225744562028035,,,,,,,,,,,,,,,,,,,,,,,,,,
,30549212.37,4370,135.16855,312.857,90.014,0.102153342753992,173,0.00117878696558887,,1.80122057711232E-7,,11.5395246052126,,0.00176327268716292,,,,,,,,,,0,2500,-89.2711020285494,,-81.7025121501826,,-4.69567462654463E-6,,0.00117878699762803,,,,,,,,,,,,,,,,,,,,,,,,,,,
,30549262.5,4370,145.18685,312.857,90.014,0.102153342753992,173,,0.000228698865819357,,3.52876178001753E-8,,2.23954462667559,,0.000345555685269327,,,,,,,,,0,5000,,-86.4671290699539,,-83.0424419327002,,7.69893976070531E-7,,0.000228698870258696,,,,,,,,,,,,,,,,,,,,,,,,,,
,30549315.34,4370,155.75185,312.857,90.014,0.102153342753992,173,0.00119365399504154,,1.77350905241607E-7,,11.685064492645,,0.00173614524332845,,,,,,,,,,0,2500,-87.8771838156339,,-81.6626108249024,,-4.90366002835444E-6,,0.00119365402954659,,,,,,,,,,,,,,,,,,,,,,,,,,,
,30549365.755,4370,165.8416,312.857,90.014,0.102153342753992,173,,0.00023144659594028,,3.83779852367043E-8,,2.26646120551976,,0.000375819799119052,,,,,,,,,0,5000,,-84.6286026018032,,-80.0855573489168,,7.32403500882318E-7,,0.000231446599910097,,,,,,,,,,,,,,,,,,,,,,,,,,
,30549418.305,4370,176.36955,312.857,90.014,0.102153342753992,173,0.00120843490602542,,1.74536550243186E-7,,11.8297613718922,,0.00170859487418992,,,,,,,,,,0,2500,-89.4731433967151,,-83.9238754596278,,-4.71428199924609E-6,,0.00120843493752671,,,,,,,,,,,,,,,,,,,,,,,,,,,
,30549468.66,4370,186.438,312.857,90.014,0.102153342753992,173,,0.000234295897676855,,3.76514190678658E-8,,2.29437300634398,,0.000368706404718138,,,,,,,,,0,5000,,-84.8491191560285,,-81.2412499147198,,7.42794332206362E-7,,0.000234295901710455,,,,,,,,,,,,,,,,,,,,,,,,,,
,30549520.645,4370,196.379,312.857,90.014,0.102153342753992,173,0.00122284952734901,,1.76285690271199E-7,,11.9708725211914,,0.00172571801597943,,,,,,,,,,0,2500,-87.121741502111,,-83.0213524596675,,-5.20027278769886E-6,,0.00122284956522811,,,,,,,,,,,,,,,,,,,,,,,,,,,
,30549571.405,4374,205.73055,312.857,90.014,0.102153342753992,173,,0.000236910149011318,,3.65939358497775E-8,,2.31998245898636,,0.000358352259291337,,,,,,,,,0,5000,,-87.2327457335738,,-80.8428594753522,,9.06599854795396E-7,,0.000236910154953802,,,,,,,,,,,,,,,,,,,,,,,,,,
,30549623.56,4374,214.9733,312.857,90.014,0.102153342753992,173,0.00123624186856448,,1.8513621494529E-7,,12.1019761519784,,0.00181235892961903,,,,,,,,,,0,2500,-84.8439560154677,,-82.7116869994838,,-5.22193245771335E-6,,0.00123624190634601,,,,,,,,,,,,,,,,,,,,,,,,,,,
,30549673.555,4374,223.5492,312.857,90.014,0.102153342753992,173,,0.000239349722167126,,3.80977454869832E-8,,2.34388092807504,,0.000373079926949412,,,,,,,,,0,5000,,-85.9535402276702,,-80.0997596798376,,9.05297282110214E-7,,0.000239349728032152,,,,,,,,,,,,,,,,,,,,,,,,,,
,30549726.43,4374,232.3296,312.857,90.014,0.102153342753992,173,0.00124872929612581,,1.76070404410002E-7,,12.2242212093915,,0.00172361095744693,,,,,,,,,,0,2500,-87.4102729958002,,-82.8022143442876,,-5.60396096176879E-6,,0.0012487293392025,,,,,,,,,,,,,,,,,,,,,,,,,,,
,30549776.61,4374,240.42775,312.857,90.014,0.102153342753992,173,,0.000241588459001975,,3.94720648633208E-8,,2.36581212398851,,0.000386539523199408,,,,,,,,,0,5000,,-83.7616840041665,,-78.6648765421384,,8.23697151540539E-7,,0.000241588463812355,,,,,,,,,,,,,,,,,,,,,,,,,,
,30549829.425,4374,248.7391,312.857,90.014,0.102153342753992,173,0.00126041221375067,,1.96897549223099E-7,,12.3385905843282,,0.00192749493968912,,,,,,,,,,0,2500,-87.9881729481962,,-82.1918602055218,,-5.62891259462901E-6,,0.00126041225680896,,,,,,,,,,,,,,,,,,,,,,,,,,,
,30549879.865,4374,256.4711,312.857,90.014,0.102153342753992,173,,0.000243850653711277,,3.88708264271857E-8,,2.3879732677445,,0.00038065303869457,,,,,,,,,0,5000,,-84.2138769879549,,-79.2741658166428,,8.82085407905028E-7,,0.000243850659176625,,,,,,,,,,,,,,,,,,,,,,,,,,
,30549931.885,4374,264.2474,312.857,90.014,0.102153342753992,173,0.00127183070863317,,1.85831575884867E-7,,12.4503714313164,,0.00181916669687043,,,,,,,,,,0,2500,-88.7656915317139,,-82.2699363229518,,-5.50440628675886E-6,,0.00127183074943805,,,,,,,,,,,,,,,,,,,,,,,,,,,
,30549983.335,4374,271.8052,312.857,90.014,0.102153342753992,173,,0.000246046592643563,,3.71267438113958E-8,,2.40948549308067,,0.00036357483220141,,,,,,,,,0,5000,,-84.9483962491384,,-81.1070848487835,,8.85536541646132E-7,,0.0002460465981026,,,,,,,,,,,,,,,,,,,,,,,,,,
,30550035.5,4374,279.2723,312.857,90.014,0.102153342753992,173,0.001282693221321,,1.76643093947118E-7,,12.5567095393287,,0.00172921779595237,,,,,,,,,,0,2500,-89.101378035151,,-82.4915221717125,,-5.80326988086605E-6,,0.0012826932662931,,,,,,,,,,,,,,,,,,,,,,,,,,,
,30550085.755,4374,286.4368,312.857,90.014,0.102153342753992,173,,0.000248089138971383,,3.88793941098425E-8,,2.4294951547036,,0.000380739351541017,,,,,,,,,0,5000,,-83.953018320193,,-79.9929250638364,,8.0685954579995E-7,,0.000248089143466165,,,,,,,,,,,,,,,,,,,,,,,,,,
,30550138.47,4374,293.7624,312.857,90.014,0.102153342753992,173,0.00129329190115143,,1.91833312067298E-7,,12.6604648892641,,0.00187792007537008,,,,,,,,,,0,2500,-89.7497219613569,,-81.4788721469203,,-5.93248379086108E-6,,0.00129329194776335,,,,,,,,,,,,,,,,,,,,,,,,,,,
,30550189.15,4374,300.74355,312.857,90.014,0.102153342753992,173,,0.000250173203670333,,4.13506092427402E-8,,2.44991167394773,,0.000404940802640686,,,,,,,,,0,5000,,-83.7438027849028,,-79.7172259466373,,9.33339124821714E-7,,0.000250173209634621,,,,,,,,,,,,,,,,,,,,,,,,,,
,30550209.36,4374,300.74705,312.857,90.014,0.102153342753992,173,,0.000250405988136085,,3.9246109225665E-8,,2.45219215255792,,0.000384331856971929,,,,,,,,,0,5000,,-83.6322115945994,,-81.0133612067326,,1.0029294959672E-6,,0.00025040599501653,,,,,,,,,,,,,,,,,,,,,,,,,,