File: Data/YT Group/RVC64e (5 nm Ta)/20170512-RVC64e.dc.raw
[Header]
TITLE,MPMS DC Measurement
BYAPP,MPMS Measurement,2.1,Raw with ABS
FILEOPENTIME, 1494628369.443000 5/12/2017, 3:32:49 PM

INFO, APPNAME, MPMS MultiVu Application, Revision 1.61,  Build 082

INFO, NAME, RVC64E
INFO, WEIGHT, 1.000
INFO, AREA, 1.000
INFO, LENGTH, 1.000
INFO, SHAPE, film on substrate
INFO, COMMENT, H in plane
INFO, SEQUENCE FILE: 20170509-RVC64b.seq


INFO, BACKGROUND DATA FILE:, None


STARTUPAXIS,X,8,LINEAR,AUTO,0.000000,0.000000
STARTUPAXIS,Y1,10,LINEAR,AUTO,0.000000,0.000000


STARTUPGROUP,Longitudinal
FIELDGROUP,Longitudinal,1,3,4,5,6,8,9,10,11,12,13,14,15,16,17,18,19,20,21,22,23
FIELDGROUP,Transverse,1,3,4,5,6,8,9,24,25,26,27,28,29,30,31,32,33,34,35,36,37

PLOT_APPEARANCE,ALL,HORZ_GRID_ON,VERT_GRID_ON,MARKERS_ONLY

[Data]
Time,Comment,Field (Oe),Start Temperature (K),End Temperature (K),Scan,Rejected,Position (cm),Rot Position (deg),Long Voltage,Long Average Voltage,Long Detrended Voltage,Long Demeaned Voltage,Long Regression Fit,Long Detrended Fit,Long Demeaned Fit,Long Scaled Response,Long Avg. Scaled Response,Long Background Response,Long Response [w/ABS],Long Detrended Resp. [w/ABS],Long Fit [w/ABS],Long Detrended Fit [w/ABS],Trans Voltage,Trans Average Voltage,Trans Detrended Voltage,Trans Demeaned Voltage,Trans Regression Fit,Trans Detrended Fit,Trans Demeaned Fit,Trans Scaled Response,Trans Avg Scaled Response,Trans Background Response,Trans Response [w/ABS],Trans Detrended Resp. [w/ABS],Trans Fit [w/ABS],Trans Detrended Fit [w/ABS],
1494628369.423,,1.000000e+001,4.996823e+000,5.000082e+000,1,0,0.000000e+000,0.000000e+000,4.272526e-002,,,,,,,1.197308e-005,,,,,,,,,,,,,,,,,,,,,
1494628369.423,,1.000000e+001,4.996823e+000,5.000082e+000,1,0,4.723404e+000,0.000000e+000,1.561151e+000,,,,,,,7.918484e-005,,,,,,,,,,,,,,,,,,,,,
1494628369.423,,1.000000e+001,4.991467e+000,4.991372e+000,2,0,3.319149e+000,0.000000e+000,-1.752804e+000,-1.755016e+000,-1.675514e+000,-1.619834e+000,-1.618596e+000,-1.539093e+000,-1.483414e+000,-7.637900e-005,-7.683749e-005,,,,,,,,,,,,,,,,,,,,
1494628521.443,,1.000000e+001,6.976003e+000,6.972896e+000,1,0,1.914894e+000,0.000000e+000,-9.959564e-001,,,,,,,-2.335788e-005,,,,,,,,,,,,,,,,,,,,,
1494628521.443,,1.000000e+001,6.997177e+000,6.976225e+000,2,0,5.106383e-001,0.000000e+000,-2.838178e-002,-3.219654e-002,4.209473e-001,4.297733e-001,5.502871e-001,1.003431e+000,1.012257e+000,2.378428e-005,2.385690e-005,,,,,,,,,,,,,,,,,,,,
1494628521.443,,1.000000e+001,6.997177e+000,6.976225e+000,2,0,5.234043e+000,0.000000e+000,-7.734799e-001,-7.603571e-001,-3.888542e-001,-2.983873e-001,1.663437e-001,5.378466e-001,6.283135e-001,-1.717026e-005,-1.621435e-005,,,,,,,,,,,,,,,,,,,,
1494628658.904,,1.000000e+001,8.960138e+000,8.954179e+000,1,0,3.829787e+000,0.000000e+000,1.552148e+000,,,,,,,9.651233e-005,,,,,,,,,,,,,,,,,,,,,
1494628658.904,,1.000000e+001,8.954179e+000,8.955370e+000,2,0,2.425532e+000,0.000000e+000,-3.282521e+000,-3.249180e+000,-2.806663e+000,-2.762216e+000,-3.641598e+000,-3.199080e+000,-3.154634e+000,-1.321394e-004,-1.305074e-004,,,,,,,,,,,,,,,,,,,,
1494628799.054,,1.000000e+001,1.092861e+001,1.092560e+001,1,0,1.021277e+000,0.000000e+000,6.460670e-001,,,,,,,5.174588e-005,,,,,,,,,,,,,,,,,,,,,
1494628799.054,,1.000000e+001,1.092861e+001,1.092560e+001,1,0,5.744681e+000,0.000000e+000,-8.429084e-001,,,,,,,-2.489901e-005,,,,,,,,,,,,,,,,,,,,,
1494628799.054,,1.000000e+001,1.093844e+001,1.092720e+001,2,0,4.340425e+000,0.000000e+000,2.093843e+000,2.053330e+000,2.355760e+000,2.439984e+000,1.279856e+000,1.582286e+000,1.666510e+000,1.167321e-004,1.147539e-004,,,,,,,,,,,,,,,,,,,,
1494628946.554,,1.000000e+001,1.291137e+001,1.291042e+001,1,0,2.936170e+000,0.000000e+000,-3.872130e+000,,,,,,,-1.649135e-004,,,,,,,,,,,,,,,,,,,,,
1494628946.554,,1.000000e+001,1.292003e+001,1.290991e+001,2,0,1.531915e+000,0.000000e+000,8.834974e-001,8.968490e-001,1.275674e+000,1.306248e+000,3.204999e-001,6.993253e-001,7.298990e-001,6.356997e-005,6.399638e-005,,,,,,,,,,,,,,,,,,,,
1494629092.374,,1.000000e+001,1.488912e+001,1.488969e+001,1,0,1.276596e-001,0.000000e+000,-1.744106e-001,,,,,,,1.424603e-005,,,,,,,,,,,,,,,,,,,,,
1494629092.374,,1.000000e+001,1.488912e+001,1.488969e+001,1,0,4.851064e+000,0.000000e+000,7.513542e-001,,,,,,,5.280800e-005,,,,,,,,,,,,,,,,,,,,,
1494629092.374,,1.000000e+001,1.489138e+001,1.489760e+001,2,0,3.446809e+000,0.000000e+000,-8.429084e-001,-8.313115e-001,-5.069790e-001,-4.362705e-001,-1.232431e+000,-9.080986e-001,-8.373901e-001,-2.227016e-005,-2.131149e-005,,,,,,,,,,,,,,,,,,,,
1494629228.204,,1.000000e+001,1.686834e+001,1.686980e+001,1,0,2.042553e+000,0.000000e+000,-1.404440e+000,,,,,,,-5.851131e-005,,,,,,,,,,,,,,,,,,,,,
1494629228.204,,1.000000e+001,1.686980e+001,1.687489e+001,2,0,6.382979e-001,0.000000e+000,4.141299e-001,4.125277e-001,5.473753e-001,5.596851e-001,1.009793e+000,1.144641e+000,1.156950e+000,2.939028e-005,2.949039e-005,,,,,,,,,,,,,,,,,,,,
1494629228.204,,1.000000e+001,1.686980e+001,1.687489e+001,2,0,5.361702e+000,0.000000e+000,-6.092927e-001,-6.105897e-001,-5.668344e-001,-4.634323e-001,3.797050e-001,4.234604e-001,5.268624e-001,-2.453999e-005,-2.463238e-005,,,,,,,,,,,,,,,,,,,,
1494629363.935,,1.000000e+001,1.884618e+001,1.884709e+001,1,0,3.957447e+000,0.000000e+000,2.617686e+000,,,,,,,1.067412e-004,,,,,,,,,,,,,,,,,,,,,
1494629363.935,,1.000000e+001,1.885071e+001,1.885071e+001,2,0,2.553191e+000,0.000000e+000,-2.587472e+000,-2.579233e+000,-2.982527e+000,-2.924311e+000,-3.061467e+000,-3.464761e+000,-3.406545e+000,-1.394724e-004,-1.390439e-004,,,,,,,,,,,,,,,,,,,,
1494629515.095,,1.000000e+001,2.082054e+001,2.082714e+001,1,0,1.148936e+000,0.000000e+000,1.469749e+000,,,,,,,6.274979e-005,,,,,,,,,,,,,,,,,,,,,
1494629515.095,,1.000000e+001,2.082054e+001,2.082714e+001,1,0,5.872340e+000,0.000000e+000,-1.615930e-001,,,,,,,-2.053218e-005,,,,,,,,,,,,,,,,,,,,,
1494629515.095,,1.000000e+001,2.083265e+001,2.083595e+001,2,0,4.468085e+000,0.000000e+000,2.470588e+000,2.480812e+000,2.186939e+000,2.278134e+000,1.793398e+000,1.499526e+000,1.590720e+000,1.059981e-004,1.067145e-004,,,,,,,,,,,,,,,,,,,,
1494629666.115,,1.000000e+001,2.280225e+001,2.280423e+001,1,0,3.063830e+000,0.000000e+000,-3.359884e+000,,,,,,,-1.450782e-004,,,,,,,,,,,,,,,,,,,,,
1494629666.115,,1.000000e+001,2.280554e+001,2.281211e+001,2,0,1.659575e+000,0.000000e+000,5.648890e-001,5.515374e-001,8.291984e-001,8.638215e-001,-5.750220e-002,2.201588e-001,2.547819e-001,4.299623e-005,4.259524e-005,,,,,,,,,,,,,,,,,,,,
1494629816.565,,1.000000e+001,2.478103e+001,2.477948e+001,1,0,2.553191e-001,0.000000e+000,-3.294423e-001,,,,,,,1.524419e-005,,,,,,,,,,,,,,,,,,,,,
1494629816.565,,1.000000e+001,2.478103e+001,2.477948e+001,1,0,4.978724e+000,0.000000e+000,-5.645838e-003,,,,,,,2.535896e-005,,,,,,,,,,,,,,,,,,,,,
1494629816.565,,1.000000e+001,2.478642e+001,2.479182e+001,2,0,3.574468e+000,0.000000e+000,2.288853e-003,4.425116e-003,5.171393e-001,5.816087e-001,-8.529698e-001,-3.402556e-001,-2.757862e-001,2.712094e-005,2.731861e-005,,,,,,,,,,,,,,,,,,,,
1494629986.166,,1.000000e+001,2.677217e+001,2.677395e+001,1,0,2.170213e+000,0.000000e+000,-1.927977e+000,,,,,,,-8.938267e-005,,,,,,,,,,,,,,,,,,,,,
1494629986.166,,1.000000e+001,2.677484e+001,2.677663e+001,2,0,7.659575e-001,0.000000e+000,6.547647e-001,6.510262e-001,6.645472e-001,6.789665e-001,1.297757e+000,1.311278e+000,1.325697e+000,3.514948e-005,3.499996e-005,,,,,,,,,,,,,,,,,,,,
1494629986.166,,1.000000e+001,2.677484e+001,2.677663e+001,2,0,5.489362e+000,0.000000e+000,-5.502403e-001,-5.657282e-001,-6.411265e-001,-5.377880e-001,4.099608e-001,3.345625e-001,4.379011e-001,-2.741507e-005,-2.825524e-005,,,,,,,,,,,,,,,,,,,,
1494630130.246,,1.000000e+001,2.875100e+001,2.875100e+001,1,0,4.085106e+000,0.000000e+000,2.777142e+000,,,,,,,1.145855e-004,,,,,,,,,,,,,,,,,,,,,
1494630130.246,,1.000000e+001,2.874998e+001,2.875304e+001,2,0,2.680851e+000,0.000000e+000,-2.981918e+000,-2.930266e+000,-3.330759e+000,-3.276825e+000,-3.137633e+000,-3.538126e+000,-3.484192e+000,-1.582949e-004,-1.556728e-004,,,,,,,,,,,,,,,,,,,,
1494630289.996,,1.000000e+001,3.073207e+001,3.072513e+001,1,0,1.276596e+000,0.000000e+000,1.235828e+000,,,,,,,6.512273e-005,,,,,,,,,,,,,,,,,,,,,
1494630289.996,,1.000000e+001,3.073207e+001,3.072513e+001,1,0,6.000000e+000,0.000000e+000,-3.924620e-001,,,,,,,-1.781324e-005,,,,,,,,,,,,,,,,,,,,,
1494630289.996,,1.000000e+001,3.073555e+001,3.072513e+001,2,0,4.595745e+000,0.000000e+000,1.841154e+000,1.904936e+000,1.905679e+000,1.996625e+000,1.311286e+000,1.312029e+000,1.402975e+000,9.023605e-005,9.322500e-005,,,,,,,,,,,,,,,,,,,,
1494630439.996,,1.000000e+001,3.271481e+001,3.270438e+001,1,0,3.191489e+000,0.000000e+000,-2.748150e+000,,,,,,,-1.135771e-004,,,,,,,,,,,,,,,,,,,,,
1494630439.996,,1.000000e+001,3.270699e+001,3.271481e+001,2,0,1.787234e+000,0.000000e+000,-9.857328e-002,-1.078813e-001,2.274411e-001,2.610097e-001,-6.115239e-001,-2.762014e-001,-2.426329e-001,1.455728e-005,1.388753e-005,,,,,,,,,,,,,,,,,,,,
1494630600.386,,1.000000e+001,3.469533e+001,3.469387e+001,1,0,3.829787e-001,0.000000e+000,-3.677424e-002,,,,,,,1.771776e-005,,,,,,,,,,,,,,,,,,,,,
1494630600.386,,1.000000e+001,3.469533e+001,3.469387e+001,1,0,5.106383e+000,0.000000e+000,-2.822919e-001,,,,,,,7.567196e-007,,,,,,,,,,,,,,,,,,,,,
1494630600.386,,1.000000e+001,3.469533e+001,3.468513e+001,2,0,3.702128e+000,0.000000e+000,1.001297e+000,1.083390e+000,1.363991e+000,1.435708e+000,-1.085018e-001,1.720988e-001,2.438157e-001,6.388962e-005,6.757191e-005,,,,,,,,,,,,,,,,,,,,
1494630760.997,,1.000000e+001,3.667731e+001,3.668379e+001,1,0,2.297872e+000,0.000000e+000,-2.403754e+000,,,,,,,-1.051460e-004,,,,,,,,,,,,,,,,,,,,,
1494630760.997,,1.000000e+001,3.667893e+001,3.666759e+001,2,0,8.936170e-001,0.000000e+000,6.582742e-001,6.427100e-001,8.060618e-001,8.231134e-001,1.247692e+000,1.411044e+000,1.428095e+000,4.233797e-005,4.153842e-005,,,,,,,,,,,,,,,,,,,,
1494630760.997,,1.000000e+001,3.667893e+001,3.666759e+001,2,0,5.617021e+000,0.000000e+000,-6.375220e-001,-6.679637e-001,-5.947419e-001,-4.875604e-001,1.888001e-001,2.620219e-001,3.692034e-001,-2.449729e-005,-2.609269e-005,,,,,,,,,,,,,,,,,,,,
1494630927.817,,1.000000e+001,3.865852e+001,3.864779e+001,1,0,4.212766e+000,0.000000e+000,2.195926e+000,,,,,,,1.094291e-004,,,,,,,,,,,,,,,,,,,,,
1494630927.817,,1.000000e+001,3.865314e+001,3.864779e+001,2,0,2.808511e+000,0.000000e+000,-3.177539e+000,-3.333868e+000,-3.261961e+000,-3.211132e+000,-3.354472e+000,-3.282565e+000,-3.231736e+000,-1.452469e-004,-1.525483e-004,,,,,,,,,,,,,,,,,,,,
1494631097.067,,1.000000e+001,4.063807e+001,4.063218e+001,1,0,1.404255e+000,0.000000e+000,1.233082e+000,,,,,,,6.219349e-005,,,,,,,,,,,,,,,,,,,,,
1494631097.067,,1.000000e+001,4.063610e+001,4.062826e+001,2,0,0.000000e+000,0.000000e+000,1.184100e-001,1.182574e-001,1.589259e-001,1.589259e-001,3.413335e-001,3.820020e-001,3.820020e-001,1.071309e-005,1.071094e-005,,,,,,,,,,,,,,,,,,,,
1494631097.067,,1.000000e+001,4.063610e+001,4.062826e+001,2,0,4.723404e+000,0.000000e+000,1.499199e+000,1.506447e+000,1.451957e+000,1.547115e+000,1.141304e+000,1.086814e+000,1.181973e+000,7.132270e-005,7.154664e-005,,,,,,,,,,,,,,,,,,,,
1494631268.767,,1.000000e+001,4.262002e+001,4.261146e+001,1,0,3.319149e+000,0.000000e+000,-1.111772e+000,,,,,,,-6.916163e-005,,,,,,,,,,,,,,,,,,,,,
1494631268.767,,1.000000e+001,4.261573e+001,4.261146e+001,2,0,1.914894e+000,0.000000e+000,-9.185932e-002,-8.728161e-002,-4.592006e-001,-4.230603e-001,-4.088871e-001,-7.808062e-001,-7.446659e-001,-1.935336e-005,-1.897647e-005,,,,,,,,,,,,,,,,,,,,
1494631434.098,,1.000000e+001,4.461147e+001,4.460213e+001,1,0,5.106383e-001,0.000000e+000,5.035477e-003,,,,,,,2.103858e-005,,,,,,,,,,,,,,,,,,,,,
1494631434.098,,1.000000e+001,4.461147e+001,4.460213e+001,1,0,5.234043e+000,0.000000e+000,-6.393530e-001,,,,,,,-1.467050e-005,,,,,,,,,,,,,,,,,,,,,
1494631434.098,,1.000000e+001,4.460213e+001,4.459279e+001,2,0,3.829787e+000,0.000000e+000,1.481498e+000,1.474251e+000,1.782278e+000,1.855826e+000,2.869197e-001,5.949473e-001,6.684949e-001,8.761125e-005,8.736090e-005,,,,,,,,,,,,,,,,,,,,
1494631589.678,,1.000000e+001,4.659557e+001,4.658136e+001,1,0,2.425532e+000,0.000000e+000,-2.698406e+000,,,,,,,-1.175689e-004,,,,,,,,,,,,,,,,,,,,,
1494631589.678,,1.000000e+001,4.657933e+001,4.658034e+001,2,0,1.021277e+000,0.000000e+000,7.515068e-001,7.483025e-001,9.431121e-001,9.630735e-001,1.234580e+000,1.429390e+000,1.449351e+000,4.778936e-005,4.784353e-005,,,,,,,,,,,,,,,,,,,,
1494631589.678,,1.000000e+001,4.657933e+001,4.658034e+001,2,0,5.744681e+000,0.000000e+000,-6.404212e-001,-6.395056e-001,-5.370175e-001,-4.247346e-001,1.027006e-001,2.051888e-001,3.174717e-001,-2.365446e-005,-2.337014e-005,,,,,,,,,,,,,,,,,,,,
1494631758.438,,1.000000e+001,4.857381e+001,4.857161e+001,1,0,4.340425e+000,0.000000e+000,1.585260e+000,,,,,,,1.005427e-004,,,,,,,,,,,,,,,,,,,,,
1494631758.438,,1.000000e+001,4.855403e+001,4.857161e+001,2,0,2.936170e+000,0.000000e+000,-3.643549e+000,-3.619440e+000,-3.102368e+000,-3.052983e+000,-3.343397e+000,-2.826325e+000,-2.776940e+000,-1.456422e-004,-1.451219e-004,,,,,,,,,,,,,,,,,,,,
1494631911.468,,1.000000e+001,5.058203e+001,5.056664e+001,1,0,1.531915e+000,0.000000e+000,8.581674e-001,,,,,,,5.635382e-005,,,,,,,,,,,,,,,,,,,,,
1494631911.468,,1.000000e+001,5.057137e+001,5.057375e+001,2,0,1.276596e-001,0.000000e+000,-1.231403e-001,-1.085679e-001,1.914060e-001,1.936843e-001,1.545099e-001,4.544839e-001,4.567621e-001,1.198643e-005,1.221060e-005,,,,,,,,,,,,,,,,,,,,
1494631911.468,,1.000000e+001,5.057137e+001,5.057375e+001,2,0,4.851064e+000,0.000000e+000,7.034409e-001,6.900893e-001,9.057676e-001,9.923415e-001,6.519578e-001,8.676361e-001,9.542100e-001,4.632775e-005,4.535008e-005,,,,,,,,,,,,,,,,,,,,
1494632065.638,,1.000000e+001,5.257621e+001,5.254696e+001,1,0,3.446809e+000,0.000000e+000,-6.803998e-001,,,,,,,-1.924994e-005,,,,,,,,,,,,,,,,,,,,,
1494632065.638,,1.000000e+001,5.254950e+001,5.253297e+001,2,0,2.042553e+000,0.000000e+000,-1.434348e+000,-1.421683e+000,-1.174853e+000,-1.139808e+000,-1.479295e+000,-1.232465e+000,-1.197419e+000,-5.406670e-005,-5.327237e-005,,,,,,,,,,,,,,,,,,,,
1494632220.639,,1.000000e+001,5.455142e+001,5.452824e+001,1,0,6.382979e-001,0.000000e+000,-1.908904e-001,,,,,,,2.516376e-005,,,,,,,,,,,,,,,,,,,,,
1494632220.639,,1.000000e+001,5.455142e+001,5.452824e+001,1,0,5.361702e+000,0.000000e+000,-1.078355e+000,,,,,,,-2.148736e-005,,,,,,,,,,,,,,,,,,,,,
1494632220.639,,1.000000e+001,5.452689e+001,5.450037e+001,2,0,3.957447e+000,0.000000e+000,1.276417e+000,1.302815e+000,1.910640e+000,1.973555e+000,2.831106e-001,8.909356e-001,9.538506e-001,9.200111e-005,9.322412e-005,,,,,,,,,,,,,,,,,,,,
1494632386.689,,1.000000e+001,5.650804e+001,5.650074e+001,1,0,2.553191e+000,0.000000e+000,-2.742809e+000,,,,,,,-1.140446e-004,,,,,,,,,,,,,,,,,,,,,
1494632386.689,,1.000000e+001,5.650220e+001,5.649783e+001,2,0,1.148936e+000,0.000000e+000,6.976425e-001,7.055773e-001,1.025622e+000,1.040659e+000,9.614982e-001,1.281543e+000,1.296580e+000,5.162604e-005,5.166422e-005,,,,,,,,,,,,,,,,,,,,
1494632386.689,,1.000000e+001,5.650220e+001,5.649783e+001,2,0,5.872340e+000,0.000000e+000,-6.788739e-001,-6.681926e-001,-4.099704e-001,-3.331105e-001,-1.043323e-001,1.538898e-001,2.307498e-001,-1.810370e-005,-1.783617e-005,,,,,,,,,,,,,,,,,,,,
1494632553.809,,1.000000e+001,5.851385e+001,5.848889e+001,1,0,4.468085e+000,0.000000e+000,1.351644e+000,,,,,,,8.648630e-005,,,,,,,,,,,,,,,,,,,,,
1494632553.809,,1.000000e+001,5.848421e+001,5.848733e+001,2,0,3.063830e+000,0.000000e+000,-2.957656e+000,-2.993210e+000,-2.550514e+000,-2.505911e+000,-2.607041e+000,-2.164345e+000,-2.119742e+000,-1.174380e-004,-1.191379e-004,,,,,,,,,,,,,,,,,,,,
1494632719.849,,1.000000e+001,6.049636e+001,6.045811e+001,1,0,1.659575e+000,0.000000e+000,3.619440e-001,,,,,,,3.410780e-005,,,,,,,,,,,,,,,,,,,,,
1494632719.849,,1.000000e+001,6.047639e+001,6.045312e+001,2,0,2.553191e-001,0.000000e+000,-1.284810e-001,-1.274128e-001,1.927373e-001,1.970682e-001,1.602627e-001,4.804129e-001,4.847438e-001,1.119156e-005,1.168105e-005,,,,,,,,,,,,,,,,,,,,
1494632719.849,,1.000000e+001,6.047639e+001,6.045312e+001,2,0,4.978724e+000,0.000000e+000,1.550317e-001,1.566339e-001,3.966634e-001,4.811149e-001,3.837904e-001,6.238200e-001,7.082714e-001,2.044896e-005,2.087998e-005,,,,,,,,,,,,,,,,,,,,
1494632880.320,,1.000000e+001,6.248164e+001,6.246925e+001,1,0,3.574468e+000,0.000000e+000,-7.858396e-002,,,,,,,1.595914e-005,,,,,,,,,,,,,,,,,,,,,
1494632880.320,,1.000000e+001,6.245863e+001,6.243566e+001,2,0,2.170213e+000,0.000000e+000,-1.751888e+000,-1.722972e+000,-1.340186e+000,-1.311129e+000,-1.824300e+000,-1.441514e+000,-1.412456e+000,-6.333960e-005,-6.158740e-005,,,,,,,,,,,,,,,,,,,,
1494633057.470,,1.000000e+001,6.446778e+001,6.440591e+001,1,0,7.659575e-001,0.000000e+000,4.654002e-002,,,,,,,2.408760e-005,,,,,,,,,,,,,,,,,,,,,
1494633057.470,,1.000000e+001,6.446778e+001,6.440591e+001,1,0,5.489362e+000,0.000000e+000,-7.785153e-001,,,,,,,-1.871759e-005,,,,,,,,,,,,,,,,,,,,,
1494633057.470,,1.000000e+001,6.443403e+001,6.443214e+001,2,0,4.085106e+000,0.000000e+000,1.204852e+000,1.210880e+000,1.575974e+000,1.632340e+000,5.451519e-001,9.102464e-001,9.666119e-001,7.639446e-005,7.686431e-005,,,,,,,,,,,,,,,,,,,,
1494633215.370,,1.000000e+001,6.646644e+001,6.642870e+001,1,0,2.680851e+000,0.000000e+000,-2.347753e+000,,,,,,,-9.092089e-005,,,,,,,,,,,,,,,,,,,,,
1494633215.370,,1.000000e+001,6.643268e+001,6.640886e+001,2,0,1.276596e+000,0.000000e+000,3.993286e-001,4.134432e-001,8.277974e-001,8.417294e-001,4.545605e-001,8.689147e-001,8.828466e-001,4.073440e-005,4.141773e-005,,,,,,,,,,,,,,,,,,,,
1494633215.370,,1.000000e+001,6.643268e+001,6.640886e+001,2,0,6.000000e+000,0.000000e+000,-6.288243e-001,-6.145571e-001,-2.517513e-001,-1.862710e-001,-2.674512e-001,9.535465e-002,1.608349e-001,-1.147279e-005,-1.064500e-005,,,,,,,,,,,,,,,,,,,,
1494633381.160,,1.000000e+001,6.844394e+001,6.840407e+001,1,0,4.595745e+000,0.000000e+000,9.088274e-001,,,,,,,5.074378e-005,,,,,,,,,,,,,,,,,,,,,
1494633381.160,,1.000000e+001,6.840197e+001,6.837889e+001,2,0,3.191489e+000,0.000000e+000,-1.508507e+000,-1.548257e+000,-1.408381e+000,-1.382411e+000,-1.290554e+000,-1.150678e+000,-1.124708e+000,-6.371410e-005,-6.557608e-005,,,,,,,,,,,,,,,,,,,,
1494633542.210,,1.000000e+001,7.041808e+001,7.039374e+001,1,0,1.787234e+000,0.000000e+000,-5.949492e-001,,,,,,,9.247990e-006,,,,,,,,,,,,,,,,,,,,,
1494633542.210,,1.000000e+001,7.039595e+001,7.038710e+001,2,0,3.829787e-001,0.000000e+000,-6.584268e-001,-6.414130e-001,1.298442e-001,1.326886e-001,-4.505742e-001,3.206829e-001,3.235274e-001,6.845730e-006,7.636241e-006,,,,,,,,,,,,,,,,,,,,
1494633542.210,,1.000000e+001,7.039595e+001,7.038710e+001,2,0,5.106383e+000,0.000000e+000,-7.168689e-001,-7.129778e-001,2.319811e-002,6.112379e-002,-4.540614e-001,2.821146e-001,3.200403e-001,1.778149e-006,2.109437e-006,,,,,,,,,,,,,,,,,,,,
1494633735.751,,1.000000e+001,7.235091e+001,7.231604e+001,1,0,3.702128e+000,0.000000e+000,2.738994e-001,,,,,,,1.783005e-005,,,,,,,,,,,,,,,,,,,,,
1494633735.751,,1.000000e+001,7.232765e+001,7.232068e+001,2,0,2.297872e+000,0.000000e+000,-8.281071e-001,-8.372625e-001,-7.467278e-001,-7.368164e-001,-8.490327e-001,-7.584980e-001,-7.485866e-001,-3.416767e-005,-3.463421e-005,,,,,,,,,,,,,,,,,,,,
1494633916.071,,1.000000e+001,7.434641e+001,7.433176e+001,1,0,8.936170e-001,0.000000e+000,-1.103227e-001,,,,,,,8.052781e-006,,,,,,,,,,,,,,,,,,,,,
1494633916.071,,1.000000e+001,7.434641e+001,7.433176e+001,1,0,5.617021e+000,0.000000e+000,-5.221637e-001,,,,,,,-2.395655e-006,,,,,,,,,,,,,,,,,,,,,
1494633916.071,,1.000000e+001,7.432687e+001,7.430244e+001,2,0,4.212766e+000,0.000000e+000,2.192722e-001,2.298009e-001,6.376477e-001,6.571268e-001,5.966057e-002,4.675075e-001,4.869865e-001,1.518291e-005,1.556519e-005,,,,,,,,,,,,,,,,,,,,
1494634085.121,,1.000000e+001,7.637587e+001,7.634250e+001,1,0,2.808511e+000,0.000000e+000,-2.135958e+000,,,,,,,-7.430532e-006,,,,,,,,,,,,,,,,,,,,,
1494634085.121,,1.000000e+001,7.633736e+001,7.630659e+001,2,0,1.404255e+000,0.000000e+000,-1.634852e+000,-1.621729e+000,1.951016e-001,1.939884e-001,-1.710495e+000,1.063357e-001,1.052226e-001,4.581081e-006,4.847647e-006,,,,,,,,,,,,,,,,,,,,
1494634249.791,,1.000000e+001,7.834763e+001,7.829651e+001,1,0,0.000000e+000,0.000000e+000,-2.635233e-001,,,,,,,-2.807719e-007,,,,,,,,,,,,,,,,,,,,,
1494634249.791,,1.000000e+001,7.834763e+001,7.829651e+001,1,0,4.723404e+000,0.000000e+000,-2.357519e-001,,,,,,,3.225705e-007,,,,,,,,,,,,,,,,,,,,,
1494634249.791,,1.000000e+001,7.830458e+001,7.831533e+001,2,0,3.319149e+000,0.000000e+000,-2.426185e-001,-2.495613e-001,-5.721338e-003,3.928393e-003,-2.484472e-001,-4.607208e-003,5.042523e-003,-9.189444e-008,-1.230842e-007,,,,,,,,,,,,,,,,,,,,
1494634409.832,,1.000000e+001,8.035751e+001,8.029277e+001,1,0,1.914894e+000,0.000000e+000,-1.162585e+000,,,,,,,-5.346810e-007,,,,,,,,,,,,,,,,,,,,,
1494634409.832,,1.000000e+001,8.029277e+001,8.030402e+001,2,0,5.106383e-001,0.000000e+000,-1.145342e+000,-1.155642e+000,-9.468718e-003,-7.194042e-003,-1.144895e+000,1.278357e-003,3.553033e-003,-1.548506e-007,-3.548666e-007,,,,,,,,,,,,,,,,,,,,
1494634409.832,,1.000000e+001,8.029277e+001,8.030402e+001,2,0,5.234043e+000,0.000000e+000,-1.125505e+000,-1.130617e+000,-5.484575e-003,1.783085e-002,-1.121334e+000,3.798133e-003,2.711356e-002,2.434172e-008,-6.077244e-009,,,,,,,,,,,,,,,,,,,,
1494634578.312,,1.000000e+001,8.232703e+001,8.227113e+001,1,0,3.829787e+000,0.000000e+000,-9.542992e-001,,,,,,,2.692286e-007,,,,,,,,,,,,,,,,,,,,,
1494634578.312,,1.000000e+001,8.227997e+001,8.225057e+001,2,0,2.425532e+000,0.000000e+000,-9.697109e-001,-9.468986e-001,2.457931e-002,3.508133e-002,-9.737427e-001,-2.264717e-003,8.237302e-003,-9.633368e-009,5.571837e-007,,,,,,,,,,,,,,,,,,,,
1494634750.582,,1.000000e+001,8.429970e+001,8.424750e+001,1,0,1.021277e+000,0.000000e+000,-1.091936e+000,,,,,,,3.251153e-007,,,,,,,,,,,,,,,,,,,,,
1494634750.582,,1.000000e+001,8.429970e+001,8.424750e+001,1,0,5.744681e+000,0.000000e+000,-1.107042e+000,,,,,,,-3.582390e-007,,,,,,,,,,,,,,,,,,,,,
1494634750.582,,1.000000e+001,8.424136e+001,8.423830e+001,2,0,4.340425e+000,0.000000e+000,-1.115435e+000,-1.095521e+000,-2.995091e-003,1.462662e-002,-1.100972e+000,-8.445339e-003,9.176373e-003,-4.681533e-007,9.073119e-009,,,,,,,,,,,,,,,,,,,,
1494634918.632,,1.000000e+001,8.629900e+001,8.625414e+001,1,0,2.936170e+000,0.000000e+000,9.079118e-002,,,,,,,-6.781243e-007,,,,,,,,,,,,,,,,,,,,,
1494634918.632,,1.000000e+001,8.624453e+001,8.626055e+001,2,0,1.531915e+000,0.000000e+000,9.002823e-002,9.727626e-002,-1.373613e-002,-1.007336e-002,1.116700e-001,6.575788e-004,4.320346e-003,-4.527101e-007,-3.759601e-007,,,,,,,,,,,,,,,,,,,,
1494635087.043,,1.000000e+001,8.827144e+001,8.823585e+001,1,0,1.276596e-001,0.000000e+000,-2.673381e-001,,,,,,,-3.211935e-007,,,,,,,,,,,,,,,,,,,,,
1494635087.043,,1.000000e+001,8.827144e+001,8.823585e+001,1,0,4.851064e+000,0.000000e+000,-2.244602e-001,,,,,,,6.428254e-007,,,,,,,,,,,,,,,,,,,,,
1494635087.043,,1.000000e+001,8.823251e+001,8.817246e+001,2,0,3.446809e+000,0.000000e+000,-2.722209e-001,-2.717632e-001,-2.095302e-002,-1.099017e-002,-2.551650e-001,-4.354798e-003,5.608052e-003,-5.060392e-007,-4.807648e-007,,,,,,,,,,,,,,,,,,,,
1494635263.553,,1.000000e+001,9.024385e+001,9.020554e+001,1,0,2.042553e+000,0.000000e+000,-9.645228e-001,,,,,,,3.998030e-007,,,,,,,,,,,,,,,,,,,,,
1494635263.553,,1.000000e+001,9.020206e+001,9.018118e+001,2,0,6.382979e-001,0.000000e+000,-9.764248e-001,-9.913787e-001,-8.332253e-003,-7.246733e-003,-9.813532e-001,1.693189e-003,2.778709e-003,7.405470e-008,-2.430679e-007,,,,,,,,,,,,,,,,,,,,
1494635263.553,,1.000000e+001,9.020206e+001,9.018118e+001,2,0,5.361702e+000,0.000000e+000,-9.411765e-001,-9.617761e-001,1.323743e-002,2.235579e-002,-9.733204e-001,1.693203e-003,1.081157e-002,8.407187e-007,3.660280e-007,,,,,,,,,,,,,,,,,,,,
1494635425.493,,1.000000e+001,9.225424e+001,9.222882e+001,1,0,3.957447e+000,0.000000e+000,-9.291219e-001,,,,,,,-3.841706e-008,,,,,,,,,,,,,,,,,,,,,
1494635425.493,,1.000000e+001,9.220703e+001,9.216351e+001,2,0,2.553191e+000,0.000000e+000,-9.541466e-001,-9.550622e-001,-2.596790e-002,-2.124023e-002,-9.378852e-001,-8.790917e-003,-4.063249e-003,-5.991533e-007,-6.233695e-007,,,,,,,,,,,,,,,,,,,,
1494635604.203,,1.000000e+001,9.423771e+001,9.418855e+001,1,0,1.148936e+000,0.000000e+000,-3.799497e-001,,,,,,,1.783883e-007,,,,,,,,,,,,,,,,,,,,,
1494635604.203,,1.000000e+001,9.423771e+001,9.418855e+001,1,0,5.872340e+000,0.000000e+000,-3.718624e-001,,,,,,,3.060632e-008,,,,,,,,,,,,,,,,,,,,,
1494635604.203,,1.000000e+001,9.418855e+001,9.416211e+001,2,0,4.468085e+000,0.000000e+000,-3.770505e-001,-3.827726e-001,-1.045850e-002,3.971040e-003,-3.697593e-001,2.554771e-003,1.698431e-002,-1.163744e-007,-1.902690e-007,,,,,,,,,,,,,,,,,,,,
1494635781.894,,1.000000e+001,9.619737e+001,9.614626e+001,1,0,3.063830e+000,0.000000e+000,6.269932e-001,,,,,,,7.290146e-007,,,,,,,,,,,,,,,,,,,,,
1494635781.894,,1.000000e+001,9.614626e+001,9.617377e+001,2,0,1.659575e+000,0.000000e+000,6.001374e-001,5.990692e-001,1.681539e-003,9.636343e-003,6.019691e-001,4.581424e-003,1.253623e-002,-1.923308e-007,-3.366586e-008,,,,,,,,,,,,,,,,,,,,
1494635958.434,,1.000000e+001,9.817458e+001,9.812962e+001,1,0,2.553191e-001,0.000000e+000,-7.168689e-001,,,,,,,3.338537e-007,,,,,,,,,,,,,,,,,,,,,
1494635958.434,,1.000000e+001,9.817458e+001,9.812962e+001,1,0,4.978724e+000,0.000000e+000,-7.063401e-001,,,,,,,3.769528e-007,,,,,,,,,,,,,,,,,,,,,
1494635958.434,,1.000000e+001,9.812553e+001,9.809286e+001,2,0,3.574468e+000,0.000000e+000,-6.916915e-001,-7.127489e-001,4.890156e-004,8.467078e-003,-7.142473e-001,-1.009326e-003,6.968737e-003,2.704855e-007,2.764591e-008,,,,,,,,,,,,,,,,,,,,
1494636127.084,,1.000000e+001,1.001680e+002,1.001001e+002,1,0,2.170213e+000,0.000000e+000,-5.076677e-001,,,,,,,1.023800e-006,,,,,,,,,,,,,,,,,,,,,
1494636127.084,,1.000000e+001,1.001171e+002,1.000747e+002,2,0,7.659575e-001,0.000000e+000,-5.355917e-001,-5.397879e-001,1.553908e-002,1.864535e-002,-5.532224e-001,2.104610e-003,5.210876e-003,3.041350e-007,2.648421e-007,,,,,,,,,,,,,,,,,,,,
1494636127.084,,1.000000e+001,1.001171e+002,1.000747e+002,2,0,5.489362e+000,0.000000e+000,-5.384909e-001,-5.477989e-001,-1.162721e-002,1.063436e-002,-5.325634e-001,3.608271e-003,2.586985e-002,1.385706e-008,-1.479693e-007,,,,,,,,,,,,,,,,,,,,
1494636359.514,,1.000000e+001,9.998997e+001,9.994766e+001,1,0,4.085106e+000,0.000000e+000,-6.425574e-001,,,,,,,-1.893986e-007,,,,,,,,,,,,,,,,,,,,,
1494636359.514,,1.000000e+001,1.000027e+002,9.995611e+001,2,0,2.680851e+000,0.000000e+000,-6.332494e-001,-6.400397e-001,-4.807288e-003,1.520634e-003,-6.416585e-001,-6.426091e-003,-9.816885e-005,-9.833457e-009,-1.205181e-007,,,,,,,,,,,,,,,,,,,,
1494636582.525,,1.000000e+001,9.786882e+001,9.783224e+001,1,0,1.276596e+000,0.000000e+000,-1.499199e+000,,,,,,,3.236128e-007,,,,,,,,,,,,,,,,,,,,,
1494636582.525,,1.000000e+001,9.786882e+001,9.783224e+001,1,0,6.000000e+000,0.000000e+000,-1.491112e+000,,,,,,,3.866626e-007,,,,,,,,,,,,,,,,,,,,,
1494636582.525,,1.000000e+001,9.783224e+001,9.795425e+001,2,0,4.595745e+000,0.000000e+000,-1.495537e+000,-1.505379e+000,-3.065294e-003,4.608512e-003,-1.498570e+000,3.743106e-003,1.141691e-002,7.174458e-008,-3.851710e-008,,,,,,,,,,,,,,,,,,,,
1494636773.645,,1.000000e+001,9.584847e+001,9.589146e+001,1,0,3.191489e+000,0.000000e+000,-9.430075e-001,,,,,,,-2.204761e-007,,,,,,,,,,,,,,,,,,,,,
1494636773.645,,1.000000e+001,9.582504e+001,9.591495e+001,2,0,1.787234e+000,0.000000e+000,-8.285649e-001,-8.918135e-001,4.226736e-002,5.016768e-002,-9.336210e-001,4.598891e-004,8.360207e-003,2.277950e-006,9.430642e-007,,,,,,,,,,,,,,,,,,,,
1494636964.265,,1.000000e+001,9.384206e+001,9.379331e+001,1,0,3.829787e-001,0.000000e+000,-1.695430e+000,,,,,,,1.590524e-007,,,,,,,,,,,,,,,,,,,,,
1494636964.265,,1.000000e+001,9.384206e+001,9.379331e+001,1,0,5.106383e+000,0.000000e+000,-1.705806e+000,,,,,,,-1.832450e-007,,,,,,,,,,,,,,,,,,,,,
1494636964.265,,1.000000e+001,9.382706e+001,9.390591e+001,2,0,3.702128e+000,0.000000e+000,-1.688106e+000,-1.685588e+000,8.414781e-003,1.928651e-002,-1.694129e+000,-1.263268e-004,1.074541e-002,6.367918e-008,2.250017e-007,,,,,,,,,,,,,,,,,,,,
1494637148.996,,1.000000e+001,9.186703e+001,9.181660e+001,1,0,2.297872e+000,0.000000e+000,-1.629664e-001,,,,,,,1.152262e-007,,,,,,,,,,,,,,,,,,,,,
1494637148.996,,1.000000e+001,9.181300e+001,9.191031e+001,2,0,8.936170e-001,0.000000e+000,-1.618982e-001,-1.713588e-001,3.085678e-003,6.167233e-003,-1.771252e-001,-2.680743e-003,4.008114e-004,2.861680e-007,7.994004e-009,,,,,,,,,,,,,,,,,,,,
1494637148.996,,1.000000e+001,9.181300e+001,9.191031e+001,2,0,5.617021e+000,0.000000e+000,-1.586938e-001,-1.621271e-001,-3.970824e-003,1.539895e-002,-1.581357e-001,2.063077e-005,1.939040e-002,4.690037e-008,3.391960e-009,,,,,,,,,,,,,,,,,,,,
1494637356.546,,1.000000e+001,9.001096e+001,8.995898e+001,1,0,4.212766e+000,0.000000e+000,-6.924544e-001,,,,,,,-9.257037e-007,,,,,,,,,,,,,,,,,,,,,
1494637356.546,,1.000000e+001,8.998669e+001,9.003870e+001,2,0,2.808511e+000,0.000000e+000,-6.700237e-001,-6.543069e-001,9.777971e-003,1.492542e-002,-6.664109e-001,-2.326064e-003,2.821386e-003,6.762275e-008,2.295028e-007,,,,,,,,,,,,,,,,,,,,
1494637556.546,,1.000000e+001,8.800604e+001,8.797947e+001,1,0,1.404255e+000,0.000000e+000,-1.146258e+000,,,,,,,-6.209739e-007,,,,,,,,,,,,,,,,,,,,,
1494637556.546,,1.000000e+001,8.796286e+001,8.802599e+001,2,0,0.000000e+000,0.000000e+000,-1.075914e+000,-1.083848e+000,4.491425e-002,4.491425e-002,-1.127806e+000,9.567738e-004,9.567738e-004,9.532378e-007,8.681218e-007,,,,,,,,,,,,,,,,,,,,
1494637556.546,,1.000000e+001,8.796286e+001,8.802599e+001,2,0,4.723404e+000,0.000000e+000,-1.106279e+000,-1.092470e+000,9.116871e-003,3.629291e-002,-1.094054e+000,7.532341e-003,3.470838e-002,-4.964750e-008,3.426212e-007,,,,,,,,,,,,,,,,,,,,
1494637752.076,,1.000000e+001,8.597629e+001,8.598902e+001,1,0,3.319149e+000,0.000000e+000,-5.065995e-001,,,,,,,-1.080069e-006,,,,,,,,,,,,,,,,,,,,,
1494637752.076,,1.000000e+001,8.594762e+001,8.603683e+001,2,0,1.914894e+000,0.000000e+000,-4.592966e-001,-4.600595e-001,5.253837e-003,1.255783e-002,-4.597993e-001,5.514101e-003,1.281810e-002,1.149183e-007,7.979179e-008,,,,,,,,,,,,,,,,,,,,
1494637961.797,,1.000000e+001,8.410043e+001,8.406374e+001,1,0,5.106383e-001,0.000000e+000,-8.493171e-001,,,,,,,4.153480e-008,,,,,,,,,,,,,,,,,,,,,
1494637961.797,,1.000000e+001,8.410043e+001,8.406374e+001,1,0,5.234043e+000,0.000000e+000,-8.258182e-001,,,,,,,4.229005e-007,,,,,,,,,,,,,,,,,,,,,
1494637961.797,,1.000000e+001,8.411574e+001,8.416777e+001,2,0,3.829787e+000,0.000000e+000,-8.505380e-001,-8.619059e-001,-1.696842e-002,-4.767835e-003,-8.461528e-001,-1.215329e-003,1.098526e-002,-8.576535e-008,-3.698206e-007,,,,,,,,,,,,,,,,,,,,
1494638158.907,,1.000000e+001,8.207755e+001,8.205121e+001,1,0,2.425532e+000,0.000000e+000,1.000992e-001,,,,,,,-8.535608e-008,,,,,,,,,,,,,,,,,,,,,
1494638158.907,,1.000000e+001,8.201903e+001,8.213025e+001,2,0,1.021277e+000,0.000000e+000,9.582666e-002,9.239338e-002,-8.256080e-003,-3.971055e-003,1.030453e-001,2.395873e-003,6.680898e-003,-3.409891e-007,-2.931197e-007,,,,,,,,,,,,,,,,,,,,
1494638158.907,,1.000000e+001,8.201903e+001,8.213025e+001,2,0,5.744681e+000,0.000000e+000,1.130694e-001,1.258869e-001,5.419236e-003,2.952250e-002,1.227859e-001,2.318252e-003,2.642152e-002,-3.513833e-008,2.748440e-007,,,,,,,,,,,,,,,,,,,,
1494638356.977,,1.000000e+001,8.012151e+001,8.011311e+001,1,0,4.340425e+000,0.000000e+000,-1.007858e+000,,,,,,,8.065763e-008,,,,,,,,,,,,,,,,,,,,,
1494638356.977,,1.000000e+001,8.013832e+001,8.021688e+001,2,0,2.936170e+000,0.000000e+000,-9.634547e-001,-9.922179e-001,1.686976e-002,2.927113e-002,-1.009418e+000,-3.301105e-004,1.207125e-002,9.360592e-007,3.985078e-007,,,,,,,,,,,,,,,,,,,,
1494638551.007,,1.000000e+001,7.813295e+001,7.810352e+001,1,0,1.531915e+000,0.000000e+000,-9.985504e-001,,,,,,,1.187647e-006,,,,,,,,,,,,,,,,,,,,,
1494638551.007,,1.000000e+001,7.815974e+001,7.821069e+001,2,0,1.276596e-001,0.000000e+000,-1.076066e+000,-1.052567e+000,-7.349508e-003,-7.483482e-003,-1.036423e+000,8.794886e-003,8.660913e-003,-6.426126e-007,-9.715222e-008,,,,,,,,,,,,,,,,,,,,
1494638551.007,,1.000000e+001,7.815974e+001,7.821069e+001,2,0,4.851064e+000,0.000000e+000,-1.045396e+000,-1.039368e+000,1.080662e-002,5.715609e-003,-1.035526e+000,1.464885e-002,9.557843e-003,1.026419e-007,2.462148e-007,,,,,,,,,,,,,,,,,,,,
1494638751.618,,1.000000e+001,7.619136e+001,7.618370e+001,1,0,3.446809e+000,0.000000e+000,-4.678416e-001,,,,,,,1.550507e-008,,,,,,,,,,,,,,,,,,,,,
1494638751.618,,1.000000e+001,7.616837e+001,7.629120e+001,2,0,2.042553e+000,0.000000e+000,-5.740444e-001,-6.095979e-001,-1.510589e-001,-1.528138e-001,-5.724697e-001,-1.139306e-001,-1.156856e-001,-2.683144e-006,-3.451537e-006,,,,,,,,,,,,,,,,,,,,
1494638946.768,,1.000000e+001,7.421707e+001,7.420490e+001,1,0,6.382979e-001,0.000000e+000,-4.510567e-001,,,,,,,2.655470e-006,,,,,,,,,,,,,,,,,,,,,
1494638946.768,,1.000000e+001,7.421707e+001,7.420490e+001,1,0,5.361702e+000,0.000000e+000,-5.256733e-001,,,,,,,7.489343e-007,,,,,,,,,,,,,,,,,,,,,
1494638946.768,,1.000000e+001,7.423659e+001,7.426584e+001,2,0,3.957447e+000,0.000000e+000,-3.897154e-001,-3.723201e-001,1.798991e-001,1.818350e-001,-4.215607e-001,1.306586e-001,1.325944e-001,4.008241e-006,4.430329e-006,,,,,,,,,,,,,,,,,,,,
1494639141.128,,1.000000e+001,7.224408e+001,7.225336e+001,1,0,2.553191e+000,0.000000e+000,-3.710994e-001,,,,,,,-1.278109e-005,,,,,,,,,,,,,,,,,,,,,
1494639141.128,,1.000000e+001,7.221162e+001,7.228352e+001,2,0,1.148936e+000,0.000000e+000,4.567025e-001,4.457161e-001,2.643154e-001,2.636485e-001,4.140361e-001,2.326354e-001,2.319685e-001,6.790982e-006,6.620678e-006,,,,,,,,,,,,,,,,,,,,
1494639141.128,,1.000000e+001,7.221162e+001,7.228352e+001,2,0,5.872340e+000,0.000000e+000,2.136263e-001,1.969177e-001,1.825871e-002,1.485012e-002,2.062827e-001,2.762378e-002,2.421519e-002,7.364929e-007,4.827700e-007,,,,,,,,,,,,,,,,,,,,
1494639340.989,,1.000000e+001,7.030095e+001,7.027008e+001,1,0,4.468085e+000,0.000000e+000,-4.663157e-001,,,,,,,5.035046e-006,,,,,,,,,,,,,,,,,,,,,
1494639340.989,,1.000000e+001,7.030537e+001,7.034952e+001,2,0,3.063830e+000,0.000000e+000,-1.081254e+000,-1.091020e+000,-4.265822e-001,-4.230847e-001,-1.098693e+000,-4.342554e-001,-4.307579e-001,-9.817198e-006,-9.914635e-006,,,,,,,,,,,,,,,,,,,,
1494639529.759,,1.000000e+001,6.833072e+001,6.829306e+001,1,0,1.659575e+000,0.000000e+000,-4.890516e-001,,,,,,,6.140968e-006,,,,,,,,,,,,,,,,,,,,,
1494639529.759,,1.000000e+001,6.829096e+001,6.836004e+001,2,0,2.553191e-001,0.000000e+000,-7.069505e-001,-7.151141e-001,1.867690e-002,1.880282e-002,-6.226067e-001,1.111843e-001,1.113102e-001,1.050383e-006,8.474599e-007,,,,,,,,,,,,,,,,,,,,
1494639529.759,,1.000000e+001,6.829096e+001,6.836004e+001,2,0,4.978724e+000,0.000000e+000,-7.405204e-001,-6.988633e-001,3.259820e-002,3.505361e-002,-5.986168e-001,1.328447e-001,1.353001e-001,-1.223962e-007,9.138876e-007,,,,,,,,,,,,,,,,,,,,
1494639723.999,,1.000000e+001,6.634543e+001,6.630782e+001,1,0,3.574468e+000,0.000000e+000,6.472877e-001,,,,,,,7.804847e-007,,,,,,,,,,,,,,,,,,,,,
1494639723.999,,1.000000e+001,6.632365e+001,6.635336e+001,2,0,2.170213e+000,0.000000e+000,1.474022e-001,1.614405e-001,-4.692861e-001,-4.674871e-001,2.530232e-001,-3.777033e-001,-3.759044e-001,-1.137267e-005,-1.086433e-005,,,,,,,,,,,,,,,,,,,,
1494639921.719,,1.000000e+001,6.440779e+001,6.438345e+001,1,0,7.659575e-001,0.000000e+000,3.326467e-002,,,,,,,4.342774e-006,,,,,,,,,,,,,,,,,,,,,
1494639921.719,,1.000000e+001,6.440779e+001,6.438345e+001,1,0,5.489362e+000,0.000000e+000,-7.339589e-002,,,,,,,1.430747e-006,,,,,,,,,,,,,,,,,,,,,
1494639921.719,,1.000000e+001,6.438345e+001,6.440218e+001,2,0,4.085106e+000,0.000000e+000,1.255818e-001,1.439689e-001,2.665698e-001,2.668386e-001,1.312714e-001,2.538723e-001,2.541411e-001,5.928192e-006,6.541004e-006,,,,,,,,,,,,,,,,,,,,
1494640117.430,,1.000000e+001,6.241799e+001,6.242506e+001,1,0,2.680851e+000,0.000000e+000,-9.166095e-001,,,,,,,-1.519671e-005,,,,,,,,,,,,,,,,,,,,,
1494640117.430,,1.000000e+001,6.239680e+001,6.241976e+001,2,0,1.276596e+000,0.000000e+000,1.216144e-001,1.176471e-001,3.877144e-001,3.898467e-001,-2.190507e-002,2.481623e-001,2.502946e-001,9.684637e-006,9.582643e-006,,,,,,,,,,,,,,,,,,,,
1494640117.430,,1.000000e+001,6.239680e+001,6.241976e+001,2,0,6.000000e+000,0.000000e+000,-2.288853e-001,-2.326238e-001,2.955409e-002,3.957585e-002,-2.351506e-001,2.702730e-002,3.704906e-002,1.017992e-006,8.293027e-007,,,,,,,,,,,,,,,,,,,,
1494640327.890,,1.000000e+001,6.047639e+001,6.044979e+001,1,0,4.595745e+000,0.000000e+000,-1.109026e+000,,,,,,,5.000860e-006,,,,,,,,,,,,,,,,,,,,,
1494640327.890,,1.000000e+001,6.044979e+001,6.048472e+001,2,0,3.191489e+000,0.000000e+000,-1.651484e+000,-1.648356e+000,-3.371362e-001,-3.347806e-001,-1.694656e+000,-3.834368e-001,-3.810812e-001,-7.860795e-006,-7.762408e-006,,,,,,,,,,,,,,,,,,,,
1494640519.500,,1.000000e+001,5.848109e+001,5.845459e+001,1,0,1.787234e+000,0.000000e+000,-4.164187e-001,,,,,,,2.378263e-006,,,,,,,,,,,,,,,,,,,,,
1494640519.500,,1.000000e+001,5.849045e+001,5.847486e+001,2,0,3.829787e-001,0.000000e+000,-4.914931e-001,-4.792859e-001,2.222207e-002,2.272469e-002,-3.476996e-001,1.538084e-001,1.543110e-001,6.178325e-007,9.499718e-007,,,,,,,,,,,,,,,,,,,,
1494640519.500,,1.000000e+001,5.849045e+001,5.847486e+001,2,0,5.106383e+000,0.000000e+000,-4.333562e-001,-4.390784e-001,5.623059e-002,6.293219e-002,-3.772535e-001,1.180555e-001,1.247571e-001,1.558301e-006,1.500654e-006,,,,,,,,,,,,,,,,,,,,
1494640708.381,,1.000000e+001,5.650512e+001,5.649345e+001,1,0,3.702128e+000,0.000000e+000,-8.676280e-001,,,,,,,3.017183e-006,,,,,,,,,,,,,,,,,,,,,
1494640708.381,,1.000000e+001,5.647887e+001,5.650657e+001,2,0,2.297872e+000,0.000000e+000,-1.607691e+000,-1.588235e+000,-6.075729e-001,-6.080498e-001,-1.494865e+000,-5.142027e-001,-5.146796e-001,-1.473489e-005,-1.413423e-005,,,,,,,,,,,,,,,,,,,,
1494640895.361,,1.000000e+001,5.453643e+001,5.454188e+001,1,0,8.936170e-001,0.000000e+000,-2.444495e-001,,,,,,,6.657681e-006,,,,,,,,,,,,,,,,,,,,,
1494640895.361,,1.000000e+001,5.453643e+001,5.454188e+001,1,0,5.617021e+000,0.000000e+000,-4.374762e-001,,,,,,,1.844171e-006,,,,,,,,,,,,,,,,,,,,,
1494640895.361,,1.000000e+001,5.452280e+001,5.449965e+001,2,0,4.212766e+000,0.000000e+000,-1.957732e-001,-2.139315e-001,2.947264e-001,2.935557e-001,-2.090389e-001,2.996190e-001,2.984483e-001,7.620592e-006,7.209516e-006,,,,,,,,,,,,,,,,,,,,
1494641083.731,,1.000000e+001,5.255077e+001,5.253679e+001,1,0,2.808511e+000,0.000000e+000,-2.112917e+000,,,,,,,-1.586200e-005,,,,,,,,,,,,,,,,,,,,,
1494641083.731,,1.000000e+001,5.255205e+001,5.255331e+001,2,0,1.404255e+000,0.000000e+000,-9.640650e-001,-9.678798e-001,4.601755e-001,4.614877e-001,-1.223927e+000,2.041282e-001,2.054404e-001,1.126930e-005,1.134414e-005,,,,,,,,,,,,,,,,,,,,
1494641276.431,,1.000000e+001,5.056664e+001,5.054533e+001,1,0,0.000000e+000,0.000000e+000,-1.068132e-003,,,,,,,6.158548e-007,,,,,,,,,,,,,,,,,,,,,
1494641276.431,,1.000000e+001,5.056664e+001,5.054533e+001,1,0,4.723404e+000,0.000000e+000,1.278706e-001,,,,,,,3.391374e-006,,,,,,,,,,,,,,,,,,,,,
1494641276.431,,1.000000e+001,5.054533e+001,5.055007e+001,2,0,3.319149e+000,0.000000e+000,-2.432288e-001,-2.391089e-001,-2.296604e-001,-2.290605e-001,-2.742536e-001,-2.648051e-001,-2.642053e-001,-5.249135e-006,-5.204223e-006,,,,,,,,,,,,,,,,,,,,
1494641469.882,,1.000000e+001,4.858370e+001,4.857600e+001,1,0,1.914894e+000,0.000000e+000,2.258335e-001,,,,,,,-4.114175e-006,,,,,,,,,,,,,,,,,,,,,
1494641469.882,,1.000000e+001,4.856831e+001,4.858480e+001,2,0,5.106383e-001,0.000000e+000,4.750134e-001,4.966049e-001,9.017910e-002,9.203425e-002,6.008870e-001,1.944612e-001,1.963164e-001,1.997878e-006,2.510320e-006,,,,,,,,,,,,,,,,,,,,
1494641469.882,,1.000000e+001,4.856831e+001,4.858480e+001,2,0,5.234043e+000,0.000000e+000,4.525826e-001,4.656290e-001,4.204310e-002,6.105840e-002,5.202577e-001,9.667177e-002,1.156871e-001,9.506875e-007,1.218507e-006,,,,,,,,,,,,,,,,,,,,
1494641653.342,,1.000000e+001,4.658745e+001,4.657324e+001,1,0,3.829787e+000,0.000000e+000,-1.101854e+000,,,,,,,5.403865e-006,,,,,,,,,,,,,,,,,,,,,
1494641653.342,,1.000000e+001,4.658034e+001,4.657628e+001,2,0,2.425532e+000,0.000000e+000,-2.000000e+000,-2.009689e+000,-6.928411e-001,-6.851780e-001,-1.948150e+000,-6.313018e-001,-6.236387e-001,-1.611008e-005,-1.618276e-005,,,,,,,,,,,,,,,,,,,,
1494641826.492,,1.000000e+001,4.461848e+001,4.460820e+001,1,0,1.021277e+000,0.000000e+000,-4.538033e-001,,,,,,,7.495648e-006,,,,,,,,,,,,,,,,,,,,,
1494641826.492,,1.000000e+001,4.461848e+001,4.460820e+001,1,0,5.744681e+000,0.000000e+000,-6.868086e-001,,,,,,,1.438877e-006,,,,,,,,,,,,,,,,,,,,,
1494641826.492,,1.000000e+001,4.460820e+001,4.460446e+001,2,0,4.340425e+000,0.000000e+000,-4.635691e-001,-4.521248e-001,2.878669e-001,3.061797e-001,-4.249474e-001,3.150443e-001,3.333571e-001,6.779779e-006,7.114738e-006,,,,,,,,,,,,,,,,,,,,
1494642010.922,,1.000000e+001,4.262302e+001,4.261016e+001,1,0,2.936170e+000,0.000000e+000,-1.520256e+000,,,,,,,-1.334255e-005,,,,,,,,,,,,,,,,,,,,,
1494642010.922,,1.000000e+001,4.261016e+001,4.261959e+001,2,0,1.531915e+000,0.000000e+000,-5.285725e-001,-5.624475e-001,3.899360e-001,3.920943e-001,-8.302322e-001,1.221513e-001,1.243097e-001,1.053898e-005,9.661222e-006,,,,,,,,,,,,,,,,,,,,
1494642192.343,,1.000000e+001,4.063806e+001,4.062238e+001,1,0,1.276596e-001,0.000000e+000,-1.269551e-001,,,,,,,1.034760e-006,,,,,,,,,,,,,,,,,,,,,
1494642192.343,,1.000000e+001,4.063806e+001,4.062238e+001,1,0,4.851064e+000,0.000000e+000,-8.636606e-002,,,,,,,1.535901e-006,,,,,,,,,,,,,,,,,,,,,
1494642192.343,,1.000000e+001,4.063493e+001,4.062003e+001,2,0,3.446809e+000,0.000000e+000,-1.647974e-001,-1.976806e-001,-5.498131e-002,-5.122501e-002,-3.072289e-001,-1.645296e-001,-1.607733e-001,-3.196546e-007,-1.039094e-006,,,,,,,,,,,,,,,,,,,,
1494642382.733,,1.000000e+001,3.865136e+001,3.864600e+001,1,0,2.042553e+000,0.000000e+000,2.740520e-001,,,,,,,-8.275647e-006,,,,,,,,,,,,,,,,,,,,,
1494642382.733,,1.000000e+001,3.864600e+001,3.864243e+001,2,0,6.382979e-001,0.000000e+000,7.487602e-001,7.632563e-001,1.200073e-001,1.184993e-001,8.787236e-001,2.354746e-001,2.339666e-001,3.002400e-006,3.391834e-006,,,,,,,,,,,,,,,,,,,,
1494642382.733,,1.000000e+001,3.864600e+001,3.864243e+001,2,0,5.361702e+000,0.000000e+000,6.868086e-001,6.968795e-001,6.478931e-002,5.212253e-002,7.126860e-001,8.059581e-002,6.792903e-002,1.311186e-006,1.592401e-006,,,,,,,,,,,,,,,,,,,,
1494642577.303,,1.000000e+001,3.666598e+001,3.666435e+001,1,0,3.957447e+000,0.000000e+000,-1.145953e-001,,,,,,,5.931273e-006,,,,,,,,,,,,,,,,,,,,,
1494642577.303,,1.000000e+001,3.666435e+001,3.666112e+001,2,0,2.553191e+000,0.000000e+000,-1.141680e+000,-1.096284e+000,-7.413025e-001,-7.387901e-001,-1.064622e+000,-7.096399e-001,-7.071275e-001,-1.837170e-005,-1.732115e-005,,,,,,,,,,,,,,,,,,,,
1494642761.123,,1.000000e+001,3.469387e+001,3.468368e+001,1,0,1.148936e+000,0.000000e+000,8.925002e-001,,,,,,,9.277591e-006,,,,,,,,,,,,,,,,,,,,,
1494642761.123,,1.000000e+001,3.469387e+001,3.468368e+001,1,0,5.872340e+000,0.000000e+000,5.856413e-001,,,,,,,1.438009e-006,,,,,,,,,,,,,,,,,,,,,
1494642761.123,,1.000000e+001,3.468659e+001,3.468659e+001,2,0,4.468085e+000,0.000000e+000,7.853819e-001,7.798123e-001,2.487590e-001,2.583456e-001,8.311014e-001,3.000481e-001,3.096346e-001,6.205709e-006,6.146213e-006,,,,,,,,,,,,,,,,,,,,
1494642956.474,,1.000000e+001,3.269657e+001,3.269527e+001,1,0,3.063830e+000,0.000000e+000,-6.573587e-001,,,,,,,-1.129212e-005,,,,,,,,,,,,,,,,,,,,,
1494642956.474,,1.000000e+001,3.270047e+001,3.270047e+001,2,0,1.659575e+000,0.000000e+000,1.142901e-001,8.735790e-002,2.562653e-001,2.589908e-001,-1.425561e-001,2.635128e-002,2.907677e-002,7.028133e-006,6.477189e-006,,,,,,,,,,,,,,,,,,,,
1494643132.384,,1.000000e+001,3.072050e+001,3.071009e+001,1,0,2.553191e-001,0.000000e+000,-1.135119e+000,,,,,,,4.580979e-007,,,,,,,,,,,,,,,,,,,,,
1494643132.384,,1.000000e+001,3.072050e+001,3.071009e+001,1,0,4.978724e+000,0.000000e+000,-1.065537e+000,,,,,,,1.722980e-006,,,,,,,,,,,,,,,,,,,,,
1494643132.384,,1.000000e+001,3.072166e+001,3.071935e+001,2,0,3.574468e+000,0.000000e+000,-1.096818e+000,-1.092851e+000,3.883649e-002,3.999054e-002,-1.180001e+000,-4.831301e-002,-4.715896e-002,1.079326e-006,1.181468e-006,,,,,,,,,,,,,,,,,,,,
1494643301.424,,1.000000e+001,2.874182e+001,2.874080e+001,1,0,2.170213e+000,0.000000e+000,-1.897612e+000,,,,,,,-1.363099e-005,,,,,,,,,,,,,,,,,,,,,
1494643301.424,,1.000000e+001,2.873672e+001,2.873978e+001,2,0,7.659575e-001,0.000000e+000,-1.121080e+000,-1.112306e+000,1.977242e-001,1.985350e-001,-1.027713e+000,2.823180e-001,2.831287e-001,4.940044e-006,5.159456e-006,,,,,,,,,,,,,,,,,,,,
1494643301.424,,1.000000e+001,2.873672e+001,2.873978e+001,2,0,5.489362e+000,0.000000e+000,-1.235370e+000,-1.226368e+000,7.866325e-002,8.447373e-002,-1.239865e+000,6.516590e-002,7.097638e-002,1.704266e-006,2.007782e-006,,,,,,,,,,,,,,,,,,,,
1494643502.934,,1.000000e+001,2.676326e+001,2.676147e+001,1,0,4.085106e+000,0.000000e+000,8.392462e-002,,,,,,,6.359463e-006,,,,,,,,,,,,,,,,,,,,,
1494643502.934,,1.000000e+001,2.676059e+001,2.676059e+001,2,0,2.680851e+000,0.000000e+000,-8.599985e-001,-8.753338e-001,-7.021593e-001,-7.008897e-001,-9.031457e-001,-7.299712e-001,-7.287016e-001,-1.605382e-005,-1.639464e-005,,,,,,,,,,,,,,,,,,,,
1494643707.575,,1.000000e+001,2.475639e+001,2.476793e+001,1,0,1.276596e+000,0.000000e+000,8.546578e-001,,,,,,,1.069021e-005,,,,,,,,,,,,,,,,,,,,,
1494643707.575,,1.000000e+001,2.475639e+001,2.476793e+001,1,0,6.000000e+000,0.000000e+000,5.217060e-001,,,,,,,2.305298e-006,,,,,,,,,,,,,,,,,,,,,
1494643707.575,,1.000000e+001,2.477101e+001,2.478873e+001,2,0,4.595745e+000,0.000000e+000,6.573587e-001,6.522470e-001,2.186107e-001,2.281635e-001,7.010592e-001,2.674230e-001,2.769758e-001,5.413973e-006,5.420792e-006,,,,,,,,,,,,,,,,,,,,
1494643924.355,,1.000000e+001,2.280160e+001,2.280488e+001,1,0,3.191489e+000,0.000000e+000,-1.501030e+000,,,,,,,-8.106348e-006,,,,,,,,,,,,,,,,,,,,,
1494643924.355,,1.000000e+001,2.280094e+001,2.280817e+001,2,0,1.787234e+000,0.000000e+000,-1.115587e+000,-1.090639e+000,5.843802e-002,6.035185e-002,-1.232540e+000,-8.346359e-002,-8.154976e-002,1.205826e-006,1.766935e-006,,,,,,,,,,,,,,,,,,,,
1494644122.945,,1.000000e+001,2.082714e+001,2.082549e+001,1,0,3.829787e-001,0.000000e+000,-9.259174e-001,,,,,,,2.266490e-006,,,,,,,,,,,,,,,,,,,,,
1494644122.945,,1.000000e+001,2.082714e+001,2.082549e+001,1,0,5.106383e+000,0.000000e+000,-9.976348e-001,,,,,,,8.614734e-008,,,,,,,,,,,,,,,,,,,,,
1494644122.945,,1.000000e+001,2.082659e+001,2.083209e+001,2,0,3.702128e+000,0.000000e+000,-8.184940e-001,-8.498513e-001,1.508513e-001,1.550781e-001,-9.403965e-001,6.030602e-002,6.453276e-002,4.690191e-006,3.844287e-006,,,,,,,,,,,,,,,,,,,,
1494644282.906,,1.000000e+001,1.887518e+001,1.885569e+001,1,0,2.297872e+000,0.000000e+000,-1.324331e+000,,,,,,,-1.544063e-005,,,,,,,,,,,,,,,,,,,,,
1494644282.906,,1.000000e+001,1.885433e+001,1.885297e+001,2,0,8.936170e-001,0.000000e+000,-4.467842e-001,-4.399939e-001,2.245409e-001,2.263172e-001,-3.612471e-001,3.032877e-001,3.050640e-001,5.633328e-006,5.750124e-006,,,,,,,,,,,,,,,,,,,,
1494644282.906,,1.000000e+001,1.885433e+001,1.885297e+001,2,0,5.617021e+000,0.000000e+000,-5.694667e-001,-5.928893e-001,6.225623e-002,7.342184e-002,-6.022633e-001,5.288221e-002,6.404781e-002,2.089135e-006,1.640808e-006,,,,,,,,,,,,,,,,,,,,
1494644441.556,,1.000000e+001,1.688583e+001,1.687562e+001,1,0,4.212766e+000,0.000000e+000,-8.316167e-002,,,,,,,6.664940e-006,,,,,,,,,,,,,,,,,,,,,
1494644441.556,,1.000000e+001,1.687489e+001,1.687416e+001,2,0,2.808511e+000,0.000000e+000,-1.048447e+000,-1.023651e+000,-6.728871e-001,-6.714662e-001,-1.052311e+000,-7.015467e-001,-7.001258e-001,-1.635888e-005,-1.570136e-005,,,,,,,,,,,,,,,,,,,,
1494644593.056,,1.000000e+001,1.490014e+001,1.489675e+001,1,0,1.404255e+000,0.000000e+000,-5.401694e-002,,,,,,,1.164044e-005,,,,,,,,,,,,,,,,,,,,,
1494644593.056,,1.000000e+001,1.489279e+001,1.489760e+001,2,0,0.000000e+000,0.000000e+000,-5.357442e-001,-5.299459e-001,1.255393e-003,1.255393e-003,-4.445276e-001,8.667362e-002,8.667362e-002,4.852791e-007,5.167940e-007,,,,,,,,,,,,,,,,,,,,
1494644593.056,,1.000000e+001,1.489279e+001,1.489760e+001,2,0,4.723404e+000,0.000000e+000,-3.727779e-001,-3.938354e-001,1.327873e-001,1.373659e-001,-2.981836e-001,2.284390e-001,2.330176e-001,3.881683e-006,3.347939e-006,,,,,,,,,,,,,,,,,,,,
1494644747.316,,1.000000e+001,1.292959e+001,1.292538e+001,1,0,3.319149e+000,0.000000e+000,-8.070497e-001,,,,,,,-5.663205e-006,,,,,,,,,,,,,,,,,,,,,
1494644747.316,,1.000000e+001,1.292587e+001,1.292205e+001,2,0,1.914894e+000,0.000000e+000,-7.374685e-001,-7.312887e-001,-1.744003e-001,-1.708684e-001,-7.548169e-001,-1.979286e-001,-1.943967e-001,-4.013609e-006,-3.789008e-006,,,,,,,,,,,,,,,,,,,,
1494644906.536,,1.000000e+001,1.093336e+001,1.092940e+001,1,0,5.106383e-001,0.000000e+000,-1.411917e+000,,,,,,,1.788125e-006,,,,,,,,,,,,,,,,,,,,,
1494644906.536,,1.000000e+001,1.093336e+001,1.092940e+001,1,0,5.234043e+000,0.000000e+000,-1.405509e+000,,,,,,,1.422286e-006,,,,,,,,,,,,,,,,,,,,,
1494644906.536,,1.000000e+001,1.092889e+001,1.093508e+001,2,0,3.829787e+000,0.000000e+000,-1.203784e+000,-1.207141e+000,2.519676e-001,2.534784e-001,-1.314100e+000,1.450085e-001,1.465193e-001,6.250302e-006,6.234515e-006,,,,,,,,,,,,,,,,,,,,
1494645062.647,,1.000000e+001,8.961132e+000,8.958349e+000,1,0,2.425532e+000,0.000000e+000,-1.153582e+000,,,,,,,-1.665700e-005,,,,,,,,,,,,,,,,,,,,,
1494645062.647,,1.000000e+001,8.958349e+000,8.960734e+000,2,0,1.021277e+000,0.000000e+000,-1.846342e-001,-1.713588e-001,2.676218e-001,2.698391e-001,-1.175976e-001,3.213830e-001,3.236004e-001,6.398428e-006,6.774060e-006,,,,,,,,,,,,,,,,,,,,
1494645062.647,,1.000000e+001,8.958349e+000,8.960734e+000,2,0,5.744681e+000,0.000000e+000,-3.715572e-001,-3.852140e-001,4.351131e-002,5.598393e-002,-3.849997e-001,4.372558e-002,5.619821e-002,1.335822e-006,1.194586e-006,,,,,,,,,,,,,,,,,,,,
1494645208.507,,1.000000e+001,6.989668e+000,6.998157e+000,1,0,4.340425e+000,0.000000e+000,3.299001e-001,,,,,,,6.945641e-006,,,,,,,,,,,,,,,,,,,,,
1494645208.507,,1.000000e+001,6.998157e+000,7.003643e+000,2,0,2.936170e+000,0.000000e+000,-5.726711e-001,-5.796139e-001,-6.259556e-001,-6.152182e-001,-5.903341e-001,-6.366758e-001,-6.259384e-001,-1.447373e-005,-1.459580e-005,,,,,,,,,,,,,,,,,,,,
1494645365.637,,1.000000e+001,5.000946e+000,4.996440e+000,1,0,1.531915e+000,0.000000e+000,-1.061723e+000,,,,,,,9.516090e-006,,,,,,,,,,,,,,,,,,,,,
1494645365.637,,1.000000e+001,4.998739e+000,4.990417e+000,2,0,1.276596e-001,0.000000e+000,-1.434196e+000,-1.445945e+000,2.447684e-003,2.741575e-003,-1.338928e+000,1.094644e-001,1.097583e-001,7.554881e-007,5.007805e-007,,,,,,,,,,,,,,,,,,,,
1494645365.637,,1.000000e+001,4.998739e+000,4.990417e+000,2,0,4.851064e+000,0.000000e+000,-1.373617e+000,-1.382162e+000,5.535639e-002,6.652427e-002,-1.246228e+000,1.912907e-001,2.024586e-001,1.738121e-006,1.526554e-006,,,,,,,,,,,,,,,,,,,,
1494645365.637,,1.000000e+001,4.998739e+000,4.990417e+000,2,0,6.000000e+000,0.000000e+000,-1.389181e+000,-1.377279e+000,5.759430e-002,7.140720e-002,-1.405223e+000,2.965021e-002,4.346311e-002,1.255845e-006,1.522973e-006,,,,,,,,,,,,,,,,,,,,