File: Data/YT Group/RVC64e (5 nm Ta)/20170512-RVC64e.dc.dat
[Header]
TITLE,MPMS DC Measurement
BYAPP,MPMS Measurement,2.1,Summary
FILEOPENTIME, 1494628369.423000 5/12/2017, 3:32:49 PM

INFO, APPNAME, MPMS MultiVu Application, Revision 1.61,  Build 082

INFO, NAME, RVC64E
INFO, WEIGHT, 1.000
INFO, AREA, 1.000
INFO, LENGTH, 1.000
INFO, SHAPE, film on substrate
INFO, COMMENT, H in plane
INFO, SEQUENCE FILE: 20170509-RVC64b.seq


INFO, BACKGROUND DATA FILE:, None


STARTUPAXIS,X,4,LINEAR,AUTO,0.000000,0.000000
STARTUPAXIS,Y1,5,LINEAR,AUTO,0.000000,0.000000


STARTUPGROUP,Longitudinal
FIELDGROUP,Longitudinal,1,2,3,4,5,6,7,8,9,15,16,17,18,27,28
FIELDGROUP,Transverse,1,2,3,4,10,11,12,13,14,19,20,21,22,27,28

PLOT_APPEARANCE,ALL,HORZ_GRID_ON,VERT_GRID_ON,MARKERS_AND_LINES

[Data]
Time,Comment,Field (Oe),Temperature (K),Long Moment (emu),Long Scan Std Dev,Long Algorithm,Long Reg Fit,Long Percent Error (%),Trans Moment (emu),Trans Scan Std Dev,Trans Algorithm,Trans Reg Fit,Trans Percent Error (%),Long Moment [w/o ABS] (emu),Long Scan Std Dev [w/o ABS],Long Reg Fit [w/o ABS],Long Percent Error [w/o ABS] (%),Trans Moment [w/o ABS] (emu),Trans Scan Std Dev [w/o ABS],Trans Reg Fit [w/o ABS],Trans Percent Error [w/o ABS] (%),Points per Scan,Scans per Measurement,Scan Length (cm),Delta Temp (K),Rot Position (deg),Error,EC Comp. Running,Using ABS,
1494628369.423,,1.000000e+001,4.994936e+000,-1.063990e-004,6.651197e-007,3,7.111678e-001,6.251184e-001,,,,,,,,,,,,,,48,2,6.000000e+000,8.709908e-003,0.000000e+000,0,,0,
1494628521.443,,1.000000e+001,6.980576e+000,-1.054593e-004,2.644571e-007,3,7.109802e-001,2.507671e-001,,,,,,,,,,,,,,48,2,6.000000e+000,2.428102e-002,0.000000e+000,0,,0,
1494628658.904,,1.000000e+001,8.955967e+000,-1.038852e-004,4.019591e-007,3,7.089430e-001,3.869263e-001,,,,,,,,,,,,,,48,2,6.000000e+000,5.959511e-003,0.000000e+000,0,,0,
1494628799.054,,1.000000e+001,1.092996e+001,-1.021890e-004,1.016011e-007,3,7.016025e-001,9.942463e-002,,,,,,,,,,,,,,48,2,6.000000e+000,1.284027e-002,0.000000e+000,0,,0,
1494628946.554,,1.000000e+001,1.291293e+001,-1.025833e-004,4.183558e-007,3,7.017442e-001,4.078207e-001,,,,,,,,,,,,,,48,2,6.000000e+000,1.011944e-002,0.000000e+000,0,,0,
1494629092.374,,1.000000e+001,1.489195e+001,-1.024108e-004,2.832204e-007,3,7.056609e-001,2.765533e-001,,,,,,,,,,,,,,48,2,6.000000e+000,8.480072e-003,0.000000e+000,0,,0,
1494629228.204,,1.000000e+001,1.687071e+001,-1.016365e-004,5.682828e-007,3,7.022718e-001,5.591325e-001,,,,,,,,,,,,,,48,2,6.000000e+000,6.549835e-003,0.000000e+000,0,,0,
1494629363.935,,1.000000e+001,1.884867e+001,-1.014021e-004,6.487178e-007,3,6.964203e-001,6.397478e-001,,,,,,,,,,,,,,48,2,6.000000e+000,4.529953e-003,0.000000e+000,0,,0,
1494629515.095,,1.000000e+001,2.082907e+001,-1.016877e-004,7.922908e-007,3,7.049843e-001,7.791412e-001,,,,,,,,,,,,,,48,2,6.000000e+000,1.541138e-002,0.000000e+000,0,,0,
1494629666.115,,1.000000e+001,2.280603e+001,-1.003796e-004,3.158184e-007,3,7.002416e-001,3.146241e-001,,,,,,,,,,,,,,48,2,6.000000e+000,9.860992e-003,0.000000e+000,0,,0,
1494629816.565,,1.000000e+001,2.478469e+001,-9.967826e-005,7.069578e-008,3,7.026715e-001,7.092398e-002,,,,,,,,,,,,,,48,2,6.000000e+000,1.234055e-002,0.000000e+000,0,,0,
1494629986.166,,1.000000e+001,2.677440e+001,-9.982331e-005,3.920706e-007,3,7.021706e-001,3.927646e-001,,,,,,,,,,,,,,48,2,6.000000e+000,4.461288e-003,0.000000e+000,0,,0,
1494630130.246,,1.000000e+001,2.875126e+001,-9.980809e-005,5.266144e-007,3,7.045219e-001,5.276269e-001,,,,,,,,,,,,,,48,2,6.000000e+000,3.059387e-003,0.000000e+000,0,,0,
1494630289.996,,1.000000e+001,3.072947e+001,-9.858497e-005,2.461310e-008,3,7.009145e-001,2.496638e-002,,,,,,,,,,,,,,48,2,6.000000e+000,1.041985e-002,0.000000e+000,0,,0,
1494630439.996,,1.000000e+001,3.271025e+001,-9.831586e-005,7.848307e-007,3,7.033712e-001,7.982748e-001,,,,,,,,,,,,,,48,2,6.000000e+000,1.042938e-002,0.000000e+000,0,,0,
1494630600.386,,1.000000e+001,3.469242e+001,-9.727634e-005,6.940288e-007,3,6.992880e-001,7.134610e-001,,,,,,,,,,,,,,48,2,6.000000e+000,1.020050e-002,0.000000e+000,0,,0,
1494630760.997,,1.000000e+001,3.667690e+001,-9.633634e-005,3.521721e-007,3,6.999104e-001,3.655652e-001,,,,,,,,,,,,,,48,2,6.000000e+000,1.619720e-002,0.000000e+000,0,,0,
1494630927.817,,1.000000e+001,3.865181e+001,-9.544512e-005,4.746665e-008,3,7.023039e-001,4.973188e-002,,,,,,,,,,,,,,48,2,6.000000e+000,1.073074e-002,0.000000e+000,0,,0,
1494631097.067,,1.000000e+001,4.063365e+001,-9.437335e-005,9.608576e-008,3,6.957780e-001,1.018145e-001,,,,,,,,,,,,,,48,2,6.000000e+000,9.807587e-003,0.000000e+000,0,,0,
1494631268.767,,1.000000e+001,4.261467e+001,-9.453687e-005,2.547847e-007,3,7.012059e-001,2.695083e-001,,,,,,,,,,,,,,48,2,6.000000e+000,8.560181e-003,0.000000e+000,0,,0,
1494631434.098,,1.000000e+001,4.460213e+001,-9.299572e-005,1.981344e-007,3,6.994939e-001,2.130576e-001,,,,,,,,,,,,,,48,2,6.000000e+000,1.868057e-002,0.000000e+000,0,,0,
1494631589.678,,1.000000e+001,4.658415e+001,-9.245750e-005,2.084705e-008,3,6.977608e-001,2.254771e-002,,,,,,,,,,,,,,48,2,6.000000e+000,1.623917e-002,0.000000e+000,0,,0,
1494631758.438,,1.000000e+001,4.856776e+001,-9.048605e-005,3.506235e-007,3,6.985424e-001,3.874890e-001,,,,,,,,,,,,,,48,2,6.000000e+000,1.977921e-002,0.000000e+000,0,,0,
1494631911.468,,1.000000e+001,5.057345e+001,-9.021078e-005,6.004897e-007,3,7.023022e-001,6.656518e-001,,,,,,,,,,,,,,48,2,6.000000e+000,1.539230e-002,0.000000e+000,0,,0,
1494632065.638,,1.000000e+001,5.255141e+001,-8.769811e-005,9.830835e-008,3,6.987144e-001,1.120986e-001,,,,,,,,,,,,,,48,2,6.000000e+000,4.323959e-002,0.000000e+000,0,,0,
1494632220.639,,1.000000e+001,5.452673e+001,-8.609497e-005,5.355870e-007,3,7.003137e-001,6.220887e-001,,,,,,,,,,,,,,48,2,6.000000e+000,5.104828e-002,0.000000e+000,0,,0,
1494632386.689,,1.000000e+001,5.650220e+001,-8.405351e-005,1.283287e-007,3,6.984900e-001,1.526750e-001,,,,,,,,,,,,,,48,2,6.000000e+000,1.021194e-002,0.000000e+000,0,,0,
1494632553.809,,1.000000e+001,5.849357e+001,-8.133405e-005,3.567459e-007,3,7.000160e-001,4.386182e-001,,,,,,,,,,,,,,48,2,6.000000e+000,2.964020e-002,0.000000e+000,0,,0,
1494632719.849,,1.000000e+001,6.047099e+001,-7.798716e-005,8.580166e-007,3,6.970892e-001,1.100202e+000,,,,,,,,,,,,,,48,2,6.000000e+000,4.323959e-002,0.000000e+000,0,,0,
1494632880.320,,1.000000e+001,6.246130e+001,-7.394265e-005,1.476117e-007,3,7.001911e-001,1.996300e-001,,,,,,,,,,,,,,48,2,6.000000e+000,4.597855e-002,0.000000e+000,0,,0,
1494633057.470,,1.000000e+001,6.443497e+001,-6.940849e-005,6.691687e-007,3,7.036120e-001,9.641021e-001,,,,,,,,,,,,,,48,2,6.000000e+000,6.187439e-002,0.000000e+000,0,,0,
1494633215.370,,1.000000e+001,6.643417e+001,-6.252241e-005,1.451422e-007,3,7.082679e-001,2.321443e-001,,,,,,,,,,,,,,48,2,6.000000e+000,5.757904e-002,0.000000e+000,0,,0,
1494633381.160,,1.000000e+001,6.840722e+001,-5.347563e-005,7.887691e-007,3,7.094947e-001,1.475007e+000,,,,,,,,,,,,,,48,2,6.000000e+000,6.504822e-002,0.000000e+000,0,,0,
1494633542.210,,1.000000e+001,7.039872e+001,-4.279884e-005,1.118975e-006,3,7.184676e-001,2.614499e+000,,,,,,,,,,,,,,48,2,6.000000e+000,3.098297e-002,0.000000e+000,0,,0,
1494633735.751,,1.000000e+001,7.232882e+001,-3.042329e-005,8.088599e-007,3,7.293872e-001,2.658686e+000,,,,,,,,,,,,,,48,2,6.000000e+000,3.486633e-002,0.000000e+000,0,,0,
1494633916.071,,1.000000e+001,7.432687e+001,-1.561857e-005,3.930610e-007,3,7.533639e-001,2.516626e+000,,,,,,,,,,,,,,48,2,6.000000e+000,4.397583e-002,0.000000e+000,0,,0,
1494634085.121,,1.000000e+001,7.634058e+001,-4.837568e-006,5.102463e-007,3,7.677926e-001,1.054758e+001,,,,,,,,,,,,,,48,2,6.000000e+000,6.928253e-002,0.000000e+000,0,,0,
1494634249.791,,1.000000e+001,7.831601e+001,-8.041820e-008,2.485015e-008,2,0.000000e+000,3.090115e+001,,,,,,,,,,,,,,48,2,6.000000e+000,5.112457e-002,0.000000e+000,0,,0,
1494634409.832,,1.000000e+001,8.031177e+001,-2.132963e-007,7.639850e-008,3,0.000000e+000,3.581801e+001,,,,,,,,,,,,,,48,2,6.000000e+000,6.474304e-002,0.000000e+000,0,,0,
1494634578.312,,1.000000e+001,8.228217e+001,-9.493635e-008,3.816363e-007,3,0.000000e+000,4.019917e+002,,,,,,,,,,,,,,48,2,6.000000e+000,7.645416e-002,0.000000e+000,0,,0,
1494634750.582,,1.000000e+001,8.425671e+001,3.640989e-008,1.547523e-007,3,0.000000e+000,4.250281e+002,,,,,,,,,,,,,,48,2,6.000000e+000,6.140137e-002,0.000000e+000,0,,0,
1494634918.632,,1.000000e+001,8.626456e+001,1.259656e-007,8.160931e-008,3,0.000000e+000,6.478697e+001,,,,,,,,,,,,,,48,2,6.000000e+000,5.447388e-002,0.000000e+000,0,,0,
1494635087.043,,1.000000e+001,8.822807e+001,-1.174219e-007,3.336787e-008,3,0.000000e+000,2.841708e+001,,,,,,,,,,,,,,48,2,6.000000e+000,9.897614e-002,0.000000e+000,0,,0,
1494635263.553,,1.000000e+001,9.020816e+001,-1.204219e-007,7.147425e-008,2,0.000000e+000,5.935318e+001,,,,,,,,,,,,,,48,2,6.000000e+000,6.266785e-002,0.000000e+000,0,,0,
1494635425.493,,1.000000e+001,9.221340e+001,-1.841443e-007,6.838378e-009,3,0.000000e+000,3.713597e+000,,,,,,,,,,,,,,48,2,6.000000e+000,9.072876e-002,0.000000e+000,0,,0,
1494635604.203,,1.000000e+001,9.419423e+001,-8.822867e-008,1.690253e-007,2,0.000000e+000,1.915764e+002,,,,,,,,,,,,,,48,2,6.000000e+000,7.559967e-002,0.000000e+000,0,,0,
1494635781.894,,1.000000e+001,9.616592e+001,-1.468406e-007,8.573320e-008,3,0.000000e+000,5.838519e+001,,,,,,,,,,,,,,48,2,6.000000e+000,5.110931e-002,0.000000e+000,0,,0,
1494635958.434,,1.000000e+001,9.813065e+001,-9.091534e-008,1.829240e-007,2,0.000000e+000,2.012026e+002,,,,,,,,,,,,,,48,2,6.000000e+000,8.172607e-002,0.000000e+000,0,,0,
1494636127.084,,1.000000e+001,1.001150e+002,-4.853444e-008,3.152080e-007,3,0.000000e+000,6.494523e+002,,,,,,,,,,,,,,48,2,6.000000e+000,9.329987e-002,0.000000e+000,0,,0,
1494636359.514,,1.000000e+001,9.997411e+001,-1.122667e-007,1.264187e-007,2,0.000000e+000,1.126057e+002,,,,,,,,,,,,,,48,2,6.000000e+000,5.503845e-002,0.000000e+000,0,,0,
1494636582.525,,1.000000e+001,9.787189e+001,-1.184698e-007,1.118684e-007,3,0.000000e+000,9.442783e+001,,,,,,,,,,,,,,48,2,6.000000e+000,1.220093e-001,0.000000e+000,0,,0,
1494636773.645,,1.000000e+001,9.586998e+001,-2.624189e-008,6.298843e-008,2,0.000000e+000,2.400301e+002,,,,,,,,,,,,,,48,2,6.000000e+000,8.990479e-002,0.000000e+000,0,,0,
1494636964.265,,1.000000e+001,9.384209e+001,-5.451788e-009,1.784770e-007,2,0.000000e+000,3.273732e+003,,,,,,,,,,,,,,48,2,6.000000e+000,1.125946e-001,0.000000e+000,0,,0,
1494637148.996,,1.000000e+001,9.185173e+001,3.901298e-008,1.886664e-007,3,0.000000e+000,4.835992e+002,,,,,,,,,,,,,,48,2,6.000000e+000,9.730530e-002,0.000000e+000,0,,0,
1494637356.546,,1.000000e+001,8.999883e+001,-3.248909e-008,5.876111e-008,2,0.000000e+000,1.808641e+002,,,,,,,,,,,,,,48,2,6.000000e+000,7.971954e-002,0.000000e+000,0,,0,
1494637556.546,,1.000000e+001,8.799359e+001,-2.445674e-007,1.308432e-007,3,0.000000e+000,5.349987e+001,,,,,,,,,,,,,,48,2,6.000000e+000,6.313324e-002,0.000000e+000,0,,0,
1494637752.076,,1.000000e+001,8.598743e+001,4.228338e-008,2.837164e-007,3,0.000000e+000,6.709879e+002,,,,,,,,,,,,,,48,2,6.000000e+000,8.921051e-002,0.000000e+000,0,,0,
1494637961.797,,1.000000e+001,8.411192e+001,-2.091100e-007,1.965398e-007,3,0.000000e+000,9.398872e+001,,,,,,,,,,,,,,48,2,6.000000e+000,1.040268e-001,0.000000e+000,0,,0,
1494638158.907,,1.000000e+001,8.206950e+001,1.853831e-007,2.040520e-008,3,0.000000e+000,1.100704e+001,,,,,,,,,,,,,,48,2,6.000000e+000,1.112213e-001,0.000000e+000,0,,0,
1494638356.977,,1.000000e+001,8.014745e+001,-2.468100e-009,2.530099e-008,3,0.000000e+000,1.025120e+003,,,,,,,,,,,,,,48,2,6.000000e+000,1.037674e-001,0.000000e+000,0,,0,
1494638551.007,,1.000000e+001,7.815173e+001,-8.138083e-007,5.815448e-007,3,2.018416e-001,7.145969e+001,,,,,,,,,,,,,,48,2,6.000000e+000,1.071701e-001,0.000000e+000,0,,0,
1494638751.618,,1.000000e+001,7.620866e+001,-3.763640e-006,6.130167e-007,3,7.068360e-001,1.628787e+001,,,,,,,,,,,,,,48,2,6.000000e+000,1.228256e-001,0.000000e+000,0,,0,
1494638946.768,,1.000000e+001,7.423109e+001,-6.450414e-006,4.916237e-007,3,7.505565e-001,7.621584e+000,,,,,,,,,,,,,,48,2,6.000000e+000,6.093597e-002,0.000000e+000,0,,0,
1494639141.128,,1.000000e+001,7.224815e+001,-7.664512e-006,3.227955e-007,3,7.724999e-001,4.211560e+000,,,,,,,,,,,,,,48,2,6.000000e+000,7.190704e-002,0.000000e+000,0,,0,
1494639340.989,,1.000000e+001,7.030648e+001,-8.458639e-006,2.348579e-007,3,7.786022e-001,2.776545e+000,,,,,,,,,,,,,,48,2,6.000000e+000,7.943726e-002,0.000000e+000,0,,0,
1494639529.759,,1.000000e+001,6.831870e+001,-8.649899e-006,7.241545e-008,3,7.699143e-001,8.371826e-001,,,,,,,,,,,,,,48,2,6.000000e+000,6.907654e-002,0.000000e+000,0,,0,
1494639723.999,,1.000000e+001,6.633257e+001,-9.120704e-006,7.567152e-008,3,7.619919e-001,8.296676e-001,,,,,,,,,,,,,,48,2,6.000000e+000,4.553986e-002,0.000000e+000,0,,0,
1494639921.719,,1.000000e+001,6.439422e+001,-9.258638e-006,8.328723e-008,3,7.639539e-001,8.995625e-001,,,,,,,,,,,,,,48,2,6.000000e+000,2.433777e-002,0.000000e+000,0,,0,
1494640117.430,,1.000000e+001,6.241490e+001,-9.359288e-006,1.666947e-007,3,7.722173e-001,1.781062e+000,,,,,,,,,,,,,,48,2,6.000000e+000,2.825928e-002,0.000000e+000,0,,0,
1494640327.890,,1.000000e+001,6.046517e+001,-9.556952e-006,1.704871e-007,3,7.693315e-001,1.783907e+000,,,,,,,,,,,,,,48,2,6.000000e+000,3.492737e-002,0.000000e+000,0,,0,
1494640519.500,,1.000000e+001,5.847525e+001,-9.598652e-006,2.273612e-007,3,7.616442e-001,2.368678e+000,,,,,,,,,,,,,,48,2,6.000000e+000,3.586197e-002,0.000000e+000,0,,0,
1494640708.381,,1.000000e+001,5.649600e+001,-9.656707e-006,3.813448e-008,3,7.642787e-001,3.949015e-001,,,,,,,,,,,,,,48,2,6.000000e+000,2.769852e-002,0.000000e+000,0,,0,
1494640895.361,,1.000000e+001,5.452519e+001,-9.837374e-006,2.139112e-007,3,7.715394e-001,2.174475e+000,,,,,,,,,,,,,,48,2,6.000000e+000,4.223251e-002,0.000000e+000,0,,0,
1494641083.731,,1.000000e+001,5.254823e+001,-1.003444e-005,1.118445e-007,3,7.615727e-001,1.114607e+000,,,,,,,,,,,,,,48,2,6.000000e+000,1.652145e-002,0.000000e+000,0,,0,
1494641276.431,,1.000000e+001,5.055184e+001,-9.844987e-006,1.345180e-007,3,7.601787e-001,1.366360e+000,,,,,,,,,,,,,,48,2,6.000000e+000,2.130890e-002,0.000000e+000,0,,0,
1494641469.882,,1.000000e+001,4.857820e+001,-9.866781e-006,4.654379e-008,3,7.602887e-001,4.717222e-001,,,,,,,,,,,,,,48,2,6.000000e+000,1.649094e-002,0.000000e+000,0,,0,
1494641653.342,,1.000000e+001,4.657933e+001,-1.006874e-005,1.292619e-007,3,7.645922e-001,1.283794e+000,,,,,,,,,,,,,,48,2,6.000000e+000,1.420975e-002,0.000000e+000,0,,0,
1494641826.492,,1.000000e+001,4.460984e+001,-1.020754e-005,6.390840e-008,3,7.701915e-001,6.260900e-001,,,,,,,,,,,,,,48,2,6.000000e+000,1.401901e-002,0.000000e+000,0,,0,
1494642010.922,,1.000000e+001,4.261573e+001,-1.012782e-005,4.670650e-008,3,7.638281e-001,4.611703e-001,,,,,,,,,,,,,,48,2,6.000000e+000,1.285934e-002,0.000000e+000,0,,0,
1494642192.343,,1.000000e+001,4.062885e+001,-1.030090e-005,1.495263e-007,3,7.711588e-001,1.451584e+000,,,,,,,,,,,,,,48,2,6.000000e+000,1.803207e-002,0.000000e+000,0,,0,
1494642382.733,,1.000000e+001,3.864645e+001,-1.010718e-005,2.885441e-008,3,7.582742e-001,2.854843e-001,,,,,,,,,,,,,,48,2,6.000000e+000,8.930206e-003,0.000000e+000,0,,0,
1494642577.303,,1.000000e+001,3.666395e+001,-1.025352e-005,1.777215e-007,3,7.685780e-001,1.733273e+000,,,,,,,,,,,,,,48,2,6.000000e+000,4.859924e-003,0.000000e+000,0,,0,
1494642761.123,,1.000000e+001,3.468768e+001,-1.035759e-005,6.776641e-008,3,7.715399e-001,6.542678e-001,,,,,,,,,,,,,,48,2,6.000000e+000,1.018906e-002,0.000000e+000,0,,0,
1494642956.474,,1.000000e+001,3.269820e+001,-1.036347e-005,1.111230e-008,3,7.684333e-001,1.072256e-001,,,,,,,,,,,,,,48,2,6.000000e+000,5.199432e-003,0.000000e+000,0,,0,
1494643132.384,,1.000000e+001,3.071790e+001,-1.030931e-005,3.654819e-007,3,7.654565e-001,3.545162e+000,,,,,,,,,,,,,,48,2,6.000000e+000,1.156998e-002,0.000000e+000,0,,0,
1494643301.424,,1.000000e+001,2.873978e+001,-1.035204e-005,9.477510e-009,3,7.696759e-001,9.155212e-002,,,,,,,,,,,,,,48,2,6.000000e+000,5.100250e-003,0.000000e+000,0,,0,
1494643502.934,,1.000000e+001,2.676148e+001,-1.030279e-005,1.949305e-007,3,7.582770e-001,1.892017e+000,,,,,,,,,,,,,,48,2,6.000000e+000,2.670288e-003,0.000000e+000,0,,0,
1494643707.575,,1.000000e+001,2.477102e+001,-1.034149e-005,4.356747e-008,3,7.671526e-001,4.212882e-001,,,,,,,,,,,,,,48,2,6.000000e+000,3.234100e-002,0.000000e+000,0,,0,
1494643924.355,,1.000000e+001,2.280390e+001,-1.028781e-005,1.152041e-007,3,7.645869e-001,1.119812e+000,,,,,,,,,,,,,,48,2,6.000000e+000,7.230759e-003,0.000000e+000,0,,0,
1494644122.945,,1.000000e+001,2.082783e+001,-1.024705e-005,1.285480e-007,3,7.534549e-001,1.254488e+000,,,,,,,,,,,,,,48,2,6.000000e+000,6.599426e-003,0.000000e+000,0,,0,
1494644282.906,,1.000000e+001,1.885954e+001,-1.017625e-005,1.478362e-007,3,7.575991e-001,1.452757e+000,,,,,,,,,,,,,,48,2,6.000000e+000,2.220917e-002,0.000000e+000,0,,0,
1494644441.556,,1.000000e+001,1.687762e+001,-1.040825e-005,1.670671e-008,3,7.618794e-001,1.605141e-001,,,,,,,,,,,,,,48,2,6.000000e+000,1.166916e-002,0.000000e+000,0,,0,
1494644593.056,,1.000000e+001,1.489682e+001,-1.025536e-005,1.063279e-007,3,7.551081e-001,1.036804e+000,,,,,,,,,,,,,,48,2,6.000000e+000,7.349968e-003,0.000000e+000,0,,0,
1494644747.316,,1.000000e+001,1.292572e+001,-1.048697e-005,2.576491e-008,3,7.637949e-001,2.456851e-001,,,,,,,,,,,,,,48,2,6.000000e+000,7.539749e-003,0.000000e+000,0,,0,
1494644906.536,,1.000000e+001,1.093168e+001,-1.018101e-005,4.622738e-008,3,7.565616e-001,4.540551e-001,,,,,,,,,,,,,,48,2,6.000000e+000,6.189346e-003,0.000000e+000,0,,0,
1494645062.647,,1.000000e+001,8.959641e+000,-1.035996e-005,4.194363e-009,3,7.677114e-001,4.048627e-002,,,,,,,,,,,,,,48,2,6.000000e+000,2.782822e-003,0.000000e+000,0,,0,
1494645208.507,,1.000000e+001,6.997406e+000,-1.048863e-005,1.409420e-007,3,7.623926e-001,1.343760e+000,,,,,,,,,,,,,,48,2,6.000000e+000,1.397514e-002,0.000000e+000,0,,0,
1494645365.637,,1.000000e+001,4.996635e+000,-1.036636e-005,1.487719e-007,3,7.608029e-001,1.435141e+000,,,,,,,,,,,,,,48,2,6.000000e+000,1.052904e-002,0.000000e+000,0,,0,